Workbook

Sheet resumo_cx
A2: Saldo Inicial | B2: 0
A3: Vendas | B3: =SUM('01'!C5,'02'!C5,'03'!C5,'04'!C5,'05'!C5,'06'!C5,'07'!C5,'08'!C5,'09'!C5,'10'!C5,'11'!C5,'12'!C5,'13'!C5,'14'!C5,'15'!C5,'16'!C5,'17'!C5,'18'!C5,'19'!C5,'20'!C5,'21'!C5,'22'!C5,'23'!C5,'24'!C5,'25'!C5,'26'!C5,'27'!C5,'28'!C5,'29'!C5,'31'!C5) -> 42888.99
A4: Entrada | B4: =SUM('01'!C6,'02'!C6,'03'!C6,'04'!C6,'05'!C6,'06'!C6,'07'!C6,'08'!C6,'09'!C6,'10'!C6,'11'!C6,'12'!C6,'13'!C6,'14'!C6,'15'!C6,'16'!C6,'17'!C6,'18'!C6,'19'!C6,'20'!C6,'21'!C6,'22'!C6,'23'!C6,'24'!C6,'25'!C6,'26'!C6,'27'!C6,'28'!C6,'29'!C6,'31'!C6) -> 28582.984
A5: Despesas | B5: =SUM('01'!C7,'02'!C7,'03'!C7,'04'!C7,'05'!C7,'06'!C7,'07'!C7,'08'!C7,'09'!C7,'10'!C7,'11'!C7,'12'!C7,'13'!C7,'14'!C7,'15'!C7,'16'!C7,'17'!C7,'18'!C7,'19'!C7,'20'!C7,'21'!C7,'22'!C7,'23'!C7,'24'!C7,'25'!C7,'26'!C7,'27'!C7,'28'!C7,'29'!C7,'31'!C7,) -> 0
A6: Entr_Desp | B6: =SUM(B4:B5) -> 28582.984
A8: Tipos de Pagtos
A9: DN | B9: =SUM('01'!C11,'02'!C11,'03'!C11,'04'!C11,'05'!C11,'06'!C11,'07'!C11,'08'!C11,'09'!C11,'10'!C11,'11'!C11,'12'!C11,'13'!C11,'14'!C11,'15'!C11,'16'!C11,'17'!C11,'18'!C11,'19'!C11,'20'!C11,'21'!C11,'22'!C11,'23'!C11,'24'!C11,'25'!C11,'26'!C11,'27'!C11,'28'!C11,'29'!C11,'31'!C11) -> 2457
A10: CTD | B10: =SUM('01'!C12,'02'!C12,'03'!C12,'04'!C12,'05'!C12,'06'!C12,'07'!C12,'08'!C12,'09'!C12,'10'!C12,'11'!C12,'12'!C12,'13'!C12,'14'!C12,'15'!C12,'16'!C12,'17'!C12,'18'!C12,'19'!C12,'20'!C12,'21'!C12,'22'!C12,'23'!C12,'24'!C12,'25'!C12,'26'!C12,'27'!C12,'28'!C12,'29'!C12,'31'!C12,) -> 4028.0043
A11: CTC | B11: =SUM('01'!C13,'02'!C13,'03'!C13,'04'!C13,'05'!C13,'06'!C13,'07'!C13,'08'!C13,'09'!C13,'10'!C13,'11'!C13,'12'!C13,'13'!C13,'14'!C13,'15'!C13,'16'!C13,'17'!C13,'18'!C13,'19'!C13,'20'!C13,'21'!C13,'22'!C13,'23'!C13,'24'!C13,'25'!C13,'26'!C13,'27'!C13,'28'!C13,'29'!C13,'31'!C13,) -> 20263.99
A12: CTC | B12: =SUM('01'!#REF!,'02'!#REF!,'03'!#REF!,'04'!#REF!,'05'!#REF!,'06'!#REF!,'07'!#REF!,'08'!#REF!,'09'!#REF!,'10'!#REF!,'11'!#REF!,'12'!#REF!,'13'!#REF!,'14'!#REF!,'15'!#REF!,'16'!#REF!,'17'!#REF!,'18'!#REF!,'19'!#REF!,'20'!#REF!,'21'!#REF!,'22'!#REF!,'23'!#REF!,'24'!#REF!,'25'!#REF!,'26'!#REF!,'27'!#REF!,'28'!#REF!,'29'!#REF!,'31'!#REF!,#REF!) -> #REF!
A13: PIX | B13: =SUM('01'!C14,'02'!C14,'03'!C14,'04'!C14,'05'!C14,'06'!C14,'07'!C14,'08'!C14,'09'!C14,'10'!C14,'11'!C14,'12'!C14,'13'!C14,'14'!C14,'15'!C14,'16'!C14,'17'!C14,'18'!C14,'19'!C14,'20'!C14,'21'!C14,'22'!C14,'23'!C14,'24'!C14,'25'!C14,'26'!C14,'27'!C14,'28'!C14,'29'!C14,'31'!C14,#REF!) -> #REF!
A14: Total | B14: =SUM(B9:B13) -> #REF!
A16: Entrega de Carne
A17: =COUNT(#REF!) -> 0 | B17: =SUM('01'!C18,'02'!C18,'03'!C18,'04'!C18,'05'!C18,'06'!C18,'07'!C18,'08'!C18,'09'!C18,'10'!C18,'11'!C18,'12'!C18,'13'!C18,'14'!C18,'15'!C18,'16'!C18,'17'!C18,'18'!C18,'19'!C18,'20'!C18,'21'!C18,'22'!C18,'23'!C18,'24'!C18,'25'!C18,'26'!C18,'27'!C18,'28'!C18,'29'!C18,'31'!C18,#REF!) -> #REF!
A18: Total | B18: =SUM(B17:B17) -> #REF!

Sheet 01
B1: 45413
B2: Fechamento Diário do Caixa
B4: Saldo Inicial | C4: 0 | E4: Vendas | K4: Despesas
B5: Vendas | C5: =SUMIF(I6:I31,">0",H6:H31) -> 0 | E5: Nº Venda | F5: Cliente | G5: Forma de Pgto | H5: Valor Venda | I5: Entrada | K5: Descrição | L5: Tipo de Pagto | M5: Valor
B6: Entrada | C6: =SUM(I6:I41) -> 0 | R6: =IF(vend1[[#This Row],[Nº Venda]]>1,1,0) -> 0
B7: Despesas | C7: =SUM(M6:M11) -> 0 | R7: =IF(vend1[[#This Row],[Nº Venda]]>1,1,0) -> 0
B8: Total entrada | C8: =SUM(C6:C7) -> 0 | R8: =IF(vend1[[#This Row],[Nº Venda]]>1,1,0) -> 0
R9: =IF(vend1[[#This Row],[Nº Venda]]>1,1,0) -> 0
B10: Tipos de Pagtos | R10: =IF(vend1[[#This Row],[Nº Venda]]>1,1,0) -> 0
B11: DN | C11: =(SUMIF($G$2:$G$31,B11,$I$2:$I$31))+(SUMIF($G$35:$G$41,B11,$H$35:$H$41)) -> 0 | O11: =IF(C15=0,0,1) -> 0 | R11: =IF(vend1[[#This Row],[Nº Venda]]>1,1,0) -> 0
B12: CTD | C12: =(SUMIF($G$2:$G$31,B12,$I$2:$I$31))+(SUMIF($G$35:$G$41,B12,$H$35:$H$41)) -> 0 | R12: =IF(vend1[[#This Row],[Nº Venda]]>1,1,0) -> 0
B13: CTC | C13: =(SUMIF($G$2:$G$31,B13,$I$2:$I$31))+(SUMIF($G$35:$G$41,B13,$H$35:$H$41)) -> 0 | K13: OS Entregue no Dia | R13: =IF(vend1[[#This Row],[Nº Venda]]>1,1,0) -> 0
B14: PIX | C14: =(SUMIF($G$2:$G$31,B14,$I$2:$I$31))+(SUMIF($G$35:$G$41,B14,$H$35:$H$41)) -> 0 | K14: OS | L14: Vendedor | M14: CARNE | R14: =IF(vend1[[#This Row],[Nº Venda]]>1,1,0) -> 0
B15: Total | C15: =SUM(C11:C14) -> 0 | R15: =IF(vend1[[#This Row],[Nº Venda]]>1,1,0) -> 0
R16: =IF(vend1[[#This Row],[Nº Venda]]>1,1,0) -> 0
B17: Entrega de Carne | R17: =IF(vend1[[#This Row],[Nº Venda]]>1,1,0) -> 0
B18: =COUNT(entr_carn1[OS]) -> 0 | C18: =SUM(entr_carn1[Valor Total]) -> 0 | R18: =IF(vend1[[#This Row],[Nº Venda]]>1,1,0) -> 0
B19: Total | C19: =SUM(C18:C18) -> 0 | R19: =IF(vend1[[#This Row],[Nº Venda]]>1,1,0) -> 0
R20: =IF(vend1[[#This Row],[Nº Venda]]>1,1,0) -> 0
B21: Venda | C21: =C5 -> 0
E24: Restante Entrada
E25: Nº Venda | F25: Cliente | G25: Forma de Pgto | H25: Valor Venda | I25: Entrada
E33: Recebimento de Carnê | K33: Entrega de Carne
E34: OS | F34: Cliente | G34: Forma de Pgto | H34: Valor Parcela | I34: Nº Parcela | K34: OS | L34: Parcelas | M34: Valor Total
Q40: Total de OS | R40: =SUM(R6:R21) -> 0

Sheet 02
B1: ='01'!B1+1 -> 45414
B2: Fechamento Diário do Caixa
B4: Saldo Inicial | C4: 0 | E4: Vendas | K4: Despesas
B5: Vendas | C5: =SUMIF(I6:I31,">0",H6:H31) -> 0 | E5: Nº Venda | F5: Cliente | G5: Forma de Pgto | H5: Valor Venda | I5: Entrada | K5: Descrição | L5: Tipo de Pagto | M5: Valor
B6: Entrada | C6: =SUM(I6:I41) -> 0 | E6: 4210 | F6: RENAN NAZARO | G6: GARANTIA | H6: 0 | I6: 0 | R6: =IF(vend2[[#This Row],[Nº Venda]]>1,1,0) -> 1
B7: Despesas | C7: =SUM(M6:M11) -> 0 | R7: =IF(vend2[[#This Row],[Nº Venda]]>1,1,0) -> 0
B8: Total entrada | C8: =SUM(C6:C7) -> 0 | R8: =IF(vend2[[#This Row],[Nº Venda]]>1,1,0) -> 0
R9: =IF(vend2[[#This Row],[Nº Venda]]>1,1,0) -> 0
B10: Tipos de Pagtos | R10: =IF(vend2[[#This Row],[Nº Venda]]>1,1,0) -> 0
B11: DN | C11: =(SUMIF($G$2:$G$31,B11,$I$2:$I$31))+(SUMIF($G$35:$G$41,B11,$H$35:$H$41)) -> 0 | O11: =IF(C15=0,0,1) -> 1 | R11: =IF(vend2[[#This Row],[Nº Venda]]>1,1,0) -> 0
B12: CTD | C12: =(SUMIF($G$2:$G$31,B12,$I$2:$I$31))+(SUMIF($G$35:$G$41,B12,$H$35:$H$41)) -> 0 | R12: =IF(vend2[[#This Row],[Nº Venda]]>1,1,0) -> 0
B13: CTC | C13: =(SUMIF($G$2:$G$31,B13,$I$2:$I$31))+(SUMIF($G$35:$G$41,B13,$H$35:$H$41)) -> 0 | K13: OS Entregue no Dia | R13: =IF(vend2[[#This Row],[Nº Venda]]>1,1,0) -> 0
B14: PIX | C14: =(SUMIF($G$2:$G$31,B14,$I$2:$I$31))+(SUMIF($G$35:$G$41,B14,$H$35:$H$41)) -> 98 | K14: Coluna1 | L14: Vendedor | M14: CARNE | R14: =IF(vend2[[#This Row],[Nº Venda]]>1,1,0) -> 0
B15: Total | C15: =SUM(C11:C14) -> 98 | R15: =IF(vend2[[#This Row],[Nº Venda]]>1,1,0) -> 0
R16: =IF(vend2[[#This Row],[Nº Venda]]>1,1,0) -> 0
B17: Entrega de Carne | R17: =IF(vend2[[#This Row],[Nº Venda]]>1,1,0) -> 0
B18: =COUNT(entr_carn2[OS]) -> 0 | C18: =SUM(entr_carn2[Valor Total]) -> 0 | R18: =IF(vend2[[#This Row],[Nº Venda]]>1,1,0) -> 0
B19: Total | C19: =SUM(C18:C18) -> 0 | R19: =IF(vend2[[#This Row],[Nº Venda]]>1,1,0) -> 0
R20: =IF(vend2[[#This Row],[Nº Venda]]>1,1,0) -> 0
B21: Venda | C21: =C5 -> 0
E24: Restante Entrada
E25: Nº Venda | F25: Cliente | G25: Forma de Pgto | H25: Valor Venda | I25: Entrada
E33: Recebimento de Carnê | K33: Entrega de Carne
E34: OS | F34: Cliente | G34: Forma de Pgto | H34: Valor Parcela | I34: Nº Parcela | K34: OS | L34: Parcelas | M34: Valor Total
E35: 4002 | F35: BRENDHA DE OLIVEIRA | G35: PIX | H35: 98 | I35: PARC. 3/5
Q40: Total de OS | R40: =SUM(R6:R21) -> 1

Sheet 03
B1: ='02'!B1+1 -> 45415
B2: Fechamento Diário do Caixa
B4: Saldo Inicial | C4: 0 | E4: Vendas | K4: Despesas
B5: Vendas | C5: =SUMIF(I6:I31,">0",H6:H31) -> 2535 | E5: Nº Venda | F5: Cliente | G5: Forma de Pgto | H5: Valor Venda | I5: Entrada | K5: Descrição | L5: Tipo de Pagto | M5: Valor
B6: Entrada | C6: =SUM(I6:I41) -> 2325 | E6: 4211 | F6: GUILHERME GRACIANO | G6: DN | H6: 735 | I6: 250 | R6: =IF(vend3[[#This Row],[Nº Venda]]>1,1,0) -> 1
B7: Despesas | C7: =SUM(M6:M11) -> 0 | E7: 4212 | F7: YASMIN FELICIANO | G7: CTC | H7: 350 | I7: 350 | R7: =IF(vend3[[#This Row],[Nº Venda]]>1,1,0) -> 1
B8: Total entrada | C8: =SUM(C6:C7) -> 2325 | E8: 4213 | F8: HERNANE JOSE | G8: CTC | H8: 1300 | I8: 1300 | R8: =IF(vend3[[#This Row],[Nº Venda]]>1,1,0) -> 1
E9: 4214 | F9: HERNANE JOSE | G9: CTC | H9: 150 | I9: 150 | R9: =IF(vend3[[#This Row],[Nº Venda]]>1,1,0) -> 1
B10: Tipos de Pagtos | R10: =IF(vend3[[#This Row],[Nº Venda]]>1,1,0) -> 0
B11: DN | C11: =(SUMIF($G$2:$G$31,B11,$I$2:$I$31))+(SUMIF($G$35:$G$41,B11,$H$35:$H$41)) -> 525 | O11: =IF(C15=0,0,1) -> 1 | R11: =IF(vend3[[#This Row],[Nº Venda]]>1,1,0) -> 0
B12: CTD | C12: =(SUMIF($G$2:$G$31,B12,$I$2:$I$31))+(SUMIF($G$35:$G$41,B12,$H$35:$H$41)) -> 0 | R12: =IF(vend3[[#This Row],[Nº Venda]]>1,1,0) -> 0
B13: CTC | C13: =(SUMIF($G$2:$G$31,B13,$I$2:$I$31))+(SUMIF($G$35:$G$41,B13,$H$35:$H$41)) -> 1800 | K13: OS Entregue no Dia | R13: =IF(vend3[[#This Row],[Nº Venda]]>1,1,0) -> 0
B14: PIX | C14: =(SUMIF($G$2:$G$31,B14,$I$2:$I$31))+(SUMIF($G$35:$G$41,B14,$H$35:$H$41)) -> 0 | K14: OS | L14: Vendedor | M14: CARNE | R14: =IF(vend3[[#This Row],[Nº Venda]]>1,1,0) -> 0
B15: Total | C15: =SUM(C11:C14) -> 2325 | K15: 4196 | L15: BETH | M15: Sim | R15: =IF(vend3[[#This Row],[Nº Venda]]>1,1,0) -> 0
K16: 4197 | L16: BETH | M16: Sim | R16: =IF(vend3[[#This Row],[Nº Venda]]>1,1,0) -> 0
B17: Entrega de Carne | R17: =IF(vend3[[#This Row],[Nº Venda]]>1,1,0) -> 0
B18: =COUNT(entr_carn3[OS]) -> 2 | C18: =SUM(entr_carn3[Valor Total]) -> 1200 | R18: =IF(vend3[[#This Row],[Nº Venda]]>1,1,0) -> 0
B19: Total | C19: =SUM(C18:C18) -> 1200 | R19: =IF(vend3[[#This Row],[Nº Venda]]>1,1,0) -> 0
R20: =IF(vend3[[#This Row],[Nº Venda]]>1,1,0) -> 0
B21: Venda | C21: =C5 -> 2535
E24: Restante Entrada
E25: Nº Venda | F25: Cliente | G25: Forma de Pgto | H25: Valor Venda | I25: Entrada
E26: 4157 | F26: JACINTO FERNANDES | G26: DN | I26: 175
E27: 4196 | F27: WALTER LUIZ | G27: DN | I27: 50
E28: 4197 | F28: WALTER LUIZ | G28: DN | I28: 50
E33: Recebimento de Carnê | K33: Entrega de Carne
E34: OS | F34: Cliente | G34: Forma de Pgto | H34: Valor Parcela | I34: Nº Parcela | K34: OS | L34: Parcelas | M34: Valor Total
K35: 4196 | L35: 6 | M35: 600
K36: 4197 | L36: 6 | M36: 600
Q40: Total de OS | R40: =SUM(R6:R21) -> 4

Sheet 04
B1: ='03'!B1+1 -> 45416
B2: Fechamento Diário do Caixa
B4: Saldo Inicial | C4: 0 | E4: Vendas | K4: Despesas
B5: Vendas | C5: =SUMIF(I6:I31,">0",H6:H31) -> 1949 | E5: Nº Venda | F5: Cliente | G5: Forma de Pgto | H5: Valor Venda | I5: Entrada | K5: Descrição | L5: Tipo de Pagto | M5: Valor
B6: Entrada | C6: =SUM(I6:I41) -> 550 | E6: 4215 | F6: ROSENILDO DE JESUS | G6: DN | H6: 1150 | I6: 150 | R6: =IF(vend4[[#This Row],[Nº Venda]]>1,1,0) -> 1
B7: Despesas | C7: =SUM(M6:M11) -> 0 | E7: 4216 | F7: ANA CAVALCANTI | G7: DN | H7: 799 | I7: 150 | R7: =IF(vend4[[#This Row],[Nº Venda]]>1,1,0) -> 1
B8: Total entrada | C8: =SUM(C6:C7) -> 550 | R8: =IF(vend4[[#This Row],[Nº Venda]]>1,1,0) -> 0
R9: =IF(vend4[[#This Row],[Nº Venda]]>1,1,0) -> 0
B10: Tipos de Pagtos | R10: =IF(vend4[[#This Row],[Nº Venda]]>1,1,0) -> 0
B11: DN | C11: =(SUMIF($G$2:$G$31,B11,$I$2:$I$31))+(SUMIF($G$35:$G$41,B11,$H$35:$H$41)) -> 500 | O11: =IF(C15=0,0,1) -> 1 | R11: =IF(vend4[[#This Row],[Nº Venda]]>1,1,0) -> 0
B12: CTD | C12: =(SUMIF($G$2:$G$31,B12,$I$2:$I$31))+(SUMIF($G$35:$G$41,B12,$H$35:$H$41)) -> 0 | R12: =IF(vend4[[#This Row],[Nº Venda]]>1,1,0) -> 0
B13: CTC | C13: =(SUMIF($G$2:$G$31,B13,$I$2:$I$31))+(SUMIF($G$35:$G$41,B13,$H$35:$H$41)) -> 200 | K13: OS Entregue no Dia | R13: =IF(vend4[[#This Row],[Nº Venda]]>1,1,0) -> 0
B14: PIX | C14: =(SUMIF($G$2:$G$31,B14,$I$2:$I$31))+(SUMIF($G$35:$G$41,B14,$H$35:$H$41)) -> 0 | K14: OS | L14: Vendedor | M14: CARNE | R14: =IF(vend4[[#This Row],[Nº Venda]]>1,1,0) -> 0
B15: Total | C15: =SUM(C11:C14) -> 700 | K15: 4024 | L15: BETH | M15: Não | R15: =IF(vend4[[#This Row],[Nº Venda]]>1,1,0) -> 0
K16: 4199 | L16: BETH | M16: Não | R16: =IF(vend4[[#This Row],[Nº Venda]]>1,1,0) -> 0
B17: Entrega de Carne | R17: =IF(vend4[[#This Row],[Nº Venda]]>1,1,0) -> 0
B18: =COUNT(entr_carn4[OS]) -> 0 | C18: =SUM(entr_carn4[Valor Total]) -> 0 | R18: =IF(vend4[[#This Row],[Nº Venda]]>1,1,0) -> 0
B19: Total | C19: =SUM(C18:C18) -> 0 | R19: =IF(vend4[[#This Row],[Nº Venda]]>1,1,0) -> 0
R20: =IF(vend4[[#This Row],[Nº Venda]]>1,1,0) -> 0
B21: Venda | C21: =C5 -> 1949
E24: Restante Entrada
E25: Nº Venda | F25: Cliente | G25: Forma de Pgto | H25: Valor Venda | I25: Entrada
E26: 4024 | F26: GILDA MARQUES | G26: CTC | I26: 200
E27: 4166 | F27: Hilda de Souza | G27: DN | I27: 50
E33: Recebimento de Carnê | K33: Entrega de Carne
E34: OS | F34: Cliente | G34: Forma de Pgto | H34: Valor Parcela | I34: Nº Parcela | K34: OS | L34: Parcelas | M34: Valor Total
E35: 3872 | F35: HILDA DE SOUZA | G35: DN | H35: 150 | I35: PARC. 5/7
Q40: Total de OS | R40: =SUM(R6:R21) -> 2

Sheet 05
B1: ='04'!B1+1 -> 45417
B2: Fechamento Diário do Caixa
B4: Saldo Inicial | C4: 0 | E4: Vendas | K4: Despesas
B5: Vendas | C5: =SUMIF(I6:I31,">0",H6:H31) -> 0 | E5: Nº Venda | F5: Cliente | G5: Forma de Pgto | H5: Valor Venda | I5: Entrada | K5: Descrição | L5: Tipo de Pagto | M5: Valor
B6: Entrada | C6: =SUM(I6:I41) -> 0 | R6: =IF(vend5[[#This Row],[Nº Venda]]>1,1,0) -> 0
B7: Despesas | C7: =SUM(M6:M11) -> 0 | R7: =IF(vend5[[#This Row],[Nº Venda]]>1,1,0) -> 0
B8: Total entrada | C8: =SUM(C6:C7) -> 0 | R8: =IF(vend5[[#This Row],[Nº Venda]]>1,1,0) -> 0
R9: =IF(vend5[[#This Row],[Nº Venda]]>1,1,0) -> 0
B10: Tipos de Pagtos | R10: =IF(vend5[[#This Row],[Nº Venda]]>1,1,0) -> 0
B11: DN | C11: =(SUMIF($G$2:$G$31,B11,$I$2:$I$31))+(SUMIF($G$35:$G$41,B11,$H$35:$H$41)) -> 0 | O11: =IF(C15=0,0,1) -> 0 | R11: =IF(vend5[[#This Row],[Nº Venda]]>1,1,0) -> 0
B12: CTD | C12: =(SUMIF($G$2:$G$31,B12,$I$2:$I$31))+(SUMIF($G$35:$G$41,B12,$H$35:$H$41)) -> 0 | R12: =IF(vend5[[#This Row],[Nº Venda]]>1,1,0) -> 0
B13: CTC | C13: =(SUMIF($G$2:$G$31,B13,$I$2:$I$31))+(SUMIF($G$35:$G$41,B13,$H$35:$H$41)) -> 0 | K13: OS Entregue no Dia | R13: =IF(vend5[[#This Row],[Nº Venda]]>1,1,0) -> 0
B14: PIX | C14: =(SUMIF($G$2:$G$31,B14,$I$2:$I$31))+(SUMIF($G$35:$G$41,B14,$H$35:$H$41)) -> 0 | K14: OS | L14: Vendedor | M14: CARNE | R14: =IF(vend5[[#This Row],[Nº Venda]]>1,1,0) -> 0
B15: Total | C15: =SUM(C11:C14) -> 0 | R15: =IF(vend5[[#This Row],[Nº Venda]]>1,1,0) -> 0
R16: =IF(vend5[[#This Row],[Nº Venda]]>1,1,0) -> 0
B17: Entrega de Carne | R17: =IF(vend5[[#This Row],[Nº Venda]]>1,1,0) -> 0
B18: =COUNT(entr_carn5[OS]) -> 0 | C18: =SUM(entr_carn5[Valor Total]) -> 0 | R18: =IF(vend5[[#This Row],[Nº Venda]]>1,1,0) -> 0
B19: Total | C19: =SUM(C18:C18) -> 0 | R19: =IF(vend5[[#This Row],[Nº Venda]]>1,1,0) -> 0
R20: =IF(vend5[[#This Row],[Nº Venda]]>1,1,0) -> 0
B21: Venda | C21: =C5 -> 0
E24: Restante Entrada
E25: Nº Venda | F25: Cliente | G25: Forma de Pgto | H25: Valor Venda | I25: Entrada
E33: Recebimento de Carnê | K33: Entrega de Carne
E34: OS | F34: Cliente | G34: Forma de Pgto | H34: Valor Parcela | I34: Nº Parcela | K34: OS | L34: Parcelas | M34: Valor Total
Q40: Total de OS | R40: =SUM(R6:R21) -> 0

Sheet 06
B1: ='05'!B1+1 -> 45418
B2: Fechamento Diário do Caixa
B4: Saldo Inicial | C4: 0 | E4: Vendas | K4: Despesas
B5: Vendas | C5: =SUMIF(I6:I31,">0",H6:H31) -> 700 | E5: Nº Venda | F5: Cliente | G5: Forma de Pgto | H5: Valor Venda | I5: Entrada | K5: Descrição | L5: Tipo de Pagto | M5: Valor
B6: Entrada | C6: =SUM(I6:I41) -> 50 | E6: 4217 | F6: ELZA ROSA DE LIMA | G6: DN | H6: 700 | I6: 50 | R6: =IF(vend[[#This Row],[Nº Venda]]>1,1,0) -> 1
B7: Despesas | C7: =SUM(M6:M11) -> 0 | R7: =IF(vend[[#This Row],[Nº Venda]]>1,1,0) -> 0
B8: Total entrada | C8: =SUM(C6:C7) -> 50 | R8: =IF(vend[[#This Row],[Nº Venda]]>1,1,0) -> 0
R9: =IF(vend[[#This Row],[Nº Venda]]>1,1,0) -> 0
B10: Tipos de Pagtos | R10: =IF(vend[[#This Row],[Nº Venda]]>1,1,0) -> 0
B11: DN | C11: =(SUMIF($G$2:$G$31,B11,$I$2:$I$31))+(SUMIF($G$35:$G$41,B11,$H$35:$H$41)) -> 50 | O11: =IF(C15=0,0,1) -> 1 | R11: =IF(vend[[#This Row],[Nº Venda]]>1,1,0) -> 0
B12: CTD | C12: =(SUMIF($G$2:$G$31,B12,$I$2:$I$31))+(SUMIF($G$35:$G$41,B12,$H$35:$H$41)) -> 175 | R12: =IF(vend[[#This Row],[Nº Venda]]>1,1,0) -> 0
B13: CTC | C13: =(SUMIF($G$2:$G$31,B13,$I$2:$I$31))+(SUMIF($G$35:$G$41,B13,$H$35:$H$41)) -> 0 | K13: OS Entregue no Dia | R13: =IF(vend[[#This Row],[Nº Venda]]>1,1,0) -> 0
B14: PIX | C14: =(SUMIF($G$2:$G$31,B14,$I$2:$I$31))+(SUMIF($G$35:$G$41,B14,$H$35:$H$41)) -> 0 | K14: OS | L14: Vendedor | M14: CARNE | R14: =IF(vend[[#This Row],[Nº Venda]]>1,1,0) -> 0
B15: Total | C15: =SUM(C11:C14) -> 225 | R15: =IF(vend[[#This Row],[Nº Venda]]>1,1,0) -> 0
R16: =IF(vend[[#This Row],[Nº Venda]]>1,1,0) -> 0
B17: Entrega de Carne | R17: =IF(vend[[#This Row],[Nº Venda]]>1,1,0) -> 0
B18: =COUNT(entr_carn6[OS]) -> 0 | C18: =SUM(entr_carn6[Valor Total]) -> 0 | R18: =IF(vend[[#This Row],[Nº Venda]]>1,1,0) -> 0
B19: Total | C19: =SUM(C18:C18) -> 0 | R19: =IF(vend[[#This Row],[Nº Venda]]>1,1,0) -> 0
R20: =IF(vend[[#This Row],[Nº Venda]]>1,1,0) -> 0
B21: Venda | C21: =C5 -> 700
E24: Restante Entrada
E25: Nº Venda | F25: Cliente | G25: Forma de Pgto | H25: Valor Venda | I25: Entrada
E33: Recebimento de Carnê | K33: Entrega de Carne
E34: OS | F34: Cliente | G34: Forma de Pgto | H34: Valor Parcela | I34: Nº Parcela | K34: OS | L34: Parcelas | M34: Valor Total
E35: 4179 | F35: ALTAMIR FRANCISCO | G35: CTD | H35: 175 | I35: PARC. 1/2
Q40: Total de OS | R40: =SUM(R6:R21) -> 1

Sheet 07
B1: ='06'!B1+1 -> 45419
B2: Fechamento Diário do Caixa
B4: Saldo Inicial | C4: 0 | E4: Vendas | K4: Despesas | U4: 0
B5: Vendas | C5: =SUMIF(I6:I31,">0",H6:H31) -> 799 | E5: Nº Venda | F5: Cliente | G5: Forma de Pgto | H5: Valor Venda | I5: Entrada | K5: Descrição | L5: Tipo de Pagto | M5: Valor
B6: Entrada | C6: =SUM(I6:I41) -> 100 | E6: 4218 | F6: JOSELIA MARIA | G6: SS | H6: 40 | I6: S/S | R6: =IF(vend7[[#This Row],[Nº Venda]]>1,1,0) -> 1
B7: Despesas | C7: =SUM(M6:M11) -> 0 | E7: 4219 | F7: LUIZA BATISTA | G7: PIX | H7: 799 | I7: 100 | R7: =IF(vend7[[#This Row],[Nº Venda]]>1,1,0) -> 1
B8: Total entrada | C8: =SUM(C6:C7) -> 100 | E8: 4220 | F8: IVALDO INACIO (cortesia) | G8: SS | H8: 0 | I8: 0 | R8: =IF(vend7[[#This Row],[Nº Venda]]>1,1,0) -> 1
R9: =IF(vend7[[#This Row],[Nº Venda]]>1,1,0) -> 0
B10: Tipos de Pagtos | R10: =IF(vend7[[#This Row],[Nº Venda]]>1,1,0) -> 0
B11: DN | C11: =(SUMIF($G$2:$G$31,B11,$I$2:$I$31))+(SUMIF($G$35:$G$41,B11,$H$35:$H$41)) -> 0 | O11: =IF(C15=0,0,1) -> 1 | R11: =IF(vend7[[#This Row],[Nº Venda]]>1,1,0) -> 0
B12: CTD | C12: =(SUMIF($G$2:$G$31,B12,$I$2:$I$31))+(SUMIF($G$35:$G$41,B12,$H$35:$H$41)) -> 0 | R12: =IF(vend7[[#This Row],[Nº Venda]]>1,1,0) -> 0
B13: CTC | C13: =(SUMIF($G$2:$G$31,B13,$I$2:$I$31))+(SUMIF($G$35:$G$41,B13,$H$35:$H$41)) -> 0 | K13: OS Entregue no Dia | R13: =IF(vend7[[#This Row],[Nº Venda]]>1,1,0) -> 0
B14: PIX | C14: =(SUMIF($G$2:$G$31,B14,$I$2:$I$31))+(SUMIF($G$35:$G$41,B14,$H$35:$H$41)) -> 385 | K14: OS | L14: Vendedor | M14: CARNE | R14: =IF(vend7[[#This Row],[Nº Venda]]>1,1,0) -> 0
B15: Total | C15: =SUM(C11:C14) -> 385 | R15: =IF(vend7[[#This Row],[Nº Venda]]>1,1,0) -> 0
R16: =IF(vend7[[#This Row],[Nº Venda]]>1,1,0) -> 0
B17: Entrega de Carne | R17: =IF(vend7[[#This Row],[Nº Venda]]>1,1,0) -> 0
B18: =COUNT(entr_carn7[OS]) -> 0 | C18: =SUM(entr_carn7[Valor Total]) -> 0 | R18: =IF(vend7[[#This Row],[Nº Venda]]>1,1,0) -> 0
B19: Total | C19: =SUM(C18:C18) -> 0 | R19: =IF(vend7[[#This Row],[Nº Venda]]>1,1,0) -> 0
R20: =IF(vend7[[#This Row],[Nº Venda]]>1,1,0) -> 0
B21: Venda | C21: =C5 -> 799
E24: Restante Entrada
E25: Nº Venda | F25: Cliente | G25: Forma de Pgto | H25: Valor Venda | I25: Entrada
E33: Recebimento de Carnê | K33: Entrega de Carne
E34: OS | F34: Cliente | G34: Forma de Pgto | H34: Valor Parcela | I34: Nº Parcela | K34: OS | L34: Parcelas | M34: Valor Total
E35: 3968 | F35: LUIZA BATISTA | G35: PIX | H35: 125 | I35: PARC. 1/5
E36: 3939 | F36: GRACIANO | G36: PIX | H36: 160 | I36: PARC. 4/4
Q40: Total de OS | R40: =SUM(R6:R21) -> 3

Sheet 08
B1: ='07'!B1+1 -> 45420
B2: Fechamento Diário do Caixa
B4: Saldo Inicial | C4: 0 | E4: Vendas | K4: Despesas
B5: Vendas | C5: =SUMIF(I6:I31,">0",H6:H31) -> 2100 | E5: Nº Venda | F5: Cliente | G5: Forma de Pgto | H5: Valor Venda | I5: Entrada | K5: Descrição | L5: Tipo de Pagto | M5: Valor
B6: Entrada | C6: =SUM(I6:I41) -> 1180 | E6: 4221 | F6: IVO FERREIRA DE MELLO | G6: CTD | H6: 800 | I6: 100 | R6: =IF(vend8[[#This Row],[Nº Venda]]>1,1,0) -> 1
B7: Despesas | C7: =SUM(M6:M11) -> 0 | E7: 4222 | F7: JEANE DE LIMA AMARAL | G7: PIX | H7: 500 | I7: 50 | R7: =IF(vend8[[#This Row],[Nº Venda]]>1,1,0) -> 1
B8: Total entrada | C8: =SUM(C6:C7) -> 1180 | E8: 4223 | F8: SONIA MARCELINO | G8: CTC | H8: 800 | I8: 500 | R8: =IF(vend8[[#This Row],[Nº Venda]]>1,1,0) -> 1
R9: =IF(vend8[[#This Row],[Nº Venda]]>1,1,0) -> 0
B10: Tipos de Pagtos | R10: =IF(vend8[[#This Row],[Nº Venda]]>1,1,0) -> 0
B11: DN | C11: =(SUMIF($G$2:$G$31,B11,$I$2:$I$31))+(SUMIF($G$35:$G$42,B11,$H$35:$H$42)) -> 0 | O11: =IF(C15=0,0,1) -> 1 | R11: =IF(vend8[[#This Row],[Nº Venda]]>1,1,0) -> 0
B12: CTD | C12: =(SUMIF($G$2:$G$31,B12,$I$2:$I$31))+(SUMIF($G$35:$G$42,B12,$H$35:$H$42)) -> 100 | R12: =IF(vend8[[#This Row],[Nº Venda]]>1,1,0) -> 0
B13: CTC | C13: =(SUMIF($G$2:$G$31,B13,$I$2:$I$31))+(SUMIF($G$35:$G$42,B13,$H$35:$H$42)) -> 500 | K13: OS Entregue no Dia | R13: =IF(vend8[[#This Row],[Nº Venda]]>1,1,0) -> 0
B14: PIX | C14: =(SUMIF($G$2:$G$31,B14,$I$2:$I$31))+(SUMIF($G$35:$G$42,B14,$H$35:$H$42)) -> 630 | K14: OS | L14: Vendedor | M14: CARNE | R14: =IF(vend8[[#This Row],[Nº Venda]]>1,1,0) -> 0
B15: Total | C15: =SUM(C11:C14) -> 1230 | K15: 4134 | L15: BETH | M15: Não | R15: =IF(vend8[[#This Row],[Nº Venda]]>1,1,0) -> 0
R16: =IF(vend8[[#This Row],[Nº Venda]]>1,1,0) -> 0
B17: Entrega de Carne | R17: =IF(vend8[[#This Row],[Nº Venda]]>1,1,0) -> 0
B18: =COUNT(entr_carn8[OS]) -> 0 | C18: =SUM(entr_carn8[Valor Total]) -> 0 | R18: =IF(vend8[[#This Row],[Nº Venda]]>1,1,0) -> 0
B19: Total | C19: =SUM(C18:C18) -> 0 | R19: =IF(vend8[[#This Row],[Nº Venda]]>1,1,0) -> 0
R20: =IF(vend8[[#This Row],[Nº Venda]]>1,1,0) -> 0
B21: Venda | C21: =C5 -> 2100
E24: Restante Entrada
E25: Nº Venda | F25: Cliente | G25: Forma de Pgto | H25: Valor Venda | I25: Entrada
E26: 4134 | F26: MARINEIA DE SOUZA | G26: PIX | I26: 530
E33: Recebimento de Carnê | K33: Entrega de Carne
E34: OS | F34: Cliente | G34: Forma de Pgto | H34: Valor Parcela | I34: Nº Parcela | K34: OS | L34: Parcelas | M34: Valor Total
E35: 3106 | F35: LUZILENE DA SILVA | G35: PIX | H35: 50 | I35: PARC. 8/10
Q40: Total de OS | R40: =SUM(R6:R21) -> 3

Sheet 09
B1: ='08'!B1+1 -> 45421
B2: Fechamento Diário do Caixa
B4: Saldo Inicial | C4: 0 | E4: Vendas | K4: Despesas
B5: Vendas | C5: =SUMIF(I6:I31,">0",H6:H31) -> 2730 | E5: Nº Venda | F5: Cliente | G5: Forma de Pgto | H5: Valor Venda | I5: Entrada | K5: Descrição | L5: Tipo de Pagto | M5: Valor
B6: Entrada | C6: =SUM(I6:I41) -> 2030 | E6: 4224 | F6: ROSANA BATISTA | G6: CTC | H6: 350 | I6: 350 | R6: =IF(vend9[[#This Row],[Nº Venda]]>1,1,0) -> 1
B7: Despesas | C7: =SUM(M6:M11) -> 0 | E7: 4225 | F7: VITORIA REGINA DA SILVA | G7: DN | H7: 675 | I7: 100 | R7: =IF(vend9[[#This Row],[Nº Venda]]>1,1,0) -> 1
B8: Total entrada | C8: =SUM(C6:C7) -> 2030 | E8: 4226 | F8: VITORIA REGINA DA SILVA | G8: DN | H8: 675 | I8: 100 | R8: =IF(vend9[[#This Row],[Nº Venda]]>1,1,0) -> 1
E9: 4227 | F9: GILDESON SUZARTE | G9: CTC | H9: 230 | I9: 230 | R9: =IF(vend9[[#This Row],[Nº Venda]]>1,1,0) -> 1
B10: Tipos de Pagtos | E10: 4228 | F10: MARIA APARECIDA LIMA | G10: CTC | H10: 800 | I10: 800 | R10: =IF(vend9[[#This Row],[Nº Venda]]>1,1,0) -> 1
B11: DN | C11: =(SUMIF($G$2:$G$31,B11,$I$2:$I$31))+(SUMIF($G$35:$G$41,B11,$H$35:$H$41)) -> 200 | O11: =IF(C15=0,0,1) -> 1 | R11: =IF(vend9[[#This Row],[Nº Venda]]>1,1,0) -> 0
B12: CTD | C12: =(SUMIF($G$2:$G$31,B12,$I$2:$I$31))+(SUMIF($G$35:$G$41,B12,$H$35:$H$41)) -> 0 | R12: =IF(vend9[[#This Row],[Nº Venda]]>1,1,0) -> 0 | V12: 0
B13: CTC | C13: =(SUMIF($G$2:$G$31,B13,$I$2:$I$31))+(SUMIF($G$35:$G$41,B13,$H$35:$H$41)) -> 2169 | K13: OS Entregue no Dia | R13: =IF(vend9[[#This Row],[Nº Venda]]>1,1,0) -> 0
B14: PIX | C14: =(SUMIF($G$2:$G$31,B14,$I$2:$I$31))+(SUMIF($G$35:$G$41,B14,$H$35:$H$41)) -> 582 | K14: OS | L14: Vendedor | M14: CARNE | R14: =IF(vend9[[#This Row],[Nº Venda]]>1,1,0) -> 0
B15: Total | C15: =SUM(C11:C14) -> 2951 | R15: =IF(vend9[[#This Row],[Nº Venda]]>1,1,0) -> 0
R16: =IF(vend9[[#This Row],[Nº Venda]]>1,1,0) -> 0
B17: Entrega de Carne | R17: =IF(vend9[[#This Row],[Nº Venda]]>1,1,0) -> 0
B18: =COUNT(entr_carn9[OS]) -> 0 | C18: =SUM(entr_carn9[Valor Total]) -> 0 | R18: =IF(vend9[[#This Row],[Nº Venda]]>1,1,0) -> 0
B19: Total | C19: =SUM(C18:C18) -> 0 | R19: =IF(vend9[[#This Row],[Nº Venda]]>1,1,0) -> 0
R20: =IF(vend9[[#This Row],[Nº Venda]]>1,1,0) -> 0
B21: Venda | C21: =C5 -> 2730
E24: Restante Entrada
E25: Nº Venda | F25: Cliente | G25: Forma de Pgto | H25: Valor Venda | I25: Entrada
E26: 4222 | F26: JEANE DE LIMA AMARAL | G26: CTC | I26: 450
E33: Recebimento de Carnê | K33: Entrega de Carne
E34: OS | F34: Cliente | G34: Forma de Pgto | H34: Valor Parcela | I34: Nº Parcela | K34: OS | L34: Parcelas | M34: Valor Total
E35: 4033 | F35: PATRICIA FRANCISCA | G35: CTC | H35: 169.5 | I35: PARC. 2/6
E36: 4034 | F36: PATRICIA FRANCISCA | G36: CTC | H36: 169.5 | I36: PARC. 2/6
E37: 3999 | F37: CELIA REGINA | G37: PIX | H37: 170 | I37: PARC. 4/5
E38: 4031 | F38: OSIAS GOMES | G38: PIX | H38: 90 | I38: PARC. 3/6
E39: 4032 | F39: OSIAS GOMES | G39: PIX | H39: 90 | I39: PARC. 3/6
E40: 4072 | F40: ALDIMEIA PEREIRA | G40: PIX | H40: 100 | I40: PARC. 2/5 | Q40: Total de OS | R40: =SUM(R6:R21) -> 5
E41: 4075 | F41: ALDIMEIA PEREIRA | G41: PIX | H41: 132 | I41: PARC. 2/5

Sheet 10
B1: ='09'!B1+1 -> 45422
B2: Fechamento Diário do Caixa
B4: Saldo Inicial | C4: 0 | E4: Vendas | K4: Despesas
B5: Vendas | C5: =SUMIF(I6:I32,">0",H6:H32) -> 0 | E5: Nº Venda | F5: Cliente | G5: Forma de Pgto | H5: Valor Venda | I5: Entrada | K5: Descrição | L5: Tipo de Pagto | M5: Valor
B6: Entrada | C6: =SUM(I6:I42) -> 0 | R6: =IF(vend10[[#This Row],[Nº Venda]]>1,1,0) -> 0
B7: Despesas | C7: =SUM(M6:M11) -> 0 | R7: =IF(vend10[[#This Row],[Nº Venda]]>1,1,0) -> 0
B8: Total entrada | C8: =SUM(C6:C7) -> 0 | R8: =IF(vend10[[#This Row],[Nº Venda]]>1,1,0) -> 0
R9: =IF(vend10[[#This Row],[Nº Venda]]>1,1,0) -> 0
B10: Tipos de Pagtos | R10: =IF(vend10[[#This Row],[Nº Venda]]>1,1,0) -> 0
B11: DN | C11: =(SUMIF($G$2:$G$32,B11,$I$2:$I$32))+(SUMIF($G$36:$G$42,B11,$H$36:$H$42)) -> 0 | O11: =IF(C15=0,0,1) -> 1 | R11: =IF(vend10[[#This Row],[Nº Venda]]>1,1,0) -> 0
B12: CTD | C12: =(SUMIF($G$2:$G$32,B12,$I$2:$I$32))+(SUMIF($G$36:$G$42,B12,$H$36:$H$42)) -> 0 | R12: =IF(vend10[[#This Row],[Nº Venda]]>1,1,0) -> 0
B13: CTC | C13: =(SUMIF($G$2:$G$32,B13,$I$2:$I$32))+(SUMIF($G$36:$G$42,B13,$H$36:$H$42)) -> 0 | K13: OS Entregue no Dia | R13: =IF(vend10[[#This Row],[Nº Venda]]>1,1,0) -> 0
B14: PIX | C14: =(SUMIF($G$2:$G$32,B14,$I$2:$I$32))+(SUMIF($G$36:$G$42,B14,$H$36:$H$42)) -> 151 | K14: OS | L14: Vendedor | M14: CARNE | R14: =IF(vend10[[#This Row],[Nº Venda]]>1,1,0) -> 0
B15: Total | C15: =SUM(C11:C14) -> 151 | K15: 4202 | L15: ANDRESSA DE SOUZA | M15: Não | R15: =IF(vend10[[#This Row],[Nº Venda]]>1,1,0) -> 0
K16: 4210 | L16: RENAN NAZARO | M16: NÃO | R16: =IF(vend10[[#This Row],[Nº Venda]]>1,1,0) -> 0
B17: Entrega de Carne | R17: =IF(vend10[[#This Row],[Nº Venda]]>1,1,0) -> 0
B18: =COUNT(entr_carn10[OS]) -> 0 | C18: =SUM(entr_carn10[Valor Total]) -> 0 | R18: =IF(vend10[[#This Row],[Nº Venda]]>1,1,0) -> 0
B19: Total | C19: =SUM(C18:C18) -> 0 | R19: =IF(vend10[[#This Row],[Nº Venda]]>1,1,0) -> 0
R20: =IF(vend10[[#This Row],[Nº Venda]]>1,1,0) -> 0
B21: Venda | C21: =C5 -> 0
E24: Restante Entrada
E25: Nº Venda | F25: Cliente | G25: Forma de Pgto | H25: Valor Venda | I25: Entrada
K33: Entrega de Carne
E34: Recebimento de Carnê | K34: OS | L34: Parcelas | M34: Valor Total
E35: Coluna1 | F35: Coluna2 | G35: Coluna3 | H35: Coluna4 | I35: Coluna5
E36: 4141 | F36: AMABELLY SILVA | G36: PIX | H36: 151 | I36: PARC. 1/3
Q40: Total de OS | R40: =SUM(R6:R21) -> 0

Sheet 11
B1: ='10'!B1+1 -> 45423
B2: Fechamento Diário do Caixa
B4: Saldo Inicial | C4: 0 | E4: Vendas | K4: Despesas
B5: Vendas | C5: =SUMIF(I6:I31,">0",H6:H31) -> 4500 | E5: Nº Venda | F5: Cliente | G5: Forma de Pgto | H5: Valor Venda | I5: Entrada | K5: Descrição | L5: Tipo de Pagto | M5: Valor
B6: Entrada | C6: =SUM(I6:I41) -> 4570 | E6: 4229 | F6: ELZAIR SOARES | G6: CTD | H6: 300 | I6: 300 | R6: =IF(vend11[[#This Row],[Nº Venda]]>1,1,0) -> 1
B7: Despesas | C7: =SUM(M6:M11) -> 0 | E7: 4229 | F7: ELZAIR SOARES | G7: CTC | H7: 550 | I7: 550 | R7: =IF(vend11[[#This Row],[Nº Venda]]>1,1,0) -> 1
B8: Total entrada | C8: =SUM(C6:C7) -> 4570 | E8: 4230 | F8: SIDNEI SOARES | G8: CTD | H8: 500 | I8: 500 | R8: =IF(vend11[[#This Row],[Nº Venda]]>1,1,0) -> 1
E9: 4230 | F9: SIDNEI SOARES | G9: CTC | H9: 350 | I9: 350 | R9: =IF(vend11[[#This Row],[Nº Venda]]>1,1,0) -> 1
B10: Tipos de Pagtos | E10: 4231 | F10: ISALTINA JULIA | G10: PIX | H10: 580 | I10: 50 | R10: =IF(vend11[[#This Row],[Nº Venda]]>1,1,0) -> 1
B11: DN | C11: =(SUMIF($G$2:$G$31,B11,$I$2:$I$31))+(SUMIF($G$35:$G$41,B11,$H$35:$H$41)) -> 0 | E11: 4232 | F11: IVANETE DE SOUZA | G11: CTD | H11: 1620 | I11: 1620 | O11: =IF(C15=0,0,1) -> 1 | R11: =IF(vend11[[#This Row],[Nº Venda]]>1,1,0) -> 1
B12: CTD | C12: =(SUMIF($G$2:$G$31,B12,$I$2:$I$31))+(SUMIF($G$35:$G$41,B12,$H$35:$H$41)) -> 2420 | E12: 4233 | F12: IVANETE DE SOUZA | G12: CTC | H12: 350 | I12: 350 | R12: =IF(vend11[[#This Row],[Nº Venda]]>1,1,0) -> 1
B13: CTC | C13: =(SUMIF($G$2:$G$31,B13,$I$2:$I$31))+(SUMIF($G$35:$G$41,B13,$H$35:$H$41)) -> 2050 | E13: 4234 | F13: IZALTINA DE SOUZA | G13: PIX | H13: 250 | I13: 50 | K13: OS Entregue no Dia | R13: =IF(vend11[[#This Row],[Nº Venda]]>1,1,0) -> 1
B14: PIX | C14: =(SUMIF($G$2:$G$31,B14,$I$2:$I$31))+(SUMIF($G$35:$G$41,B14,$H$35:$H$41)) -> 197 | K14: OS | L14: Vendedor | M14: CARNE | R14: =IF(vend11[[#This Row],[Nº Venda]]>1,1,0) -> 0
B15: Total | C15: =SUM(C11:C14) -> 4667 | K15: 4149 | L15: BETH | M15: Não | R15: =IF(vend11[[#This Row],[Nº Venda]]>1,1,0) -> 0
K16: 4207 | L16: BETH | M16: Não | R16: =IF(vend11[[#This Row],[Nº Venda]]>1,1,0) -> 0
B17: Entrega de Carne | K17: 4208 | L17: BETH | M17: Não | R17: =IF(vend11[[#This Row],[Nº Venda]]>1,1,0) -> 0
B18: =COUNT(entr_carn11[OS]) -> 0 | C18: =SUM(entr_carn11[Valor Total]) -> 0 | K18: 4205 | L18: BETH | M18: Não | R18: =IF(vend11[[#This Row],[Nº Venda]]>1,1,0) -> 0
B19: Total | C19: =SUM(C18:C18) -> 0 | K19: 4206 | L19: BETH | M19: Não | R19: =IF(vend11[[#This Row],[Nº Venda]]>1,1,0) -> 0
R20: =IF(vend11[[#This Row],[Nº Venda]]>1,1,0) -> 0
B21: Venda | C21: =C5 -> 4500
E24: Restante Entrada
E25: Nº Venda | F25: Cliente | G25: Forma de Pgto | H25: Valor Venda | I25: Entrada
E26: 4207 | F26: AMANDA BALBINO | G26: CTC | I26: 224.99
E27: 4208 | F27: AMANDA BALBINO | G27: CTC | I27: 575.01
E33: Recebimento de Carnê | K33: Entrega de Carne
E34: OS | F34: Cliente | G34: Forma de Pgto | H34: Valor Parcela | I34: Nº Parcela | K34: OS | L34: Parcelas | M34: Valor Total
E35: 3947 | F35: MARIO MIRANDA | G35: PIX | H35: 97 | I35: PARC. 6/6
Q40: Total de OS | R40: =SUM(R6:R21) -> 8

Sheet 12
B1: ='11'!B1+1 -> 45424
B2: Fechamento Diário do Caixa
B4: Saldo Inicial | C4: 0 | E4: Vendas | K4: Despesas
B5: Vendas | C5: =SUMIF(I6:I31,">0",H6:H31) -> 0 | E5: Nº Venda | F5: Cliente | G5: Forma de Pgto | H5: Valor Venda | I5: Entrada | K5: Descrição | L5: Tipo de Pagto | M5: Valor
B6: Entrada | C6: =SUM(I6:I41) -> 0 | R6: =IF(vend12[[#This Row],[Nº Venda]]>1,1,0) -> 0
B7: Despesas | C7: =SUM(M6:M11) -> 0 | R7: =IF(vend12[[#This Row],[Nº Venda]]>1,1,0) -> 0
B8: Total entrada | C8: =SUM(C6:C7) -> 0 | R8: =IF(vend12[[#This Row],[Nº Venda]]>1,1,0) -> 0
R9: =IF(vend12[[#This Row],[Nº Venda]]>1,1,0) -> 0
B10: Tipos de Pagtos | R10: =IF(vend12[[#This Row],[Nº Venda]]>1,1,0) -> 0
B11: DN | C11: =(SUMIF($G$2:$G$31,B11,$I$2:$I$31))+(SUMIF($G$35:$G$41,B11,$H$35:$H$41)) -> 0 | O11: =IF(C15=0,0,1) -> 0 | R11: =IF(vend12[[#This Row],[Nº Venda]]>1,1,0) -> 0
B12: CTD | C12: =(SUMIF($G$2:$G$31,B12,$I$2:$I$31))+(SUMIF($G$35:$G$41,B12,$H$35:$H$41)) -> 0 | R12: =IF(vend12[[#This Row],[Nº Venda]]>1,1,0) -> 0
B13: CTC | C13: =(SUMIF($G$2:$G$31,B13,$I$2:$I$31))+(SUMIF($G$35:$G$41,B13,$H$35:$H$41)) -> 0 | K13: OS Entregue no Dia | R13: =IF(vend12[[#This Row],[Nº Venda]]>1,1,0) -> 0
B14: PIX | C14: =(SUMIF($G$2:$G$31,B14,$I$2:$I$31))+(SUMIF($G$35:$G$41,B14,$H$35:$H$41)) -> 0 | K14: OS | L14: Vendedor | M14: CARNE | R14: =IF(vend12[[#This Row],[Nº Venda]]>1,1,0) -> 0
B15: Total | C15: =SUM(C11:C14) -> 0 | R15: =IF(vend12[[#This Row],[Nº Venda]]>1,1,0) -> 0
R16: =IF(vend12[[#This Row],[Nº Venda]]>1,1,0) -> 0
B17: Entrega de Carne | R17: =IF(vend12[[#This Row],[Nº Venda]]>1,1,0) -> 0
B18: =COUNT(entr_carn12[OS]) -> 0 | C18: =SUM(entr_carn12[Valor Total]) -> 0 | R18: =IF(vend12[[#This Row],[Nº Venda]]>1,1,0) -> 0
B19: Total | C19: =SUM(C18:C18) -> 0 | R19: =IF(vend12[[#This Row],[Nº Venda]]>1,1,0) -> 0
R20: =IF(vend12[[#This Row],[Nº Venda]]>1,1,0) -> 0
B21: Venda | C21: =C5 -> 0
E24: Restante Entrada
E25: Nº Venda | F25: Cliente | G25: Forma de Pgto | H25: Valor Venda | I25: Entrada
E33: Recebimento de Carnê | K33: Entrega de Carne
E34: OS | F34: Cliente | G34: Forma de Pgto | H34: Valor Parcela | I34: Nº Parcela | K34: OS | L34: Parcelas | M34: Valor Total
Q40: Total de OS | R40: =SUM(R6:R21) -> 0

Sheet 13
B1: ='12'!B1+1 -> 45425
B2: Fechamento Diário do Caixa
B4: Saldo Inicial | C4: 0 | E4: Vendas | K4: Despesas
B5: Vendas | C5: =SUMIF(I6:I31,">0",H6:H31) -> 1800 | E5: Nº Venda | F5: Cliente | G5: Forma de Pgto | H5: Valor Venda | I5: Entrada | K5: Descrição | L5: Tipo de Pagto | M5: Valor
B6: Entrada | C6: =SUM(I6:I41) -> 1900 | E6: 4235 | F6: JUSCELINO DOS PASSO | G6: CTC | H6: 500 | I6: 50 | R6: =IF(vend13[[#This Row],[Nº Venda]]>1,1,0) -> 1
B7: Despesas | C7: =SUM(M6:M11) -> 0 | E7: 4235 | F7: JUSCELINO DOS PASSO | G7: CTD | I7: 200 | R7: =IF(vend13[[#This Row],[Nº Venda]]>1,1,0) -> 1
B8: Total entrada | C8: =SUM(C6:C7) -> 1900 | E8: 4236 | F8: SUELI FAUSTINO | G8: GARANTIA | I8: 0 | R8: =IF(vend13[[#This Row],[Nº Venda]]>1,1,0) -> 1
E9: 4237 | F9: SARITA TALMELI | G9: CTC | H9: 500 | I9: 500 | R9: =IF(vend13[[#This Row],[Nº Venda]]>1,1,0) -> 1
B10: Tipos de Pagtos | E10: 4238 | F10: HELENA SOARRES | G10: PIX | H10: 550 | I10: 50 | R10: =IF(vend13[[#This Row],[Nº Venda]]>1,1,0) -> 1
B11: DN | C11: =(SUMIF($G$2:$G$31,B11,$I$2:$I$31))+(SUMIF($G$35:$G$41,B11,$H$35:$H$41)) -> 0 | E11: 4239 | F11: CRISTIANE CAETANO | G11: CTD | H11: 250 | I11: 100 | O11: =IF(C15=0,0,1) -> 1 | R11: =IF(vend13[[#This Row],[Nº Venda]]>1,1,0) -> 1
B12: CTD | C12: =(SUMIF($G$2:$G$31,B12,$I$2:$I$31))+(SUMIF($G$35:$G$41,B12,$H$35:$H$41)) -> 300 | R12: =IF(vend13[[#This Row],[Nº Venda]]>1,1,0) -> 0
B13: CTC | C13: =(SUMIF($G$2:$G$31,B13,$I$2:$I$31))+(SUMIF($G$35:$G$41,B13,$H$35:$H$41)) -> 1550 | K13: OS Entregue no Dia | R13: =IF(vend13[[#This Row],[Nº Venda]]>1,1,0) -> 0
B14: PIX | C14: =(SUMIF($G$2:$G$31,B14,$I$2:$I$31))+(SUMIF($G$35:$G$41,B14,$H$35:$H$41)) -> 50 | K14: OS | L14: Vendedor | M14: CARNE | R14: =IF(vend13[[#This Row],[Nº Venda]]>1,1,0) -> 0
B15: Total | C15: =SUM(C11:C14) -> 1900 | R15: =IF(vend13[[#This Row],[Nº Venda]]>1,1,0) -> 0
R16: =IF(vend13[[#This Row],[Nº Venda]]>1,1,0) -> 0
B17: Entrega de Carne | R17: =IF(vend13[[#This Row],[Nº Venda]]>1,1,0) -> 0
B18: =COUNT(entr_carn13[OS]) -> 0 | C18: =SUM(entr_carn13[Valor Total]) -> 0 | R18: =IF(vend13[[#This Row],[Nº Venda]]>1,1,0) -> 0
B19: Total | C19: =SUM(C18:C18) -> 0 | R19: =IF(vend13[[#This Row],[Nº Venda]]>1,1,0) -> 0
R20: =IF(vend13[[#This Row],[Nº Venda]]>1,1,0) -> 0
B21: Venda | C21: =C5 -> 1800
E24: Restante Entrada
E25: Nº Venda | F25: Cliente | G25: Forma de Pgto | H25: Valor Venda | I25: Entrada
E26: 4201 | F26: ANDREA PEREIRA | G26: CTC | I26: 1000
E33: Recebimento de Carnê | K33: Entrega de Carne
E34: OS | F34: Cliente | G34: Forma de Pgto | H34: Valor Parcela | I34: Nº Parcela | K34: OS | L34: Parcelas | M34: Valor Total
Q40: Total de OS | R40: =SUM(R6:R21) -> 6

Sheet 14
B1: ='13'!B1+1 -> 45426
B2: Fechamento Diário do Caixa
B4: Saldo Inicial | C4: 0 | E4: Vendas | K4: Despesas
B5: Vendas | C5: =SUMIF(I6:I31,">0",H6:H31) -> 0 | E5: Nº Venda | F5: Cliente | G5: Forma de Pgto | H5: Valor Venda | I5: Entrada | K5: Descrição | L5: Tipo de Pagto | M5: Valor
B6: Entrada | C6: =SUM(I6:I41) -> 585 | R6: =IF(vend14[[#This Row],[Nº Venda]]>1,1,0) -> 0
B7: Despesas | C7: =SUM(M6:M11) -> 0 | R7: =IF(vend14[[#This Row],[Nº Venda]]>1,1,0) -> 0
B8: Total entrada | C8: =SUM(C6:C7) -> 585 | R8: =IF(vend14[[#This Row],[Nº Venda]]>1,1,0) -> 0
R9: =IF(vend14[[#This Row],[Nº Venda]]>1,1,0) -> 0
B10: Tipos de Pagtos | R10: =IF(vend14[[#This Row],[Nº Venda]]>1,1,0) -> 0
B11: DN | C11: =(SUMIF($G$2:$G$31,B11,$I$2:$I$31))+(SUMIF($G$35:$G$41,B11,$H$35:$H$41)) -> 0 | O11: =IF(C15=0,0,1) -> 1 | R11: =IF(vend14[[#This Row],[Nº Venda]]>1,1,0) -> 0
B12: CTD | C12: =(SUMIF($G$2:$G$31,B12,$I$2:$I$31))+(SUMIF($G$35:$G$41,B12,$H$35:$H$41)) -> 0 | R12: =IF(vend14[[#This Row],[Nº Venda]]>1,1,0) -> 0
B13: CTC | C13: =(SUMIF($G$2:$G$31,B13,$I$2:$I$31))+(SUMIF($G$35:$G$41,B13,$H$35:$H$41)) -> 485 | K13: OS Entregue no Dia | R13: =IF(vend14[[#This Row],[Nº Venda]]>1,1,0) -> 0
B14: PIX | C14: =(SUMIF($G$2:$G$31,B14,$I$2:$I$31))+(SUMIF($G$35:$G$41,B14,$H$35:$H$41)) -> 507 | K14: OS | L14: Vendedor | M14: CARNE | R14: =IF(vend14[[#This Row],[Nº Venda]]>1,1,0) -> 0
B15: Total | C15: =SUM(C11:C14) -> 992 | K15: 4165 | L15: BETH | M15: Não | R15: =IF(vend14[[#This Row],[Nº Venda]]>1,1,0) -> 0
K16: 4209 | L16: BETH | M16: Não | R16: =IF(vend14[[#This Row],[Nº Venda]]>1,1,0) -> 0
B17: Entrega de Carne | K17: 4225 | L17: BETH | M17: Não | R17: =IF(vend14[[#This Row],[Nº Venda]]>1,1,0) -> 0
B18: =COUNT(entr_carn14[OS]) -> 2 | C18: =SUM(entr_carn14[Valor Total]) -> 1449 | K18: 4166 | L18: BETH | M18: Sim | R18: =IF(vend14[[#This Row],[Nº Venda]]>1,1,0) -> 0
B19: Total | C19: =SUM(C18:C18) -> 1449 | K19: 4158 | L19: BETH | M19: Sim | R19: =IF(vend14[[#This Row],[Nº Venda]]>1,1,0) -> 0
R20: =IF(vend14[[#This Row],[Nº Venda]]>1,1,0) -> 0
B21: Venda | C21: =C5 -> 0
E24: Restante Entrada
E25: Nº Venda | F25: Cliente | G25: Forma de Pgto | H25: Valor Venda | I25: Entrada
E26: 4204 | F26: ODILIA / BETH | G26: PIX | I26: 100
E27: 4211 | F27: GUILERME GRACIANO | G27: CTC | I27: 485
E33: Recebimento de Carnê | K33: Entrega de Carne
E34: OS | F34: Cliente | G34: Forma de Pgto | H34: Valor Parcela | I34: Nº Parcela | K34: OS | L34: Parcelas | M34: Valor Total
E35: 4080 | F35: JAQUELINE MOREIRA | G35: PIX | H35: 112 | I35: PARC. 2/6 | K35: 4166 | L35: 5 | M35: 649
E36: 4081 | F36: JAQUELINE MOREIRA | G36: PIX | H36: 112 | I36: PARC. 2/6 | K36: 4158 | L36: 5 | M36: 800
E37: 4057 | F37: ELENITA DIAS | G37: PIX | H37: 183 | I37: PARC. 3/6
Q40: Total de OS | R40: =SUM(R6:R21) -> 0

Sheet 15
B1: ='14'!B1+1 -> 45427
B2: Fechamento Diário do Caixa
B4: Saldo Inicial | C4: 0 | E4: Vendas | K4: Despesas
B5: Vendas | C5: =SUMIF(I6:I31,">0",H6:H31) -> 7350 | E5: Nº Venda | F5: Cliente | G5: Forma de Pgto | H5: Valor Venda | I5: Entrada | K5: Descrição | L5: Tipo de Pagto | M5: Valor
B6: Entrada | C6: =SUM(I6:I41) -> 4765 | E6: 4240 | F6: GIVANILDO DA SILVA | G6: CTC | H6: 1000 | I6: 1000 | R6: =IF(vend15[[#This Row],[Nº Venda]]>1,1,0) -> 1
B7: Despesas | C7: =SUM(M6:M11) -> 0 | E7: 4241 | F7: ISABELLY VIEIRA | G7: CTD | H7: 1590 | I7: 150 | R7: =IF(vend15[[#This Row],[Nº Venda]]>1,1,0) -> 1
B8: Total entrada | C8: =SUM(C6:C7) -> 4765 | E8: 4242 | F8: ISABELLY VIEIRA | G8: CTD | H8: 730 | I8: 150 | R8: =IF(vend15[[#This Row],[Nº Venda]]>1,1,0) -> 1
E9: 4243 | F9: VALDIRENE CLEMENTINO | G9: GARANTIA | H9: 0 | I9: 0 | R9: =IF(vend15[[#This Row],[Nº Venda]]>1,1,0) -> 1
B10: Tipos de Pagtos | E10: 4244 | F10: ANDREIA GOMES | G10: SS | H10: 35 | I10: 0 | R10: =IF(vend15[[#This Row],[Nº Venda]]>1,1,0) -> 1
B11: DN | C11: =(SUMIF($G$2:$G$31,B11,$I$2:$I$31))+(SUMIF($G$35:$G$41,B11,$H$35:$H$41)) -> 185 | E11: 4245 | F11: DOMINGOS ALEIXO | G11: CTC | H11: 800 | I11: 500 | O11: =IF(C15=0,0,1) -> 1 | R11: =IF(vend15[[#This Row],[Nº Venda]]>1,1,0) -> 1
B12: CTD | C12: =(SUMIF($G$2:$G$31,B12,$I$2:$I$31))+(SUMIF($G$35:$G$41,B12,$H$35:$H$41)) -> 300 | E12: 4246 | F12: DOMINGOS ALEIXO | G12: CTC | H12: 1200 | I12: 1200 | R12: =IF(vend15[[#This Row],[Nº Venda]]>1,1,0) -> 1
B13: CTC | C13: =(SUMIF($G$2:$G$31,B13,$I$2:$I$31))+(SUMIF($G$35:$G$41,B13,$H$35:$H$41)) -> 4280 | E13: 4247 | F13: NAYRA RODRIGUES | G13: CTC | H13: 1180 | I13: 1180 | K13: OS Entregue no Dia | R13: =IF(vend15[[#This Row],[Nº Venda]]>1,1,0) -> 1
B14: PIX | C14: =(SUMIF($G$2:$G$31,B14,$I$2:$I$31))+(SUMIF($G$35:$G$41,B14,$H$35:$H$41)) -> 334 | E14: 4248 | F14: NAYRA RODRIGUES | G14: CTC | H14: 100 | I14: 100 | K14: OS | L14: Vendedor | M14: CARNE | R14: =IF(vend15[[#This Row],[Nº Venda]]>1,1,0) -> 1
B15: Total | C15: =SUM(C11:C14) -> 5099 | E15: 4249 | F15: AYSLA TATIANA | G15: DN | H15: 450 | I15: 10 | R15: =IF(vend15[[#This Row],[Nº Venda]]>1,1,0) -> 1
E16: 4250 | F16: JOSE LUIZ DE OLIVEIRA | G16: CTC | H16: 300 | I16: 300 | R16: =IF(vend15[[#This Row],[Nº Venda]]>1,1,0) -> 1
B17: Entrega de Carne | E17: 4251 | F17: GIDELSON SUZARTE | G17: SS | R17: =IF(vend15[[#This Row],[Nº Venda]]>1,1,0) -> 1
B18: =COUNT(entr_carn15[OS]) -> 0 | C18: =SUM(entr_carn15[Valor Total]) -> 0 | R18: =IF(vend15[[#This Row],[Nº Venda]]>1,1,0) -> 0
B19: Total | C19: =SUM(C18:C18) -> 0 | R19: =IF(vend15[[#This Row],[Nº Venda]]>1,1,0) -> 0
R20: =IF(vend15[[#This Row],[Nº Venda]]>1,1,0) -> 0
B21: Venda | C21: =C5 -> 7350
E24: Restante Entrada
E25: Nº Venda | F25: Cliente | G25: Forma de Pgto | H25: Valor Venda | I25: Entrada
E26: 4157 | F26: JACINTO FELICIANO | G26: DN | I26: 175
E33: Recebimento de Carnê | K33: Entrega de Carne
E34: OS | F34: Cliente | G34: Forma de Pgto | H34: Valor Parcela | I34: Nº Parcela | K34: OS | L34: Parcelas | M34: Valor Total
E35: 4013 | F35: CELI RAMOS | G35: PIX | H35: 334 | I35: PARC. 3/7
Q40: Total de OS | R40: =SUM(R6:R21) -> 12

Sheet 17
B1: ='16'!B1+1 -> 45429
B2: Fechamento Diário do Caixa
B4: Saldo Inicial | C4: 0 | E4: Vendas | K4: Despesas
B5: Vendas | C5: =SUMIF(I6:I31,">0",H6:H31) -> 1250 | E5: Nº Venda | F5: Cliente | G5: Forma de Pgto | H5: Valor Venda | I5: Entrada | K5: Descrição | L5: Tipo de Pagto | M5: Valor
B6: Entrada | C6: =SUM(I6:I41) -> 850 | E6: 4252 | F6: IURAPUAN LUIZ | G6: PIX | H6: 1250 | I6: 50 | R6: =IF(vend17[[#This Row],[Nº Venda]]>1,1,0) -> 1
B7: Despesas | C7: =SUM(M6:M11) -> 0 | E7: 4253 | F7: IURAPUAN LUIZ | G7: SS | H7: 0 | I7: 0 | R7: =IF(vend17[[#This Row],[Nº Venda]]>1,1,0) -> 1
B8: Total entrada | C8: =SUM(C6:C7) -> 850 | R8: =IF(vend17[[#This Row],[Nº Venda]]>1,1,0) -> 0
R9: =IF(vend17[[#This Row],[Nº Venda]]>1,1,0) -> 0
B10: Tipos de Pagtos | R10: =IF(vend17[[#This Row],[Nº Venda]]>1,1,0) -> 0
B11: DN | C11: =(SUMIF($G$2:$G$31,B11,$I$2:$I$31))+(SUMIF($G$35:$G$41,B11,$H$35:$H$41)) -> 0 | O11: =IF(C15=0,0,1) -> 1 | R11: =IF(vend17[[#This Row],[Nº Venda]]>1,1,0) -> 0
B12: CTD | C12: =(SUMIF($G$2:$G$31,B12,$I$2:$I$31))+(SUMIF($G$35:$G$41,B12,$H$35:$H$41)) -> 150 | R12: =IF(vend17[[#This Row],[Nº Venda]]>1,1,0) -> 0
B13: CTC | C13: =(SUMIF($G$2:$G$31,B13,$I$2:$I$31))+(SUMIF($G$35:$G$41,B13,$H$35:$H$41)) -> 650 | K13: OS Entregue no Dia | R13: =IF(vend17[[#This Row],[Nº Venda]]>1,1,0) -> 0
B14: PIX | C14: =(SUMIF($G$2:$G$31,B14,$I$2:$I$31))+(SUMIF($G$35:$G$41,B14,$H$35:$H$41)) -> 50 | K14: OS | L14: Vendedor | M14: CARNE | R14: =IF(vend17[[#This Row],[Nº Venda]]>1,1,0) -> 0
B15: Total | C15: =SUM(C11:C14) -> 850 | K15: 4217 | L15: BETH | M15: Não | R15: =IF(vend17[[#This Row],[Nº Venda]]>1,1,0) -> 0
K16: 4183 | L16: BETH | M16: Sim | R16: =IF(vend17[[#This Row],[Nº Venda]]>1,1,0) -> 0
B17: Entrega de Carne | K17: 4184 | L17: BETH | M17: Sim | R17: =IF(vend17[[#This Row],[Nº Venda]]>1,1,0) -> 0
B18: =COUNT(entr_carn17[OS]) -> 2 | C18: =SUM(entr_carn17[Valor Total]) -> 600 | K18: 4236 | L18: BETH | M18: Não | R18: =IF(vend17[[#This Row],[Nº Venda]]>1,1,0) -> 0
B19: Total | C19: =SUM(C18:C18) -> 600 | R19: =IF(vend17[[#This Row],[Nº Venda]]>1,1,0) -> 0
R20: =IF(vend17[[#This Row],[Nº Venda]]>1,1,0) -> 0
B21: Venda | C21: =C5 -> 1250
E24: Restante Entrada
E25: Nº Venda | F25: Cliente | G25: Forma de Pgto | H25: Valor Venda | I25: Entrada
E26: 4217 | F26: ELIZA ROSA DE LIMA | G26: CTC | I26: 650
E27: 4183 | F27: JOSEFA DEA SILVA | G27: CTD | I27: 75
E28: 4184 | F28: JOSEFA DA SILVA | G28: CTD | I28: 75
E33: Recebimento de Carnê | K33: Entrega de Carne
E34: OS | F34: Cliente | G34: Forma de Pgto | H34: Valor Parcela | I34: Nº Parcela | K34: OS | L34: Parcelas | M34: Valor Total
K35: 4183 | L35: 5 | M35: 300
K36: 4184 | L36: 5 | M36: 300
Q40: Total de OS | R40: =SUM(R6:R21) -> 2

Sheet 16
B1: ='15'!B1+1 -> 45428
B2: Fechamento Diário do Caixa
B4: Saldo Inicial | C4: 0 | E4: Vendas | K4: Despesas
B5: Vendas | C5: =SUMIF(I6:I31,">0",H6:H31) -> 0 | E5: Nº Venda | F5: Cliente | G5: Forma de Pgto | H5: Valor Venda | I5: Entrada | K5: Descrição | L5: Tipo de Pagto | M5: Valor
B6: Entrada | C6: =SUM(I6:I41) -> 40 | R6: =IF(vend16[[#This Row],[Nº Venda]]>1,1,0) -> 0
B7: Despesas | C7: =SUM(M6:M11) -> 0 | R7: =IF(vend16[[#This Row],[Nº Venda]]>1,1,0) -> 0
B8: Total entrada | C8: =SUM(C6:C7) -> 40 | R8: =IF(vend16[[#This Row],[Nº Venda]]>1,1,0) -> 0
R9: =IF(vend16[[#This Row],[Nº Venda]]>1,1,0) -> 0
B10: Tipos de Pagtos | R10: =IF(vend16[[#This Row],[Nº Venda]]>1,1,0) -> 0
B11: DN | C11: =(SUMIF($G$2:$G$31,B11,$I$2:$I$31))+(SUMIF($G$35:$G$41,B11,$H$35:$H$41)) -> 0 | O11: =IF(C15=0,0,1) -> 1 | R11: =IF(vend16[[#This Row],[Nº Venda]]>1,1,0) -> 0
B12: CTD | C12: =(SUMIF($G$2:$G$31,B12,$I$2:$I$31))+(SUMIF($G$35:$G$41,B12,$H$35:$H$41)) -> 40 | R12: =IF(vend16[[#This Row],[Nº Venda]]>1,1,0) -> 0
B13: CTC | C13: =(SUMIF($G$2:$G$31,B13,$I$2:$I$31))+(SUMIF($G$35:$G$41,B13,$H$35:$H$41)) -> 0 | K13: OS Entregue no Dia | R13: =IF(vend16[[#This Row],[Nº Venda]]>1,1,0) -> 0
B14: PIX | C14: =(SUMIF($G$2:$G$31,B14,$I$2:$I$31))+(SUMIF($G$35:$G$41,B14,$H$35:$H$41)) -> 200 | K14: OS | L14: Vendedor | M14: CARNE | R14: =IF(vend16[[#This Row],[Nº Venda]]>1,1,0) -> 0
B15: Total | C15: =SUM(C11:C14) -> 240 | K15: 4222 | L15: BETH | M15: Não | R15: =IF(vend16[[#This Row],[Nº Venda]]>1,1,0) -> 0
K16: 4218 | L16: BETH | M16: Não | R16: =IF(vend16[[#This Row],[Nº Venda]]>1,1,0) -> 0
B17: Entrega de Carne | R17: =IF(vend16[[#This Row],[Nº Venda]]>1,1,0) -> 0
B18: =COUNT(entr_carn16[OS]) -> 0 | C18: =SUM(entr_carn16[Valor Total]) -> 0 | R18: =IF(vend16[[#This Row],[Nº Venda]]>1,1,0) -> 0
B19: Total | C19: =SUM(C18:C18) -> 0 | R19: =IF(vend16[[#This Row],[Nº Venda]]>1,1,0) -> 0
R20: =IF(vend16[[#This Row],[Nº Venda]]>1,1,0) -> 0
B21: Venda | C21: =C5 -> 0
E24: Restante Entrada
E25: Nº Venda | F25: Cliente | G25: Forma de Pgto | H25: Valor Venda | I25: Entrada
E26: 4218 | F26: JOSÉLIA MARIA | G26: CTD | I26: 40
E33: Recebimento de Carnê | K33: Entrega de Carne
E34: OS | F34: Cliente | G34: Forma de Pgto | H34: Valor Parcela | I34: Nº Parcela | K34: OS | L34: Parcelas | M34: Valor Total
E35: 4125 | F35: MARIA DO CARMNO SILVA | G35: PIX | H35: 200 | I35: PARC. 1/5
Q40: Total de OS | R40: =SUM(R6:R21) -> 0

Sheet 18
B1: ='17'!B1+1 -> 45430
B2: Fechamento Diário do Caixa
B4: Saldo Inicial | C4: 0 | E4: Vendas | K4: Despesas
B5: Vendas | C5: =SUMIF(I6:I31,">0",H6:H31) -> 3500 | E5: Nº Venda | F5: Cliente | G5: Forma de Pgto | H5: Valor Venda | I5: Entrada | K5: Descrição | L5: Tipo de Pagto | M5: Valor
B6: Entrada | C6: =SUM(I6:I41) -> 1299.99 | E6: 4254 | F6: VERONICE DOS SANTOS | G6: PIX | H6: 1400 | I6: 150 | R6: =IF(vend18[[#This Row],[Nº Venda]]>1,1,0) -> 1
B7: Despesas | C7: =SUM(M6:M11) -> 0 | E7: 4255 | F7: SERGIO ROBERTO | G7: PIX | H7: 1250 | I7: 100 | R7: =IF(vend18[[#This Row],[Nº Venda]]>1,1,0) -> 1
B8: Total entrada | C8: =SUM(C6:C7) -> 1299.99 | E8: 4256 | F8: SERGIO ROBERTO | G8: PIX | H8: 850 | I8: 49.99 | R8: =IF(vend18[[#This Row],[Nº Venda]]>1,1,0) -> 1
R9: =IF(vend18[[#This Row],[Nº Venda]]>1,1,0) -> 0
B10: Tipos de Pagtos | R10: =IF(vend18[[#This Row],[Nº Venda]]>1,1,0) -> 0
B11: DN | C11: =(SUMIF($G$2:$G$31,B11,$I$2:$I$31))+(SUMIF($G$35:$G$41,B11,$H$35:$H$41)) -> 0 | O11: =IF(C15=0,0,1) -> 1 | R11: =IF(vend18[[#This Row],[Nº Venda]]>1,1,0) -> 0
B12: CTD | C12: =(SUMIF($G$2:$G$31,B12,$I$2:$I$31))+(SUMIF($G$35:$G$41,B12,$H$35:$H$41)) -> 125 | R12: =IF(vend18[[#This Row],[Nº Venda]]>1,1,0) -> 0
B13: CTC | C13: =(SUMIF($G$2:$G$31,B13,$I$2:$I$31))+(SUMIF($G$35:$G$41,B13,$H$35:$H$41)) -> 1000 | K13: OS Entregue no Dia | R13: =IF(vend18[[#This Row],[Nº Venda]]>1,1,0) -> 0
B14: PIX | C14: =(SUMIF($G$2:$G$31,B14,$I$2:$I$31))+(SUMIF($G$35:$G$41,B14,$H$35:$H$41)) -> 299.99 | K14: OS | L14: Vendedor | M14: CARNE | R14: =IF(vend18[[#This Row],[Nº Venda]]>1,1,0) -> 0
B15: Total | C15: =SUM(C11:C14) -> 1424.99 | K15: 4216 | L15: BETH | M15: Sim | R15: =IF(vend18[[#This Row],[Nº Venda]]>1,1,0) -> 0
K16: 4224 | L16: LARISSA | M16: Não | R16: =IF(vend18[[#This Row],[Nº Venda]]>1,1,0) -> 0
B17: Entrega de Carne | K17: 4215 | L17: BETH | M17: Não | R17: =IF(vend18[[#This Row],[Nº Venda]]>1,1,0) -> 0
B18: =COUNT(entr_carn18[OS]) -> 1 | C18: =SUM(entr_carn18[Valor Total]) -> 649 | K18: 4212 | L18: BETH | M18: Não | R18: =IF(vend18[[#This Row],[Nº Venda]]>1,1,0) -> 0
B19: Total | C19: =SUM(C18:C18) -> 649 | R19: =IF(vend18[[#This Row],[Nº Venda]]>1,1,0) -> 0
R20: =IF(vend18[[#This Row],[Nº Venda]]>1,1,0) -> 0
B21: Venda | C21: =C5 -> 3500
E24: Restante Entrada
E25: Nº Venda | F25: Cliente | G25: Forma de Pgto | H25: Valor Venda | I25: Entrada
E26: 4215 | F26: ROSENILDO DE JESUS | G26: CTC | I26: 1000
E33: Recebimento de Carnê | K33: Entrega de Carne
E34: OS | F34: Cliente | G34: Forma de Pgto | H34: Valor Parcela | I34: Nº Parcela | K34: OS | L34: Parcelas | M34: Valor Total
E35: 4104 | F35: JOÃO CARLOS | G35: CTD | H35: 125 | I35: PARC. 2/4 | K35: 4216 | L35: 3 | M35: 649
Q40: Total de OS | R40: =SUM(R6:R21) -> 3

Sheet 19
B1: ='18'!B1+1 -> 45431
B2: Fechamento Diário do Caixa
B4: Saldo Inicial | C4: 0 | E4: Vendas | K4: Despesas
B5: Vendas | C5: =SUMIF(I6:I31,">0",H6:H31) -> 0 | E5: Nº Venda | F5: Cliente | G5: Forma de Pgto | H5: Valor Venda | I5: Entrada | K5: Descrição | L5: Tipo de Pagto | M5: Valor
B6: Entrada | C6: =SUM(I6:I41) -> 0 | R6: =IF(vend19[[#This Row],[Nº Venda]]>1,1,0) -> 0
B7: Despesas | C7: =SUM(M6:M11) -> 0 | R7: =IF(vend19[[#This Row],[Nº Venda]]>1,1,0) -> 0
B8: Total entrada | C8: =SUM(C6:C7) -> 0 | R8: =IF(vend19[[#This Row],[Nº Venda]]>1,1,0) -> 0
R9: =IF(vend19[[#This Row],[Nº Venda]]>1,1,0) -> 0
B10: Tipos de Pagtos | R10: =IF(vend19[[#This Row],[Nº Venda]]>1,1,0) -> 0
B11: DN | C11: =(SUMIF($G$2:$G$31,B11,$I$2:$I$31))+(SUMIF($G$35:$G$41,B11,$H$35:$H$41)) -> 0 | O11: =IF(C15=0,0,1) -> 0 | R11: =IF(vend19[[#This Row],[Nº Venda]]>1,1,0) -> 0
B12: CTD | C12: =(SUMIF($G$2:$G$31,B12,$I$2:$I$31))+(SUMIF($G$35:$G$41,B12,$H$35:$H$41)) -> 0 | R12: =IF(vend19[[#This Row],[Nº Venda]]>1,1,0) -> 0
B13: CTC | C13: =(SUMIF($G$2:$G$31,B13,$I$2:$I$31))+(SUMIF($G$35:$G$41,B13,$H$35:$H$41)) -> 0 | K13: OS Entregue no Dia | R13: =IF(vend19[[#This Row],[Nº Venda]]>1,1,0) -> 0
B14: PIX | C14: =(SUMIF($G$2:$G$31,B14,$I$2:$I$31))+(SUMIF($G$35:$G$41,B14,$H$35:$H$41)) -> 0 | K14: OS | L14: Vendedor | M14: CARNE | R14: =IF(vend19[[#This Row],[Nº Venda]]>1,1,0) -> 0
B15: Total | C15: =SUM(C11:C14) -> 0 | R15: =IF(vend19[[#This Row],[Nº Venda]]>1,1,0) -> 0
R16: =IF(vend19[[#This Row],[Nº Venda]]>1,1,0) -> 0
B17: Entrega de Carne | R17: =IF(vend19[[#This Row],[Nº Venda]]>1,1,0) -> 0
B18: =COUNT(entr_carn19[OS]) -> 0 | C18: =SUM(entr_carn19[Valor Total]) -> 0 | R18: =IF(vend19[[#This Row],[Nº Venda]]>1,1,0) -> 0
B19: Total | C19: =SUM(C18:C18) -> 0 | R19: =IF(vend19[[#This Row],[Nº Venda]]>1,1,0) -> 0
R20: =IF(vend19[[#This Row],[Nº Venda]]>1,1,0) -> 0
B21: Venda | C21: =C5 -> 0
E24: Restante Entrada
E25: Nº Venda | F25: Cliente | G25: Forma de Pgto | H25: Valor Venda | I25: Entrada
E33: Recebimento de Carnê | K33: Entrega de Carne
E34: OS | F34: Cliente | G34: Forma de Pgto | H34: Valor Parcela | I34: Nº Parcela | K34: OS | L34: Parcelas | M34: Valor Total
Q40: Total de OS | R40: =SUM(R6:R21) -> 0

Sheet 20
B1: ='19'!B1+1 -> 45432
B2: Fechamento Diário do Caixa
B4: Saldo Inicial | C4: 0 | E4: Vendas | K4: Despesas
B5: Vendas | C5: =SUMIF(I6:I31,">0",H6:H31) -> 0 | E5: Nº Venda | F5: Cliente | G5: Forma de Pgto | H5: Valor Venda | I5: Entrada | K5: Descrição | L5: Tipo de Pagto | M5: Valor
B6: Entrada | C6: =SUM(I6:I41) -> 205 | R6: =IF(vend20[[#This Row],[Nº Venda]]>1,1,0) -> 0
B7: Despesas | C7: =SUM(M6:M11) -> 0 | R7: =IF(vend20[[#This Row],[Nº Venda]]>1,1,0) -> 0
B8: Total entrada | C8: =SUM(C6:C7) -> 205 | R8: =IF(vend20[[#This Row],[Nº Venda]]>1,1,0) -> 0
R9: =IF(vend20[[#This Row],[Nº Venda]]>1,1,0) -> 0
B10: Tipos de Pagtos | R10: =IF(vend20[[#This Row],[Nº Venda]]>1,1,0) -> 0
B11: DN | C11: =(SUMIF($G$2:$G$31,B11,$I$2:$I$31))+(SUMIF($G$35:$G$41,B11,$H$35:$H$41)) -> 185 | O11: =IF(C15=0,0,1) -> 1 | R11: =IF(vend20[[#This Row],[Nº Venda]]>1,1,0) -> 0
B12: CTD | C12: =(SUMIF($G$2:$G$31,B12,$I$2:$I$31))+(SUMIF($G$35:$G$41,B12,$H$35:$H$41)) -> 0 | R12: =IF(vend20[[#This Row],[Nº Venda]]>1,1,0) -> 0
B13: CTC | C13: =(SUMIF($G$2:$G$31,B13,$I$2:$I$31))+(SUMIF($G$35:$G$41,B13,$H$35:$H$41)) -> 0 | K13: OS Entregue no Dia | R13: =IF(vend20[[#This Row],[Nº Venda]]>1,1,0) -> 0
B14: PIX | C14: =(SUMIF($G$2:$G$31,B14,$I$2:$I$31))+(SUMIF($G$35:$G$41,B14,$H$35:$H$41)) -> 400 | K14: OS | L14: Vendedor | M14: CARNE | R14: =IF(vend20[[#This Row],[Nº Venda]]>1,1,0) -> 0
B15: Total | C15: =SUM(C11:C14) -> 585 | K15: 4244 | L15: BETH | M15: Não | R15: =IF(vend20[[#This Row],[Nº Venda]]>1,1,0) -> 0
K16: 4219 | L16: BETH | M16: Sim | R16: =IF(vend20[[#This Row],[Nº Venda]]>1,1,0) -> 0
B17: Entrega de Carne | R17: =IF(vend20[[#This Row],[Nº Venda]]>1,1,0) -> 0
B18: =COUNT(entr_carn20[OS]) -> 1 | C18: =SUM(entr_carn20[Valor Total]) -> 699 | R18: =IF(vend20[[#This Row],[Nº Venda]]>1,1,0) -> 0
B19: Total | C19: =SUM(C18:C18) -> 699 | R19: =IF(vend20[[#This Row],[Nº Venda]]>1,1,0) -> 0
R20: =IF(vend20[[#This Row],[Nº Venda]]>1,1,0) -> 0
B21: Venda | C21: =C5 -> 0
E24: Restante Entrada
E25: Nº Venda | F25: Cliente | G25: Forma de Pgto | H25: Valor Venda | I25: Entrada
E26: 4125 | F26: VITÓRIA REGINA | G26: PIX | I26: 50
E27: 4126 | F27: VITÓRIA REGINA | G27: PIX | I27: 50
E28: 4244 | F28: ANDREIA GOMES | G28: DN | I28: 35
E29: 4231 | F29: ISALTINA JULIA SANTOS | G29: PIX | I29: 35
E30: 4234 | F30: ISALTINA JULIA SANTOS | G30: PIX | I30: 35
E33: Recebimento de Carnê | K33: Entrega de Carne
E34: OS | F34: Cliente | G34: Forma de Pgto | H34: Valor Parcela | I34: Nº Parcela | K34: OS | L34: Parcelas | M34: Valor Total
E35: 4091 | F35: SABRINA DA SILVA | G35: PIX | H35: 230 | I35: PARC. 2/5 | K35: 4219 | L35: 5 | M35: 699
E36: 4161 | F36: ILVANETE PEREIRA | G36: DN | H36: 150 | I36: PARC. 5/5
Q40: Total de OS | R40: =SUM(R6:R21) -> 0

Sheet 21
B1: ='20'!B1+1 -> 45433
B2: Fechamento Diário do Caixa
B4: Saldo Inicial | C4: 0 | E4: Vendas | K4: Despesas
B5: Vendas | C5: =SUMIF(I6:I31,">0",H6:H31) -> 1450 | E5: Nº Venda | F5: Cliente | G5: Forma de Pgto | H5: Valor Venda | I5: Entrada | K5: Descrição | L5: Tipo de Pagto | M5: Valor
B6: Entrada | C6: =SUM(I6:I41) -> 1150 | E6: 4257 | F6: JANAINA DOS SANTOS | G6: PIX | H6: 450 | I6: 150 | R6: =IF(vend21[[#This Row],[Nº Venda]]>1,1,0) -> 1
B7: Despesas | C7: =SUM(M6:M11) -> 0 | E7: 4258 | F7: DOUGLAS LOPES | G7: PIX | H7: 850 | I7: 150 | R7: =IF(vend21[[#This Row],[Nº Venda]]>1,1,0) -> 1
B8: Total entrada | C8: =SUM(C6:C7) -> 1150 | E8: 4259 | F8: RAQUEL BATISTA | G8: GARANTIA | R8: =IF(vend21[[#This Row],[Nº Venda]]>1,1,0) -> 1
E9: 4260 | F9: JANETE DOS ANJOS | G9: CTC | H9: 150 | I9: 150 | R9: =IF(vend21[[#This Row],[Nº Venda]]>1,1,0) -> 1
B10: Tipos de Pagtos | R10: =IF(vend21[[#This Row],[Nº Venda]]>1,1,0) -> 0
B11: DN | C11: =(SUMIF($G$2:$G$31,B11,$I$2:$I$31))+(SUMIF($G$35:$G$41,B11,$H$35:$H$41)) -> 0 | O11: =IF(C15=0,0,1) -> 1 | R11: =IF(vend21[[#This Row],[Nº Venda]]>1,1,0) -> 0
B12: CTD | C12: =(SUMIF($G$2:$G$31,B12,$I$2:$I$31))+(SUMIF($G$35:$G$41,B12,$H$35:$H$41)) -> 0 | R12: =IF(vend21[[#This Row],[Nº Venda]]>1,1,0) -> 0
B13: CTC | C13: =(SUMIF($G$2:$G$31,B13,$I$2:$I$31))+(SUMIF($G$35:$G$41,B13,$H$35:$H$41)) -> 850 | K13: OS Entregue no Dia | R13: =IF(vend21[[#This Row],[Nº Venda]]>1,1,0) -> 0
B14: PIX | C14: =(SUMIF($G$2:$G$31,B14,$I$2:$I$31))+(SUMIF($G$35:$G$41,B14,$H$35:$H$41)) -> 544 | K14: OS | L14: Vendedor | M14: CARNE | R14: =IF(vend21[[#This Row],[Nº Venda]]>1,1,0) -> 0
B15: Total | C15: =SUM(C11:C14) -> 1394 | K15: 4228 | L15: BETH | M15: Não | R15: =IF(vend21[[#This Row],[Nº Venda]]>1,1,0) -> 0
K16: 4213 | L16: BETH | M16: Não | R16: =IF(vend21[[#This Row],[Nº Venda]]>1,1,0) -> 0
B17: Entrega de Carne | K17: 4221 | L17: BETH | M17: Não | R17: =IF(vend21[[#This Row],[Nº Venda]]>1,1,0) -> 0
B18: =COUNT(entr_carn21[OS]) -> 0 | C18: =SUM(entr_carn21[Valor Total]) -> 0 | R18: =IF(vend21[[#This Row],[Nº Venda]]>1,1,0) -> 0
B19: Total | C19: =SUM(C18:C18) -> 0 | R19: =IF(vend21[[#This Row],[Nº Venda]]>1,1,0) -> 0
R20: =IF(vend21[[#This Row],[Nº Venda]]>1,1,0) -> 0
B21: Venda | C21: =C5 -> 1450
E24: Restante Entrada
E25: Nº Venda | F25: Cliente | G25: Forma de Pgto | H25: Valor Venda | I25: Entrada
E26: 4221 | F26: IVO FERREIRA | G26: CTC | I26: 700
E33: Recebimento de Carnê | K33: Entrega de Carne
E34: OS | F34: Cliente | G34: Forma de Pgto | H34: Valor Parcela | I34: Nº Parcela | K34: OS | L34: Parcelas | M34: Valor Total
E35: 4004 | F35: TAIANE SILVA | G35: PIX | H35: 64 | I35: PARC. 4/4
E36: 3971 | F36: JOSEMARE SOARES | G36: PIX | H36: 180 | I36: PARC. 4/4
Q40: Total de OS | R40: =SUM(R6:R21) -> 4

Sheet 22
B1: ='21'!B1+1 -> 45434
B2: Fechamento Diário do Caixa
B4: Saldo Inicial | C4: 0 | E4: Vendas | K4: Despesas
B5: Vendas | C5: =SUMIF(I6:I31,">0",H6:H31) -> 1300 | E5: Nº Venda | F5: Cliente | G5: Forma de Pgto | H5: Valor Venda | I5: Entrada | K5: Descrição | L5: Tipo de Pagto | M5: Valor
B6: Entrada | C6: =SUM(I6:I41) -> 680 | E6: 4261 | F6: EDIMILSON ZERBETTI | G6: GARANTIA | R6: =IF(vend22[[#This Row],[Nº Venda]]>1,1,0) -> 1
B7: Despesas | C7: =SUM(M6:M11) -> 0 | E7: 4262 | F7: SULAMITA RENATA | G7: CTC | H7: 1300 | I7: 150 | R7: =IF(vend22[[#This Row],[Nº Venda]]>1,1,0) -> 1
B8: Total entrada | C8: =SUM(C6:C7) -> 680 | R8: =IF(vend22[[#This Row],[Nº Venda]]>1,1,0) -> 0
R9: =IF(vend22[[#This Row],[Nº Venda]]>1,1,0) -> 0
B10: Tipos de Pagtos | R10: =IF(vend22[[#This Row],[Nº Venda]]>1,1,0) -> 0
B11: DN | C11: =(SUMIF($G$2:$G$31,B11,$I$2:$I$31))+(SUMIF($G$35:$G$41,B11,$H$35:$H$41)) -> 0 | O11: =IF(C15=0,0,1) -> 1 | R11: =IF(vend22[[#This Row],[Nº Venda]]>1,1,0) -> 0
B12: CTD | C12: =(SUMIF($G$2:$G$31,B12,$I$2:$I$31))+(SUMIF($G$35:$G$41,B12,$H$35:$H$41)) -> 130 | R12: =IF(vend22[[#This Row],[Nº Venda]]>1,1,0) -> 0
B13: CTC | C13: =(SUMIF($G$2:$G$31,B13,$I$2:$I$31))+(SUMIF($G$35:$G$41,B13,$H$35:$H$41)) -> 350 | K13: OS Entregue no Dia | R13: =IF(vend22[[#This Row],[Nº Venda]]>1,1,0) -> 0
B14: PIX | C14: =(SUMIF($G$2:$G$31,B14,$I$2:$I$31))+(SUMIF($G$35:$G$41,B14,$H$35:$H$41)) -> 480 | K14: OS | L14: Vendedor | M14: CARNE | R14: =IF(vend22[[#This Row],[Nº Venda]]>1,1,0) -> 0
B15: Total | C15: =SUM(C11:C14) -> 960 | K15: 4225 | L15: BETH | M15: Sim | R15: =IF(vend22[[#This Row],[Nº Venda]]>1,1,0) -> 0
K16: 4226 | L16: BETH | M16: Sim | R16: =IF(vend22[[#This Row],[Nº Venda]]>1,1,0) -> 0
B17: Entrega de Carne | K17: 4249 | L17: TATY | M17: Sim | R17: =IF(vend22[[#This Row],[Nº Venda]]>1,1,0) -> 0
B18: =COUNT(entr_carn22[OS]) -> 3 | C18: =SUM(entr_carn22[Valor Total]) -> 1090 | K18: 4269 | L18: BETH | M18: Não | R18: =IF(vend22[[#This Row],[Nº Venda]]>1,1,0) -> 0
B19: Total | C19: =SUM(C18:C18) -> 1090 | R19: =IF(vend22[[#This Row],[Nº Venda]]>1,1,0) -> 0
R20: =IF(vend22[[#This Row],[Nº Venda]]>1,1,0) -> 0
B21: Venda | C21: =C5 -> 1300
E24: Restante Entrada
