Workbook

Sheet resumo_cx
A2: Saldo Inicial | B2: 0
A3: Vendas | B3: =SUM('01'!C5,'02'!C5,'03'!C5,'04'!C5,'05'!C5,'06'!C5,'07'!C5,'08'!C5,'09'!C5,'10'!C5,'11'!C5,'12'!C5,'13'!C5,'14'!C5,'15'!C5,'16'!C5,'17'!C5,'18'!C5,'19'!C5,'20'!C5,'21'!C5,'22'!C5,'23'!C5,'24'!C5,'25'!C5,'26'!C5,'27'!C5,'28'!C5,'29'!C5,'30'!C5,#REF!) -> #REF!
A4: Entrada | B4: =SUM('01'!C6,'02'!C6,'03'!C6,'04'!C6,'05'!C6,'06'!C6,'07'!C6,'08'!C6,'09'!C6,'10'!C6,'11'!C6,'12'!C6,'13'!C6,'14'!C6,'15'!C6,'16'!C6,'17'!C6,'18'!C6,'19'!C6,'20'!C6,'21'!C6,'22'!C6,'23'!C6,'24'!C6,'25'!C6,'26'!C6,'27'!C6,'28'!C6,'29'!C6,'30'!C6,#REF!) -> #REF!
A5: Despesas | B5: =SUM('01'!C7,'02'!C7,'03'!C7,'04'!C7,'05'!C7,'06'!C7,'07'!C7,'08'!C7,'09'!C7,'10'!C7,'11'!C7,'12'!C7,'13'!C7,'14'!C7,'15'!C7,'16'!C7,'17'!C7,'18'!C7,'19'!C7,'20'!C7,'21'!C7,'22'!C7,'23'!C7,'24'!C7,'25'!C7,'26'!C7,'27'!C7,'28'!C7,'29'!C7,'30'!C7,#REF!) -> #REF!
A6: Entr_Desp | B6: =SUM(B4:B5) -> #REF!
A8: Tipos de Pagtos
A9: DN | B9: =SUM('01'!C11,'02'!C11,'03'!C11,'04'!C11,'05'!C11,'06'!C11,'07'!C11,'08'!C11,'09'!C11,'10'!C11,'11'!C11,'12'!C11,'13'!C11,'14'!C11,'15'!C11,'16'!C11,'17'!C11,'18'!C11,'19'!C11,'20'!C11,'21'!C11,'22'!C11,'23'!C11,'24'!C11,'25'!C11,'26'!C11,'27'!C11,'28'!C11,'29'!C11,'30'!C11,#REF!) -> #REF!
A10: CTD | B10: =SUM('01'!C12,'02'!C12,'03'!C12,'04'!C12,'05'!C12,'06'!C12,'07'!C12,'08'!C12,'09'!C12,'10'!C12,'11'!C12,'12'!C12,'13'!C12,'14'!C12,'15'!C12,'16'!C12,'17'!C12,'18'!C12,'19'!C12,'20'!C12,'21'!C12,'22'!C12,'23'!C12,'24'!C12,'25'!C12,'26'!C12,'27'!C12,'28'!C12,'29'!C12,'30'!C12,#REF!) -> #REF!
A11: CTC | B11: =SUM('01'!C13,'02'!C13,'03'!C13,'04'!C13,'05'!C13,'06'!C13,'07'!C13,'08'!C13,'09'!C13,'10'!C13,'11'!C13,'12'!C13,'13'!C13,'14'!C13,'15'!C13,'16'!C13,'17'!C13,'18'!C13,'19'!C13,'20'!C13,'21'!C13,'22'!C13,'23'!C13,'24'!C13,'25'!C13,'26'!C13,'27'!C13,'28'!C13,'29'!C13,'30'!C13,#REF!) -> #REF!
A12: CTC | B12: =SUM('01'!#REF!,'02'!#REF!,'03'!#REF!,'04'!#REF!,'05'!#REF!,'06'!#REF!,'07'!#REF!,'08'!#REF!,'09'!#REF!,'10'!#REF!,'11'!#REF!,'12'!#REF!,'13'!#REF!,'14'!#REF!,'15'!#REF!,'16'!#REF!,'17'!#REF!,'18'!#REF!,'19'!#REF!,'20'!#REF!,'21'!#REF!,'22'!#REF!,'23'!#REF!,'24'!#REF!,'25'!#REF!,'26'!#REF!,'27'!#REF!,'28'!#REF!,'29'!#REF!,'30'!#REF!,#REF!) -> #REF!
A13: PIX | B13: =SUM('01'!C14,'02'!C14,'03'!C14,'04'!C14,'05'!C14,'06'!C14,'07'!C14,'08'!C14,'09'!C14,'10'!C14,'11'!C14,'12'!C14,'13'!C14,'14'!C14,'15'!C14,'16'!C14,'17'!C14,'18'!C14,'19'!C14,'20'!C14,'21'!C14,'22'!C14,'23'!C14,'24'!C14,'25'!C14,'26'!C14,'27'!C14,'28'!C14,'29'!C14,'30'!C14,#REF!) -> #REF!
A14: Total | B14: =SUM(B9:B13) -> #REF!
A16: Entrega de Carne
A17: =COUNT(#REF!) -> 0 | B17: =SUM('01'!C18,'02'!C18,'03'!C18,'04'!C18,'05'!C18,'06'!C18,'07'!C18,'08'!C18,'09'!C18,'10'!C18,'11'!C18,'12'!C18,'13'!C18,'14'!C18,'15'!C18,'16'!C18,'17'!C18,'18'!C18,'19'!C18,'20'!C18,'21'!C18,'22'!C18,'23'!C18,'24'!C18,'25'!C18,'26'!C18,'27'!C18,'28'!C18,'29'!C18,'30'!C18,#REF!) -> #REF!
A18: Total | B18: =SUM(B17:B17) -> #REF!

Sheet 01
B1: 45413
B2: Fechamento Diário do Caixa
B4: Saldo Inicial | C4: 0 | E4: Vendas | K4: Despesas
B5: Vendas | C5: =SUMIF(I6:I31,">0",H6:H31) -> 0 | E5: Nº Venda | F5: Cliente | G5: Forma de Pgto | H5: Valor Venda | I5: Entrada | K5: Descrição | L5: Tipo de Pagto | M5: Valor
B6: Entrada | C6: =SUM(I6:I41) -> 0 | R6: =IF(vend1[[#This Row],[Nº Venda]]>1,1,0) -> 0
B7: Despesas | C7: =SUM(M6:M11) -> 0 | R7: =IF(vend1[[#This Row],[Nº Venda]]>1,1,0) -> 0
B8: Total entrada | C8: =SUM(C6:C7) -> 0 | R8: =IF(vend1[[#This Row],[Nº Venda]]>1,1,0) -> 0
R9: =IF(vend1[[#This Row],[Nº Venda]]>1,1,0) -> 0
B10: Tipos de Pagtos | R10: =IF(vend1[[#This Row],[Nº Venda]]>1,1,0) -> 0
B11: DN | C11: =(SUMIF($G$2:$G$31,B11,$I$2:$I$31))+(SUMIF($G$35:$G$41,B11,$H$35:$H$41)) -> 0 | O11: =IF(C15=0,0,1) -> 0 | R11: =IF(vend1[[#This Row],[Nº Venda]]>1,1,0) -> 0
B12: CTD | C12: =(SUMIF($G$2:$G$31,B12,$I$2:$I$31))+(SUMIF($G$35:$G$41,B12,$H$35:$H$41)) -> 0 | R12: =IF(vend1[[#This Row],[Nº Venda]]>1,1,0) -> 0
B13: CTC | C13: =(SUMIF($G$2:$G$31,B13,$I$2:$I$31))+(SUMIF($G$35:$G$41,B13,$H$35:$H$41)) -> 0 | K13: OS Entregue no Dia | R13: =IF(vend1[[#This Row],[Nº Venda]]>1,1,0) -> 0
B14: PIX | C14: =(SUMIF($G$2:$G$31,B14,$I$2:$I$31))+(SUMIF($G$35:$G$41,B14,$H$35:$H$41)) -> 0 | K14: OS | L14: Vendedor | M14: CARNE | R14: =IF(vend1[[#This Row],[Nº Venda]]>1,1,0) -> 0
B15: Total | C15: =SUM(C11:C14) -> 0 | R15: =IF(vend1[[#This Row],[Nº Venda]]>1,1,0) -> 0
R16: =IF(vend1[[#This Row],[Nº Venda]]>1,1,0) -> 0
B17: Entrega de Carne | R17: =IF(vend1[[#This Row],[Nº Venda]]>1,1,0) -> 0
B18: =COUNT(entr_carn1[OS]) -> 0 | C18: =SUM(entr_carn1[Valor Total]) -> 0 | R18: =IF(vend1[[#This Row],[Nº Venda]]>1,1,0) -> 0
B19: Total | C19: =SUM(C18:C18) -> 0 | R19: =IF(vend1[[#This Row],[Nº Venda]]>1,1,0) -> 0
R20: =IF(vend1[[#This Row],[Nº Venda]]>1,1,0) -> 0
B21: Venda | C21: =C5 -> 0
E24: Restante Entrada
E25: Nº Venda | F25: Cliente | G25: Forma de Pgto | H25: Valor Venda | I25: Entrada
E33: Recebimento de Carnê | K33: Entrega de Carne
E34: OS | F34: Cliente | G34: Forma de Pgto | H34: Valor Parcela | I34: Nº Parcela | K34: OS | L34: Parcelas | M34: Valor Total
Q40: Total de OS | R40: =SUM(R6:R21) -> 0

Sheet 02
B1: ='01'!B1+1 -> 45414
B2: Fechamento Diário do Caixa
B4: Saldo Inicial | C4: 0 | E4: Vendas | K4: Despesas
B5: Vendas | C5: =SUMIF(I6:I31,">0",H6:H31) -> 150 | E5: Nº Venda | F5: Cliente | G5: Forma de Pgto | H5: Valor Venda | I5: Entrada | K5: Descrição | L5: Tipo de Pagto | M5: Valor
B6: Entrada | C6: =SUM(I6:I41) -> 150 | E6: 669 | F6: JANAINA DAIANE | G6: SS | H6: 70 | R6: =IF(vend2[[#This Row],[Nº Venda]]>1,1,0) -> 1
B7: Despesas | C7: =SUM(M6:M11) -> 0 | E7: 670 | F7: MARILENE PAULA | G7: CTC | H7: 150 | I7: 150 | R7: =IF(vend2[[#This Row],[Nº Venda]]>1,1,0) -> 1
B8: Total entrada | C8: =SUM(C6:C7) -> 150 | R8: =IF(vend2[[#This Row],[Nº Venda]]>1,1,0) -> 0
R9: =IF(vend2[[#This Row],[Nº Venda]]>1,1,0) -> 0
B10: Tipos de Pagtos | R10: =IF(vend2[[#This Row],[Nº Venda]]>1,1,0) -> 0
B11: DN | C11: =(SUMIF($G$2:$G$31,B11,$I$2:$I$31))+(SUMIF($G$35:$G$41,B11,$H$35:$H$41)) -> 158 | O11: =IF(C15=0,0,1) -> 1 | R11: =IF(vend2[[#This Row],[Nº Venda]]>1,1,0) -> 0
B12: CTD | C12: =(SUMIF($G$2:$G$31,B12,$I$2:$I$31))+(SUMIF($G$35:$G$41,B12,$H$35:$H$41)) -> 0 | R12: =IF(vend2[[#This Row],[Nº Venda]]>1,1,0) -> 0
B13: CTC | C13: =(SUMIF($G$2:$G$31,B13,$I$2:$I$31))+(SUMIF($G$35:$G$41,B13,$H$35:$H$41)) -> 150 | K13: OS Entregue no Dia | R13: =IF(vend2[[#This Row],[Nº Venda]]>1,1,0) -> 0
B14: PIX | C14: =(SUMIF($G$2:$G$31,B14,$I$2:$I$31))+(SUMIF($G$35:$G$41,B14,$H$35:$H$41)) -> 0 | K14: Coluna1 | L14: Vendedor | M14: CARNE | R14: =IF(vend2[[#This Row],[Nº Venda]]>1,1,0) -> 0
B15: Total | C15: =SUM(C11:C14) -> 308 | R15: =IF(vend2[[#This Row],[Nº Venda]]>1,1,0) -> 0
R16: =IF(vend2[[#This Row],[Nº Venda]]>1,1,0) -> 0
B17: Entrega de Carne | R17: =IF(vend2[[#This Row],[Nº Venda]]>1,1,0) -> 0
B18: =COUNT(entr_carn2[OS]) -> 0 | C18: =SUM(entr_carn2[Valor Total]) -> 0 | R18: =IF(vend2[[#This Row],[Nº Venda]]>1,1,0) -> 0
B19: Total | C19: =SUM(C18:C18) -> 0 | R19: =IF(vend2[[#This Row],[Nº Venda]]>1,1,0) -> 0
R20: =IF(vend2[[#This Row],[Nº Venda]]>1,1,0) -> 0
B21: Venda | C21: =C5 -> 150
E24: Restante Entrada
E25: Nº Venda | F25: Cliente | G25: Forma de Pgto | H25: Valor Venda | I25: Entrada
E33: Recebimento de Carnê | K33: Entrega de Carne
E34: OS | F34: Cliente | G34: Forma de Pgto | H34: Valor Parcela | I34: Nº Parcela | K34: OS | L34: Parcelas | M34: Valor Total
E35: 618 | F35: CICERA DE LIMA | G35: DN | H35: 158 | I35: PARC. 1/6
Q40: Total de OS | R40: =SUM(R6:R21) -> 2

Sheet 03
B1: ='02'!B1+1 -> 45415
B2: Fechamento Diário do Caixa
B4: Saldo Inicial | C4: 0 | E4: Vendas | K4: Despesas
B5: Vendas | C5: =SUMIF(I6:I31,">0",H6:H31) -> 0 | E5: Nº Venda | F5: Cliente | G5: Forma de Pgto | H5: Valor Venda | I5: Entrada | K5: Descrição | L5: Tipo de Pagto | M5: Valor
B6: Entrada | C6: =SUM(I6:I41) -> 200 | R6: =IF(vend3[[#This Row],[Nº Venda]]>1,1,0) -> 0
B7: Despesas | C7: =SUM(M6:M11) -> 0 | R7: =IF(vend3[[#This Row],[Nº Venda]]>1,1,0) -> 0
B8: Total entrada | C8: =SUM(C6:C7) -> 200 | R8: =IF(vend3[[#This Row],[Nº Venda]]>1,1,0) -> 0
R9: =IF(vend3[[#This Row],[Nº Venda]]>1,1,0) -> 0
B10: Tipos de Pagtos | R10: =IF(vend3[[#This Row],[Nº Venda]]>1,1,0) -> 0
B11: DN | C11: =(SUMIF($G$2:$G$31,B11,$I$2:$I$31))+(SUMIF($G$35:$G$41,B11,$H$35:$H$41)) -> 0 | O11: =IF(C15=0,0,1) -> 1 | R11: =IF(vend3[[#This Row],[Nº Venda]]>1,1,0) -> 0
B12: CTD | C12: =(SUMIF($G$2:$G$31,B12,$I$2:$I$31))+(SUMIF($G$35:$G$41,B12,$H$35:$H$41)) -> 0 | R12: =IF(vend3[[#This Row],[Nº Venda]]>1,1,0) -> 0
B13: CTC | C13: =(SUMIF($G$2:$G$31,B13,$I$2:$I$31))+(SUMIF($G$35:$G$41,B13,$H$35:$H$41)) -> 0 | K13: OS Entregue no Dia | R13: =IF(vend3[[#This Row],[Nº Venda]]>1,1,0) -> 0
B14: PIX | C14: =(SUMIF($G$2:$G$31,B14,$I$2:$I$31))+(SUMIF($G$35:$G$41,B14,$H$35:$H$41)) -> 200 | K14: OS | L14: Vendedor | M14: CARNE | R14: =IF(vend3[[#This Row],[Nº Venda]]>1,1,0) -> 0
B15: Total | C15: =SUM(C11:C14) -> 200 | K15: 664 | L15: LUANA | M15: Não | R15: =IF(vend3[[#This Row],[Nº Venda]]>1,1,0) -> 0
R16: =IF(vend3[[#This Row],[Nº Venda]]>1,1,0) -> 0
B17: Entrega de Carne | R17: =IF(vend3[[#This Row],[Nº Venda]]>1,1,0) -> 0
B18: =COUNT(entr_carn3[OS]) -> 0 | C18: =SUM(entr_carn3[Valor Total]) -> 0 | R18: =IF(vend3[[#This Row],[Nº Venda]]>1,1,0) -> 0
B19: Total | C19: =SUM(C18:C18) -> 0 | R19: =IF(vend3[[#This Row],[Nº Venda]]>1,1,0) -> 0
R20: =IF(vend3[[#This Row],[Nº Venda]]>1,1,0) -> 0
B21: Venda | C21: =C5 -> 0
E24: Restante Entrada
E25: Nº Venda | F25: Cliente | G25: Forma de Pgto | H25: Valor Venda | I25: Entrada
E26: 664 | F26: JAO IRAN | G26: PIX | H26: 0 | I26: 200
E33: Recebimento de Carnê | K33: Entrega de Carne
E34: OS | F34: Cliente | G34: Forma de Pgto | H34: Valor Parcela | I34: Nº Parcela | K34: OS | L34: Parcelas | M34: Valor Total
Q40: Total de OS | R40: =SUM(R6:R21) -> 0

Sheet 04
B1: ='03'!B1+1 -> 45416
B2: Fechamento Diário do Caixa
B4: Saldo Inicial | C4: 0 | E4: Vendas | K4: Despesas
B5: Vendas | C5: =SUMIF(I6:I31,">0",H6:H31) -> 2850 | E5: Nº Venda | F5: Cliente | G5: Forma de Pgto | H5: Valor Venda | I5: Entrada | K5: Descrição | L5: Tipo de Pagto | M5: Valor
B6: Entrada | C6: =SUM(I6:I41) -> 1250 | E6: 671 | F6: MARIA VILMA | G6: CTC | H6: 1100 | I6: 1100 | R6: =IF(vend4[[#This Row],[Nº Venda]]>1,1,0) -> 1
B7: Despesas | C7: =SUM(M6:M11) -> 0 | E7: 672 | F7: PATRICIA PACIFICO | G7: PIX | H7: 1150 | I7: 50 | R7: =IF(vend4[[#This Row],[Nº Venda]]>1,1,0) -> 1
B8: Total entrada | C8: =SUM(C6:C7) -> 1250 | E8: 673 | F8: MARIA MOURO | G8: DN | H8: 600 | I8: 100 | R8: =IF(vend4[[#This Row],[Nº Venda]]>1,1,0) -> 1
R9: =IF(vend4[[#This Row],[Nº Venda]]>1,1,0) -> 0
B10: Tipos de Pagtos | R10: =IF(vend4[[#This Row],[Nº Venda]]>1,1,0) -> 0
B11: DN | C11: =(SUMIF($G$2:$G$31,B11,$I$2:$I$31))+(SUMIF($G$35:$G$41,B11,$H$35:$H$41)) -> 100 | O11: =IF(C15=0,0,1) -> 1 | R11: =IF(vend4[[#This Row],[Nº Venda]]>1,1,0) -> 0
B12: CTD | C12: =(SUMIF($G$2:$G$31,B12,$I$2:$I$31))+(SUMIF($G$35:$G$41,B12,$H$35:$H$41)) -> 0 | R12: =IF(vend4[[#This Row],[Nº Venda]]>1,1,0) -> 0
B13: CTC | C13: =(SUMIF($G$2:$G$31,B13,$I$2:$I$31))+(SUMIF($G$35:$G$41,B13,$H$35:$H$41)) -> 1100 | K13: OS Entregue no Dia | R13: =IF(vend4[[#This Row],[Nº Venda]]>1,1,0) -> 0
B14: PIX | C14: =(SUMIF($G$2:$G$31,B14,$I$2:$I$31))+(SUMIF($G$35:$G$41,B14,$H$35:$H$41)) -> 50 | K14: OS | L14: Vendedor | M14: CARNE | R14: =IF(vend4[[#This Row],[Nº Venda]]>1,1,0) -> 0
B15: Total | C15: =SUM(C11:C14) -> 1250 | R15: =IF(vend4[[#This Row],[Nº Venda]]>1,1,0) -> 0
R16: =IF(vend4[[#This Row],[Nº Venda]]>1,1,0) -> 0
B17: Entrega de Carne | R17: =IF(vend4[[#This Row],[Nº Venda]]>1,1,0) -> 0
B18: =COUNT(entr_carn4[OS]) -> 0 | C18: =SUM(entr_carn4[Valor Total]) -> 0 | R18: =IF(vend4[[#This Row],[Nº Venda]]>1,1,0) -> 0
B19: Total | C19: =SUM(C18:C18) -> 0 | R19: =IF(vend4[[#This Row],[Nº Venda]]>1,1,0) -> 0
R20: =IF(vend4[[#This Row],[Nº Venda]]>1,1,0) -> 0
B21: Venda | C21: =C5 -> 2850
E24: Restante Entrada
E25: Nº Venda | F25: Cliente | G25: Forma de Pgto | H25: Valor Venda | I25: Entrada
E33: Recebimento de Carnê | K33: Entrega de Carne
E34: OS | F34: Cliente | G34: Forma de Pgto | H34: Valor Parcela | I34: Nº Parcela | K34: OS | L34: Parcelas | M34: Valor Total
Q40: Total de OS | R40: =SUM(R6:R21) -> 3

Sheet 05
B1: ='04'!B1+1 -> 45417
B2: Fechamento Diário do Caixa
B4: Saldo Inicial | C4: 0 | E4: Vendas | K4: Despesas
B5: Vendas | C5: =SUMIF(I6:I31,">0",H6:H31) -> 0 | E5: Nº Venda | F5: Cliente | G5: Forma de Pgto | H5: Valor Venda | I5: Entrada | K5: Descrição | L5: Tipo de Pagto | M5: Valor
B6: Entrada | C6: =SUM(I6:I41) -> 0 | R6: =IF(vend5[[#This Row],[Nº Venda]]>1,1,0) -> 0
B7: Despesas | C7: =SUM(M6:M11) -> 0 | R7: =IF(vend5[[#This Row],[Nº Venda]]>1,1,0) -> 0
B8: Total entrada | C8: =SUM(C6:C7) -> 0 | R8: =IF(vend5[[#This Row],[Nº Venda]]>1,1,0) -> 0
R9: =IF(vend5[[#This Row],[Nº Venda]]>1,1,0) -> 0
B10: Tipos de Pagtos | R10: =IF(vend5[[#This Row],[Nº Venda]]>1,1,0) -> 0
B11: DN | C11: =(SUMIF($G$2:$G$31,B11,$I$2:$I$31))+(SUMIF($G$35:$G$41,B11,$H$35:$H$41)) -> 0 | O11: =IF(C15=0,0,1) -> 0 | R11: =IF(vend5[[#This Row],[Nº Venda]]>1,1,0) -> 0
B12: CTD | C12: =(SUMIF($G$2:$G$31,B12,$I$2:$I$31))+(SUMIF($G$35:$G$41,B12,$H$35:$H$41)) -> 0 | R12: =IF(vend5[[#This Row],[Nº Venda]]>1,1,0) -> 0
B13: CTC | C13: =(SUMIF($G$2:$G$31,B13,$I$2:$I$31))+(SUMIF($G$35:$G$41,B13,$H$35:$H$41)) -> 0 | K13: OS Entregue no Dia | R13: =IF(vend5[[#This Row],[Nº Venda]]>1,1,0) -> 0
B14: PIX | C14: =(SUMIF($G$2:$G$31,B14,$I$2:$I$31))+(SUMIF($G$35:$G$41,B14,$H$35:$H$41)) -> 0 | K14: OS | L14: Vendedor | M14: CARNE | R14: =IF(vend5[[#This Row],[Nº Venda]]>1,1,0) -> 0
B15: Total | C15: =SUM(C11:C14) -> 0 | R15: =IF(vend5[[#This Row],[Nº Venda]]>1,1,0) -> 0
R16: =IF(vend5[[#This Row],[Nº Venda]]>1,1,0) -> 0
B17: Entrega de Carne | R17: =IF(vend5[[#This Row],[Nº Venda]]>1,1,0) -> 0
B18: =COUNT(entr_carn5[OS]) -> 0 | C18: =SUM(entr_carn5[Valor Total]) -> 0 | R18: =IF(vend5[[#This Row],[Nº Venda]]>1,1,0) -> 0
B19: Total | C19: =SUM(C18:C18) -> 0 | R19: =IF(vend5[[#This Row],[Nº Venda]]>1,1,0) -> 0
R20: =IF(vend5[[#This Row],[Nº Venda]]>1,1,0) -> 0
B21: Venda | C21: =C5 -> 0
E24: Restante Entrada
E25: Nº Venda | F25: Cliente | G25: Forma de Pgto | H25: Valor Venda | I25: Entrada
E33: Recebimento de Carnê | K33: Entrega de Carne
E34: OS | F34: Cliente | G34: Forma de Pgto | H34: Valor Parcela | I34: Nº Parcela | K34: OS | L34: Parcelas | M34: Valor Total
Q40: Total de OS | R40: =SUM(R6:R21) -> 0

Sheet 06
B1: ='05'!B1+1 -> 45418
B2: Fechamento Diário do Caixa
B4: Saldo Inicial | C4: 0 | E4: Vendas | K4: Despesas
B5: Vendas | C5: =SUMIF(I6:I31,">0",H6:H31) -> 1400 | E5: Nº Venda | F5: Cliente | G5: Forma de Pgto | H5: Valor Venda | I5: Entrada | K5: Descrição | L5: Tipo de Pagto | M5: Valor
B6: Entrada | C6: =SUM(I6:I41) -> 1300 | E6: 674 | F6: LUIS CLAUDIO | G6: CTC | H6: 700 | I6: 200 | R6: =IF(vend[[#This Row],[Nº Venda]]>1,1,0) -> 1
B7: Despesas | C7: =SUM(M6:M11) -> 0 | E7: 675 | F7: ELIZABETE CEZAR | G7: CTC | H7: 700 | I7: 200 | R7: =IF(vend[[#This Row],[Nº Venda]]>1,1,0) -> 1
B8: Total entrada | C8: =SUM(C6:C7) -> 1300 | R8: =IF(vend[[#This Row],[Nº Venda]]>1,1,0) -> 0
R9: =IF(vend[[#This Row],[Nº Venda]]>1,1,0) -> 0
B10: Tipos de Pagtos | R10: =IF(vend[[#This Row],[Nº Venda]]>1,1,0) -> 0
B11: DN | C11: =(SUMIF($G$2:$G$31,B11,$I$2:$I$31))+(SUMIF($G$35:$G$41,B11,$H$35:$H$41)) -> 0 | O11: =IF(C15=0,0,1) -> 1 | R11: =IF(vend[[#This Row],[Nº Venda]]>1,1,0) -> 0
B12: CTD | C12: =(SUMIF($G$2:$G$31,B12,$I$2:$I$31))+(SUMIF($G$35:$G$41,B12,$H$35:$H$41)) -> 900 | R12: =IF(vend[[#This Row],[Nº Venda]]>1,1,0) -> 0
B13: CTC | C13: =(SUMIF($G$2:$G$31,B13,$I$2:$I$31))+(SUMIF($G$35:$G$41,B13,$H$35:$H$41)) -> 400 | K13: OS Entregue no Dia | R13: =IF(vend[[#This Row],[Nº Venda]]>1,1,0) -> 0
B14: PIX | C14: =(SUMIF($G$2:$G$31,B14,$I$2:$I$31))+(SUMIF($G$35:$G$41,B14,$H$35:$H$41)) -> 0 | K14: OS | L14: Vendedor | M14: CARNE | R14: =IF(vend[[#This Row],[Nº Venda]]>1,1,0) -> 0
B15: Total | C15: =SUM(C11:C14) -> 1300 | K15: 662 | L15: LUANA | M15: Não | R15: =IF(vend[[#This Row],[Nº Venda]]>1,1,0) -> 0
R16: =IF(vend[[#This Row],[Nº Venda]]>1,1,0) -> 0
B17: Entrega de Carne | R17: =IF(vend[[#This Row],[Nº Venda]]>1,1,0) -> 0
B18: =COUNT(entr_carn6[OS]) -> 0 | C18: =SUM(entr_carn6[Valor Total]) -> 0 | R18: =IF(vend[[#This Row],[Nº Venda]]>1,1,0) -> 0
B19: Total | C19: =SUM(C18:C18) -> 0 | R19: =IF(vend[[#This Row],[Nº Venda]]>1,1,0) -> 0
R20: =IF(vend[[#This Row],[Nº Venda]]>1,1,0) -> 0
B21: Venda | C21: =C5 -> 1400
E24: Restante Entrada
E25: Nº Venda | F25: Cliente | G25: Forma de Pgto | H25: Valor Venda | I25: Entrada
E26: 662 | F26: ADEILDO FERREIRA | G26: CTD | I26: 900
E33: Recebimento de Carnê | K33: Entrega de Carne
E34: OS | F34: Cliente | G34: Forma de Pgto | H34: Valor Parcela | I34: Nº Parcela | K34: OS | L34: Parcelas | M34: Valor Total
Q40: Total de OS | R40: =SUM(R6:R21) -> 2

Sheet 07
B1: ='06'!B1+1 -> 45419
B2: Fechamento Diário do Caixa
B4: Saldo Inicial | C4: 0 | E4: Vendas | K4: Despesas | U4: 0
B5: Vendas | C5: =SUMIF(I6:I31,">0",H6:H31) -> 0 | E5: Nº Venda | F5: Cliente | G5: Forma de Pgto | H5: Valor Venda | I5: Entrada | K5: Descrição | L5: Tipo de Pagto | M5: Valor
B6: Entrada | C6: =SUM(I6:I41) -> 100 | K6: CLINICA | L6: TRANSF - BANCARIA | M6: 180 | R6: =IF(vend7[[#This Row],[Nº Venda]]>1,1,0) -> 0
B7: Despesas | C7: =SUM(M6:M11) -> 180 | R7: =IF(vend7[[#This Row],[Nº Venda]]>1,1,0) -> 0
B8: Total entrada | C8: =SUM(C6:C7) -> 280 | R8: =IF(vend7[[#This Row],[Nº Venda]]>1,1,0) -> 0
R9: =IF(vend7[[#This Row],[Nº Venda]]>1,1,0) -> 0
B10: Tipos de Pagtos | R10: =IF(vend7[[#This Row],[Nº Venda]]>1,1,0) -> 0
B11: DN | C11: =(SUMIF($G$2:$G$31,B11,$I$2:$I$31))+(SUMIF($G$35:$G$41,B11,$H$35:$H$41)) -> 420 | O11: =IF(C15=0,0,1) -> 1 | R11: =IF(vend7[[#This Row],[Nº Venda]]>1,1,0) -> 0
B12: CTD | C12: =(SUMIF($G$2:$G$31,B12,$I$2:$I$31))+(SUMIF($G$35:$G$41,B12,$H$35:$H$41)) -> 0 | R12: =IF(vend7[[#This Row],[Nº Venda]]>1,1,0) -> 0
B13: CTC | C13: =(SUMIF($G$2:$G$31,B13,$I$2:$I$31))+(SUMIF($G$35:$G$41,B13,$H$35:$H$41)) -> 0 | K13: OS Entregue no Dia | R13: =IF(vend7[[#This Row],[Nº Venda]]>1,1,0) -> 0
B14: PIX | C14: =(SUMIF($G$2:$G$31,B14,$I$2:$I$31))+(SUMIF($G$35:$G$41,B14,$H$35:$H$41)) -> 0 | K14: OS | L14: Vendedor | M14: CARNE | R14: =IF(vend7[[#This Row],[Nº Venda]]>1,1,0) -> 0
B15: Total | C15: =SUM(C11:C14) -> 420 | R15: =IF(vend7[[#This Row],[Nº Venda]]>1,1,0) -> 0
R16: =IF(vend7[[#This Row],[Nº Venda]]>1,1,0) -> 0
B17: Entrega de Carne | R17: =IF(vend7[[#This Row],[Nº Venda]]>1,1,0) -> 0
B18: =COUNT(entr_carn7[OS]) -> 0 | C18: =SUM(entr_carn7[Valor Total]) -> 0 | R18: =IF(vend7[[#This Row],[Nº Venda]]>1,1,0) -> 0
B19: Total | C19: =SUM(C18:C18) -> 0 | R19: =IF(vend7[[#This Row],[Nº Venda]]>1,1,0) -> 0
R20: =IF(vend7[[#This Row],[Nº Venda]]>1,1,0) -> 0
B21: Venda | C21: =C5 -> 0
E24: Restante Entrada
E25: Nº Venda | F25: Cliente | G25: Forma de Pgto | H25: Valor Venda | I25: Entrada
E26: 674 | F26: LUIS CLAUDIO | G26: DN | H26: 0 | I26: 50
E27: 675 | F27: ELIZABETE CEZAR | G27: DN | H27: 0 | I27: 50
E33: Recebimento de Carnê | K33: Entrega de Carne
E34: OS | F34: Cliente | G34: Forma de Pgto | H34: Valor Parcela | I34: Nº Parcela | K34: OS | L34: Parcelas | M34: Valor Total
E35: 599 | F35: ALEXANDRE DA SILVA | G35: DN | H35: 120 | I35: PARC. 2/10
E36: 637 | F36: ALICE DE ALMEIDA | G36: DN | H36: 100 | I36: PARC. 1/8
E37: 637 | F37: ALICE DE ALMEIDA | G37: DN | H37: 100 | I37: PARC. 2/8
Q40: Total de OS | R40: =SUM(R6:R21) -> 0

Sheet 08
B1: ='07'!B1+1 -> 45420
B2: Fechamento Diário do Caixa
B4: Saldo Inicial | C4: 0 | E4: Vendas | K4: Despesas
B5: Vendas | C5: =SUMIF(I6:I31,">0",H6:H31) -> 0 | E5: Nº Venda | F5: Cliente | G5: Forma de Pgto | H5: Valor Venda | I5: Entrada | K5: Descrição | L5: Tipo de Pagto | M5: Valor
B6: Entrada | C6: =SUM(I6:I41) -> 0 | R6: =IF(vend8[[#This Row],[Nº Venda]]>1,1,0) -> 0
B7: Despesas | C7: =SUM(M6:M11) -> 0 | R7: =IF(vend8[[#This Row],[Nº Venda]]>1,1,0) -> 0
B8: Total entrada | C8: =SUM(C6:C7) -> 0 | R8: =IF(vend8[[#This Row],[Nº Venda]]>1,1,0) -> 0
R9: =IF(vend8[[#This Row],[Nº Venda]]>1,1,0) -> 0
B10: Tipos de Pagtos | R10: =IF(vend8[[#This Row],[Nº Venda]]>1,1,0) -> 0
B11: DN | C11: =(SUMIF($G$2:$G$31,B11,$I$2:$I$31))+(SUMIF($G$35:$G$42,B11,$H$35:$H$42)) -> 100 | O11: =IF(C15=0,0,1) -> 1 | R11: =IF(vend8[[#This Row],[Nº Venda]]>1,1,0) -> 0
B12: CTD | C12: =(SUMIF($G$2:$G$31,B12,$I$2:$I$31))+(SUMIF($G$35:$G$42,B12,$H$35:$H$42)) -> 0 | R12: =IF(vend8[[#This Row],[Nº Venda]]>1,1,0) -> 0
B13: CTC | C13: =(SUMIF($G$2:$G$31,B13,$I$2:$I$31))+(SUMIF($G$35:$G$42,B13,$H$35:$H$42)) -> 0 | K13: OS Entregue no Dia | R13: =IF(vend8[[#This Row],[Nº Venda]]>1,1,0) -> 0
B14: PIX | C14: =(SUMIF($G$2:$G$31,B14,$I$2:$I$31))+(SUMIF($G$35:$G$42,B14,$H$35:$H$42)) -> 0 | K14: OS | L14: Vendedor | M14: CARNE | R14: =IF(vend8[[#This Row],[Nº Venda]]>1,1,0) -> 0
B15: Total | C15: =SUM(C11:C14) -> 100 | R15: =IF(vend8[[#This Row],[Nº Venda]]>1,1,0) -> 0
R16: =IF(vend8[[#This Row],[Nº Venda]]>1,1,0) -> 0
B17: Entrega de Carne | R17: =IF(vend8[[#This Row],[Nº Venda]]>1,1,0) -> 0
B18: =COUNT(entr_carn8[OS]) -> 0 | C18: =SUM(entr_carn8[Valor Total]) -> 0 | R18: =IF(vend8[[#This Row],[Nº Venda]]>1,1,0) -> 0
B19: Total | C19: =SUM(C18:C18) -> 0 | R19: =IF(vend8[[#This Row],[Nº Venda]]>1,1,0) -> 0
R20: =IF(vend8[[#This Row],[Nº Venda]]>1,1,0) -> 0
B21: Venda | C21: =C5 -> 0
E24: Restante Entrada
E25: Nº Venda | F25: Cliente | G25: Forma de Pgto | H25: Valor Venda | I25: Entrada
E33: Recebimento de Carnê | K33: Entrega de Carne
E34: OS | F34: Cliente | G34: Forma de Pgto | H34: Valor Parcela | I34: Nº Parcela | K34: OS | L34: Parcelas | M34: Valor Total
E35: 622 | F35: MARIA DO CARMO | G35: DN | H35: 100 | I35: PARC. 2/2
Q40: Total de OS | R40: =SUM(R6:R21) -> 0

Sheet 09
B1: ='08'!B1+1 -> 45421
B2: Fechamento Diário do Caixa
B4: Saldo Inicial | C4: 0 | E4: Vendas | K4: Despesas
B5: Vendas | C5: =SUMIF(I6:I31,">0",H6:H31) -> 4675 | E5: Nº Venda | F5: Cliente | G5: Forma de Pgto | H5: Valor Venda | I5: Entrada | K5: Descrição | L5: Tipo de Pagto | M5: Valor
B6: Entrada | C6: =SUM(I6:I41) -> 555 | E6: 676 | F6: MARIA INES | G6: CTD | H6: 848 | I6: 80 | K6: agua | L6: pix | M6: 13 | R6: =IF(vend9[[#This Row],[Nº Venda]]>1,1,0) -> 1
B7: Despesas | C7: =SUM(M6:M11) -> 27 | E7: 677 | F7: MARIA INES | G7: CTD | H7: 150 | I7: 20 | K7: pilha | L7: pix | M7: 14 | R7: =IF(vend9[[#This Row],[Nº Venda]]>1,1,0) -> 1
B8: Total entrada | C8: =SUM(C6:C7) -> 582 | E8: 678 | F8: ADEILTON ALVES | G8: DN | H8: 890 | I8: 100 | R8: =IF(vend9[[#This Row],[Nº Venda]]>1,1,0) -> 1
E9: 679 | F9: ROSEMARY | G9: DN | H9: 690 | I9: 100 | R9: =IF(vend9[[#This Row],[Nº Venda]]>1,1,0) -> 1
B10: Tipos de Pagtos | E10: 680 | F10: antonio jorge | G10: CTD | H10: 799 | I10: 150 | R10: =IF(vend9[[#This Row],[Nº Venda]]>1,1,0) -> 1
B11: DN | C11: =(SUMIF($G$2:$G$31,B11,$I$2:$I$31))+(SUMIF($G$35:$G$41,B11,$H$35:$H$41)) -> 375 | E11: 681 | F11: deusirene soraia | G11: DN | H11: 799 | I11: 100 | O11: =IF(C15=0,0,1) -> 1 | R11: =IF(vend9[[#This Row],[Nº Venda]]>1,1,0) -> 1
B12: CTD | C12: =(SUMIF($G$2:$G$31,B12,$I$2:$I$31))+(SUMIF($G$35:$G$41,B12,$H$35:$H$41)) -> 250 | E12: 682 | F12: HELLEN | G12: PIX | H12: 499 | I12: 5 | R12: =IF(vend9[[#This Row],[Nº Venda]]>1,1,0) -> 1 | V12: 0
B13: CTC | C13: =(SUMIF($G$2:$G$31,B13,$I$2:$I$31))+(SUMIF($G$35:$G$41,B13,$H$35:$H$41)) -> 0 | K13: OS Entregue no Dia | R13: =IF(vend9[[#This Row],[Nº Venda]]>1,1,0) -> 0
B14: PIX | C14: =(SUMIF($G$2:$G$31,B14,$I$2:$I$31))+(SUMIF($G$35:$G$41,B14,$H$35:$H$41)) -> 5 | K14: OS | L14: Vendedor | M14: CARNE | R14: =IF(vend9[[#This Row],[Nº Venda]]>1,1,0) -> 0
B15: Total | C15: =SUM(C11:C14) -> 630 | K15: 663 | L15: luana | M15: Não | R15: =IF(vend9[[#This Row],[Nº Venda]]>1,1,0) -> 0
R16: =IF(vend9[[#This Row],[Nº Venda]]>1,1,0) -> 0
B17: Entrega de Carne | R17: =IF(vend9[[#This Row],[Nº Venda]]>1,1,0) -> 0
B18: =COUNT(entr_carn9[OS]) -> 0 | C18: =SUM(entr_carn9[Valor Total]) -> 0 | R18: =IF(vend9[[#This Row],[Nº Venda]]>1,1,0) -> 0
B19: Total | C19: =SUM(C18:C18) -> 0 | R19: =IF(vend9[[#This Row],[Nº Venda]]>1,1,0) -> 0
R20: =IF(vend9[[#This Row],[Nº Venda]]>1,1,0) -> 0
B21: Venda | C21: =C5 -> 4675
E24: Restante Entrada
E25: Nº Venda | F25: Cliente | G25: Forma de Pgto | H25: Valor Venda | I25: Entrada
E33: Recebimento de Carnê | K33: Entrega de Carne
E34: OS | F34: Cliente | G34: Forma de Pgto | H34: Valor Parcela | I34: Nº Parcela | K34: OS | L34: Parcelas | M34: Valor Total
E35: 633 | F35: inacio jose | G35: DN | H35: 75 | I35: PARC. 1/4
Q40: Total de OS | R40: =SUM(R6:R21) -> 7

Sheet 10
B1: ='09'!B1+1 -> 45422
B2: Fechamento Diário do Caixa
B4: Saldo Inicial | C4: 0 | E4: Vendas | K4: Despesas
B5: Vendas | C5: =SUMIF(I6:I32,">0",H6:H32) -> 0 | E5: Nº Venda | F5: Cliente | G5: Forma de Pgto | H5: Valor Venda | I5: Entrada | K5: Descrição | L5: Tipo de Pagto | M5: Valor
B6: Entrada | C6: =SUM(I6:I42) -> 1370 | R6: =IF(vend10[[#This Row],[Nº Venda]]>1,1,0) -> 0
B7: Despesas | C7: =SUM(M6:M11) -> 0 | R7: =IF(vend10[[#This Row],[Nº Venda]]>1,1,0) -> 0
B8: Total entrada | C8: =SUM(C6:C7) -> 1370 | R8: =IF(vend10[[#This Row],[Nº Venda]]>1,1,0) -> 0
R9: =IF(vend10[[#This Row],[Nº Venda]]>1,1,0) -> 0
B10: Tipos de Pagtos | R10: =IF(vend10[[#This Row],[Nº Venda]]>1,1,0) -> 0
B11: DN | C11: =(SUMIF($G$2:$G$32,B11,$I$2:$I$32))+(SUMIF($G$36:$G$42,B11,$H$36:$H$42)) -> 0 | O11: =IF(C15=0,0,1) -> 1 | R11: =IF(vend10[[#This Row],[Nº Venda]]>1,1,0) -> 0
B12: CTD | C12: =(SUMIF($G$2:$G$32,B12,$I$2:$I$32))+(SUMIF($G$36:$G$42,B12,$H$36:$H$42)) -> 0 | R12: =IF(vend10[[#This Row],[Nº Venda]]>1,1,0) -> 0
B13: CTC | C13: =(SUMIF($G$2:$G$32,B13,$I$2:$I$32))+(SUMIF($G$36:$G$42,B13,$H$36:$H$42)) -> 0 | K13: OS Entregue no Dia | R13: =IF(vend10[[#This Row],[Nº Venda]]>1,1,0) -> 0
B14: PIX | C14: =(SUMIF($G$2:$G$32,B14,$I$2:$I$32))+(SUMIF($G$36:$G$42,B14,$H$36:$H$42)) -> 1515 | K14: OS | L14: Vendedor | M14: CARNE | R14: =IF(vend10[[#This Row],[Nº Venda]]>1,1,0) -> 0
B15: Total | C15: =SUM(C11:C14) -> 1515 | K15: 669 | L15: luana | M15: Não | R15: =IF(vend10[[#This Row],[Nº Venda]]>1,1,0) -> 0
R16: =IF(vend10[[#This Row],[Nº Venda]]>1,1,0) -> 0
B17: Entrega de Carne | R17: =IF(vend10[[#This Row],[Nº Venda]]>1,1,0) -> 0
B18: =COUNT(entr_carn10[OS]) -> 0 | C18: =SUM(entr_carn10[Valor Total]) -> 0 | R18: =IF(vend10[[#This Row],[Nº Venda]]>1,1,0) -> 0
B19: Total | C19: =SUM(C18:C18) -> 0 | R19: =IF(vend10[[#This Row],[Nº Venda]]>1,1,0) -> 0
R20: =IF(vend10[[#This Row],[Nº Venda]]>1,1,0) -> 0
B21: Venda | C21: =C5 -> 0
E24: Restante Entrada
E25: Nº Venda | F25: Cliente | G25: Forma de Pgto | H25: Valor Venda | I25: Entrada
E26: 678 | F26: ADEILTON ALVES | G26: PIX | H26: 0 | I26: 650
E27: 679 | F27: ROZEMARY | G27: PIX | H27: 0 | I27: 650
E28: 669 | F28: JANAINA | G28: PIX | H28: 0 | I28: 70
K33: Entrega de Carne
E34: Recebimento de Carnê | K34: OS | L34: Parcelas | M34: Valor Total
E35: Coluna1 | F35: Coluna2 | G35: Coluna3 | H35: Coluna4 | I35: Coluna5
E36: 522 | F36: VERA LUCIA | G36: PIX | H36: 145 | I36: PARC. 5/7
Q40: Total de OS | R40: =SUM(R6:R21) -> 0

Sheet 11
B1: ='10'!B1+1 -> 45423
B2: Fechamento Diário do Caixa
B4: Saldo Inicial | C4: 0 | E4: Vendas | K4: Despesas
B5: Vendas | C5: =SUMIF(I6:I31,">0",H6:H31) -> 0 | E5: Nº Venda | F5: Cliente | G5: Forma de Pgto | H5: Valor Venda | I5: Entrada | K5: Descrição | L5: Tipo de Pagto | M5: Valor
B6: Entrada | C6: =SUM(I6:I41) -> 1485 | R6: =IF(vend11[[#This Row],[Nº Venda]]>1,1,0) -> 0
B7: Despesas | C7: =SUM(M6:M11) -> 0 | R7: =IF(vend11[[#This Row],[Nº Venda]]>1,1,0) -> 0
B8: Total entrada | C8: =SUM(C6:C7) -> 1485 | R8: =IF(vend11[[#This Row],[Nº Venda]]>1,1,0) -> 0
R9: =IF(vend11[[#This Row],[Nº Venda]]>1,1,0) -> 0
B10: Tipos de Pagtos | R10: =IF(vend11[[#This Row],[Nº Venda]]>1,1,0) -> 0
B11: DN | C11: =(SUMIF($G$2:$G$31,B11,$I$2:$I$31))+(SUMIF($G$35:$G$41,B11,$H$35:$H$41)) -> 0 | O11: =IF(C15=0,0,1) -> 1 | R11: =IF(vend11[[#This Row],[Nº Venda]]>1,1,0) -> 0
B12: CTD | C12: =(SUMIF($G$2:$G$31,B12,$I$2:$I$31))+(SUMIF($G$35:$G$41,B12,$H$35:$H$41)) -> 0 | R12: =IF(vend11[[#This Row],[Nº Venda]]>1,1,0) -> 0
B13: CTC | C13: =(SUMIF($G$2:$G$31,B13,$I$2:$I$31))+(SUMIF($G$35:$G$41,B13,$H$35:$H$41)) -> 1485 | K13: OS Entregue no Dia | R13: =IF(vend11[[#This Row],[Nº Venda]]>1,1,0) -> 0
B14: PIX | C14: =(SUMIF($G$2:$G$31,B14,$I$2:$I$31))+(SUMIF($G$35:$G$41,B14,$H$35:$H$41)) -> 0 | K14: OS | L14: Vendedor | M14: CARNE | R14: =IF(vend11[[#This Row],[Nº Venda]]>1,1,0) -> 0
B15: Total | C15: =SUM(C11:C14) -> 1485 | R15: =IF(vend11[[#This Row],[Nº Venda]]>1,1,0) -> 0
R16: =IF(vend11[[#This Row],[Nº Venda]]>1,1,0) -> 0
B17: Entrega de Carne | R17: =IF(vend11[[#This Row],[Nº Venda]]>1,1,0) -> 0
B18: =COUNT(entr_carn11[OS]) -> 0 | C18: =SUM(entr_carn11[Valor Total]) -> 0 | R18: =IF(vend11[[#This Row],[Nº Venda]]>1,1,0) -> 0
B19: Total | C19: =SUM(C18:C18) -> 0 | R19: =IF(vend11[[#This Row],[Nº Venda]]>1,1,0) -> 0
R20: =IF(vend11[[#This Row],[Nº Venda]]>1,1,0) -> 0
B21: Venda | C21: =C5 -> 0
E24: Restante Entrada
E25: Nº Venda | F25: Cliente | G25: Forma de Pgto | H25: Valor Venda | I25: Entrada
E26: 682 | F26: HELLEN | G26: CTC | H26: 0 | I26: 485
E27: 668 | F27: ANA LUCIA | G27: CTC | H27: 0 | I27: 1000
E33: Recebimento de Carnê | K33: Entrega de Carne
E34: OS | F34: Cliente | G34: Forma de Pgto | H34: Valor Parcela | I34: Nº Parcela | K34: OS | L34: Parcelas | M34: Valor Total
Q40: Total de OS | R40: =SUM(R6:R21) -> 0

Sheet 12
B1: ='11'!B1+1 -> 45424
B2: Fechamento Diário do Caixa
B4: Saldo Inicial | C4: 0 | E4: Vendas | K4: Despesas
B5: Vendas | C5: =SUMIF(I6:I31,">0",H6:H31) -> 0 | E5: Nº Venda | F5: Cliente | G5: Forma de Pgto | H5: Valor Venda | I5: Entrada | K5: Descrição | L5: Tipo de Pagto | M5: Valor
B6: Entrada | C6: =SUM(I6:I41) -> 0 | R6: =IF(vend12[[#This Row],[Nº Venda]]>1,1,0) -> 0
B7: Despesas | C7: =SUM(M6:M11) -> 0 | R7: =IF(vend12[[#This Row],[Nº Venda]]>1,1,0) -> 0
B8: Total entrada | C8: =SUM(C6:C7) -> 0 | R8: =IF(vend12[[#This Row],[Nº Venda]]>1,1,0) -> 0
R9: =IF(vend12[[#This Row],[Nº Venda]]>1,1,0) -> 0
B10: Tipos de Pagtos | R10: =IF(vend12[[#This Row],[Nº Venda]]>1,1,0) -> 0
B11: DN | C11: =(SUMIF($G$2:$G$31,B11,$I$2:$I$31))+(SUMIF($G$35:$G$41,B11,$H$35:$H$41)) -> 0 | O11: =IF(C15=0,0,1) -> 0 | R11: =IF(vend12[[#This Row],[Nº Venda]]>1,1,0) -> 0
B12: CTD | C12: =(SUMIF($G$2:$G$31,B12,$I$2:$I$31))+(SUMIF($G$35:$G$41,B12,$H$35:$H$41)) -> 0 | R12: =IF(vend12[[#This Row],[Nº Venda]]>1,1,0) -> 0
B13: CTC | C13: =(SUMIF($G$2:$G$31,B13,$I$2:$I$31))+(SUMIF($G$35:$G$41,B13,$H$35:$H$41)) -> 0 | K13: OS Entregue no Dia | R13: =IF(vend12[[#This Row],[Nº Venda]]>1,1,0) -> 0
B14: PIX | C14: =(SUMIF($G$2:$G$31,B14,$I$2:$I$31))+(SUMIF($G$35:$G$41,B14,$H$35:$H$41)) -> 0 | K14: OS | L14: Vendedor | M14: CARNE | R14: =IF(vend12[[#This Row],[Nº Venda]]>1,1,0) -> 0
B15: Total | C15: =SUM(C11:C14) -> 0 | R15: =IF(vend12[[#This Row],[Nº Venda]]>1,1,0) -> 0
R16: =IF(vend12[[#This Row],[Nº Venda]]>1,1,0) -> 0
B17: Entrega de Carne | R17: =IF(vend12[[#This Row],[Nº Venda]]>1,1,0) -> 0
B18: =COUNT(entr_carn12[OS]) -> 0 | C18: =SUM(entr_carn12[Valor Total]) -> 0 | R18: =IF(vend12[[#This Row],[Nº Venda]]>1,1,0) -> 0
B19: Total | C19: =SUM(C18:C18) -> 0 | R19: =IF(vend12[[#This Row],[Nº Venda]]>1,1,0) -> 0
R20: =IF(vend12[[#This Row],[Nº Venda]]>1,1,0) -> 0
B21: Venda | C21: =C5 -> 0
E24: Restante Entrada
E25: Nº Venda | F25: Cliente | G25: Forma de Pgto | H25: Valor Venda | I25: Entrada
E33: Recebimento de Carnê | K33: Entrega de Carne
E34: OS | F34: Cliente | G34: Forma de Pgto | H34: Valor Parcela | I34: Nº Parcela | K34: OS | L34: Parcelas | M34: Valor Total
Q40: Total de OS | R40: =SUM(R6:R21) -> 0

Sheet 13
B1: ='12'!B1+1 -> 45425
B2: Fechamento Diário do Caixa
B4: Saldo Inicial | C4: 0 | E4: Vendas | K4: Despesas
B5: Vendas | C5: =SUMIF(I6:I31,">0",H6:H31) -> 250 | E5: Nº Venda | F5: Cliente | G5: Forma de Pgto | H5: Valor Venda | I5: Entrada | K5: Descrição | L5: Tipo de Pagto | M5: Valor
B6: Entrada | C6: =SUM(I6:I41) -> 250 | E6: 683 | F6: MARIA DO AMPARO | G6: CTC | H6: 250 | I6: 250 | R6: =IF(vend13[[#This Row],[Nº Venda]]>1,1,0) -> 1
B7: Despesas | C7: =SUM(M6:M11) -> 0 | R7: =IF(vend13[[#This Row],[Nº Venda]]>1,1,0) -> 0
B8: Total entrada | C8: =SUM(C6:C7) -> 250 | R8: =IF(vend13[[#This Row],[Nº Venda]]>1,1,0) -> 0
R9: =IF(vend13[[#This Row],[Nº Venda]]>1,1,0) -> 0
B10: Tipos de Pagtos | R10: =IF(vend13[[#This Row],[Nº Venda]]>1,1,0) -> 0
B11: DN | C11: =(SUMIF($G$2:$G$31,B11,$I$2:$I$31))+(SUMIF($G$35:$G$41,B11,$H$35:$H$41)) -> 0 | O11: =IF(C15=0,0,1) -> 1 | R11: =IF(vend13[[#This Row],[Nº Venda]]>1,1,0) -> 0
B12: CTD | C12: =(SUMIF($G$2:$G$31,B12,$I$2:$I$31))+(SUMIF($G$35:$G$41,B12,$H$35:$H$41)) -> 0 | R12: =IF(vend13[[#This Row],[Nº Venda]]>1,1,0) -> 0
B13: CTC | C13: =(SUMIF($G$2:$G$31,B13,$I$2:$I$31))+(SUMIF($G$35:$G$41,B13,$H$35:$H$41)) -> 250 | K13: OS Entregue no Dia | R13: =IF(vend13[[#This Row],[Nº Venda]]>1,1,0) -> 0
B14: PIX | C14: =(SUMIF($G$2:$G$31,B14,$I$2:$I$31))+(SUMIF($G$35:$G$41,B14,$H$35:$H$41)) -> 0 | K14: OS | L14: Vendedor | M14: CARNE | R14: =IF(vend13[[#This Row],[Nº Venda]]>1,1,0) -> 0
B15: Total | C15: =SUM(C11:C14) -> 250 | R15: =IF(vend13[[#This Row],[Nº Venda]]>1,1,0) -> 0
R16: =IF(vend13[[#This Row],[Nº Venda]]>1,1,0) -> 0
B17: Entrega de Carne | R17: =IF(vend13[[#This Row],[Nº Venda]]>1,1,0) -> 0
B18: =COUNT(entr_carn13[OS]) -> 0 | C18: =SUM(entr_carn13[Valor Total]) -> 0 | R18: =IF(vend13[[#This Row],[Nº Venda]]>1,1,0) -> 0
B19: Total | C19: =SUM(C18:C18) -> 0 | R19: =IF(vend13[[#This Row],[Nº Venda]]>1,1,0) -> 0
R20: =IF(vend13[[#This Row],[Nº Venda]]>1,1,0) -> 0
B21: Venda | C21: =C5 -> 250
E24: Restante Entrada
E25: Nº Venda | F25: Cliente | G25: Forma de Pgto | H25: Valor Venda | I25: Entrada
E33: Recebimento de Carnê | K33: Entrega de Carne
E34: OS | F34: Cliente | G34: Forma de Pgto | H34: Valor Parcela | I34: Nº Parcela | K34: OS | L34: Parcelas | M34: Valor Total
Q40: Total de OS | R40: =SUM(R6:R21) -> 1

Sheet 14
B1: ='13'!B1+1 -> 45426
B2: Fechamento Diário do Caixa
B4: Saldo Inicial | C4: 0 | E4: Vendas | K4: Despesas
B5: Vendas | C5: =SUMIF(I6:I31,">0",H6:H31) -> 1400 | E5: Nº Venda | F5: Cliente | G5: Forma de Pgto | H5: Valor Venda | I5: Entrada | K5: Descrição | L5: Tipo de Pagto | M5: Valor
B6: Entrada | C6: =SUM(I6:I41) -> 100 | E6: 684 | F6: PEDRO PERTRULIO | G6: GARANTIA | H6: 0 | I6: 0 | R6: =IF(vend14[[#This Row],[Nº Venda]]>1,1,0) -> 1
B7: Despesas | C7: =SUM(M6:M11) -> 0 | E7: 685 | F7: THONY FORVILUS | G7: CTD | H7: 700 | I7: 50 | R7: =IF(vend14[[#This Row],[Nº Venda]]>1,1,0) -> 1
B8: Total entrada | C8: =SUM(C6:C7) -> 100 | E8: 686 | F8: THONY FORVILUS | G8: CTD | H8: 700 | I8: 50 | R8: =IF(vend14[[#This Row],[Nº Venda]]>1,1,0) -> 1
R9: =IF(vend14[[#This Row],[Nº Venda]]>1,1,0) -> 0
B10: Tipos de Pagtos | R10: =IF(vend14[[#This Row],[Nº Venda]]>1,1,0) -> 0
B11: DN | C11: =(SUMIF($G$2:$G$31,B11,$I$2:$I$31))+(SUMIF($G$35:$G$41,B11,$H$35:$H$41)) -> 0 | O11: =IF(C15=0,0,1) -> 1 | R11: =IF(vend14[[#This Row],[Nº Venda]]>1,1,0) -> 0
B12: CTD | C12: =(SUMIF($G$2:$G$31,B12,$I$2:$I$31))+(SUMIF($G$35:$G$41,B12,$H$35:$H$41)) -> 100 | R12: =IF(vend14[[#This Row],[Nº Venda]]>1,1,0) -> 0
B13: CTC | C13: =(SUMIF($G$2:$G$31,B13,$I$2:$I$31))+(SUMIF($G$35:$G$41,B13,$H$35:$H$41)) -> 0 | K13: OS Entregue no Dia | R13: =IF(vend14[[#This Row],[Nº Venda]]>1,1,0) -> 0
B14: PIX | C14: =(SUMIF($G$2:$G$31,B14,$I$2:$I$31))+(SUMIF($G$35:$G$41,B14,$H$35:$H$41)) -> 147.7 | K14: OS | L14: Vendedor | M14: CARNE | R14: =IF(vend14[[#This Row],[Nº Venda]]>1,1,0) -> 0
B15: Total | C15: =SUM(C11:C14) -> 247.7 | R15: =IF(vend14[[#This Row],[Nº Venda]]>1,1,0) -> 0
R16: =IF(vend14[[#This Row],[Nº Venda]]>1,1,0) -> 0
B17: Entrega de Carne | R17: =IF(vend14[[#This Row],[Nº Venda]]>1,1,0) -> 0
B18: =COUNT(entr_carn14[OS]) -> 0 | C18: =SUM(entr_carn14[Valor Total]) -> 0 | R18: =IF(vend14[[#This Row],[Nº Venda]]>1,1,0) -> 0
B19: Total | C19: =SUM(C18:C18) -> 0 | R19: =IF(vend14[[#This Row],[Nº Venda]]>1,1,0) -> 0
R20: =IF(vend14[[#This Row],[Nº Venda]]>1,1,0) -> 0
B21: Venda | C21: =C5 -> 1400
E24: Restante Entrada
E25: Nº Venda | F25: Cliente | G25: Forma de Pgto | H25: Valor Venda | I25: Entrada
E33: Recebimento de Carnê | K33: Entrega de Carne
E34: OS | F34: Cliente | G34: Forma de Pgto | H34: Valor Parcela | I34: Nº Parcela | K34: OS | L34: Parcelas | M34: Valor Total
E35: 521 | F35: VERA LUCIA | G35: PIX | H35: 85 | I35: PARC. 5/7
E36: 624 | F36: CARINE ALMEIDA | G36: PIX | H36: 62.7 | I36: PARC. 1/10
Q40: Total de OS | R40: =SUM(R6:R21) -> 3

Sheet 15
B1: ='14'!B1+1 -> 45427
B2: Fechamento Diário do Caixa
B4: Saldo Inicial | C4: 0 | E4: Vendas | K4: Despesas
B5: Vendas | C5: =SUMIF(I6:I31,">0",H6:H31) -> 0 | E5: Nº Venda | F5: Cliente | G5: Forma de Pgto | H5: Valor Venda | I5: Entrada | K5: Descrição | L5: Tipo de Pagto | M5: Valor
B6: Entrada | C6: =SUM(I6:I41) -> 0 | R6: =IF(vend15[[#This Row],[Nº Venda]]>1,1,0) -> 0
B7: Despesas | C7: =SUM(M6:M11) -> 0 | R7: =IF(vend15[[#This Row],[Nº Venda]]>1,1,0) -> 0
B8: Total entrada | C8: =SUM(C6:C7) -> 0 | R8: =IF(vend15[[#This Row],[Nº Venda]]>1,1,0) -> 0
R9: =IF(vend15[[#This Row],[Nº Venda]]>1,1,0) -> 0
B10: Tipos de Pagtos | R10: =IF(vend15[[#This Row],[Nº Venda]]>1,1,0) -> 0
B11: DN | C11: =(SUMIF($G$2:$G$31,B11,$I$2:$I$31))+(SUMIF($G$35:$G$41,B11,$H$35:$H$41)) -> 0 | O11: =IF(C15=0,0,1) -> 0 | R11: =IF(vend15[[#This Row],[Nº Venda]]>1,1,0) -> 0
B12: CTD | C12: =(SUMIF($G$2:$G$31,B12,$I$2:$I$31))+(SUMIF($G$35:$G$41,B12,$H$35:$H$41)) -> 0 | R12: =IF(vend15[[#This Row],[Nº Venda]]>1,1,0) -> 0
B13: CTC | C13: =(SUMIF($G$2:$G$31,B13,$I$2:$I$31))+(SUMIF($G$35:$G$41,B13,$H$35:$H$41)) -> 0 | K13: OS Entregue no Dia | R13: =IF(vend15[[#This Row],[Nº Venda]]>1,1,0) -> 0
B14: PIX | C14: =(SUMIF($G$2:$G$31,B14,$I$2:$I$31))+(SUMIF($G$35:$G$41,B14,$H$35:$H$41)) -> 0 | K14: OS | L14: Vendedor | M14: CARNE | R14: =IF(vend15[[#This Row],[Nº Venda]]>1,1,0) -> 0
B15: Total | C15: =SUM(C11:C14) -> 0 | K15: 667 | L15: LUANA | M15: Não | R15: =IF(vend15[[#This Row],[Nº Venda]]>1,1,0) -> 0
K16: 668 | L16: LUANA | M16: Não | R16: =IF(vend15[[#This Row],[Nº Venda]]>1,1,0) -> 0
B17: Entrega de Carne | R17: =IF(vend15[[#This Row],[Nº Venda]]>1,1,0) -> 0
B18: =COUNT(entr_carn15[OS]) -> 0 | C18: =SUM(entr_carn15[Valor Total]) -> 0 | R18: =IF(vend15[[#This Row],[Nº Venda]]>1,1,0) -> 0
B19: Total | C19: =SUM(C18:C18) -> 0 | R19: =IF(vend15[[#This Row],[Nº Venda]]>1,1,0) -> 0
R20: =IF(vend15[[#This Row],[Nº Venda]]>1,1,0) -> 0
B21: Venda | C21: =C5 -> 0
E24: Restante Entrada
E25: Nº Venda | F25: Cliente | G25: Forma de Pgto | H25: Valor Venda | I25: Entrada
E33: Recebimento de Carnê | K33: Entrega de Carne
E34: OS | F34: Cliente | G34: Forma de Pgto | H34: Valor Parcela | I34: Nº Parcela | K34: OS | L34: Parcelas | M34: Valor Total
Q40: Total de OS | R40: =SUM(R6:R21) -> 0

Sheet 16
B1: ='15'!B1+1 -> 45428
B2: Fechamento Diário do Caixa
B4: Saldo Inicial | C4: 0 | E4: Vendas | K4: Despesas
B5: Vendas | C5: =SUMIF(I6:I31,">0",H6:H31) -> 6411.99 | E5: Nº Venda | F5: Cliente | G5: Forma de Pgto | H5: Valor Venda | I5: Entrada | K5: Descrição | L5: Tipo de Pagto | M5: Valor
B6: Entrada | C6: =SUM(I6:I41) -> 2829.99 | E6: 687 | F6: JOSE MANOEL | G6: CTC | H6: 390 | I6: 390 | K6: AGUA | L6: DN | M6: 13 | R6: =IF(vend16[[#This Row],[Nº Venda]]>1,1,0) -> 1
B7: Despesas | C7: =SUM(M6:M11) -> 13 | E7: 688 | F7: ATILLA COSTA | G7: CTC | H7: 350 | I7: 350 | R7: =IF(vend16[[#This Row],[Nº Venda]]>1,1,0) -> 1
B8: Total entrada | C8: =SUM(C6:C7) -> 2842.99 | E8: 689 | F8: ATILLA COSTA | G8: CTC | H8: 949 | I8: 650 | R8: =IF(vend16[[#This Row],[Nº Venda]]>1,1,0) -> 1
E9: 690 | F9: LUIZ CESPEDES | G9: CTD | H9: 598 | I9: 10 | R9: =IF(vend16[[#This Row],[Nº Venda]]>1,1,0) -> 1
B10: Tipos de Pagtos | E10: 691 | F10: EDMILSON | G10: DN | H10: 500 | I10: 20 | R10: =IF(vend16[[#This Row],[Nº Venda]]>1,1,0) -> 1
B11: DN | C11: =(SUMIF($G$2:$G$31,B11,$I$2:$I$31))+(SUMIF($G$35:$G$41,B11,$H$35:$H$41)) -> 320 | E11: 692 | F11: JENIFFER VITORIA | G11: PIX | H11: 784 | I11: 20 | O11: =IF(C15=0,0,1) -> 1 | R11: =IF(vend16[[#This Row],[Nº Venda]]>1,1,0) -> 1
B12: CTD | C12: =(SUMIF($G$2:$G$31,B12,$I$2:$I$31))+(SUMIF($G$35:$G$41,B12,$H$35:$H$41)) -> 10 | E12: 693 | F12: JOSE CARLOS | G12: DN | H12: 590 | I12: 100 | R12: =IF(vend16[[#This Row],[Nº Venda]]>1,1,0) -> 1
B13: CTC | C13: =(SUMIF($G$2:$G$31,B13,$I$2:$I$31))+(SUMIF($G$35:$G$41,B13,$H$35:$H$41)) -> 2479.99 | E13: 694 | F13: SOLANGE DO ESOIRITO SANTO SOUZA | G13: DN | H13: 1161 | I13: 200 | K13: OS Entregue no Dia | R13: =IF(vend16[[#This Row],[Nº Venda]]>1,1,0) -> 1
B14: PIX | C14: =(SUMIF($G$2:$G$31,B14,$I$2:$I$31))+(SUMIF($G$35:$G$41,B14,$H$35:$H$41)) -> 20 | E14: 695 | F14: LENEIDE RIBEIRO LISBOA | G14: CTC | H14: 499.99 | I14: 499.99 | K14: OS | L14: Vendedor | M14: CARNE | R14: =IF(vend16[[#This Row],[Nº Venda]]>1,1,0) -> 1
B15: Total | C15: =SUM(C11:C14) -> 2829.99 | E15: 696 | F15: ROSA PARECIDA DOS SANTOS | G15: CTC | H15: 590 | I15: 590 | R15: =IF(vend16[[#This Row],[Nº Venda]]>1,1,0) -> 1
R16: =IF(vend16[[#This Row],[Nº Venda]]>1,1,0) -> 0
B17: Entrega de Carne | R17: =IF(vend16[[#This Row],[Nº Venda]]>1,1,0) -> 0
B18: =COUNT(entr_carn16[OS]) -> 0 | C18: =SUM(entr_carn16[Valor Total]) -> 0 | R18: =IF(vend16[[#This Row],[Nº Venda]]>1,1,0) -> 0
B19: Total | C19: =SUM(C18:C18) -> 0 | R19: =IF(vend16[[#This Row],[Nº Venda]]>1,1,0) -> 0
R20: =IF(vend16[[#This Row],[Nº Venda]]>1,1,0) -> 0
B21: Venda | C21: =C5 -> 6411.99
E24: Restante Entrada
E25: Nº Venda | F25: Cliente | G25: Forma de Pgto | H25: Valor Venda | I25: Entrada
E33: Recebimento de Carnê | K33: Entrega de Carne
E34: OS | F34: Cliente | G34: Forma de Pgto | H34: Valor Parcela | I34: Nº Parcela | K34: OS | L34: Parcelas | M34: Valor Total
Q40: Total de OS | R40: =SUM(R6:R21) -> 10

Sheet 17
B1: ='16'!B1+1 -> 45429
B2: Fechamento Diário do Caixa
B4: Saldo Inicial | C4: 0 | E4: Vendas | K4: Despesas
B5: Vendas | C5: =SUMIF(I6:I31,">0",H6:H31) -> 0 | E5: Nº Venda | F5: Cliente | G5: Forma de Pgto | H5: Valor Venda | I5: Entrada | K5: Descrição | L5: Tipo de Pagto | M5: Valor
B6: Entrada | C6: =SUM(I6:I41) -> 250 | K6: REPARO | L6: PIX | M6: 75 | R6: =IF(vend17[[#This Row],[Nº Venda]]>1,1,0) -> 0
B7: Despesas | C7: =SUM(M6:M11) -> 165 | K7: PEDREIRO | L7: DN | M7: 90 | R7: =IF(vend17[[#This Row],[Nº Venda]]>1,1,0) -> 0
B8: Total entrada | C8: =SUM(C6:C7) -> 415 | R8: =IF(vend17[[#This Row],[Nº Venda]]>1,1,0) -> 0
R9: =IF(vend17[[#This Row],[Nº Venda]]>1,1,0) -> 0
B10: Tipos de Pagtos | R10: =IF(vend17[[#This Row],[Nº Venda]]>1,1,0) -> 0
B11: DN | C11: =(SUMIF($G$2:$G$31,B11,$I$2:$I$31))+(SUMIF($G$35:$G$41,B11,$H$35:$H$41)) -> 0 | O11: =IF(C15=0,0,1) -> 1 | R11: =IF(vend17[[#This Row],[Nº Venda]]>1,1,0) -> 0
B12: CTD | C12: =(SUMIF($G$2:$G$31,B12,$I$2:$I$31))+(SUMIF($G$35:$G$41,B12,$H$35:$H$41)) -> 250 | R12: =IF(vend17[[#This Row],[Nº Venda]]>1,1,0) -> 0
B13: CTC | C13: =(SUMIF($G$2:$G$31,B13,$I$2:$I$31))+(SUMIF($G$35:$G$41,B13,$H$35:$H$41)) -> 0 | K13: OS Entregue no Dia | R13: =IF(vend17[[#This Row],[Nº Venda]]>1,1,0) -> 0
B14: PIX | C14: =(SUMIF($G$2:$G$31,B14,$I$2:$I$31))+(SUMIF($G$35:$G$41,B14,$H$35:$H$41)) -> 0 | K14: OS | L14: Vendedor | M14: CARNE | R14: =IF(vend17[[#This Row],[Nº Venda]]>1,1,0) -> 0
B15: Total | C15: =SUM(C11:C14) -> 250 | K15: 680 | L15: LUANA | M15: Sim | R15: =IF(vend17[[#This Row],[Nº Venda]]>1,1,0) -> 0
K16: 672 | L16: LUANA | M16: Sim | R16: =IF(vend17[[#This Row],[Nº Venda]]>1,1,0) -> 0
B17: Entrega de Carne | K17: 682 | L17: LUANA | M17: Não | R17: =IF(vend17[[#This Row],[Nº Venda]]>1,1,0) -> 0
B18: =COUNT(entr_carn17[OS]) -> 2 | C18: =SUM(entr_carn17[Valor Total]) -> 1500 | K18: 671 | L18: LUANA | M18: Não | R18: =IF(vend17[[#This Row],[Nº Venda]]>1,1,0) -> 0
B19: Total | C19: =SUM(C18:C18) -> 1500 | R19: =IF(vend17[[#This Row],[Nº Venda]]>1,1,0) -> 0
R20: =IF(vend17[[#This Row],[Nº Venda]]>1,1,0) -> 0
B21: Venda | C21: =C5 -> 0
E24: Restante Entrada
E25: Nº Venda | F25: Cliente | G25: Forma de Pgto | H25: Valor Venda | I25: Entrada
E26: 680 | F26: ANTONIO JORGE A.D.S.LIMA | G26: CTD | H26: 0 | I26: 150
E27: 672 | F27: PATRICIA PACIFICO DA SILVA | G27: CTD | H27: 0 | I27: 100
E33: Recebimento de Carnê | K33: Entrega de Carne
E34: OS | F34: Cliente | G34: Forma de Pgto | H34: Valor Parcela | I34: Nº Parcela | K34: OS | L34: Parcelas | M34: Valor Total
K35: 680 | L35: 5 | M35: 500
K36: 672 | L36: 5 | M36: 1000
Q40: Total de OS | R40: =SUM(R6:R21) -> 0

Sheet 18
B1: ='17'!B1+1 -> 45430
B2: Fechamento Diário do Caixa
B4: Saldo Inicial | C4: 0 | E4: Vendas | K4: Despesas
B5: Vendas | C5: =SUMIF(I6:I31,">0",H6:H31) -> 10 | E5: Nº Venda | F5: Cliente | G5: Forma de Pgto | H5: Valor Venda | I5: Entrada | K5: Descrição | L5: Tipo de Pagto | M5: Valor
B6: Entrada | C6: =SUM(I6:I41) -> 10 | E6: 697 | F6: Maria amparo | G6: DN | H6: 10 | I6: 10 | R6: =IF(vend18[[#This Row],[Nº Venda]]>1,1,0) -> 1
B7: Despesas | C7: =SUM(M6:M11) -> 0 | R7: =IF(vend18[[#This Row],[Nº Venda]]>1,1,0) -> 0
B8: Total entrada | C8: =SUM(C6:C7) -> 10 | R8: =IF(vend18[[#This Row],[Nº Venda]]>1,1,0) -> 0
R9: =IF(vend18[[#This Row],[Nº Venda]]>1,1,0) -> 0
B10: Tipos de Pagtos | R10: =IF(vend18[[#This Row],[Nº Venda]]>1,1,0) -> 0
B11: DN | C11: =(SUMIF($G$2:$G$31,B11,$I$2:$I$31))+(SUMIF($G$35:$G$41,B11,$H$35:$H$41)) -> 10 | O11: =IF(C15=0,0,1) -> 1 | R11: =IF(vend18[[#This Row],[Nº Venda]]>1,1,0) -> 0
B12: CTD | C12: =(SUMIF($G$2:$G$31,B12,$I$2:$I$31))+(SUMIF($G$35:$G$41,B12,$H$35:$H$41)) -> 0 | R12: =IF(vend18[[#This Row],[Nº Venda]]>1,1,0) -> 0
B13: CTC | C13: =(SUMIF($G$2:$G$31,B13,$I$2:$I$31))+(SUMIF($G$35:$G$41,B13,$H$35:$H$41)) -> 0 | K13: OS Entregue no Dia | R13: =IF(vend18[[#This Row],[Nº Venda]]>1,1,0) -> 0
B14: PIX | C14: =(SUMIF($G$2:$G$31,B14,$I$2:$I$31))+(SUMIF($G$35:$G$41,B14,$H$35:$H$41)) -> 79.9 | K14: OS | L14: Vendedor | M14: CARNE | R14: =IF(vend18[[#This Row],[Nº Venda]]>1,1,0) -> 0
B15: Total | C15: =SUM(C11:C14) -> 89.9 | K15: 683 | L15: LUANA | M15: Não | R15: =IF(vend18[[#This Row],[Nº Venda]]>1,1,0) -> 0
K16: 665 | L16: LUANA | M16: Não | R16: =IF(vend18[[#This Row],[Nº Venda]]>1,1,0) -> 0
B17: Entrega de Carne | R17: =IF(vend18[[#This Row],[Nº Venda]]>1,1,0) -> 0
B18: =COUNT(entr_carn18[OS]) -> 0 | C18: =SUM(entr_carn18[Valor Total]) -> 0 | R18: =IF(vend18[[#This Row],[Nº Venda]]>1,1,0) -> 0
B19: Total | C19: =SUM(C18:C18) -> 0 | R19: =IF(vend18[[#This Row],[Nº Venda]]>1,1,0) -> 0
R20: =IF(vend18[[#This Row],[Nº Venda]]>1,1,0) -> 0
B21: Venda | C21: =C5 -> 10
E24: Restante Entrada
E25: Nº Venda | F25: Cliente | G25: Forma de Pgto | H25: Valor Venda | I25: Entrada
E33: Recebimento de Carnê | K33: Entrega de Carne
E34: OS | F34: Cliente | G34: Forma de Pgto | H34: Valor Parcela | I34: Nº Parcela | K34: OS | L34: Parcelas | M34: Valor Total
E35: 608 | F35: ANA LUCIA FEITOSA | G35: PIX | H35: 79.9 | I35: PARC. 2/6
Q40: Total de OS | R40: =SUM(R6:R21) -> 1

Sheet 19
B1: ='18'!B1+1 -> 45431
B2: Fechamento Diário do Caixa
B4: Saldo Inicial | C4: 0 | E4: Vendas | K4: Despesas
B5: Vendas | C5: =SUMIF(I6:I31,">0",H6:H31) -> 0 | E5: Nº Venda | F5: Cliente | G5: Forma de Pgto | H5: Valor Venda | I5: Entrada | K5: Descrição | L5: Tipo de Pagto | M5: Valor
B6: Entrada | C6: =SUM(I6:I41) -> 0 | R6: =IF(vend19[[#This Row],[Nº Venda]]>1,1,0) -> 0
B7: Despesas | C7: =SUM(M6:M11) -> 0 | R7: =IF(vend19[[#This Row],[Nº Venda]]>1,1,0) -> 0
B8: Total entrada | C8: =SUM(C6:C7) -> 0 | R8: =IF(vend19[[#This Row],[Nº Venda]]>1,1,0) -> 0
R9: =IF(vend19[[#This Row],[Nº Venda]]>1,1,0) -> 0
B10: Tipos de Pagtos | R10: =IF(vend19[[#This Row],[Nº Venda]]>1,1,0) -> 0
B11: DN | C11: =(SUMIF($G$2:$G$31,B11,$I$2:$I$31))+(SUMIF($G$35:$G$41,B11,$H$35:$H$41)) -> 0 | O11: =IF(C15=0,0,1) -> 0 | R11: =IF(vend19[[#This Row],[Nº Venda]]>1,1,0) -> 0
B12: CTD | C12: =(SUMIF($G$2:$G$31,B12,$I$2:$I$31))+(SUMIF($G$35:$G$41,B12,$H$35:$H$41)) -> 0 | R12: =IF(vend19[[#This Row],[Nº Venda]]>1,1,0) -> 0
B13: CTC | C13: =(SUMIF($G$2:$G$31,B13,$I$2:$I$31))+(SUMIF($G$35:$G$41,B13,$H$35:$H$41)) -> 0 | K13: OS Entregue no Dia | R13: =IF(vend19[[#This Row],[Nº Venda]]>1,1,0) -> 0
B14: PIX | C14: =(SUMIF($G$2:$G$31,B14,$I$2:$I$31))+(SUMIF($G$35:$G$41,B14,$H$35:$H$41)) -> 0 | K14: OS | L14: Vendedor | M14: CARNE | R14: =IF(vend19[[#This Row],[Nº Venda]]>1,1,0) -> 0
B15: Total | C15: =SUM(C11:C14) -> 0 | R15: =IF(vend19[[#This Row],[Nº Venda]]>1,1,0) -> 0
R16: =IF(vend19[[#This Row],[Nº Venda]]>1,1,0) -> 0
B17: Entrega de Carne | R17: =IF(vend19[[#This Row],[Nº Venda]]>1,1,0) -> 0
B18: =COUNT(entr_carn19[OS]) -> 0 | C18: =SUM(entr_carn19[Valor Total]) -> 0 | R18: =IF(vend19[[#This Row],[Nº Venda]]>1,1,0) -> 0
B19: Total | C19: =SUM(C18:C18) -> 0 | R19: =IF(vend19[[#This Row],[Nº Venda]]>1,1,0) -> 0
R20: =IF(vend19[[#This Row],[Nº Venda]]>1,1,0) -> 0
B21: Venda | C21: =C5 -> 0
E24: Restante Entrada
E25: Nº Venda | F25: Cliente | G25: Forma de Pgto | H25: Valor Venda | I25: Entrada
E33: Recebimento de Carnê | K33: Entrega de Carne
E34: OS | F34: Cliente | G34: Forma de Pgto | H34: Valor Parcela | I34: Nº Parcela | K34: OS | L34: Parcelas | M34: Valor Total
Q40: Total de OS | R40: =SUM(R6:R21) -> 0

Sheet 20
B1: ='19'!B1+1 -> 45432
B2: Fechamento Diário do Caixa
B4: Saldo Inicial | C4: 0 | E4: Vendas | K4: Despesas
B5: Vendas | C5: =SUMIF(I6:I31,">0",H6:H31) -> 550 | E5: Nº Venda | F5: Cliente | G5: Forma de Pgto | H5: Valor Venda | I5: Entrada | K5: Descrição | L5: Tipo de Pagto | M5: Valor
B6: Entrada | C6: =SUM(I6:I41) -> 10 | E6: 698 | F6: MARIA INES | G6: GARANTIA | H6: 0 | I6: 0 | R6: =IF(vend20[[#This Row],[Nº Venda]]>1,1,0) -> 1
B7: Despesas | C7: =SUM(M6:M11) -> 0 | E7: 699 | F7: RUANA MARIA | G7: CTC | H7: 550 | I7: 10 | R7: =IF(vend20[[#This Row],[Nº Venda]]>1,1,0) -> 1
B8: Total entrada | C8: =SUM(C6:C7) -> 10 | R8: =IF(vend20[[#This Row],[Nº Venda]]>1,1,0) -> 0 | V8: 0
R9: =IF(vend20[[#This Row],[Nº Venda]]>1,1,0) -> 0
B10: Tipos de Pagtos | R10: =IF(vend20[[#This Row],[Nº Venda]]>1,1,0) -> 0
B11: DN | C11: =(SUMIF($G$2:$G$31,B11,$I$2:$I$31))+(SUMIF($G$35:$G$41,B11,$H$35:$H$41)) -> 0 | O11: =IF(C15=0,0,1) -> 1 | R11: =IF(vend20[[#This Row],[Nº Venda]]>1,1,0) -> 0
B12: CTD | C12: =(SUMIF($G$2:$G$31,B12,$I$2:$I$31))+(SUMIF($G$35:$G$41,B12,$H$35:$H$41)) -> 0 | R12: =IF(vend20[[#This Row],[Nº Venda]]>1,1,0) -> 0
B13: CTC | C13: =(SUMIF($G$2:$G$31,B13,$I$2:$I$31))+(SUMIF($G$35:$G$41,B13,$H$35:$H$41)) -> 10 | K13: OS Entregue no Dia | R13: =IF(vend20[[#This Row],[Nº Venda]]>1,1,0) -> 0
B14: PIX | C14: =(SUMIF($G$2:$G$31,B14,$I$2:$I$31))+(SUMIF($G$35:$G$41,B14,$H$35:$H$41)) -> 0 | K14: OS | L14: Vendedor | M14: CARNE | R14: =IF(vend20[[#This Row],[Nº Venda]]>1,1,0) -> 0
B15: Total | C15: =SUM(C11:C14) -> 10 | R15: =IF(vend20[[#This Row],[Nº Venda]]>1,1,0) -> 0
R16: =IF(vend20[[#This Row],[Nº Venda]]>1,1,0) -> 0
B17: Entrega de Carne | R17: =IF(vend20[[#This Row],[Nº Venda]]>1,1,0) -> 0
B18: =COUNT(entr_carn20[OS]) -> 0 | C18: =SUM(entr_carn20[Valor Total]) -> 0 | R18: =IF(vend20[[#This Row],[Nº Venda]]>1,1,0) -> 0
B19: Total | C19: =SUM(C18:C18) -> 0 | R19: =IF(vend20[[#This Row],[Nº Venda]]>1,1,0) -> 0
R20: =IF(vend20[[#This Row],[Nº Venda]]>1,1,0) -> 0
B21: Venda | C21: =C5 -> 550
E24: Restante Entrada
E25: Nº Venda | F25: Cliente | G25: Forma de Pgto | H25: Valor Venda | I25: Entrada
E33: Recebimento de Carnê | K33: Entrega de Carne
E34: OS | F34: Cliente | G34: Forma de Pgto | H34: Valor Parcela | I34: Nº Parcela | K34: OS | L34: Parcelas | M34: Valor Total
Q40: Total de OS | R40: =SUM(R6:R21) -> 2

Sheet 21
B1: ='20'!B1+1 -> 45433
B2: Fechamento Diário do Caixa
B4: Saldo Inicial | C4: 0 | E4: Vendas | K4: Despesas
B5: Vendas | C5: =SUMIF(I6:I31,">0",H6:H31) -> 0 | E5: Nº Venda | F5: Cliente | G5: Forma de Pgto | H5: Valor Venda | I5: Entrada | K5: Descrição | L5: Tipo de Pagto | M5: Valor
B6: Entrada | C6: =SUM(I6:I41) -> 1440 | R6: =IF(vend21[[#This Row],[Nº Venda]]>1,1,0) -> 0
B7: Despesas | C7: =SUM(M6:M11) -> 0 | R7: =IF(vend21[[#This Row],[Nº Venda]]>1,1,0) -> 0
B8: Total entrada | C8: =SUM(C6:C7) -> 1440 | R8: =IF(vend21[[#This Row],[Nº Venda]]>1,1,0) -> 0
R9: =IF(vend21[[#This Row],[Nº Venda]]>1,1,0) -> 0
B10: Tipos de Pagtos | R10: =IF(vend21[[#This Row],[Nº Venda]]>1,1,0) -> 0
B11: DN | C11: =(SUMIF($G$2:$G$31,B11,$I$2:$I$31))+(SUMIF($G$35:$G$41,B11,$H$35:$H$41)) -> 0 | O11: =IF(C15=0,0,1) -> 1 | R11: =IF(vend21[[#This Row],[Nº Venda]]>1,1,0) -> 0
B12: CTD | C12: =(SUMIF($G$2:$G$31,B12,$I$2:$I$31))+(SUMIF($G$35:$G$41,B12,$H$35:$H$41)) -> 0 | R12: =IF(vend21[[#This Row],[Nº Venda]]>1,1,0) -> 0
B13: CTC | C13: =(SUMIF($G$2:$G$31,B13,$I$2:$I$31))+(SUMIF($G$35:$G$41,B13,$H$35:$H$41)) -> 1440 | K13: OS Entregue no Dia | R13: =IF(vend21[[#This Row],[Nº Venda]]>1,1,0) -> 0
B14: PIX | C14: =(SUMIF($G$2:$G$31,B14,$I$2:$I$31))+(SUMIF($G$35:$G$41,B14,$H$35:$H$41)) -> 0 | K14: OS | L14: Vendedor | M14: CARNE | R14: =IF(vend21[[#This Row],[Nº Venda]]>1,1,0) -> 0
B15: Total | C15: =SUM(C11:C14) -> 1440 | K15: 679 | L15: LUANA | M15: Não | R15: =IF(vend21[[#This Row],[Nº Venda]]>1,1,0) -> 0
K16: 674 | L16: LUANA | M16: Não | R16: =IF(vend21[[#This Row],[Nº Venda]]>1,1,0) -> 0
B17: Entrega de Carne | K17: 675 | L17: LUANA | M17: Não | R17: =IF(vend21[[#This Row],[Nº Venda]]>1,1,0) -> 0
B18: =COUNT(entr_carn21[OS]) -> 0 | C18: =SUM(entr_carn21[Valor Total]) -> 0 | R18: =IF(vend21[[#This Row],[Nº Venda]]>1,1,0) -> 0
B19: Total | C19: =SUM(C18:C18) -> 0 | R19: =IF(vend21[[#This Row],[Nº Venda]]>1,1,0) -> 0
R20: =IF(vend21[[#This Row],[Nº Venda]]>1,1,0) -> 0
B21: Venda | C21: =C5 -> 0
E24: Restante Entrada
E25: Nº Venda | F25: Cliente | G25: Forma de Pgto | H25: Valor Venda | I25: Entrada
E26: 674 | F26: LUIZ CLAUDIO | G26: CTC | H26: 0 | I26: 450
E27: 675 | F27: ELIZABTEH | G27: CTC | H27: 0 | I27: 450
E28: 699 | F28: RUANA MARIA | G28: CTC | H28: 0 | I28: 540
E33: Recebimento de Carnê | K33: Entrega de Carne
E34: OS | F34: Cliente | G34: Forma de Pgto | H34: Valor Parcela | I34: Nº Parcela | K34: OS | L34: Parcelas | M34: Valor Total
Q40: Total de OS | R40: =SUM(R6:R21) -> 0

Sheet 22
B1: ='21'!B1+1 -> 45434
B2: Fechamento Diário do Caixa
B4: Saldo Inicial | C4: 0 | E4: Vendas | K4: Despesas
B5: Vendas | C5: =SUMIF(I6:I31,">0",H6:H31) -> 699 | E5: Nº Venda | F5: Cliente | G5: Forma de Pgto | H5: Valor Venda | I5: Entrada | K5: Descrição | L5: Tipo de Pagto | M5: Valor
B6: Entrada | C6: =SUM(I6:I41) -> 699 | E6: 700 | F6: LINDALVA ALMEIDA | G6: CTC | H6: 699 | I6: 699 | R6: =IF(vend22[[#This Row],[Nº Venda]]>1,1,0) -> 1
B7: Despesas | C7: =SUM(M6:M11) -> 0 | R7: =IF(vend22[[#This Row],[Nº Venda]]>1,1,0) -> 0
B8: Total entrada | C8: =SUM(C6:C7) -> 699 | R8: =IF(vend22[[#This Row],[Nº Venda]]>1,1,0) -> 0
R9: =IF(vend22[[#This Row],[Nº Venda]]>1,1,0) -> 0
B10: Tipos de Pagtos | R10: =IF(vend22[[#This Row],[Nº Venda]]>1,1,0) -> 0
B11: DN | C11: =(SUMIF($G$2:$G$31,B11,$I$2:$I$31))+(SUMIF($G$35:$G$41,B11,$H$35:$H$41)) -> 0 | O11: =IF(C15=0,0,1) -> 1 | R11: =IF(vend22[[#This Row],[Nº Venda]]>1,1,0) -> 0
B12: CTD | C12: =(SUMIF($G$2:$G$31,B12,$I$2:$I$31))+(SUMIF($G$35:$G$41,B12,$H$35:$H$41)) -> 0 | R12: =IF(vend22[[#This Row],[Nº Venda]]>1,1,0) -> 0
B13: CTC | C13: =(SUMIF($G$2:$G$31,B13,$I$2:$I$31))+(SUMIF($G$35:$G$41,B13,$H$35:$H$41)) -> 699 | K13: OS Entregue no Dia | R13: =IF(vend22[[#This Row],[Nº Venda]]>1,1,0) -> 0
B14: PIX | C14: =(SUMIF($G$2:$G$31,B14,$I$2:$I$31))+(SUMIF($G$35:$G$41,B14,$H$35:$H$41)) -> 64.9 | K14: OS | L14: Vendedor | M14: CARNE | R14: =IF(vend22[[#This Row],[Nº Venda]]>1,1,0) -> 0
B15: Total | C15: =SUM(C11:C14) -> 763.9 | R15: =IF(vend22[[#This Row],[Nº Venda]]>1,1,0) -> 0
R16: =IF(vend22[[#This Row],[Nº Venda]]>1,1,0) -> 0
B17: Entrega de Carne | R17: =IF(vend22[[#This Row],[Nº Venda]]>1,1,0) -> 0
B18: =COUNT(entr_carn22[OS]) -> 0 | C18: =SUM(entr_carn22[Valor Total]) -> 0 | R18: =IF(vend22[[#This Row],[Nº Venda]]>1,1,0) -> 0
B19: Total | C19: =SUM(C18:C18) -> 0 | R19: =IF(vend22[[#This Row],[Nº Venda]]>1,1,0) -> 0
R20: =IF(vend22[[#This Row],[Nº Venda]]>1,1,0) -> 0
B21: Venda | C21: =C5 -> 699
E24: Restante Entrada
E25: Nº Venda | F25: Cliente | G25: Forma de Pgto | H25: Valor Venda | I25: Entrada
E33: Recebimento de Carnê | K33: Entrega de Carne
E34: OS | F34: Cliente | G34: Forma de Pgto | H34: Valor Parcela | I34: Nº Parcela | K34: OS | L34: Parcelas | M34: Valor Total
E35: 473 | F35: JARDEL WEVERTON | G35: PIX | H35: 64.9 | I35: PARC. 7/10
Q40: Total de OS | R40: =SUM(R6:R21) -> 1

Sheet 24
B1: ='23'!B1+1 -> 45436
B2: Fechamento Diário do Caixa
B4: Saldo Inicial | C4: 0 | E4: Vendas | K4: Despesas
B5: Vendas | C5: =SUMIF(I6:I31,">0",H6:H31) -> 0 | E5: Nº Venda | F5: Cliente | G5: Forma de Pgto | H5: Valor Venda | I5: Entrada | K5: Descrição | L5: Tipo de Pagto | M5: Valor
B6: Entrada | C6: =SUM(I6:I41) -> 0 | R6: =IF(vend24[[#This Row],[Nº Venda]]>1,1,0) -> 0
B7: Despesas | C7: =SUM(M6:M11) -> 0 | R7: =IF(vend24[[#This Row],[Nº Venda]]>1,1,0) -> 0
B8: Total entrada | C8: =SUM(C6:C7) -> 0 | R8: =IF(vend24[[#This Row],[Nº Venda]]>1,1,0) -> 0
R9: =IF(vend24[[#This Row],[Nº Venda]]>1,1,0) -> 0
B10: Tipos de Pagtos | R10: =IF(vend24[[#This Row],[Nº Venda]]>1,1,0) -> 0
B11: DN | C11: =(SUMIF($G$2:$G$31,B11,$I$2:$I$31))+(SUMIF($G$35:$G$41,B11,$H$35:$H$41)) -> 95 | O11: =IF(C15=0,0,1) -> 1 | R11: =IF(vend24[[#This Row],[Nº Venda]]>1,1,0) -> 0
B12: CTD | C12: =(SUMIF($G$2:$G$31,B12,$I$2:$I$31))+(SUMIF($G$35:$G$41,B12,$H$35:$H$41)) -> 0 | R12: =IF(vend24[[#This Row],[Nº Venda]]>1,1,0) -> 0
B13: CTC | C13: =(SUMIF($G$2:$G$31,B13,$I$2:$I$31))+(SUMIF($G$35:$G$41,B13,$H$35:$H$41)) -> 0 | K13: OS Entregue no Dia | R13: =IF(vend24[[#This Row],[Nº Venda]]>1,1,0) -> 0
B14: PIX | C14: =(SUMIF($G$2:$G$31,B14,$I$2:$I$31))+(SUMIF($G$35:$G$41,B14,$H$35:$H$41)) -> 0 | K14: OS | L14: Vendedor | M14: CARNE | R14: =IF(vend24[[#This Row],[Nº Venda]]>1,1,0) -> 0
B15: Total | C15: =SUM(C11:C14) -> 95 | R15: =IF(vend24[[#This Row],[Nº Venda]]>1,1,0) -> 0
R16: =IF(vend24[[#This Row],[Nº Venda]]>1,1,0) -> 0
B17: Entrega de Carne | R17: =IF(vend24[[#This Row],[Nº Venda]]>1,1,0) -> 0
B18: =COUNT(entr_carn24[OS]) -> 0 | C18: =SUM(entr_carn24[Valor Total]) -> 0 | R18: =IF(vend24[[#This Row],[Nº Venda]]>1,1,0) -> 0
B19: Total | C19: =SUM(C18:C18) -> 0 | R19: =IF(vend24[[#This Row],[Nº Venda]]>1,1,0) -> 0
R20: =IF(vend24[[#This Row],[Nº Venda]]>1,1,0) -> 0
B21: Venda | C21: =C5 -> 0
E24: Restante Entrada
E25: Nº Venda | F25: Cliente | G25: Forma de Pgto | H25: Valor Venda | I25: Entrada
E33: Recebimento de Carnê | K33: Entrega de Carne
E34: OS | F34: Cliente | G34: Forma de Pgto | H34: Valor Parcela | I34: Nº Parcela | K34: OS | L34: Parcelas | M34: Valor Total
E35: 316 | F35: ALINE MENESE | G35: DN | H35: 95 | I35: PARC. 5/7
Q40: Total de OS | R40: =SUM(R6:R21) -> 0

Sheet 23
B1: ='22'!B1+1 -> 45435
B2: Fechamento Diário do Caixa
B4: Saldo Inicial | C4: 0 | E4: Vendas | K4: Despesas
B5: Vendas | C5: =SUMIF(I6:I31,">0",H6:H31) -> 0 | E5: Nº Venda | F5: Cliente | G5: Forma de Pgto | H5: Valor Venda | I5: Entrada | K5: Descrição | L5: Tipo de Pagto | M5: Valor
B6: Entrada | C6: =SUM(I6:I41) -> 500 | R6: =IF(vend23[[#This Row],[Nº Venda]]>1,1,0) -> 0
B7: Despesas | C7: =SUM(M6:M11) -> 0 | R7: =IF(vend23[[#This Row],[Nº Venda]]>1,1,0) -> 0
B8: Total entrada | C8: =SUM(C6:C7) -> 500 | R8: =IF(vend23[[#This Row],[Nº Venda]]>1,1,0) -> 0
R9: =IF(vend23[[#This Row],[Nº Venda]]>1,1,0) -> 0
B10: Tipos de Pagtos | R10: =IF(vend23[[#This Row],[Nº Venda]]>1,1,0) -> 0
B11: DN | C11: =(SUMIF($G$2:$G$31,B11,$I$2:$I$31))+(SUMIF($G$35:$G$44,B11,$H$35:$H$44)) -> 0 | O11: =IF(C15=0,0,1) -> 1 | R11: =IF(vend23[[#This Row],[Nº Venda]]>1,1,0) -> 0
B12: CTD | C12: =(SUMIF($G$2:$G$31,B12,$I$2:$I$31))+(SUMIF($G$35:$G$44,B12,$H$35:$H$44)) -> 0 | R12: =IF(vend23[[#This Row],[Nº Venda]]>1,1,0) -> 0
B13: CTC | C13: =(SUMIF($G$2:$G$31,B13,$I$2:$I$31))+(SUMIF($G$35:$G$44,B13,$H$35:$H$44)) -> 0 | K13: OS Entregue no Dia | R13: =IF(vend23[[#This Row],[Nº Venda]]>1,1,0) -> 0
