Workbook

Sheet resumo_cx
P1: Colaboradores
A2: Saldo Inicial | B2: 0 | P2: ROGÉRIO
A3: Vendas | B3: =SUM('01'!C5,'02'!C5,'03'!C5,'04'!C5,'05'!C5,'06'!C5,'07'!C5,'08'!C5,'09'!C5,'10'!C5,'11'!C5,'12'!C5,'13'!C5,'14'!C5,'15'!C5,'16'!C5,'17'!C5,'18'!C5,'19'!C5,'20'!C5,'21'!C5,'22'!C5,'23'!C5,'24'!C5,'25'!C5,'26'!C5,'27'!C5,'28'!C5,'29'!C5,'30'!C5,'31'!C5) -> 6414 | P3: JOCY
A4: Entrada | B4: =SUM('01'!C6,'02'!C6,'03'!C6,'04'!C6,'05'!C6,'06'!C6,'07'!C6,'08'!C6,'09'!C6,'10'!C6,'11'!C6,'12'!C6,'13'!C6,'14'!C6,'15'!C6,'16'!C6,'17'!C6,'18'!C6,'19'!C6,'20'!C6,'21'!C6,'22'!C6,'23'!C6,'24'!C6,'25'!C6,'26'!C6,'27'!C6,'28'!C6,'29'!C6,'30'!C6,'31'!C6) -> 10774.5 | P4: MARIA
A5: Despesas | B5: =SUM('01'!C7,'02'!C7,'03'!C7,'04'!C7,'05'!C7,'06'!C7,'07'!C7,'08'!C7,'09'!C7,'10'!C7,'11'!C7,'12'!C7,'13'!C7,'14'!C7,'15'!C7,'16'!C7,'17'!C7,'18'!C7,'19'!C7,'20'!C7,'21'!C7,'22'!C7,'23'!C7,'24'!C7,'25'!C7,'26'!C7,'27'!C7,'28'!C7,'29'!C7,'30'!C7,'31'!C7) -> 246 | P5: WEVILLY
A6: Entr_Desp | B6: =SUM(B4:B5) -> 11020.5 | P6: BETH
P7: ARIANI
A8: Tipos de Pagtos | P8: ROSÂNGELA
A9: DN | B9: =SUM('01'!C11,'02'!C11,'03'!C11,'04'!C11,'05'!C11,'06'!C11,'07'!C11,'08'!C11,'09'!C11,'10'!C11,'11'!C11,'12'!C11,'13'!C11,'14'!C11,'15'!C11,'16'!C11,'17'!C11,'18'!C11,'19'!C11,'20'!C11,'21'!C11,'22'!C11,'23'!C11,'24'!C11,'25'!C11,'26'!C11,'27'!C11,'28'!C11,'29'!C11,'30'!C11,'31'!C11) -> 1711.5 | P9: TATY
A10: CTD | B10: =SUM('01'!C12,'02'!C12,'03'!C12,'04'!C12,'05'!C12,'06'!C12,'07'!C12,'08'!C12,'09'!C12,'10'!C12,'11'!C12,'12'!C12,'13'!C12,'14'!C12,'15'!C12,'16'!C12,'17'!C12,'18'!C12,'19'!C12,'20'!C12,'21'!C12,'22'!C12,'23'!C12,'24'!C12,'25'!C12,'26'!C12,'27'!C12,'28'!C12,'29'!C12,'30'!C12,'31'!C12) -> 2101 | P10: LARISSA
A11: CTC | B11: =SUM('01'!C13,'02'!C13,'03'!C13,'04'!C13,'05'!C13,'06'!C13,'07'!C13,'08'!C13,'09'!C13,'10'!C13,'11'!C13,'12'!C13,'13'!C13,'14'!C13,'15'!C13,'16'!C13,'17'!C13,'18'!C13,'19'!C13,'20'!C13,'21'!C13,'22'!C13,'23'!C13,'24'!C13,'25'!C13,'26'!C13,'27'!C13,'28'!C13,'29'!C13,'30'!C13,'31'!C13) -> 2143 | P11: ERIKA
A12: PCTC | B12: =SUM('01'!C14,'02'!C14,'03'!C14,'04'!C14,'05'!C14,'06'!C14,'07'!C14,'08'!C14,'09'!C14,'10'!C14,'11'!C14,'12'!C14,'13'!C14,'14'!C14,'15'!C14,'16'!C14,'17'!C14,'18'!C14,'19'!C14,'20'!C14,'21'!C14,'22'!C14,'23'!C14,'24'!C14,'25'!C14,'26'!C14,'27'!C14,'28'!C14,'29'!C14,'30'!C14,'31'!C14) -> 1880 | P12: LUANA
A13: PIX | B13: =SUM('01'!C15,'02'!C15,'03'!C15,'04'!C15,'05'!C15,'06'!C15,'07'!C15,'08'!C15,'09'!C15,'10'!C15,'11'!C15,'12'!C15,'13'!C15,'14'!C15,'15'!C15,'16'!C15,'17'!C15,'18'!C15,'19'!C15,'20'!C15,'21'!C15,'22'!C15,'23'!C15,'24'!C15,'25'!C15,'26'!C15,'27'!C15,'28'!C15,'29'!C15,'30'!C15,'31'!C15) -> 2939 | P13: FELIPE
A14: Total | B14: =SUM(B9:B13) -> 10774.5
A16: Entrega de Carne
A17: =COUNT(#REF!) -> 0 | B17: =SUM('01'!C19,'02'!C19,'03'!C19,'04'!C19,'05'!C19,'06'!C19,'07'!C19,'08'!C19,'09'!C19,'10'!C19,'11'!C19,'12'!C19,'13'!C19,'14'!C19,'15'!C19,'16'!C19,'17'!C19,'18'!C19,'19'!C19,'20'!C19,'21'!C19,'22'!C19,'23'!C19,'24'!C19,'25'!C19,'26'!C19,'27'!C19,'28'!C19,'29'!C19,'30'!C19,'31'!C19) -> 1943.99
A18: Total | B18: =SUM(B17:B17) -> 1943.99

Sheet 01
B1: 45597
B2: Fechamento Diário do Caixa - Escritório
B4: Saldo Inicial | C4: 0 | E4: Vendas | K4: Despesas
B5: Vendas | C5: =SUMIF(I6:I31,">0",H6:H31) -> 0 | E5: Nº Venda | F5: Cliente | G5: Forma de Pgto | H5: Valor Venda | I5: Entrada | K5: Descrição | L5: Tipo de Pagto | M5: Valor
B6: Entrada | C6: =C16 -> 3370 | R6: =IF(vend1[[#This Row],[Nº Venda]]>1,1,0) -> 0
B7: Despesas | C7: =SUM(M6:M11) -> 0 | R7: =IF(vend1[[#This Row],[Nº Venda]]>1,1,0) -> 0
B8: Total entrada | C8: =SUM(C6:C7) -> 3370 | R8: =IF(vend1[[#This Row],[Nº Venda]]>1,1,0) -> 0
R9: =IF(vend1[[#This Row],[Nº Venda]]>1,1,0) -> 0
B10: Tipos de Pagtos | R10: =IF(vend1[[#This Row],[Nº Venda]]>1,1,0) -> 0
B11: DN | C11: =(SUMIF($G$2:$G$33,B11,$I$2:$I$33))+(SUMIF($G$37:$G$43,B11,$H$37:$H$43)) -> 440 | O11: =IF(C16=0,0,1) -> 1 | R11: =IF(vend1[[#This Row],[Nº Venda]]>1,1,0) -> 0
B12: CTD | C12: =(SUMIF($G$2:$G$33,B12,$I$2:$I$33))+(SUMIF($G$37:$G$43,B12,$H$37:$H$43)) -> 300 | R12: =IF(vend1[[#This Row],[Nº Venda]]>1,1,0) -> 0
B13: CTC | C13: =(SUMIF($G$2:$G$33,B13,$I$2:$I$33))+(SUMIF($G$37:$G$43,B13,$H$37:$H$43)) -> 0 | K13: OS Entregue no Dia | R13: =IF(vend1[[#This Row],[Nº Venda]]>1,1,0) -> 0
B14: PCTC | C14: =(SUMIF($G$2:$G$33,B14,$I$2:$I$33))+(SUMIF($G$37:$G$43,B14,$H$37:$H$43)) -> 1880 | K14: OS | L14: Vendedor | M14: CARNE | R14: =IF(vend1[[#This Row],[Nº Venda]]>1,1,0) -> 0
B15: PIX | C15: =(SUMIF($G$2:$G$31,B15,$I$2:$I$31))+(SUMIF($G$37:$G$43,B15,$H$37:$H$43)) -> 750 | K15: 6805 | L15: TATY | M15: Não | R15: =IF(vend1[[#This Row],[Nº Venda]]>1,1,0) -> 0
B16: Total | C16: =SUM(C11:C15) -> 3370 | K16: 6914 | L16: TATY | M16: Não | R16: =IF(vend1[[#This Row],[Nº Venda]]>1,1,0) -> 0
K17: 6928 | L17: LUANA | M17: Não | R17: =IF(vend1[[#This Row],[Nº Venda]]>1,1,0) -> 0
B18: Entrega de Carne | R18: =IF(vend1[[#This Row],[Nº Venda]]>1,1,0) -> 0
B19: =COUNT(entr_carn1[OS]) -> 1 | C19: =SUM(entr_carn1[Valor Total]) -> 470 | R19: =IF(vend1[[#This Row],[Nº Venda]]>1,1,0) -> 0
B20: Total | C20: =SUM(C19:C19) -> 470 | R20: =IF(vend1[[#This Row],[Nº Venda]]>1,1,0) -> 0
B22: Venda | C22: =C5 -> 0
E24: Restante Entrada
E25: Nº Venda | F25: Cliente | G25: Forma de Pgto | H25: Valor Venda | I25: Entrada
E26: 6916 | F26: MARIA FATIMA | G26: DN | H26: 0 | I26: 290
E27: 6804 | F27: ALESSANDRA SIMOES | G27: PIX | H27: 0 | I27: 375
E28: 6805 | F28: ALESSANDRA SIMOES | G28: PIX | H28: 0 | I28: 375
E29: 6928 | F29: MAYME SANTOS | G29: CTD | H29: 0 | I29: 300
E30: 6926 | F30: JOSE MOREIRA | G30: PCTC | H30: 0 | I30: 490
E31: 6927 | F31: JOSE MOREIRA | G31: PCTC | H31: 0 | I31: 490
E32: 6914 | F32: SANDRA ROSE | G32: PCTC | H32: 0 | I32: 900
E33: 6912 | F33: GILMAR CESAR | G33: DN | H33: 0 | I33: 150 | K33: Entrega de Carne
K34: OS | L34: Parcelas | M34: Valor Total
E35: Recebimento de Carnê | K35: 6928 | L35: 5 | M35: 470
E36: OS | F36: Cliente | G36: Forma de Pgto | H36: Valor Parcela | I36: Nº Parcela
Q40: Total de OS | R40: =SUM(R6:R21) -> 0

Sheet 02
B1: ='01'!B1+1 -> 45598
B2: Fechamento Diário do Caixa
B4: Saldo Inicial | C4: 0 | E4: Vendas | K4: Despesas
B5: Vendas | C5: =SUMIF(I6:I31,">0",H6:H31) -> 0 | E5: Nº Venda | F5: Cliente | G5: Forma de Pgto | H5: Valor Venda | I5: Entrada | K5: Descrição | L5: Tipo de Pagto | M5: Valor
B6: Entrada | C6: =C16 -> 0 | R6: =IF(vend2[[#This Row],[Nº Venda]]>1,1,0) -> 0
B7: Despesas | C7: =SUM(M6:M11) -> 0 | R7: =IF(vend2[[#This Row],[Nº Venda]]>1,1,0) -> 0
B8: Total entrada | C8: =SUM(C6:C7) -> 0 | R8: =IF(vend2[[#This Row],[Nº Venda]]>1,1,0) -> 0
R9: =IF(vend2[[#This Row],[Nº Venda]]>1,1,0) -> 0
B10: Tipos de Pagtos | R10: =IF(vend2[[#This Row],[Nº Venda]]>1,1,0) -> 0
B11: DN | C11: =(SUMIF($G$2:$G$31,B11,$I$2:$I$31))+(SUMIF($G$35:$G$41,B11,$H$35:$H$41)) -> 0 | O11: =IF(C16=0,0,1) -> 0 | R11: =IF(vend2[[#This Row],[Nº Venda]]>1,1,0) -> 0
B12: CTD | C12: =(SUMIF($G$2:$G$31,B12,$I$2:$I$31))+(SUMIF($G$35:$G$41,B12,$H$35:$H$41)) -> 0 | R12: =IF(vend2[[#This Row],[Nº Venda]]>1,1,0) -> 0
B13: CTC | C13: =(SUMIF($G$2:$G$31,B13,$I$2:$I$31))+(SUMIF($G$35:$G$41,B13,$H$35:$H$41)) -> 0 | K13: OS Entregue no Dia | R13: =IF(vend2[[#This Row],[Nº Venda]]>1,1,0) -> 0
B14: PCTC | C14: =(SUMIF($G$2:$G$31,B14,$I$2:$I$31))+(SUMIF($G$35:$G$41,B14,$H$35:$H$41)) -> 0 | K14: OS | L14: Vendedor | M14: CARNE | R14: =IF(vend2[[#This Row],[Nº Venda]]>1,1,0) -> 0
B15: PIX | C15: =(SUMIF($G$2:$G$31,B15,$I$2:$I$31))+(SUMIF($G$35:$G$41,B15,$H$35:$H$41)) -> 0 | K15: 6926 | L15: LUANA | M15: Não | R15: =IF(vend2[[#This Row],[Nº Venda]]>1,1,0) -> 0
B16: Total | C16: =SUM(C11:C15) -> 0 | K16: 6927 | L16: LUANA | M16: Não | R16: =IF(vend2[[#This Row],[Nº Venda]]>1,1,0) -> 0
R17: =IF(vend2[[#This Row],[Nº Venda]]>1,1,0) -> 0
B18: Entrega de Carne | R18: =IF(vend2[[#This Row],[Nº Venda]]>1,1,0) -> 0
B19: =COUNT(entr_carn2[OS]) -> 0 | C19: =SUM(entr_carn2[Valor Total]) -> 0 | R19: =IF(vend2[[#This Row],[Nº Venda]]>1,1,0) -> 0
B20: Total | C20: =SUM(C19:C19) -> 0 | R20: =IF(vend2[[#This Row],[Nº Venda]]>1,1,0) -> 0
B22: Venda | C22: =C5 -> 0
E24: Restante Entrada
E25: Nº Venda | F25: Cliente | G25: Forma de Pgto | H25: Valor Venda | I25: Entrada
E33: Recebimento de Carnê | K33: Entrega de Carne
E34: OS | F34: Cliente | G34: Forma de Pgto | H34: Valor Parcela | I34: Nº Parcela | K34: OS | L34: Parcelas | M34: Valor Total | U34: V
Q40: Total de OS | R40: =SUM(R6:R21) -> 0

Sheet 03
B1: ='02'!B1+1 -> 45599
B2: Fechamento Diário do Caixa
B4: Saldo Inicial | C4: 0 | E4: Vendas | K4: Despesas
B5: Vendas | C5: =SUMIF(I6:I31,">0",H6:H31) -> 0 | E5: Nº Venda | F5: Cliente | G5: Forma de Pgto | H5: Valor Venda | I5: Entrada | K5: Descrição | L5: Tipo de Pagto | M5: Valor
B6: Entrada | C6: =C16 -> 0 | R6: =IF(vend3[[#This Row],[Nº Venda]]>1,1,0) -> 0
B7: Despesas | C7: =SUM(M6:M11) -> 0 | R7: =IF(vend3[[#This Row],[Nº Venda]]>1,1,0) -> 0
B8: Total entrada | C8: =SUM(C6:C7) -> 0 | R8: =IF(vend3[[#This Row],[Nº Venda]]>1,1,0) -> 0
R9: =IF(vend3[[#This Row],[Nº Venda]]>1,1,0) -> 0
B10: Tipos de Pagtos | R10: =IF(vend3[[#This Row],[Nº Venda]]>1,1,0) -> 0
B11: DN | C11: =(SUMIF($G$2:$G$31,B11,$I$2:$I$31))+(SUMIF($G$35:$G$41,B11,$H$35:$H$41)) -> 0 | O11: =IF(C16=0,0,1) -> 0 | R11: =IF(vend3[[#This Row],[Nº Venda]]>1,1,0) -> 0
B12: CTD | C12: =(SUMIF($G$2:$G$31,B12,$I$2:$I$31))+(SUMIF($G$35:$G$41,B12,$H$35:$H$41)) -> 0 | R12: =IF(vend3[[#This Row],[Nº Venda]]>1,1,0) -> 0
B13: CTC | C13: =(SUMIF($G$2:$G$31,B13,$I$2:$I$31))+(SUMIF($G$35:$G$41,B13,$H$35:$H$41)) -> 0 | K13: OS Entregue no Dia | R13: =IF(vend3[[#This Row],[Nº Venda]]>1,1,0) -> 0
B14: PCTC | C14: =(SUMIF($G$2:$G$31,B14,$I$2:$I$31))+(SUMIF($G$35:$G$41,B14,$H$35:$H$41)) -> 0 | K14: OS | L14: Vendedor | M14: CARNE | R14: =IF(vend3[[#This Row],[Nº Venda]]>1,1,0) -> 0
B15: PIX | C15: =(SUMIF($G$2:$G$31,B15,$I$2:$I$31))+(SUMIF($G$35:$G$41,B15,$H$35:$H$41)) -> 0 | R15: =IF(vend3[[#This Row],[Nº Venda]]>1,1,0) -> 0
B16: Total | C16: =SUM(C11:C15) -> 0 | R16: =IF(vend3[[#This Row],[Nº Venda]]>1,1,0) -> 0
R17: =IF(vend3[[#This Row],[Nº Venda]]>1,1,0) -> 0
B18: Entrega de Carne | R18: =IF(vend3[[#This Row],[Nº Venda]]>1,1,0) -> 0
B19: =COUNT(entr_carn3[OS]) -> 0 | C19: =SUM(entr_carn3[Valor Total]) -> 0 | R19: =IF(vend3[[#This Row],[Nº Venda]]>1,1,0) -> 0
B20: Total | C20: =SUM(C19:C19) -> 0 | R20: =IF(vend3[[#This Row],[Nº Venda]]>1,1,0) -> 0
B22: Venda | C22: =C5 -> 0
E24: Restante Entrada
E25: Nº Venda | F25: Cliente | G25: Forma de Pgto | H25: Valor Venda | I25: Entrada
E33: Recebimento de Carnê | K33: Entrega de Carne
E34: OS | F34: Cliente | G34: Forma de Pgto | H34: Valor Parcela | I34: Nº Parcela | K34: OS | L34: Parcelas | M34: Valor Total
Q40: Total de OS | R40: =SUM(R6:R21) -> 0

Sheet 04
B1: ='03'!B1+1 -> 45600
B2: Fechamento Diário do Caixa
B4: Saldo Inicial | C4: 0 | E4: Vendas | K4: Despesas
B5: Vendas | C5: =SUMIF(I6:I31,">0",H6:H31) -> 0 | E5: Nº Venda | F5: Cliente | G5: Forma de Pgto | H5: Valor Venda | I5: Entrada | K5: Descrição | L5: Tipo de Pagto | M5: Valor
B6: Entrada | C6: =C16 -> 50 | R6: =IF(vend4[[#This Row],[Nº Venda]]>1,1,0) -> 0
B7: Despesas | C7: =SUM(M6:M11) -> 0 | R7: =IF(vend4[[#This Row],[Nº Venda]]>1,1,0) -> 0
B8: Total entrada | C8: =SUM(C6:C7) -> 50 | R8: =IF(vend4[[#This Row],[Nº Venda]]>1,1,0) -> 0
R9: =IF(vend4[[#This Row],[Nº Venda]]>1,1,0) -> 0
B10: Tipos de Pagtos | R10: =IF(vend4[[#This Row],[Nº Venda]]>1,1,0) -> 0
B11: DN | C11: =(SUMIF($G$2:$G$31,B11,$I$2:$I$31))+(SUMIF($G$35:$G$41,B11,$H$35:$H$41)) -> 0 | O11: =IF(C16=0,0,1) -> 1 | R11: =IF(vend4[[#This Row],[Nº Venda]]>1,1,0) -> 0
B12: CTD | C12: =(SUMIF($G$2:$G$31,B12,$I$2:$I$31))+(SUMIF($G$35:$G$41,B12,$H$35:$H$41)) -> 50 | R12: =IF(vend4[[#This Row],[Nº Venda]]>1,1,0) -> 0
B13: CTC | C13: =(SUMIF($G$2:$G$31,B13,$I$2:$I$31))+(SUMIF($G$35:$G$41,B13,$H$35:$H$41)) -> 0 | K13: OS Entregue no Dia | R13: =IF(vend4[[#This Row],[Nº Venda]]>1,1,0) -> 0
B14: PCTC | C14: =(SUMIF($G$2:$G$31,B14,$I$2:$I$31))+(SUMIF($G$35:$G$41,B14,$H$35:$H$41)) -> 0 | K14: OS | L14: Vendedor | M14: CARNE | R14: =IF(vend4[[#This Row],[Nº Venda]]>1,1,0) -> 0
B15: PIX | C15: =(SUMIF($G$2:$G$31,B15,$I$2:$I$31))+(SUMIF($G$35:$G$41,B15,$H$35:$H$41)) -> 0 | R15: =IF(vend4[[#This Row],[Nº Venda]]>1,1,0) -> 0
B16: Total | C16: =SUM(C11:C15) -> 50 | R16: =IF(vend4[[#This Row],[Nº Venda]]>1,1,0) -> 0
R17: =IF(vend4[[#This Row],[Nº Venda]]>1,1,0) -> 0
B18: Entrega de Carne | R18: =IF(vend4[[#This Row],[Nº Venda]]>1,1,0) -> 0
B19: =COUNT(entr_carn4[OS]) -> 0 | C19: =SUM(entr_carn4[Valor Total]) -> 0 | R19: =IF(vend4[[#This Row],[Nº Venda]]>1,1,0) -> 0
B20: Total | C20: =SUM(C19:C19) -> 0 | R20: =IF(vend4[[#This Row],[Nº Venda]]>1,1,0) -> 0
B22: Venda | C22: =C5 -> 0
E24: Restante Entrada
E25: Nº Venda | F25: Cliente | G25: Forma de Pgto | H25: Valor Venda | I25: Entrada
E33: Recebimento de Carnê | K33: Entrega de Carne
E34: OS | F34: Cliente | G34: Forma de Pgto | H34: Valor Parcela | I34: Nº Parcela | K34: OS | L34: Parcelas | M34: Valor Total
E35: 878 | F35: REGINA APARECIDA | G35: CTD | H35: 50 | I35: PARC. 3/6
Q40: Total de OS | R40: =SUM(R6:R21) -> 0

Sheet 05
B1: ='04'!B1+1 -> 45601
B2: Fechamento Diário do Caixa
B4: Saldo Inicial | C4: 0 | E4: Vendas | K4: Despesas
B5: Vendas | C5: =SUMIF(I6:I31,">0",H6:H31) -> 0 | E5: Nº Venda | F5: Cliente | G5: Forma de Pgto | H5: Valor Venda | I5: Entrada | K5: Descrição | L5: Tipo de Pagto | M5: Valor
B6: Entrada | C6: =C16 -> 799 | E6: 6940 | F6: LAERCIO AUGUSTO | G6: GARANTIA | H6: 0 | I6: 0 | R6: =IF(vend5[[#This Row],[Nº Venda]]>1,1,0) -> 1
B7: Despesas | C7: =SUM(M6:M11) -> 0 | R7: =IF(vend5[[#This Row],[Nº Venda]]>1,1,0) -> 0
B8: Total entrada | C8: =SUM(C6:C7) -> 799 | R8: =IF(vend5[[#This Row],[Nº Venda]]>1,1,0) -> 0
R9: =IF(vend5[[#This Row],[Nº Venda]]>1,1,0) -> 0
B10: Tipos de Pagtos | R10: =IF(vend5[[#This Row],[Nº Venda]]>1,1,0) -> 0
B11: DN | C11: =(SUMIF($G$2:$G$31,B11,$I$2:$I$31))+(SUMIF($G$35:$G$41,B11,$H$35:$H$41)) -> 100 | O11: =IF(C16=0,0,1) -> 1 | R11: =IF(vend5[[#This Row],[Nº Venda]]>1,1,0) -> 0
B12: CTD | C12: =(SUMIF($G$2:$G$31,B12,$I$2:$I$31))+(SUMIF($G$35:$G$41,B12,$H$35:$H$41)) -> 699 | R12: =IF(vend5[[#This Row],[Nº Venda]]>1,1,0) -> 0
B13: CTC | C13: =(SUMIF($G$2:$G$31,B13,$I$2:$I$31))+(SUMIF($G$35:$G$41,B13,$H$35:$H$41)) -> 0 | K13: OS Entregue no Dia | R13: =IF(vend5[[#This Row],[Nº Venda]]>1,1,0) -> 0
B14: PCTC | C14: =(SUMIF($G$2:$G$31,B14,$I$2:$I$31))+(SUMIF($G$35:$G$41,B14,$H$35:$H$41)) -> 0 | K14: OS | L14: Vendedor | M14: CARNE | R14: =IF(vend5[[#This Row],[Nº Venda]]>1,1,0) -> 0
B15: PIX | C15: =(SUMIF($G$2:$G$31,B15,$I$2:$I$31))+(SUMIF($G$35:$G$41,B15,$H$35:$H$41)) -> 0 | K15: 6931 | L15: LUANA | M15: NÃO | R15: =IF(vend5[[#This Row],[Nº Venda]]>1,1,0) -> 0
B16: Total | C16: =SUM(C11:C15) -> 799 | K16: 6936 | L16: LUANA | M16: NÃO | R16: =IF(vend5[[#This Row],[Nº Venda]]>1,1,0) -> 0
R17: =IF(vend5[[#This Row],[Nº Venda]]>1,1,0) -> 0
B18: Entrega de Carne | R18: =IF(vend5[[#This Row],[Nº Venda]]>1,1,0) -> 0
B19: =COUNT(entr_carn5[OS]) -> 0 | C19: =SUM(entr_carn5[Valor Total]) -> 0 | R19: =IF(vend5[[#This Row],[Nº Venda]]>1,1,0) -> 0
B20: Total | C20: =SUM(C19:C19) -> 0 | R20: =IF(vend5[[#This Row],[Nº Venda]]>1,1,0) -> 0
B22: Venda | C22: =C5 -> 0
E24: Restante Entrada
E25: Nº Venda | F25: Cliente | G25: Forma de Pgto | H25: Valor Venda | I25: Entrada
E26: 6934 | F26: REGILNALDO DE OLIVEIRA | G26: CTD | H26: 0 | I26: 699
E33: Recebimento de Carnê | K33: Entrega de Carne
E34: OS | F34: Cliente | G34: Forma de Pgto | H34: Valor Parcela | I34: Nº Parcela | K34: OS | L34: Parcelas | M34: Valor Total
E35: 6637 | F35: ALICE ALMEIDA | G35: DN | H35: 100 | I35: PARC. 7/8
Q40: Total de OS | R40: =SUM(R6:R21) -> 1

Sheet 06
B1: ='05'!B1+1 -> 45602
B2: Fechamento Diário do Caixa
B4: Saldo Inicial | C4: 0 | E4: Vendas | K4: Despesas
B5: Vendas | C5: =SUMIF(I6:I31,">0",H6:H31) -> 0 | E5: Nº Venda | F5: Cliente | G5: Forma de Pgto | H5: Valor Venda | I5: Entrada | K5: Descrição | L5: Tipo de Pagto | M5: Valor
B6: Entrada | C6: =C16 -> 220 | E6: 6941 | F6: Eliane da Silva Santos | G6: GARANTIA | H6: 0 | I6: 0 | K6: AGUA | L6: PIX | M6: 13 | R6: =IF(vend[[#This Row],[Nº Venda]]>1,1,0) -> 1
B7: Despesas | C7: =SUM(M6:M11) -> 13 | R7: =IF(vend[[#This Row],[Nº Venda]]>1,1,0) -> 0
B8: Total entrada | C8: =SUM(C6:C7) -> 233 | R8: =IF(vend[[#This Row],[Nº Venda]]>1,1,0) -> 0
R9: =IF(vend[[#This Row],[Nº Venda]]>1,1,0) -> 0
B10: Tipos de Pagtos | R10: =IF(vend[[#This Row],[Nº Venda]]>1,1,0) -> 0
B11: DN | C11: =(SUMIF($G$2:$G$31,B11,$I$2:$I$31))+(SUMIF($G$35:$G$41,B11,$H$35:$H$41)) -> 220 | O11: =IF(C16=0,0,1) -> 1 | R11: =IF(vend[[#This Row],[Nº Venda]]>1,1,0) -> 0
B12: CTD | C12: =(SUMIF($G$2:$G$31,B12,$I$2:$I$31))+(SUMIF($G$35:$G$41,B12,$H$35:$H$41)) -> 0 | R12: =IF(vend[[#This Row],[Nº Venda]]>1,1,0) -> 0
B13: CTC | C13: =(SUMIF($G$2:$G$31,B13,$I$2:$I$31))+(SUMIF($G$35:$G$41,B13,$H$35:$H$41)) -> 0 | K13: OS Entregue no Dia | R13: =IF(vend[[#This Row],[Nº Venda]]>1,1,0) -> 0
B14: PCTC | C14: =(SUMIF($G$2:$G$31,B14,$I$2:$I$31))+(SUMIF($G$35:$G$41,B14,$H$35:$H$41)) -> 0 | K14: OS | L14: Vendedor | M14: CARNE | R14: =IF(vend[[#This Row],[Nº Venda]]>1,1,0) -> 0
B15: PIX | C15: =(SUMIF($G$2:$G$31,B15,$I$2:$I$31))+(SUMIF($G$35:$G$41,B15,$H$35:$H$41)) -> 0 | K15: 6865 | L15: LUANA | M15: Sim | R15: =IF(vend[[#This Row],[Nº Venda]]>1,1,0) -> 0
B16: Total | C16: =SUM(C11:C15) -> 220 | R16: =IF(vend[[#This Row],[Nº Venda]]>1,1,0) -> 0
R17: =IF(vend[[#This Row],[Nº Venda]]>1,1,0) -> 0
B18: Entrega de Carne | R18: =IF(vend[[#This Row],[Nº Venda]]>1,1,0) -> 0
B19: =COUNT(entr_carn6[OS]) -> 1 | C19: =SUM(entr_carn6[Valor Total]) -> 494 | R19: =IF(vend[[#This Row],[Nº Venda]]>1,1,0) -> 0
B20: Total | C20: =SUM(C19:C19) -> 494 | R20: =IF(vend[[#This Row],[Nº Venda]]>1,1,0) -> 0
B22: Venda | C22: =C5 -> 0
E24: Restante Entrada
E25: Nº Venda | F25: Cliente | G25: Forma de Pgto | H25: Valor Venda | I25: Entrada
E26: 6865 | F26: LEZIVALDO DE MELLO | G26: DN | H26: 0 | I26: 100
E33: Recebimento de Carnê | K33: Entrega de Carne
E34: OS | F34: Cliente | G34: Forma de Pgto | H34: Valor Parcela | I34: Nº Parcela | K34: OS | L34: Parcelas | M34: Valor Total
E35: 6599 | F35: ALEXANDRE DA SILVA | G35: DN | H35: 120 | I35: PARC. 8/10 | K35: 6865 | L35: 5 | M35: 494
Q40: Total de OS | R40: =SUM(R6:R21) -> 1

Sheet 07
B1: ='06'!B1+1 -> 45603
B2: Fechamento Diário do Caixa
B4: Saldo Inicial | C4: 0 | E4: Vendas | K4: Despesas | U4: 0
B5: Vendas | C5: =SUMIF(I6:I31,">0",H6:H31) -> 0 | E5: Nº Venda | F5: Cliente | G5: Forma de Pgto | H5: Valor Venda | I5: Entrada | K5: Descrição | L5: Tipo de Pagto | M5: Valor
B6: Entrada | C6: =C16 -> 281.5 | K6: PARTE DO VALE TRASPORTE | L6: DN | M6: 220 | R6: =IF(vend7[[#This Row],[Nº Venda]]>1,1,0) -> 0
B7: Despesas | C7: =SUM(M6:M11) -> 220 | R7: =IF(vend7[[#This Row],[Nº Venda]]>1,1,0) -> 0
B8: Total entrada | C8: =SUM(C6) -> 281.5 | R8: =IF(vend7[[#This Row],[Nº Venda]]>1,1,0) -> 0
R9: =IF(vend7[[#This Row],[Nº Venda]]>1,1,0) -> 0
B10: Tipos de Pagtos | R10: =IF(vend7[[#This Row],[Nº Venda]]>1,1,0) -> 0
B11: DN | C11: =(SUMIF($G$2:$G$31,B11,$I$2:$I$31))+(SUMIF($G$35:$G$41,B11,$H$35:$H$41)) -> 281.5 | O11: =IF(C16=0,0,1) -> 1 | R11: =IF(vend7[[#This Row],[Nº Venda]]>1,1,0) -> 0
B12: CTD | C12: =(SUMIF($G$2:$G$31,B12,$I$2:$I$31))+(SUMIF($G$35:$G$41,B12,$H$35:$H$41)) -> 0 | R12: =IF(vend7[[#This Row],[Nº Venda]]>1,1,0) -> 0
B13: CTC | C13: =(SUMIF($G$2:$G$31,B13,$I$2:$I$31))+(SUMIF($G$35:$G$41,B13,$H$35:$H$41)) -> 0 | K13: OS Entregue no Dia | R13: =IF(vend7[[#This Row],[Nº Venda]]>1,1,0) -> 0
B14: PCTC | C14: =(SUMIF($G$2:$G$31,B14,$I$2:$I$31))+(SUMIF($G$35:$G$41,B14,$H$35:$H$41)) -> 0 | K14: OS | L14: Vendedor | M14: CARNE | R14: =IF(vend7[[#This Row],[Nº Venda]]>1,1,0) -> 0
B15: PIX | C15: =(SUMIF($G$2:$G$31,B15,$I$2:$I$31))+(SUMIF($G$35:$G$41,B15,$H$35:$H$41)) -> 0 | R15: =IF(vend7[[#This Row],[Nº Venda]]>1,1,0) -> 0
B16: Total | C16: =SUM(C11:C15) -> 281.5 | R16: =IF(vend7[[#This Row],[Nº Venda]]>1,1,0) -> 0
R17: =IF(vend7[[#This Row],[Nº Venda]]>1,1,0) -> 0
B18: Entrega de Carne | R18: =IF(vend7[[#This Row],[Nº Venda]]>1,1,0) -> 0
B19: =COUNT(entr_carn7[OS]) -> 0 | C19: =SUM(entr_carn7[Valor Total]) -> 0 | R19: =IF(vend7[[#This Row],[Nº Venda]]>1,1,0) -> 0
B20: Total | C20: =SUM(C19:C19) -> 0 | R20: =IF(vend7[[#This Row],[Nº Venda]]>1,1,0) -> 0
B22: Venda | C22: =C5 -> 0
E24: Restante Entrada
E25: Nº Venda | F25: Cliente | G25: Forma de Pgto | H25: Valor Venda | I25: Entrada
E33: Recebimento de Carnê | K33: Entrega de Carne
E34: OS | F34: Cliente | G34: Forma de Pgto | H34: Valor Parcela | I34: Nº Parcela | K34: OS | L34: Parcelas | M34: Valor Total
E35: 794 | F35: CARLOS ROBERTO | G35: DN | H35: 87.5 | I35: PARC. 4/8
E36: 871 | F36: MANOEL SAMPAIO | G36: DN | H36: 134 | I36: PARC. 1/7
E37: 712 | F37: PATRICIA DA SILVA | G37: DN | H37: 60 | I37: PARC. 4/9
Q40: Total de OS | R40: =SUM(R6:R21) -> 0

Sheet 08
B1: ='07'!B1+1 -> 45604
B2: Fechamento Diário do Caixa
B4: Saldo Inicial | C4: 0 | E4: Vendas | K4: Despesas
B5: Vendas | C5: =SUMIF(I6:I31,">0",H6:H31) -> 294 | E5: Nº Venda | F5: Cliente | G5: Forma de Pgto | H5: Valor Venda | I5: Entrada | K5: Descrição | L5: Tipo de Pagto | M5: Valor
B6: Entrada | C6: =C16 -> 393 | E6: 6942 | F6: SIDNEI FERNANDES | G6: CTC | H6: 294 | I6: 294 | R6: =IF(vend8[[#This Row],[Nº Venda]]>1,1,0) -> 1
B7: Despesas | C7: =SUM(M6:M11) -> 0 | R7: =IF(vend8[[#This Row],[Nº Venda]]>1,1,0) -> 0
B8: Total entrada | C8: =SUM(C6:C7) -> 393 | R8: =IF(vend8[[#This Row],[Nº Venda]]>1,1,0) -> 0
R9: =IF(vend8[[#This Row],[Nº Venda]]>1,1,0) -> 0
B10: Tipos de Pagtos | R10: =IF(vend8[[#This Row],[Nº Venda]]>1,1,0) -> 0
B11: DN | C11: =(SUMIF($G$2:$G$31,B11,$I$2:$I$31))+(SUMIF($G$35:$G$42,B11,$H$35:$H$42)) -> 0 | O11: =IF(C16=0,0,1) -> 1 | R11: =IF(vend8[[#This Row],[Nº Venda]]>1,1,0) -> 0
B12: CTD | C12: =(SUMIF($G$2:$G$31,B12,$I$2:$I$31))+(SUMIF($G$35:$G$42,B12,$H$35:$H$42)) -> 99 | R12: =IF(vend8[[#This Row],[Nº Venda]]>1,1,0) -> 0
B13: CTC | C13: =(SUMIF($G$2:$G$31,B13,$I$2:$I$31))+(SUMIF($G$35:$G$42,B13,$H$35:$H$42)) -> 294 | K13: OS Entregue no Dia | R13: =IF(vend8[[#This Row],[Nº Venda]]>1,1,0) -> 0
B14: PCTC | C14: =(SUMIF($G$2:$G$31,B14,$I$2:$I$31))+(SUMIF($G$35:$G$42,B14,$H$35:$H$42)) -> 0 | K14: OS | L14: Vendedor | M14: CARNE | R14: =IF(vend8[[#This Row],[Nº Venda]]>1,1,0) -> 0
B15: PIX | C15: =(SUMIF($G$2:$G$31,B15,$I$2:$I$31))+(SUMIF($G$35:$G$42,B15,$H$35:$H$42)) -> 0 | R15: =IF(vend8[[#This Row],[Nº Venda]]>1,1,0) -> 0
B16: Total | C16: =SUM(C11:C15) -> 393 | R16: =IF(vend8[[#This Row],[Nº Venda]]>1,1,0) -> 0
R17: =IF(vend8[[#This Row],[Nº Venda]]>1,1,0) -> 0
B18: Entrega de Carne | R18: =IF(vend8[[#This Row],[Nº Venda]]>1,1,0) -> 0
B19: =COUNT(entr_carn8[OS]) -> 0 | C19: =SUM(entr_carn8[Valor Total]) -> 0 | R19: =IF(vend8[[#This Row],[Nº Venda]]>1,1,0) -> 0
B20: Total | C20: =SUM(C19:C19) -> 0 | R20: =IF(vend8[[#This Row],[Nº Venda]]>1,1,0) -> 0
B22: Venda | C22: =C5 -> 294
E24: Restante Entrada
E25: Nº Venda | F25: Cliente | G25: Forma de Pgto | H25: Valor Venda | I25: Entrada
E33: Recebimento de Carnê | K33: Entrega de Carne
E34: OS | F34: Cliente | G34: Forma de Pgto | H34: Valor Parcela | I34: Nº Parcela | K34: OS | L34: Parcelas | M34: Valor Total
E35: 721 | F35: EDNEIA POMPEU | G35: CTD | H35: 99 | I35: PARC. 1/5
Q40: Total de OS | R40: =SUM(R6:R21) -> 1

Sheet 09
B1: ='08'!B1+1 -> 45605
B2: Fechamento Diário do Caixa
B4: Saldo Inicial | C4: 0 | E4: Vendas | K4: Despesas
B5: Vendas | C5: =SUMIF(I6:I31,">0",H6:H31) -> 0 | E5: Nº Venda | F5: Cliente | G5: Forma de Pgto | H5: Valor Venda | I5: Entrada | K5: Descrição | L5: Tipo de Pagto | M5: Valor
B6: Entrada | C6: =C16 -> 258 | R6: =IF(vend9[[#This Row],[Nº Venda]]>1,1,0) -> 0
B7: Despesas | C7: =SUM(M6:M11) -> 0 | R7: =IF(vend9[[#This Row],[Nº Venda]]>1,1,0) -> 0
B8: Total entrada | C8: =SUM(C6:C7) -> 258 | R8: =IF(vend9[[#This Row],[Nº Venda]]>1,1,0) -> 0
R9: =IF(vend9[[#This Row],[Nº Venda]]>1,1,0) -> 0
B10: Tipos de Pagtos | R10: =IF(vend9[[#This Row],[Nº Venda]]>1,1,0) -> 0
B11: DN | C11: =(SUMIF($G$2:$G$31,B11,$I$2:$I$31))+(SUMIF($G$35:$G$41,B11,$H$35:$H$41)) -> 0 | O11: =IF(C16=0,0,1) -> 1 | R11: =IF(vend9[[#This Row],[Nº Venda]]>1,1,0) -> 0
B12: CTD | C12: =(SUMIF($G$2:$G$31,B12,$I$2:$I$31))+(SUMIF($G$35:$G$41,B12,$H$35:$H$41)) -> 258 | R12: =IF(vend9[[#This Row],[Nº Venda]]>1,1,0) -> 0 | V12: 0
B13: CTC | C13: =(SUMIF($G$2:$G$31,B13,$I$2:$I$31))+(SUMIF($G$35:$G$41,B13,$H$35:$H$41)) -> 0 | K13: OS Entregue no Dia | R13: =IF(vend9[[#This Row],[Nº Venda]]>1,1,0) -> 0
B14: PCTC | C14: =(SUMIF($G$2:$G$31,B14,$I$2:$I$31))+(SUMIF($G$35:$G$41,B14,$H$35:$H$41)) -> 0 | K14: OS | L14: Vendedor | M14: CARNE | R14: =IF(vend9[[#This Row],[Nº Venda]]>1,1,0) -> 0
B15: PIX | C15: =(SUMIF($G$2:$G$31,B15,$I$2:$I$31))+(SUMIF($G$35:$G$41,B15,$H$35:$H$41)) -> 0 | K15: 775 | L15: ROGÉRIO | M15: Sim | R15: =IF(vend9[[#This Row],[Nº Venda]]>1,1,0) -> 0
B16: Total | C16: =SUM(C11:C15) -> 258 | R16: =IF(vend9[[#This Row],[Nº Venda]]>1,1,0) -> 0
R17: =IF(vend9[[#This Row],[Nº Venda]]>1,1,0) -> 0
B18: Entrega de Carne | R18: =IF(vend9[[#This Row],[Nº Venda]]>1,1,0) -> 0
B19: =COUNT(entr_carn9[OS]) -> 1 | C19: =SUM(entr_carn9[Valor Total]) -> 489.99 | R19: =IF(vend9[[#This Row],[Nº Venda]]>1,1,0) -> 0
B20: Total | C20: =SUM(C19:C19) -> 489.99 | R20: =IF(vend9[[#This Row],[Nº Venda]]>1,1,0) -> 0
B22: Venda | C22: =C5 -> 0
E24: Restante Entrada
E25: Nº Venda | F25: Cliente | G25: Forma de Pgto | H25: Valor Venda | I25: Entrada
E26: 775 | F26: ADAIR APARECIDO | G26: CTD | I26: 100
E33: Recebimento de Carnê | K33: Entrega de Carne
E34: OS | F34: Cliente | G34: Forma de Pgto | H34: Valor Parcela | I34: Nº Parcela | K34: OS | L34: Parcelas | M34: Valor Total
E35: 781 | F35: VALTER ALMEIDA | G35: CTD | H35: 158 | I35: PARC. 4/5 | K35: 775 | L35: 10 | M35: 489.99
Q40: Total de OS | R40: =SUM(R6:R21) -> 0

Sheet 10
B1: ='09'!B1+1 -> 45606
B2: Fechamento Diário do Caixa
B4: Saldo Inicial | C4: 0 | E4: Vendas | K4: Despesas
B5: Vendas | C5: =SUMIF(I6:I32,">0",H6:H32) -> 0 | E5: Nº Venda | F5: Cliente | G5: Forma de Pgto | H5: Valor Venda | I5: Entrada | K5: Descrição | L5: Tipo de Pagto | M5: Valor
B6: Entrada | C6: =C16 -> 0 | R6: =IF(vend10[[#This Row],[Nº Venda]]>1,1,0) -> 0
B7: Despesas | C7: =SUM(M6:M11) -> 0 | R7: =IF(vend10[[#This Row],[Nº Venda]]>1,1,0) -> 0
B8: Total entrada | C8: =SUM(C6:C7) -> 0 | R8: =IF(vend10[[#This Row],[Nº Venda]]>1,1,0) -> 0
R9: =IF(vend10[[#This Row],[Nº Venda]]>1,1,0) -> 0
B10: Tipos de Pagtos | R10: =IF(vend10[[#This Row],[Nº Venda]]>1,1,0) -> 0
B11: DN | C11: =(SUMIF($G$2:$G$32,B11,$I$2:$I$32))+(SUMIF($G$36:$G$42,B11,$H$36:$H$42)) -> 0 | O11: =IF(C16=0,0,1) -> 0 | R11: =IF(vend10[[#This Row],[Nº Venda]]>1,1,0) -> 0
B12: CTD | C12: =(SUMIF($G$2:$G$32,B12,$I$2:$I$32))+(SUMIF($G$36:$G$42,B12,$H$36:$H$42)) -> 0 | R12: =IF(vend10[[#This Row],[Nº Venda]]>1,1,0) -> 0
B13: CTC | C13: =(SUMIF($G$2:$G$32,B13,$I$2:$I$32))+(SUMIF($G$36:$G$42,B13,$H$36:$H$42)) -> 0 | K13: OS Entregue no Dia | R13: =IF(vend10[[#This Row],[Nº Venda]]>1,1,0) -> 0
B14: PCTC | C14: =(SUMIF($G$2:$G$32,B14,$I$2:$I$32))+(SUMIF($G$36:$G$42,B14,$H$36:$H$42)) -> 0 | K14: OS | L14: Vendedor | M14: CARNE | R14: =IF(vend10[[#This Row],[Nº Venda]]>1,1,0) -> 0
B15: PIX | C15: =(SUMIF($G$2:$G$32,B15,$I$2:$I$32))+(SUMIF($G$36:$G$42,B15,$H$36:$H$42)) -> 0 | R15: =IF(vend10[[#This Row],[Nº Venda]]>1,1,0) -> 0
B16: Total | C16: =SUM(C11:C15) -> 0 | R16: =IF(vend10[[#This Row],[Nº Venda]]>1,1,0) -> 0
R17: =IF(vend10[[#This Row],[Nº Venda]]>1,1,0) -> 0
B18: Entrega de Carne | R18: =IF(vend10[[#This Row],[Nº Venda]]>1,1,0) -> 0
B19: =COUNT(entr_carn10[OS]) -> 0 | C19: =SUM(entr_carn10[Valor Total]) -> 0 | R19: =IF(vend10[[#This Row],[Nº Venda]]>1,1,0) -> 0
B20: Total | C20: =SUM(C19:C19) -> 0 | R20: =IF(vend10[[#This Row],[Nº Venda]]>1,1,0) -> 0
B22: Venda | C22: =C5 -> 0
E24: Restante Entrada
E25: Nº Venda | F25: Cliente | G25: Forma de Pgto | H25: Valor Venda | I25: Entrada
K33: Entrega de Carne
E34: Recebimento de Carnê | K34: OS | L34: Parcelas | M34: Valor Total
E35: OS | F35: Cliente | G35: Forma de Pgto | H35: Valor Parcela | I35: Nº Parcela
Q40: Total de OS | R40: =SUM(R6:R21) -> 0

Sheet 11
B1: ='10'!B1+1 -> 45607
B2: Fechamento Diário do Caixa
B4: Saldo Inicial | C4: 0 | E4: Vendas | K4: Despesas
B5: Vendas | C5: =SUMIF(I6:I31,">0",H6:H31) -> 400 | E5: Nº Venda | F5: Cliente | G5: Forma de Pgto | H5: Valor Venda | I5: Entrada | K5: Descrição | L5: Tipo de Pagto | M5: Valor
B6: Entrada | C6: =C16 -> 999 | E6: 6943 | F6: JEANE MARTINS | G6: CTC | H6: 400 | I6: 400 | R6: =IF(vend11[[#This Row],[Nº Venda]]>1,1,0) -> 1
B7: Despesas | C7: =SUM(M6:M11) -> 0 | R7: =IF(vend11[[#This Row],[Nº Venda]]>1,1,0) -> 0
B8: Total entrada | C8: =SUM(C6:C7) -> 999 | R8: =IF(vend11[[#This Row],[Nº Venda]]>1,1,0) -> 0
R9: =IF(vend11[[#This Row],[Nº Venda]]>1,1,0) -> 0
B10: Tipos de Pagtos | R10: =IF(vend11[[#This Row],[Nº Venda]]>1,1,0) -> 0
B11: DN | C11: =(SUMIF($G$2:$G$31,B11,$I$2:$I$31))+(SUMIF($G$35:$G$41,B11,$H$35:$H$41)) -> 0 | O11: =IF(C16=0,0,1) -> 1 | R11: =IF(vend11[[#This Row],[Nº Venda]]>1,1,0) -> 0
B12: CTD | C12: =(SUMIF($G$2:$G$31,B12,$I$2:$I$31))+(SUMIF($G$35:$G$41,B12,$H$35:$H$41)) -> 0 | R12: =IF(vend11[[#This Row],[Nº Venda]]>1,1,0) -> 0
B13: CTC | C13: =(SUMIF($G$2:$G$31,B13,$I$2:$I$31))+(SUMIF($G$35:$G$41,B13,$H$35:$H$41)) -> 999 | K13: OS Entregue no Dia | R13: =IF(vend11[[#This Row],[Nº Venda]]>1,1,0) -> 0
B14: PCTC | C14: =(SUMIF($G$2:$G$31,B14,$I$2:$I$31))+(SUMIF($G$35:$G$41,B14,$H$35:$H$41)) -> 0 | K14: OS | L14: Vendedor | M14: CARNE | R14: =IF(vend11[[#This Row],[Nº Venda]]>1,1,0) -> 0
B15: PIX | C15: =(SUMIF($G$2:$G$31,B15,$I$2:$I$31))+(SUMIF($G$35:$G$41,B15,$H$35:$H$41)) -> 0 | R15: =IF(vend11[[#This Row],[Nº Venda]]>1,1,0) -> 0
B16: Total | C16: =SUM(C11:C15) -> 999 | R16: =IF(vend11[[#This Row],[Nº Venda]]>1,1,0) -> 0
R17: =IF(vend11[[#This Row],[Nº Venda]]>1,1,0) -> 0
B18: Entrega de Carne | R18: =IF(vend11[[#This Row],[Nº Venda]]>1,1,0) -> 0
B19: =COUNT(entr_carn11[OS]) -> 0 | C19: =SUM(entr_carn11[Valor Total]) -> 0 | R19: =IF(vend11[[#This Row],[Nº Venda]]>1,1,0) -> 0
B20: Total | C20: =SUM(C19:C19) -> 0 | R20: =IF(vend11[[#This Row],[Nº Venda]]>1,1,0) -> 0
B22: Venda | C22: =C5 -> 400
E24: Restante Entrada
E25: Nº Venda | F25: Cliente | G25: Forma de Pgto | H25: Valor Venda | I25: Entrada
E26: 826 | F26: PAULO HENRIQUE | G26: CTC | I26: 599
E33: Recebimento de Carnê | K33: Entrega de Carne
E34: OS | F34: Cliente | G34: Forma de Pgto | H34: Valor Parcela | I34: Nº Parcela | K34: OS | L34: Parcelas | M34: Valor Total
Q40: Total de OS | R40: =SUM(R6:R21) -> 1

Sheet 12
B1: ='11'!B1+1 -> 45608
B2: Fechamento Diário do Caixa
B4: Saldo Inicial | C4: 0 | E4: Vendas | K4: Despesas
B5: Vendas | C5: =SUMIF(I6:I31,">0",H6:H31) -> 880 | E5: Nº Venda | F5: Cliente | G5: Forma de Pgto | H5: Valor Venda | I5: Entrada | K5: Descrição | L5: Tipo de Pagto | M5: Valor
B6: Entrada | C6: =C16 -> 530 | E6: 6944 | F6: ELIANE DA SILVA | G6: CTC | H6: 280 | I6: 280 | R6: =IF(vend12[[#This Row],[Nº Venda]]>1,1,0) -> 1
B7: Despesas | C7: =SUM(M6:M11) -> 0 | E7: 6945 | F7: SEVERINO ROMUALDO | G7: DN | H7: 600 | I7: 150 | R7: =IF(vend12[[#This Row],[Nº Venda]]>1,1,0) -> 1
B8: Total entrada | C8: =SUM(C6:C7) -> 530 | R8: =IF(vend12[[#This Row],[Nº Venda]]>1,1,0) -> 0
R9: =IF(vend12[[#This Row],[Nº Venda]]>1,1,0) -> 0
B10: Tipos de Pagtos | R10: =IF(vend12[[#This Row],[Nº Venda]]>1,1,0) -> 0
B11: DN | C11: =(SUMIF($G$2:$G$31,B11,$I$2:$I$31))+(SUMIF($G$35:$G$41,B11,$H$35:$H$41)) -> 150 | O11: =IF(C16=0,0,1) -> 1 | R11: =IF(vend12[[#This Row],[Nº Venda]]>1,1,0) -> 0
B12: CTD | C12: =(SUMIF($G$2:$G$31,B12,$I$2:$I$31))+(SUMIF($G$35:$G$41,B12,$H$35:$H$41)) -> 100 | R12: =IF(vend12[[#This Row],[Nº Venda]]>1,1,0) -> 0
B13: CTC | C13: =(SUMIF($G$2:$G$31,B13,$I$2:$I$31))+(SUMIF($G$35:$G$41,B13,$H$35:$H$41)) -> 280 | K13: OS Entregue no Dia | R13: =IF(vend12[[#This Row],[Nº Venda]]>1,1,0) -> 0
B14: PCTC | C14: =(SUMIF($G$2:$G$31,B14,$I$2:$I$31))+(SUMIF($G$35:$G$41,B14,$H$35:$H$41)) -> 0 | K14: OS | L14: Vendedor | M14: CARNE | R14: =IF(vend12[[#This Row],[Nº Venda]]>1,1,0) -> 0
B15: PIX | C15: =(SUMIF($G$2:$G$31,B15,$I$2:$I$31))+(SUMIF($G$35:$G$41,B15,$H$35:$H$41)) -> 0 | K15: 6940 | L15: LUANA | M15: Não | R15: =IF(vend12[[#This Row],[Nº Venda]]>1,1,0) -> 0
B16: Total | C16: =SUM(C11:C15) -> 530 | K16: 6939 | L16: LUANA | M16: Não | R16: =IF(vend12[[#This Row],[Nº Venda]]>1,1,0) -> 0
R17: =IF(vend12[[#This Row],[Nº Venda]]>1,1,0) -> 0
B18: Entrega de Carne | R18: =IF(vend12[[#This Row],[Nº Venda]]>1,1,0) -> 0
B19: =COUNT(entr_carn12[OS]) -> 0 | C19: =SUM(entr_carn12[Valor Total]) -> 0 | R19: =IF(vend12[[#This Row],[Nº Venda]]>1,1,0) -> 0
B20: Total | C20: =SUM(C19:C19) -> 0 | R20: =IF(vend12[[#This Row],[Nº Venda]]>1,1,0) -> 0
B22: Venda | C22: =C5 -> 880
E24: Restante Entrada
E25: Nº Venda | F25: Cliente | G25: Forma de Pgto | H25: Valor Venda | I25: Entrada
E33: Recebimento de Carnê | K33: Entrega de Carne
E34: OS | F34: Cliente | G34: Forma de Pgto | H34: Valor Parcela | I34: Nº Parcela | K34: OS | L34: Parcelas | M34: Valor Total
E35: 821 | F35: PEDRO EXPEDITO | G35: CTD | H35: 100 | I35: PARC. 3/5
Q40: Total de OS | R40: =SUM(R6:R21) -> 2

Sheet 13
B1: ='12'!B1+1 -> 45609
B2: Fechamento Diário do Caixa
B4: Saldo Inicial | C4: 0 | E4: Vendas | K4: Despesas
B5: Vendas | C5: =SUMIF(I6:I31,">0",H6:H31) -> 880 | E5: Nº Venda | F5: Cliente | G5: Forma de Pgto | H5: Valor Venda | I5: Entrada | K5: Descrição | L5: Tipo de Pagto | M5: Valor
B6: Entrada | C6: =C16 -> 100 | E6: 6946 | F6: JUVENAL BORGES | G6: CTD | H6: 880 | I6: 100 | R6: =IF(vend13[[#This Row],[Nº Venda]]>1,1,0) -> 1
B7: Despesas | C7: =SUM(M6:M11) -> 0 | R7: =IF(vend13[[#This Row],[Nº Venda]]>1,1,0) -> 0
B8: Total entrada | C8: =SUM(C6:C7) -> 100 | R8: =IF(vend13[[#This Row],[Nº Venda]]>1,1,0) -> 0
R9: =IF(vend13[[#This Row],[Nº Venda]]>1,1,0) -> 0
B10: Tipos de Pagtos | R10: =IF(vend13[[#This Row],[Nº Venda]]>1,1,0) -> 0
B11: DN | C11: =(SUMIF($G$2:$G$31,B11,$I$2:$I$31))+(SUMIF($G$35:$G$41,B11,$H$35:$H$41)) -> 0 | O11: =IF(C16=0,0,1) -> 1 | R11: =IF(vend13[[#This Row],[Nº Venda]]>1,1,0) -> 0
B12: CTD | C12: =(SUMIF($G$2:$G$31,B12,$I$2:$I$31))+(SUMIF($G$35:$G$41,B12,$H$35:$H$41)) -> 100 | R12: =IF(vend13[[#This Row],[Nº Venda]]>1,1,0) -> 0
B13: CTC | C13: =(SUMIF($G$2:$G$31,B13,$I$2:$I$31))+(SUMIF($G$35:$G$41,B13,$H$35:$H$41)) -> 0 | K13: OS Entregue no Dia | R13: =IF(vend13[[#This Row],[Nº Venda]]>1,1,0) -> 0
B14: PCTC | C14: =(SUMIF($G$2:$G$31,B14,$I$2:$I$31))+(SUMIF($G$35:$G$41,B14,$H$35:$H$41)) -> 0 | K14: OS | L14: Vendedor | M14: CARNE | R14: =IF(vend13[[#This Row],[Nº Venda]]>1,1,0) -> 0
B15: PIX | C15: =(SUMIF($G$2:$G$31,B15,$I$2:$I$31))+(SUMIF($G$35:$G$41,B15,$H$35:$H$41)) -> 0 | K15: 6937 | L15: LUANA | M15: Não | R15: =IF(vend13[[#This Row],[Nº Venda]]>1,1,0) -> 0
B16: Total | C16: =SUM(C11:C15) -> 100 | R16: =IF(vend13[[#This Row],[Nº Venda]]>1,1,0) -> 0
R17: =IF(vend13[[#This Row],[Nº Venda]]>1,1,0) -> 0
B18: Entrega de Carne | R18: =IF(vend13[[#This Row],[Nº Venda]]>1,1,0) -> 0
B19: =COUNT(entr_carn13[OS]) -> 0 | C19: =SUM(entr_carn13[Valor Total]) -> 0 | R19: =IF(vend13[[#This Row],[Nº Venda]]>1,1,0) -> 0
B20: Total | C20: =SUM(C19:C19) -> 0 | R20: =IF(vend13[[#This Row],[Nº Venda]]>1,1,0) -> 0
B22: Venda | C22: =C5 -> 880
E24: Restante Entrada
E25: Nº Venda | F25: Cliente | G25: Forma de Pgto | H25: Valor Venda | I25: Entrada
E33: Recebimento de Carnê | K33: Entrega de Carne
E34: OS | F34: Cliente | G34: Forma de Pgto | H34: Valor Parcela | I34: Nº Parcela | K34: OS | L34: Parcelas | M34: Valor Total
Q40: Total de OS | R40: =SUM(R6:R21) -> 1

Sheet 14
B1: ='13'!B1+1 -> 45610
B2: Fechamento Diário do Caixa
B4: Saldo Inicial | C4: 0 | E4: Vendas | K4: Despesas
B5: Vendas | C5: =SUMIF(I6:I31,">0",H6:H31) -> 0 | E5: Nº Venda | F5: Cliente | G5: Forma de Pgto | H5: Valor Venda | I5: Entrada | K5: Descrição | L5: Tipo de Pagto | M5: Valor
B6: Entrada | C6: =C16 -> 0 | R6: =IF(vend14[[#This Row],[Nº Venda]]>1,1,0) -> 0
B7: Despesas | C7: =SUM(M6:M11) -> 0 | R7: =IF(vend14[[#This Row],[Nº Venda]]>1,1,0) -> 0
B8: Total entrada | C8: =SUM(C6:C7) -> 0 | R8: =IF(vend14[[#This Row],[Nº Venda]]>1,1,0) -> 0
R9: =IF(vend14[[#This Row],[Nº Venda]]>1,1,0) -> 0
B10: Tipos de Pagtos | R10: =IF(vend14[[#This Row],[Nº Venda]]>1,1,0) -> 0
B11: DN | C11: =(SUMIF($G$2:$G$31,B11,$I$2:$I$31))+(SUMIF($G$35:$G$41,B11,$H$35:$H$41)) -> 0 | O11: =IF(C16=0,0,1) -> 0 | R11: =IF(vend14[[#This Row],[Nº Venda]]>1,1,0) -> 0
B12: CTD | C12: =(SUMIF($G$2:$G$31,B12,$I$2:$I$31))+(SUMIF($G$35:$G$41,B12,$H$35:$H$41)) -> 0 | R12: =IF(vend14[[#This Row],[Nº Venda]]>1,1,0) -> 0
B13: CTC | C13: =(SUMIF($G$2:$G$31,B13,$I$2:$I$31))+(SUMIF($G$35:$G$41,B13,$H$35:$H$41)) -> 0 | K13: OS Entregue no Dia | R13: =IF(vend14[[#This Row],[Nº Venda]]>1,1,0) -> 0
B14: PCTC | C14: =(SUMIF($G$2:$G$31,B14,$I$2:$I$31))+(SUMIF($G$35:$G$41,B14,$H$35:$H$41)) -> 0 | K14: OS | L14: Vendedor | M14: CARNE | R14: =IF(vend14[[#This Row],[Nº Venda]]>1,1,0) -> 0
B15: PIX | C15: =(SUMIF($G$2:$G$31,B15,$I$2:$I$31))+(SUMIF($G$35:$G$41,B15,$H$35:$H$41)) -> 0 | R15: =IF(vend14[[#This Row],[Nº Venda]]>1,1,0) -> 0
B16: Total | C16: =SUM(C11:C15) -> 0 | R16: =IF(vend14[[#This Row],[Nº Venda]]>1,1,0) -> 0
R17: =IF(vend14[[#This Row],[Nº Venda]]>1,1,0) -> 0
B18: Entrega de Carne | R18: =IF(vend14[[#This Row],[Nº Venda]]>1,1,0) -> 0
B19: =COUNT(entr_carn14[OS]) -> 0 | C19: =SUM(entr_carn14[Valor Total]) -> 0 | R19: =IF(vend14[[#This Row],[Nº Venda]]>1,1,0) -> 0
B20: Total | C20: =SUM(C19:C19) -> 0 | R20: =IF(vend14[[#This Row],[Nº Venda]]>1,1,0) -> 0
B22: Venda | C22: =C5 -> 0
E24: Restante Entrada
E25: Nº Venda | F25: Cliente | G25: Forma de Pgto | H25: Valor Venda | I25: Entrada
E33: Recebimento de Carnê | K33: Entrega de Carne
E34: OS | F34: Cliente | G34: Forma de Pgto | H34: Valor Parcela | I34: Nº Parcela | K34: OS | L34: Parcelas | M34: Valor Total
C37: 0
Q40: Total de OS | R40: =SUM(R6:R21) -> 0

Sheet 15
B1: ='14'!B1+1 -> 45611
B2: Fechamento Diário do Caixa
B4: Saldo Inicial | C4: 0 | E4: Vendas | K4: Despesas
B5: Vendas | C5: =SUMIF(I6:I31,">0",H6:H31) -> 0 | E5: Nº Venda | F5: Cliente | G5: Forma de Pgto | H5: Valor Venda | I5: Entrada | K5: Descrição | L5: Tipo de Pagto | M5: Valor
B6: Entrada | C6: =C16 -> 0 | R6: =IF(vend15[[#This Row],[Nº Venda]]>1,1,0) -> 0
B7: Despesas | C7: =SUM(M6:M11) -> 0 | R7: =IF(vend15[[#This Row],[Nº Venda]]>1,1,0) -> 0
B8: Total entrada | C8: =SUM(C6:C7) -> 0 | R8: =IF(vend15[[#This Row],[Nº Venda]]>1,1,0) -> 0
R9: =IF(vend15[[#This Row],[Nº Venda]]>1,1,0) -> 0
B10: Tipos de Pagtos | R10: =IF(vend15[[#This Row],[Nº Venda]]>1,1,0) -> 0
B11: DN | C11: =(SUMIF($G$2:$G$31,B11,$I$2:$I$31))+(SUMIF($G$35:$G$41,B11,$H$35:$H$41)) -> 0 | O11: =IF(C16=0,0,1) -> 0 | R11: =IF(vend15[[#This Row],[Nº Venda]]>1,1,0) -> 0
B12: CTD | C12: =(SUMIF($G$2:$G$31,B12,$I$2:$I$31))+(SUMIF($G$35:$G$41,B12,$H$35:$H$41)) -> 0 | R12: =IF(vend15[[#This Row],[Nº Venda]]>1,1,0) -> 0
B13: CTC | C13: =(SUMIF($G$2:$G$31,B13,$I$2:$I$31))+(SUMIF($G$35:$G$41,B13,$H$35:$H$41)) -> 0 | K13: OS Entregue no Dia | R13: =IF(vend15[[#This Row],[Nº Venda]]>1,1,0) -> 0
B14: PCTC | C14: =(SUMIF($G$2:$G$31,B14,$I$2:$I$31))+(SUMIF($G$35:$G$41,B14,$H$35:$H$41)) -> 0 | K14: OS | L14: Vendedor | M14: CARNE | R14: =IF(vend15[[#This Row],[Nº Venda]]>1,1,0) -> 0
B15: PIX | C15: =(SUMIF($G$2:$G$31,B15,$I$2:$I$31))+(SUMIF($G$35:$G$41,B15,$H$35:$H$41)) -> 0 | R15: =IF(vend15[[#This Row],[Nº Venda]]>1,1,0) -> 0
B16: Total | C16: =SUM(C11:C15) -> 0 | R16: =IF(vend15[[#This Row],[Nº Venda]]>1,1,0) -> 0
R17: =IF(vend15[[#This Row],[Nº Venda]]>1,1,0) -> 0
B18: Entrega de Carne | R18: =IF(vend15[[#This Row],[Nº Venda]]>1,1,0) -> 0
B19: =COUNT(entr_carn15[OS]) -> 0 | C19: =SUM(entr_carn15[Valor Total]) -> 0 | R19: =IF(vend15[[#This Row],[Nº Venda]]>1,1,0) -> 0
B20: Total | C20: =SUM(C19:C19) -> 0 | R20: =IF(vend15[[#This Row],[Nº Venda]]>1,1,0) -> 0
B22: Venda | C22: =C5 -> 0
E24: Restante Entrada
E25: Nº Venda | F25: Cliente | G25: Forma de Pgto | H25: Valor Venda | I25: Entrada
E33: Recebimento de Carnê | K33: Entrega de Carne
E34: OS | F34: Cliente | G34: Forma de Pgto | H34: Valor Parcela | I34: Nº Parcela | K34: OS | L34: Parcelas | M34: Valor Total
Q40: Total de OS | R40: =SUM(R6:R21) -> 0

Sheet 16
B1: ='15'!B1+1 -> 45612
B2: Fechamento Diário do Caixa
B4: Saldo Inicial | C4: 0 | E4: Vendas | K4: Despesas
B5: Vendas | C5: =SUMIF(I6:I31,">0",H6:H31) -> 0 | E5: Nº Venda | F5: Cliente | G5: Forma de Pgto | H5: Valor Venda | I5: Entrada | K5: Descrição | L5: Tipo de Pagto | M5: Valor
B6: Entrada | C6: =C16 -> 100 | R6: =IF(vend16[[#This Row],[Nº Venda]]>1,1,0) -> 0
B7: Despesas | C7: =SUM(M6:M11) -> 0 | R7: =IF(vend16[[#This Row],[Nº Venda]]>1,1,0) -> 0
B8: Total entrada | C8: =SUM(C6:C7) -> 100 | R8: =IF(vend16[[#This Row],[Nº Venda]]>1,1,0) -> 0
R9: =IF(vend16[[#This Row],[Nº Venda]]>1,1,0) -> 0
B10: Tipos de Pagtos | R10: =IF(vend16[[#This Row],[Nº Venda]]>1,1,0) -> 0
B11: DN | C11: =(SUMIF($G$2:$G$31,B11,$I$2:$I$31))+(SUMIF($G$35:$G$41,B11,$H$35:$H$41)) -> 0 | O11: =IF(C16=0,0,1) -> 1 | R11: =IF(vend16[[#This Row],[Nº Venda]]>1,1,0) -> 0
B12: CTD | C12: =(SUMIF($G$2:$G$31,B12,$I$2:$I$31))+(SUMIF($G$35:$G$41,B12,$H$35:$H$41)) -> 0 | R12: =IF(vend16[[#This Row],[Nº Venda]]>1,1,0) -> 0
B13: CTC | C13: =(SUMIF($G$2:$G$31,B13,$I$2:$I$31))+(SUMIF($G$35:$G$41,B13,$H$35:$H$41)) -> 0 | K13: OS Entregue no Dia | R13: =IF(vend16[[#This Row],[Nº Venda]]>1,1,0) -> 0
B14: PCTC | C14: =(SUMIF($G$2:$G$31,B14,$I$2:$I$31))+(SUMIF($G$35:$G$41,B14,$H$35:$H$41)) -> 0 | K14: OS | L14: Vendedor | M14: CARNE | R14: =IF(vend16[[#This Row],[Nº Venda]]>1,1,0) -> 0
B15: PIX | C15: =(SUMIF($G$2:$G$31,B15,$I$2:$I$31))+(SUMIF($G$35:$G$41,B15,$H$35:$H$41)) -> 100 | R15: =IF(vend16[[#This Row],[Nº Venda]]>1,1,0) -> 0
B16: Total | C16: =SUM(C11:C15) -> 100 | R16: =IF(vend16[[#This Row],[Nº Venda]]>1,1,0) -> 0
R17: =IF(vend16[[#This Row],[Nº Venda]]>1,1,0) -> 0
B18: Entrega de Carne | R18: =IF(vend16[[#This Row],[Nº Venda]]>1,1,0) -> 0
B19: =COUNT(entr_carn16[OS]) -> 0 | C19: =SUM(entr_carn16[Valor Total]) -> 0 | R19: =IF(vend16[[#This Row],[Nº Venda]]>1,1,0) -> 0
B20: Total | C20: =SUM(C19:C19) -> 0 | R20: =IF(vend16[[#This Row],[Nº Venda]]>1,1,0) -> 0
B22: Venda | C22: =C5 -> 0
E24: Restante Entrada
E25: Nº Venda | F25: Cliente | G25: Forma de Pgto | H25: Valor Venda | I25: Entrada
E33: Recebimento de Carnê | K33: Entrega de Carne
E34: OS | F34: Cliente | G34: Forma de Pgto | H34: Valor Parcela | I34: Nº Parcela | K34: OS | L34: Parcelas | M34: Valor Total
E35: 772 | F35: VANESSA GOMES | G35: PIX | H35: 100 | I35: PARC. 3/4
Q40: Total de OS | R40: =SUM(R6:R21) -> 0

Sheet 17
B1: ='16'!B1+1 -> 45613
B2: Fechamento Diário do Caixa
B4: Saldo Inicial | C4: 0 | E4: Vendas | K4: Despesas
B5: Vendas | C5: =SUMIF(I6:I31,">0",H6:H31) -> 0 | E5: Nº Venda | F5: Cliente | G5: Forma de Pgto | H5: Valor Venda | I5: Entrada | K5: Descrição | L5: Tipo de Pagto | M5: Valor
B6: Entrada | C6: =C16 -> 0 | R6: =IF(vend17[[#This Row],[Nº Venda]]>1,1,0) -> 0
B7: Despesas | C7: =SUM(M6:M11) -> 0 | R7: =IF(vend17[[#This Row],[Nº Venda]]>1,1,0) -> 0
B8: Total entrada | C8: =SUM(C6:C7) -> 0 | R8: =IF(vend17[[#This Row],[Nº Venda]]>1,1,0) -> 0
R9: =IF(vend17[[#This Row],[Nº Venda]]>1,1,0) -> 0
B10: Tipos de Pagtos | R10: =IF(vend17[[#This Row],[Nº Venda]]>1,1,0) -> 0
B11: DN | C11: =(SUMIF($G$2:$G$31,B11,$I$2:$I$31))+(SUMIF($G$35:$G$41,B11,$H$35:$H$41)) -> 0 | O11: =IF(C16=0,0,1) -> 0 | R11: =IF(vend17[[#This Row],[Nº Venda]]>1,1,0) -> 0
B12: CTD | C12: =(SUMIF($G$2:$G$31,B12,$I$2:$I$31))+(SUMIF($G$35:$G$41,B12,$H$35:$H$41)) -> 0 | R12: =IF(vend17[[#This Row],[Nº Venda]]>1,1,0) -> 0
B13: CTC | C13: =(SUMIF($G$2:$G$31,B13,$I$2:$I$31))+(SUMIF($G$35:$G$41,B13,$H$35:$H$41)) -> 0 | K13: OS Entregue no Dia | R13: =IF(vend17[[#This Row],[Nº Venda]]>1,1,0) -> 0
B14: PCTC | C14: =(SUMIF($G$2:$G$31,B14,$I$2:$I$31))+(SUMIF($G$35:$G$41,B14,$H$35:$H$41)) -> 0 | K14: OS | L14: Vendedor | M14: CARNE | R14: =IF(vend17[[#This Row],[Nº Venda]]>1,1,0) -> 0
B15: PIX | C15: =(SUMIF($G$2:$G$31,B15,$I$2:$I$31))+(SUMIF($G$35:$G$41,B15,$H$35:$H$41)) -> 0 | R15: =IF(vend17[[#This Row],[Nº Venda]]>1,1,0) -> 0
B16: Total | C16: =SUM(C11:C15) -> 0 | R16: =IF(vend17[[#This Row],[Nº Venda]]>1,1,0) -> 0
R17: =IF(vend17[[#This Row],[Nº Venda]]>1,1,0) -> 0
B18: Entrega de Carne | R18: =IF(vend17[[#This Row],[Nº Venda]]>1,1,0) -> 0
B19: =COUNT(entr_carn17[OS]) -> 0 | C19: =SUM(entr_carn17[Valor Total]) -> 0 | R19: =IF(vend17[[#This Row],[Nº Venda]]>1,1,0) -> 0
B20: Total | C20: =SUM(C19:C19) -> 0 | R20: =IF(vend17[[#This Row],[Nº Venda]]>1,1,0) -> 0
B22: Venda | C22: =C5 -> 0
E24: Restante Entrada
E25: Nº Venda | F25: Cliente | G25: Forma de Pgto | H25: Valor Venda | I25: Entrada
E33: Recebimento de Carnê | K33: Entrega de Carne
E34: OS | F34: Cliente | G34: Forma de Pgto | H34: Valor Parcela | I34: Nº Parcela | K34: OS | L34: Parcelas | M34: Valor Total
Q40: Total de OS | R40: =SUM(R6:R21) -> 0

Sheet 18
B1: ='17'!B1+1 -> 45614
B2: Fechamento Diário do Caixa
B4: Saldo Inicial | C4: 0 | E4: Vendas | K4: Despesas
B5: Vendas | C5: =SUMIF(I6:I31,">0",H6:H31) -> 145 | E5: Nº Venda | F5: Cliente | G5: Forma de Pgto | H5: Valor Venda | I5: Entrada | K5: Descrição | L5: Tipo de Pagto | M5: Valor
B6: Entrada | C6: =C16 -> 250 | E6: 6947 | F6: FELIPE DE MOURA | G6: DN | H6: 100 | I6: 25 | R6: =IF(vend18[[#This Row],[Nº Venda]]>1,1,0) -> 1
B7: Despesas | C7: =SUM(M6:M11) -> 0 | E7: 6948 | F7: FELIPE DE MOURA | G7: DN | H7: 45 | I7: 25 | R7: =IF(vend18[[#This Row],[Nº Venda]]>1,1,0) -> 1
B8: Total entrada | C8: =SUM(C6:C7) -> 250 | E8: 6949 | F8: FELIPE DE MOURA | G8: SS | H8: 495 | I8: 0 | R8: =IF(vend18[[#This Row],[Nº Venda]]>1,1,0) -> 1
R9: =IF(vend18[[#This Row],[Nº Venda]]>1,1,0) -> 0
B10: Tipos de Pagtos | R10: =IF(vend18[[#This Row],[Nº Venda]]>1,1,0) -> 0
B11: DN | C11: =(SUMIF($G$2:$G$31,B11,$I$2:$I$31))+(SUMIF($G$35:$G$41,B11,$H$35:$H$41)) -> 250 | O11: =IF(C16=0,0,1) -> 1 | R11: =IF(vend18[[#This Row],[Nº Venda]]>1,1,0) -> 0
B12: CTD | C12: =(SUMIF($G$2:$G$31,B12,$I$2:$I$31))+(SUMIF($G$35:$G$41,B12,$H$35:$H$41)) -> 0 | R12: =IF(vend18[[#This Row],[Nº Venda]]>1,1,0) -> 0
B13: CTC | C13: =(SUMIF($G$2:$G$31,B13,$I$2:$I$31))+(SUMIF($G$35:$G$41,B13,$H$35:$H$41)) -> 0 | K13: OS Entregue no Dia | R13: =IF(vend18[[#This Row],[Nº Venda]]>1,1,0) -> 0
B14: PCTC | C14: =(SUMIF($G$2:$G$31,B14,$I$2:$I$31))+(SUMIF($G$35:$G$41,B14,$H$35:$H$41)) -> 0 | K14: OS | L14: Vendedor | M14: CARNE | R14: =IF(vend18[[#This Row],[Nº Venda]]>1,1,0) -> 0
B15: PIX | C15: =(SUMIF($G$2:$G$31,B15,$I$2:$I$31))+(SUMIF($G$35:$G$41,B15,$H$35:$H$41)) -> 0 | K15: 6912 | L15: LARISSA | M15: Sim | R15: =IF(vend18[[#This Row],[Nº Venda]]>1,1,0) -> 0
B16: Total | C16: =SUM(C11:C15) -> 250 | R16: =IF(vend18[[#This Row],[Nº Venda]]>1,1,0) -> 0
R17: =IF(vend18[[#This Row],[Nº Venda]]>1,1,0) -> 0
B18: Entrega de Carne | R18: =IF(vend18[[#This Row],[Nº Venda]]>1,1,0) -> 0
B19: =COUNT(entr_carn18[OS]) -> 1 | C19: =SUM(entr_carn18[Valor Total]) -> 290 | R19: =IF(vend18[[#This Row],[Nº Venda]]>1,1,0) -> 0
B20: Total | C20: =SUM(C19:C19) -> 290 | R20: =IF(vend18[[#This Row],[Nº Venda]]>1,1,0) -> 0
B22: Venda | C22: =C5 -> 145
E24: Restante Entrada
E25: Nº Venda | F25: Cliente | G25: Forma de Pgto | H25: Valor Venda | I25: Entrada
E26: 6912 | F26: GILMAR CESAR | G26: DN | H26: 0 | I26: 200
E33: Recebimento de Carnê | K33: Entrega de Carne
E34: OS | F34: Cliente | G34: Forma de Pgto | H34: Valor Parcela | I34: Nº Parcela | K34: OS | L34: Parcelas | M34: Valor Total
K35: 6912 | L35: 5 | M35: 290
Q40: Total de OS | R40: =SUM(R6:R21) -> 3

Sheet 19
B1: ='18'!B1+1 -> 45615
B2: Fechamento Diário do Caixa
B4: Saldo Inicial | C4: 0 | E4: Vendas | K4: Despesas
B5: Vendas | C5: =SUMIF(I6:I31,">0",H6:H31) -> 495 | E5: Nº Venda | F5: Cliente | G5: Forma de Pgto | H5: Valor Venda | I5: Entrada | K5: Descrição | L5: Tipo de Pagto | M5: Valor
B6: Entrada | C6: =C16 -> 613 | K6: AGUA | L6: PIX | M6: 13 | R6: =IF(vend19[[#This Row],[Nº Venda]]>1,1,0) -> 0
B7: Despesas | C7: =SUM(M6:M11) -> 13 | R7: =IF(vend19[[#This Row],[Nº Venda]]>1,1,0) -> 0
B8: Total entrada | C8: =SUM(C6:C7) -> 626 | R8: =IF(vend19[[#This Row],[Nº Venda]]>1,1,0) -> 0
R9: =IF(vend19[[#This Row],[Nº Venda]]>1,1,0) -> 0
B10: Tipos de Pagtos | R10: =IF(vend19[[#This Row],[Nº Venda]]>1,1,0) -> 0
B11: DN | C11: =(SUMIF($G$2:$G$31,B11,$I$2:$I$31))+(SUMIF($G$35:$G$41,B11,$H$35:$H$41)) -> 0 | O11: =IF(C16=0,0,1) -> 1 | R11: =IF(vend19[[#This Row],[Nº Venda]]>1,1,0) -> 0
B12: CTD | C12: =(SUMIF($G$2:$G$31,B12,$I$2:$I$31))+(SUMIF($G$35:$G$41,B12,$H$35:$H$41)) -> 495 | R12: =IF(vend19[[#This Row],[Nº Venda]]>1,1,0) -> 0
B13: CTC | C13: =(SUMIF($G$2:$G$31,B13,$I$2:$I$31))+(SUMIF($G$35:$G$41,B13,$H$35:$H$41)) -> 0 | K13: OS Entregue no Dia | R13: =IF(vend19[[#This Row],[Nº Venda]]>1,1,0) -> 0
B14: PCTC | C14: =(SUMIF($G$2:$G$31,B14,$I$2:$I$31))+(SUMIF($G$35:$G$41,B14,$H$35:$H$41)) -> 0 | K14: OS | L14: Vendedor | M14: CARNE | R14: =IF(vend19[[#This Row],[Nº Venda]]>1,1,0) -> 0
B15: PIX | C15: =(SUMIF($G$2:$G$31,B15,$I$2:$I$31))+(SUMIF($G$35:$G$41,B15,$H$35:$H$41)) -> 118 | R15: =IF(vend19[[#This Row],[Nº Venda]]>1,1,0) -> 0
B16: Total | C16: =SUM(C11:C15) -> 613 | R16: =IF(vend19[[#This Row],[Nº Venda]]>1,1,0) -> 0
R17: =IF(vend19[[#This Row],[Nº Venda]]>1,1,0) -> 0
B18: Entrega de Carne | R18: =IF(vend19[[#This Row],[Nº Venda]]>1,1,0) -> 0
B19: =COUNT(entr_carn19[OS]) -> 0 | C19: =SUM(entr_carn19[Valor Total]) -> 0 | R19: =IF(vend19[[#This Row],[Nº Venda]]>1,1,0) -> 0
B20: Total | C20: =SUM(C19:C19) -> 0 | R20: =IF(vend19[[#This Row],[Nº Venda]]>1,1,0) -> 0
B22: Venda | C22: =C5 -> 495
E24: Restante Entrada
E25: Nº Venda | F25: Cliente | G25: Forma de Pgto | H25: Valor Venda | I25: Entrada
E26: 6949 | F26: FELIPE DE MOURA | G26: CTD | H26: 495 | I26: 495
E33: Recebimento de Carnê | K33: Entrega de Carne
E34: OS | F34: Cliente | G34: Forma de Pgto | H34: Valor Parcela | I34: Nº Parcela | K34: OS | L34: Parcelas | M34: Valor Total
E35: 811 | F35: ERICK CRISTIANO | G35: PIX | H35: 118 | I35: PARC. 2/5
Q40: Total de OS | R40: =SUM(R6:R21) -> 0

Sheet 20
B1: ='19'!B1+1 -> 45616
B2: Fechamento Diário do Caixa
B4: Saldo Inicial | C4: 0 | E4: Vendas | K4: Despesas
B5: Vendas | C5: =SUMIF(I6:I31,">0",H6:H31) -> 0 | E5: Nº Venda | F5: Cliente | G5: Forma de Pgto | H5: Valor Venda | I5: Entrada | K5: Descrição | L5: Tipo de Pagto | M5: Valor
B6: Entrada | C6: =C16 -> 0 | R6: =IF(vend20[[#This Row],[Nº Venda]]>1,1,0) -> 0
B7: Despesas | C7: =SUM(M6:M11) -> 0 | R7: =IF(vend20[[#This Row],[Nº Venda]]>1,1,0) -> 0
B8: Total entrada | C8: =SUM(C6:C7) -> 0 | R8: =IF(vend20[[#This Row],[Nº Venda]]>1,1,0) -> 0
R9: =IF(vend20[[#This Row],[Nº Venda]]>1,1,0) -> 0
B10: Tipos de Pagtos | R10: =IF(vend20[[#This Row],[Nº Venda]]>1,1,0) -> 0
B11: DN | C11: =(SUMIF($G$2:$G$31,B11,$I$2:$I$31))+(SUMIF($G$35:$G$41,B11,$H$35:$H$41)) -> 0 | O11: =IF(C16=0,0,1) -> 0 | R11: =IF(vend20[[#This Row],[Nº Venda]]>1,1,0) -> 0
B12: CTD | C12: =(SUMIF($G$2:$G$31,B12,$I$2:$I$31))+(SUMIF($G$35:$G$41,B12,$H$35:$H$41)) -> 0 | R12: =IF(vend20[[#This Row],[Nº Venda]]>1,1,0) -> 0
B13: CTC | C13: =(SUMIF($G$2:$G$31,B13,$I$2:$I$31))+(SUMIF($G$35:$G$41,B13,$H$35:$H$41)) -> 0 | K13: OS Entregue no Dia | R13: =IF(vend20[[#This Row],[Nº Venda]]>1,1,0) -> 0
B14: PCTC | C14: =(SUMIF($G$2:$G$31,B14,$I$2:$I$31))+(SUMIF($G$35:$G$41,B14,$H$35:$H$41)) -> 0 | K14: OS | L14: Vendedor | M14: CARNE | R14: =IF(vend20[[#This Row],[Nº Venda]]>1,1,0) -> 0
B15: PIX | C15: =(SUMIF($G$2:$G$31,B15,$I$2:$I$31))+(SUMIF($G$35:$G$41,B15,$H$35:$H$41)) -> 0 | R15: =IF(vend20[[#This Row],[Nº Venda]]>1,1,0) -> 0
B16: Total | C16: =SUM(C11:C15) -> 0 | R16: =IF(vend20[[#This Row],[Nº Venda]]>1,1,0) -> 0
R17: =IF(vend20[[#This Row],[Nº Venda]]>1,1,0) -> 0
B18: Entrega de Carne | R18: =IF(vend20[[#This Row],[Nº Venda]]>1,1,0) -> 0
B19: =COUNT(entr_carn20[OS]) -> 0 | C19: =SUM(entr_carn20[Valor Total]) -> 0 | R19: =IF(vend20[[#This Row],[Nº Venda]]>1,1,0) -> 0
B20: Total | C20: =SUM(C19:C19) -> 0 | R20: =IF(vend20[[#This Row],[Nº Venda]]>1,1,0) -> 0
B22: Venda | C22: =C5 -> 0
E24: Restante Entrada
E25: Nº Venda | F25: Cliente | G25: Forma de Pgto | H25: Valor Venda | I25: Entrada
E33: Recebimento de Carnê | K33: Entrega de Carne
E34: OS | F34: Cliente | G34: Forma de Pgto | H34: Valor Parcela | I34: Nº Parcela | K34: OS | L34: Parcelas | M34: Valor Total
Q40: Total de OS | R40: =SUM(R6:R21) -> 0

Sheet 21
B1: ='20'!B1+1 -> 45617
B2: Fechamento Diário do Caixa
B4: Saldo Inicial | C4: 0 | E4: Vendas | K4: Despesas
B5: Vendas | C5: =SUMIF(I6:I31,">0",H6:H31) -> 0 | E5: Nº Venda | F5: Cliente | G5: Forma de Pgto | H5: Valor Venda | I5: Entrada | K5: Descrição | L5: Tipo de Pagto | M5: Valor
B6: Entrada | C6: =C16 -> 0 | R6: =IF(vend21[[#This Row],[Nº Venda]]>1,1,0) -> 0
B7: Despesas | C7: =SUM(M6:M11) -> 0 | R7: =IF(vend21[[#This Row],[Nº Venda]]>1,1,0) -> 0
B8: Total entrada | C8: =SUM(C6:C7) -> 0 | R8: =IF(vend21[[#This Row],[Nº Venda]]>1,1,0) -> 0
R9: =IF(vend21[[#This Row],[Nº Venda]]>1,1,0) -> 0
B10: Tipos de Pagtos | R10: =IF(vend21[[#This Row],[Nº Venda]]>1,1,0) -> 0
B11: DN | C11: =(SUMIF($G$2:$G$31,B11,$I$2:$I$31))+(SUMIF($G$35:$G$41,B11,$H$35:$H$41)) -> 0 | O11: =IF(C16=0,0,1) -> 0 | R11: =IF(vend21[[#This Row],[Nº Venda]]>1,1,0) -> 0
B12: CTD | C12: =(SUMIF($G$2:$G$31,B12,$I$2:$I$31))+(SUMIF($G$35:$G$41,B12,$H$35:$H$41)) -> 0 | R12: =IF(vend21[[#This Row],[Nº Venda]]>1,1,0) -> 0
B13: CTC | C13: =(SUMIF($G$2:$G$31,B13,$I$2:$I$31))+(SUMIF($G$35:$G$41,B13,$H$35:$H$41)) -> 0 | K13: OS Entregue no Dia | R13: =IF(vend21[[#This Row],[Nº Venda]]>1,1,0) -> 0
B14: PCTC | C14: =(SUMIF($G$2:$G$31,B14,$I$2:$I$31))+(SUMIF($G$35:$G$41,B14,$H$35:$H$41)) -> 0 | K14: OS | L14: Vendedor | M14: CARNE | R14: =IF(vend21[[#This Row],[Nº Venda]]>1,1,0) -> 0
B15: PIX | C15: =(SUMIF($G$2:$G$31,B15,$I$2:$I$31))+(SUMIF($G$35:$G$41,B15,$H$35:$H$41)) -> 0 | R15: =IF(vend21[[#This Row],[Nº Venda]]>1,1,0) -> 0
B16: Total | C16: =SUM(C11:C15) -> 0 | R16: =IF(vend21[[#This Row],[Nº Venda]]>1,1,0) -> 0
R17: =IF(vend21[[#This Row],[Nº Venda]]>1,1,0) -> 0
B18: Entrega de Carne | R18: =IF(vend21[[#This Row],[Nº Venda]]>1,1,0) -> 0
B19: =COUNT(entr_carn21[OS]) -> 0 | C19: =SUM(entr_carn21[Valor Total]) -> 0 | R19: =IF(vend21[[#This Row],[Nº Venda]]>1,1,0) -> 0
B20: Total | C20: =SUM(C19:C19) -> 0 | R20: =IF(vend21[[#This Row],[Nº Venda]]>1,1,0) -> 0
B22: Venda | C22: =C5 -> 0
E24: Restante Entrada
E25: Nº Venda | F25: Cliente | G25: Forma de Pgto | H25: Valor Venda | I25: Entrada
E33: Recebimento de Carnê | K33: Entrega de Carne
E34: OS | F34: Cliente | G34: Forma de Pgto | H34: Valor Parcela | I34: Nº Parcela | K34: OS | L34: Parcelas | M34: Valor Total
Q40: Total de OS | R40: =SUM(R6:R21) -> 0

Sheet 22
B1: ='21'!B1+1 -> 45618
B2: Fechamento Diário do Caixa
B4: Saldo Inicial | C4: 0 | E4: Vendas | K4: Despesas
B5: Vendas | C5: =SUMIF(I6:I31,">0",H6:H31) -> 1850 | E5: Nº Venda | F5: Cliente | G5: Forma de Pgto | H5: Valor Venda | I5: Entrada | K5: Descrição | L5: Tipo de Pagto | M5: Valor
B6: Entrada | C6: =C16 -> 1471 | E6: 6950 | F6: DAVID FLAVIO | G6: PIX | H6: 640 | I6: 50 | R6: =IF(vend22[[#This Row],[Nº Venda]]>1,1,0) -> 1
B7: Despesas | C7: =SUM(M6:M11) -> 0 | E7: 6951 | F7: REJANE DA SILVA | G7: PIX | H7: 680 | I7: 100 | R7: =IF(vend22[[#This Row],[Nº Venda]]>1,1,0) -> 1
B8: Total entrada | C8: =SUM(C6:C7) -> 1471 | E8: 6952 | F8: REJANE DA SILVA | G8: PIX | H8: 530 | I8: 100 | R8: =IF(vend22[[#This Row],[Nº Venda]]>1,1,0) -> 1
R9: =IF(vend22[[#This Row],[Nº Venda]]>1,1,0) -> 0
B10: Tipos de Pagtos | R10: =IF(vend22[[#This Row],[Nº Venda]]>1,1,0) -> 0
B11: DN | C11: =(SUMIF($G$2:$G$31,B11,$I$2:$I$31))+(SUMIF($G$35:$G$41,B11,$H$35:$H$41)) -> 0 | O11: =IF(C16=0,0,1) -> 1 | R11: =IF(vend22[[#This Row],[Nº Venda]]>1,1,0) -> 0
B12: CTD | C12: =(SUMIF($G$2:$G$31,B12,$I$2:$I$31))+(SUMIF($G$35:$G$41,B12,$H$35:$H$41)) -> 0 | R12: =IF(vend22[[#This Row],[Nº Venda]]>1,1,0) -> 0
B13: CTC | C13: =(SUMIF($G$2:$G$31,B13,$I$2:$I$31))+(SUMIF($G$35:$G$41,B13,$H$35:$H$41)) -> 0 | K13: OS Entregue no Dia | R13: =IF(vend22[[#This Row],[Nº Venda]]>1,1,0) -> 0
B14: PCTC | C14: =(SUMIF($G$2:$G$31,B14,$I$2:$I$31))+(SUMIF($G$35:$G$41,B14,$H$35:$H$41)) -> 0 | K14: OS | L14: Vendedor | M14: CARNE | R14: =IF(vend22[[#This Row],[Nº Venda]]>1,1,0) -> 0
B15: PIX | C15: =(SUMIF($G$2:$G$31,B15,$I$2:$I$31))+(SUMIF($G$35:$G$41,B15,$H$35:$H$41)) -> 1471 | K15: 6929 | L15: LUANA | M15: Não | R15: =IF(vend22[[#This Row],[Nº Venda]]>1,1,0) -> 0
B16: Total | C16: =SUM(C11:C15) -> 1471 | R16: =IF(vend22[[#This Row],[Nº Venda]]>1,1,0) -> 0
R17: =IF(vend22[[#This Row],[Nº Venda]]>1,1,0) -> 0
B18: Entrega de Carne | R18: =IF(vend22[[#This Row],[Nº Venda]]>1,1,0) -> 0
B19: =COUNT(entr_carn22[OS]) -> 0 | C19: =SUM(entr_carn22[Valor Total]) -> 0 | R19: =IF(vend22[[#This Row],[Nº Venda]]>1,1,0) -> 0
B20: Total | C20: =SUM(C19:C19) -> 0 | R20: =IF(vend22[[#This Row],[Nº Venda]]>1,1,0) -> 0
B22: Venda | C22: =C5 -> 1850
E24: Restante Entrada
E25: Nº Venda | F25: Cliente | G25: Forma de Pgto | H25: Valor Venda | I25: Entrada
E26: 6929 | F26: ANA LUCIA | G26: PIX | H26: 0 | I26: 819
E33: Recebimento de Carnê | K33: Entrega de Carne
E34: OS | F34: Cliente | G34: Forma de Pgto | H34: Valor Parcela | I34: Nº Parcela | K34: OS | L34: Parcelas | M34: Valor Total
E35: 798 | F35: JESILENE SILVA SOARES | G35: PIX | H35: 95 | I35: PARC. 2/9
E36: 810 | F36: CLEONICE ROCHA | G36: PIX | H36: 140 | I36: PARC. 3/5
E37: 798 | F37: MARCO ANTONIO | G37: PIX | H37: 167 | I37: PARC. 3/5
Q40: Total de OS | R40: =SUM(R6:R21) -> 3

Sheet 23
B1: ='22'!B1+1 -> 45619
B2: Fechamento Diário do Caixa
B4: Saldo Inicial | C4: 0 | E4: Vendas | K4: Despesas
B5: Vendas | C5: =SUMIF(I6:I31,">0",H6:H31) -> 0 | E5: Nº Venda | F5: Cliente | G5: Forma de Pgto | H5: Valor Venda | I5: Entrada | K5: Descrição | L5: Tipo de Pagto | M5: Valor
B6: Entrada | C6: =C16 -> 0 | R6: =IF(vend23[[#This Row],[Nº Venda]]>1,1,0) -> 0
B7: Despesas | C7: =SUM(M6:M11) -> 0 | R7: =IF(vend23[[#This Row],[Nº Venda]]>1,1,0) -> 0
B8: Total entrada | C8: =SUM(C6:C7) -> 0 | R8: =IF(vend23[[#This Row],[Nº Venda]]>1,1,0) -> 0
R9: =IF(vend23[[#This Row],[Nº Venda]]>1,1,0) -> 0
B10: Tipos de Pagtos | R10: =IF(vend23[[#This Row],[Nº Venda]]>1,1,0) -> 0
B11: DN | C11: =(SUMIF($G$2:$G$31,B11,$I$2:$I$31))+(SUMIF($G$35:$G$44,B11,$H$35:$H$44)) -> 0 | O11: =IF(C16=0,0,1) -> 0 | R11: =IF(vend23[[#This Row],[Nº Venda]]>1,1,0) -> 0
B12: CTD | C12: =(SUMIF($G$2:$G$31,B12,$I$2:$I$31))+(SUMIF($G$35:$G$44,B12,$H$35:$H$44)) -> 0 | R12: =IF(vend23[[#This Row],[Nº Venda]]>1,1,0) -> 0
B13: CTC | C13: =(SUMIF($G$2:$G$31,B13,$I$2:$I$31))+(SUMIF($G$35:$G$44,B13,$H$35:$H$44)) -> 0 | K13: OS Entregue no Dia | R13: =IF(vend23[[#This Row],[Nº Venda]]>1,1,0) -> 0
B14: PCTC | C14: =(SUMIF($G$2:$G$31,B14,$I$2:$I$31))+(SUMIF($G$35:$G$44,B14,$H$35:$H$44)) -> 0 | K14: OS | L14: Vendedor | M14: CARNE | R14: =IF(vend23[[#This Row],[Nº Venda]]>1,1,0) -> 0
B15: PIX | C15: =(SUMIF($G$2:$G$31,B15,$I$2:$I$31))+(SUMIF($G$35:$G$44,B15,$H$35:$H$44)) -> 0 | R15: =IF(vend23[[#This Row],[Nº Venda]]>1,1,0) -> 0
B16: Total | C16: =SUM(C11:C15) -> 0 | R16: =IF(vend23[[#This Row],[Nº Venda]]>1,1,0) -> 0
R17: =IF(vend23[[#This Row],[Nº Venda]]>1,1,0) -> 0
B18: Entrega de Carne | R18: =IF(vend23[[#This Row],[Nº Venda]]>1,1,0) -> 0
B19: =COUNT(entr_carn23[OS]) -> 0 | C19: =SUM(entr_carn23[Valor Total]) -> 0 | R19: =IF(vend23[[#This Row],[Nº Venda]]>1,1,0) -> 0
B20: Total | C20: =SUM(C19:C19) -> 0 | R20: =IF(vend23[[#This Row],[Nº Venda]]>1,1,0) -> 0
B22: Venda | C22: =C5 -> 0
E24: Restante Entrada
E25: Nº Venda | F25: Cliente | G25: Forma de Pgto | H25: Valor Venda | I25: Entrada
E33: Recebimento de Carnê | K33: Entrega de Carne
E34: OS | F34: Cliente | G34: Forma de Pgto | H34: Valor Parcela | I34: Nº Parcela | K34: OS | L34: Parcelas | M34: Valor Total
Q40: Total de OS | R40: =SUM(R6:R21) -> 0

Sheet 24
B1: ='23'!B1+1 -> 45620
B2: Fechamento Diário do Caixa
B4: Saldo Inicial | C4: 0 | E4: Vendas | K4: Despesas
