Workbook

Sheet resumo_cx
A2: Saldo Inicial | B2: 0
A3: Vendas | B3: =SUM('01'!C5,'02'!C5,'03'!C5,'04'!C5,'05'!C5,'06'!C5,'07'!C5,'08'!C5,'09'!C5,'10'!C5,'11'!C5,'12'!C5,'13'!C5,'14'!C5,'15'!C5,'16'!C5,'17'!C5,'18'!C5,'19'!C5,'20'!C5,'21'!C5,'22'!C5,'23'!C5,'24'!C5,'25'!C5,'26'!C5,'27'!C5,'28'!C5,'29'!C5,'30'!C5,'31'!C5) -> 22569.95
A4: Entrada | B4: =B14 -> 20186.64
A5: Despesas | B5: =SUM('01'!C7,'02'!C7,'03'!C7,'04'!C7,'05'!C7,'06'!C7,'07'!C7,'08'!C7,'09'!C7,'10'!C7,'11'!C7,'12'!C7,'13'!C7,'14'!C7,'15'!C7,'16'!C7,'17'!C7,'18'!C7,'19'!C7,'20'!C7,'21'!C7,'22'!C7,'23'!C7,'24'!C7,'25'!C7,'26'!C7,'27'!C7,'28'!C7,'29'!C7,'30'!C7,'31'!C7) -> 1072.5
A6: Entr_Desp | B6: =SUM(B4:B5) -> 21259.14
A8: Tipos de Pagtos
A9: DN | B9: =SUM('01'!C11,'02'!C11,'03'!C11,'04'!C11,'05'!C11,'06'!C11,'07'!C11,'08'!C11,'09'!C11,'10'!C11,'11'!C11,'12'!C11,'13'!C11,'14'!C11,'15'!C11,'16'!C11,'17'!C11,'18'!C11,'19'!C11,'20'!C11,'21'!C11,'22'!C11,'23'!C11,'24'!C11,'25'!C11,'26'!C11,'27'!C11,'28'!C11,'29'!C11,'30'!C11,'31'!C11) -> 2892.5
A10: CTD | B10: =SUM('01'!C12,'02'!C12,'03'!C12,'04'!C12,'05'!C12,'06'!C12,'07'!C12,'08'!C12,'09'!C12,'10'!C12,'11'!C12,'12'!C12,'13'!C12,'14'!C12,'15'!C12,'16'!C12,'17'!C12,'18'!C12,'19'!C12,'20'!C12,'21'!C12,'22'!C12,'23'!C12,'24'!C12,'25'!C12,'26'!C12,'27'!C12,'28'!C12,'29'!C12,'30'!C12,'31'!C12) -> 3490.38
A11: CTC | B11: =SUM('01'!C13,'02'!C13,'03'!C13,'04'!C13,'05'!C13,'06'!C13,'07'!C13,'08'!C13,'09'!C13,'10'!C13,'11'!C13,'12'!C13,'13'!C13,'14'!C13,'15'!C13,'16'!C13,'17'!C13,'18'!C13,'19'!C13,'20'!C13,'21'!C13,'22'!C13,'23'!C13,'24'!C13,'25'!C13,'26'!C13,'27'!C13,'28'!C13,'29'!C13,'30'!C13,'31'!C13) -> 239.8
A12: PCTC | B12: =SUM('01'!C14,'02'!C14,'03'!C14,'04'!C14,'05'!C14,'06'!C14,'07'!C14,'08'!C14,'09'!C14,'10'!C14,'11'!C14,'12'!C14,'13'!C14,'14'!C14,'15'!C14,'16'!C14,'17'!C14,'18'!C14,'19'!C14,'20'!C14,'21'!C14,'22'!C14,'23'!C14,'24'!C14,'25'!C14,'26'!C14,'27'!C14,'28'!C14,'29'!C14,'30'!C14,'31'!C14) -> 10300.96
A13: PIX | B13: =SUM('01'!C15,'02'!C15,'03'!C15,'04'!C15,'05'!C15,'06'!C15,'07'!C15,'08'!C15,'09'!C15,'10'!C15,'11'!C15,'12'!C15,'13'!C15,'14'!C15,'15'!C15,'16'!C15,'17'!C15,'18'!C15,'19'!C15,'20'!C15,'21'!C15,'22'!C15,'23'!C15,'24'!C15,'25'!C15,'26'!C15,'27'!C15,'28'!C15,'29'!C15,'30'!C15,'31'!C15) -> 3263
A14: Total | B14: =SUM(B9:B13) -> 20186.64
A16: Entrega de Carne
A17: =COUNT(entr_carn1[OS]) -> 0 | B17: =SUM('01'!C19,'02'!C19,'03'!C19,'04'!C19,'05'!C19,'06'!C19,'07'!C19,'08'!C19,'09'!C19,'10'!C19,'11'!C19,'12'!C19,'13'!C19,'14'!C19,'15'!C19,'16'!C19,'17'!C19,'18'!C19,'19'!C19,'20'!C19,'21'!C19,'22'!C19,'23'!C19,'24'!C19,'25'!C19,'26'!C19,'27'!C19,'28'!C19,'29'!C19,'30'!C19,'31'!C19) -> 2851
A18: Total | B18: =SUM(B17:B17) -> 2851

Sheet 01
B1: 45261
B2: Fechamento Diário do Caixa
B4: Saldo Inicial | C4: 0 | E4: Vendas | K4: Despesas
B5: Vendas | C5: =SUMIF(I6:I31,">0",H6:H31) -> 0 | E5: Nº Venda | F5: Cliente | G5: Forma de Pgto | H5: Valor Venda | I5: Entrada | K5: Descrição | L5: Tipo de Pagto | M5: Valor
B6: Entrada | C6: =SUM(I6:I41) -> 749.99 | K6: porta | L6: pix | M6: 100 | R6: =IF(vend1[[#This Row],[Nº Venda]]>1,1,0) -> 0
B7: Despesas | C7: =SUM(M6:M11) -> 100 | R7: =IF(vend1[[#This Row],[Nº Venda]]>1,1,0) -> 0
B8: Total entrada | C8: =SUM(C6:C7) -> 849.99 | R8: =IF(vend1[[#This Row],[Nº Venda]]>1,1,0) -> 0
R9: =IF(vend1[[#This Row],[Nº Venda]]>1,1,0) -> 0
B10: Tipos de Pagtos | R10: =IF(vend1[[#This Row],[Nº Venda]]>1,1,0) -> 0
B11: DN | C11: =(SUMIF($G$2:$G$31,B11,$I$2:$I$31))+(SUMIF($G$35:$G$41,B11,$H$35:$H$41)) -> 0 | O11: =IF(C16=0,0,1) -> 1 | R11: =IF(vend1[[#This Row],[Nº Venda]]>1,1,0) -> 0
B12: CTD | C12: =(SUMIF($G$2:$G$31,B12,$I$2:$I$31))+(SUMIF($G$35:$G$41,B12,$H$35:$H$41)) -> 0 | R12: =IF(vend1[[#This Row],[Nº Venda]]>1,1,0) -> 0
B13: CTC | C13: =(SUMIF($G$2:$G$31,B13,$I$2:$I$31))+(SUMIF($G$35:$G$41,B13,$H$35:$H$41)) -> 0 | K13: OS Entregue no Dia | R13: =IF(vend1[[#This Row],[Nº Venda]]>1,1,0) -> 0
B14: PCTC | C14: =(SUMIF($G$2:$G$31,B14,$I$2:$I$31))+(SUMIF($G$35:$G$41,B14,$H$35:$H$41)) -> 749.99 | K14: OS | L14: Vendedor | M14: CARNE | R14: =IF(vend1[[#This Row],[Nº Venda]]>1,1,0) -> 0
B15: PIX | C15: =(SUMIF($G$2:$G$31,B15,$I$2:$I$31))+(SUMIF($G$35:$G$41,B15,$H$35:$H$41)) -> 0 | K15: 1790 | L15: Wevilly | M15: Não | R15: =IF(vend1[[#This Row],[Nº Venda]]>1,1,0) -> 0
B16: Total | C16: =SUM(C11:C15) -> 749.99 | K16: 1801 | L16: Wevilly | M16: Não | R16: =IF(vend1[[#This Row],[Nº Venda]]>1,1,0) -> 0
R17: =IF(vend1[[#This Row],[Nº Venda]]>1,1,0) -> 0
B18: Entrega de Carne | R18: =IF(vend1[[#This Row],[Nº Venda]]>1,1,0) -> 0
B19: =COUNT(entr_carn1[OS]) -> 0 | C19: =SUM(entr_carn1[Valor Total]) -> 0 | R19: =IF(vend1[[#This Row],[Nº Venda]]>1,1,0) -> 0
B20: Total | C20: =SUM(C19:C19) -> 0 | R20: =IF(vend1[[#This Row],[Nº Venda]]>1,1,0) -> 0
B22: Venda | C22: =C5 -> 0
E24: Restante Entrada
E25: Nº Venda | F25: Cliente | G25: Forma de Pgto | H25: Valor Venda | I25: Entrada
E26: 1790 | F26: NANCY H | G26: PCTC | I26: 749.99
E33: Recebimento de Carnê | K33: Entrega de Carne
E34: OS | F34: Cliente | G34: Forma de Pgto | H34: Valor Parcela | I34: Nº Parcela | K34: OS | L34: Parcelas | M34: Valor Total
Q40: Total de OS | R40: =SUM(R6:R21) -> 0

Sheet 02
B1: ='01'!B1+1 -> 45262
B2: Fechamento Diário do Caixa
B4: Saldo Inicial | C4: 0 | E4: Vendas | K4: Despesas
B5: Vendas | C5: =SUMIF(I6:I31,">0",H6:H31) -> 30.5 | E5: Nº Venda | F5: Cliente | G5: Forma de Pgto | H5: Valor Venda | I5: Entrada | K5: Descrição | L5: Tipo de Pagto | M5: Valor
B6: Entrada | C6: =SUM(I6:I41) -> 0.5 | E6: 1832 | F6: MARI NEIDE | G6: DN | H6: 30.5 | I6: 0.5 | R6: =IF(vend2[[#This Row],[Nº Venda]]>1,1,0) -> 1
B7: Despesas | C7: =SUM(M6:M11) -> 0 | R7: =IF(vend2[[#This Row],[Nº Venda]]>1,1,0) -> 0
B8: Total entrada | C8: =SUM(C6:C7) -> 0.5 | R8: =IF(vend2[[#This Row],[Nº Venda]]>1,1,0) -> 0
R9: =IF(vend2[[#This Row],[Nº Venda]]>1,1,0) -> 0
B10: Tipos de Pagtos | R10: =IF(vend2[[#This Row],[Nº Venda]]>1,1,0) -> 0
B11: DN | C11: =(SUMIF($G$2:$G$31,B11,$I$2:$I$31))+(SUMIF($G$35:$G$41,B11,$H$35:$H$41)) -> 0.5 | O11: =IF(C16=0,0,1) -> 1 | R11: =IF(vend2[[#This Row],[Nº Venda]]>1,1,0) -> 0
B12: CTD | C12: =(SUMIF($G$2:$G$31,B12,$I$2:$I$31))+(SUMIF($G$35:$G$41,B12,$H$35:$H$41)) -> 0 | R12: =IF(vend2[[#This Row],[Nº Venda]]>1,1,0) -> 0
B13: CTC | C13: =(SUMIF($G$2:$G$31,B13,$I$2:$I$31))+(SUMIF($G$35:$G$41,B13,$H$35:$H$41)) -> 0 | K13: OS Entregue no Dia | R13: =IF(vend2[[#This Row],[Nº Venda]]>1,1,0) -> 0
B14: PCTC | C14: =(SUMIF($G$2:$G$31,B14,$I$2:$I$31))+(SUMIF($G$35:$G$41,B14,$H$35:$H$41)) -> 0 | K14: OS | L14: Vendedor | M14: CARNE | R14: =IF(vend2[[#This Row],[Nº Venda]]>1,1,0) -> 0
B15: PIX | C15: =(SUMIF($G$2:$G$31,B15,$I$2:$I$31))+(SUMIF($G$35:$G$41,B15,$H$35:$H$41)) -> 0 | K15: 1806 | L15: Maria | M15: Não | R15: =IF(vend2[[#This Row],[Nº Venda]]>1,1,0) -> 0
B16: Total | C16: =SUM(C11:C15) -> 0.5 | R16: =IF(vend2[[#This Row],[Nº Venda]]>1,1,0) -> 0
R17: =IF(vend2[[#This Row],[Nº Venda]]>1,1,0) -> 0
B18: Entrega de Carne | R18: =IF(vend2[[#This Row],[Nº Venda]]>1,1,0) -> 0
B19: =COUNT(entr_carn2[OS]) -> 0 | C19: =SUM(entr_carn2[Valor Total]) -> 0 | R19: =IF(vend2[[#This Row],[Nº Venda]]>1,1,0) -> 0
B20: Total | C20: =SUM(C19:C19) -> 0 | R20: =IF(vend2[[#This Row],[Nº Venda]]>1,1,0) -> 0
B22: Venda | C22: =C5 -> 30.5
E24: Restante Entrada
E25: Nº Venda | F25: Cliente | G25: Forma de Pgto | H25: Valor Venda | I25: Entrada
E33: Recebimento de Carnê | K33: Entrega de Carne
E34: OS | F34: Cliente | G34: Forma de Pgto | H34: Valor Parcela | I34: Nº Parcela | K34: OS | L34: Parcelas | M34: Valor Total
Q40: Total de OS | R40: =SUM(R6:R21) -> 1

Sheet 03
B1: ='02'!B1+1 -> 45263
B2: Fechamento Diário do Caixa
B4: Saldo Inicial | C4: 0 | E4: Vendas | K4: Despesas
B5: Vendas | C5: =SUMIF(I6:I31,">0",H6:H31) -> 0 | E5: Nº Venda | F5: Cliente | G5: Forma de Pgto | H5: Valor Venda | I5: Entrada | K5: Descrição | L5: Tipo de Pagto | M5: Valor
B6: Entrada | C6: =SUM(I6:I41) -> 0 | R6: =IF(vend3[[#This Row],[Nº Venda]]>1,1,0) -> 0
B7: Despesas | C7: =SUM(M6:M11) -> 0 | R7: =IF(vend3[[#This Row],[Nº Venda]]>1,1,0) -> 0
B8: Total entrada | C8: =SUM(C6:C7) -> 0 | R8: =IF(vend3[[#This Row],[Nº Venda]]>1,1,0) -> 0
R9: =IF(vend3[[#This Row],[Nº Venda]]>1,1,0) -> 0
B10: Tipos de Pagtos | R10: =IF(vend3[[#This Row],[Nº Venda]]>1,1,0) -> 0
B11: DN | C11: =(SUMIF($G$2:$G$31,B11,$I$2:$I$31))+(SUMIF($G$35:$G$41,B11,$H$35:$H$41)) -> 0 | O11: =IF(C16=0,0,1) -> 0 | R11: =IF(vend3[[#This Row],[Nº Venda]]>1,1,0) -> 0
B12: CTD | C12: =(SUMIF($G$2:$G$31,B12,$I$2:$I$31))+(SUMIF($G$35:$G$41,B12,$H$35:$H$41)) -> 0 | R12: =IF(vend3[[#This Row],[Nº Venda]]>1,1,0) -> 0
B13: CTC | C13: =(SUMIF($G$2:$G$31,B13,$I$2:$I$31))+(SUMIF($G$35:$G$41,B13,$H$35:$H$41)) -> 0 | K13: OS Entregue no Dia | R13: =IF(vend3[[#This Row],[Nº Venda]]>1,1,0) -> 0
B14: PCTC | C14: =(SUMIF($G$2:$G$31,B14,$I$2:$I$31))+(SUMIF($G$35:$G$41,B14,$H$35:$H$41)) -> 0 | K14: OS | L14: Vendedor | M14: CARNE | R14: =IF(vend3[[#This Row],[Nº Venda]]>1,1,0) -> 0
B15: PIX | C15: =(SUMIF($G$2:$G$31,B15,$I$2:$I$31))+(SUMIF($G$35:$G$41,B15,$H$35:$H$41)) -> 0 | R15: =IF(vend3[[#This Row],[Nº Venda]]>1,1,0) -> 0
B16: Total | C16: =SUM(C11:C15) -> 0 | R16: =IF(vend3[[#This Row],[Nº Venda]]>1,1,0) -> 0
R17: =IF(vend3[[#This Row],[Nº Venda]]>1,1,0) -> 0
B18: Entrega de Carne | R18: =IF(vend3[[#This Row],[Nº Venda]]>1,1,0) -> 0
B19: =COUNT(entr_carn3[OS]) -> 0 | C19: =SUM(entr_carn3[Valor Total]) -> 0 | R19: =IF(vend3[[#This Row],[Nº Venda]]>1,1,0) -> 0
B20: Total | C20: =SUM(C19:C19) -> 0 | R20: =IF(vend3[[#This Row],[Nº Venda]]>1,1,0) -> 0
B22: Venda | C22: =C5 -> 0
E24: Restante Entrada
E25: Nº Venda | F25: Cliente | G25: Forma de Pgto | H25: Valor Venda | I25: Entrada
E33: Recebimento de Carnê | K33: Entrega de Carne
E34: OS | F34: Cliente | G34: Forma de Pgto | H34: Valor Parcela | I34: Nº Parcela | K34: OS | L34: Parcelas | M34: Valor Total
Q40: Total de OS | R40: =SUM(R6:R21) -> 0

Sheet 04
B1: ='03'!B1+1 -> 45264
B2: Fechamento Diário do Caixa
B4: Saldo Inicial | C4: 0 | E4: Vendas | K4: Despesas
B5: Vendas | C5: =SUMIF(I6:I31,">0",H6:H31) -> 150 | E5: Nº Venda | F5: Cliente | G5: Forma de Pgto | H5: Valor Venda | I5: Entrada | K5: Descrição | L5: Tipo de Pagto | M5: Valor
B6: Entrada | C6: =SUM(I6:I41) -> 300 | E6: 1833 | F6: MARIA APARECIDA | G6: CTD | H6: 150 | I6: 100 | R6: =IF(vend4[[#This Row],[Nº Venda]]>1,1,0) -> 1
B7: Despesas | C7: =SUM(M6:M11) -> 0 | R7: =IF(vend4[[#This Row],[Nº Venda]]>1,1,0) -> 0
B8: Total entrada | C8: =SUM(C6:C7) -> 300 | R8: =IF(vend4[[#This Row],[Nº Venda]]>1,1,0) -> 0
R9: =IF(vend4[[#This Row],[Nº Venda]]>1,1,0) -> 0
B10: Tipos de Pagtos | R10: =IF(vend4[[#This Row],[Nº Venda]]>1,1,0) -> 0
B11: DN | C11: =(SUMIF($G$2:$G$31,B11,$I$2:$I$31))+(SUMIF($G$35:$G$41,B11,$H$35:$H$41)) -> 85 | O11: =IF(C16=0,0,1) -> 1 | R11: =IF(vend4[[#This Row],[Nº Venda]]>1,1,0) -> 0
B12: CTD | C12: =(SUMIF($G$2:$G$31,B12,$I$2:$I$31))+(SUMIF($G$35:$G$41,B12,$H$35:$H$41)) -> 100 | R12: =IF(vend4[[#This Row],[Nº Venda]]>1,1,0) -> 0
B13: CTC | C13: =(SUMIF($G$2:$G$31,B13,$I$2:$I$31))+(SUMIF($G$35:$G$41,B13,$H$35:$H$41)) -> 0 | K13: OS Entregue no Dia | R13: =IF(vend4[[#This Row],[Nº Venda]]>1,1,0) -> 0
B14: PCTC | C14: =(SUMIF($G$2:$G$31,B14,$I$2:$I$31))+(SUMIF($G$35:$G$41,B14,$H$35:$H$41)) -> 200 | K14: OS | L14: Vendedor | M14: CARNE | R14: =IF(vend4[[#This Row],[Nº Venda]]>1,1,0) -> 0
B15: PIX | C15: =(SUMIF($G$2:$G$31,B15,$I$2:$I$31))+(SUMIF($G$35:$G$41,B15,$H$35:$H$41)) -> 0 | K15: 1821 | L15: Taty | M15: Não | R15: =IF(vend4[[#This Row],[Nº Venda]]>1,1,0) -> 0
B16: Total | C16: =SUM(C11:C15) -> 385 | K16: 1766 | L16: William | M16: Não | R16: =IF(vend4[[#This Row],[Nº Venda]]>1,1,0) -> 0
R17: =IF(vend4[[#This Row],[Nº Venda]]>1,1,0) -> 0
B18: Entrega de Carne | R18: =IF(vend4[[#This Row],[Nº Venda]]>1,1,0) -> 0
B19: =COUNT(entr_carn4[OS]) -> 0 | C19: =SUM(entr_carn4[Valor Total]) -> 0 | R19: =IF(vend4[[#This Row],[Nº Venda]]>1,1,0) -> 0
B20: Total | C20: =SUM(C19:C19) -> 0 | R20: =IF(vend4[[#This Row],[Nº Venda]]>1,1,0) -> 0
B22: Venda | C22: =C5 -> 150
E24: Restante Entrada
E25: Nº Venda | F25: Cliente | G25: Forma de Pgto | H25: Valor Venda | I25: Entrada
E26: 1804 | F26: FRANCISCA SANTOS | G26: PCTC | I26: 200
E33: Recebimento de Carnê | K33: Entrega de Carne
E34: OS | F34: Cliente | G34: Forma de Pgto | H34: Valor Parcela | I34: Nº Parcela | K34: OS | L34: Parcelas | M34: Valor Total
E35: 1695 | F35: GERALDA GOMES | G35: DN | H35: 85 | I35: PARC. 2/6
Q40: Total de OS | R40: =SUM(R6:R21) -> 1

Sheet 05
B1: ='04'!B1+1 -> 45265
B2: Fechamento Diário do Caixa
B4: Saldo Inicial | C4: 0 | E4: Vendas | K4: Despesas
B5: Vendas | C5: =SUMIF(I6:I31,">0",H6:H31) -> 40.5 | E5: Nº Venda | F5: Cliente | G5: Forma de Pgto | H5: Valor Venda | I5: Entrada | K5: Descrição | L5: Tipo de Pagto | M5: Valor
B6: Entrada | C6: =SUM(I6:I41) -> 200.5 | E6: 1835 | F6: JARDIEL XAVIER | G6: SS | H6: GARANTIA | I6: 0 | R6: =IF(vend5[[#This Row],[Nº Venda]]>1,1,0) -> 1
B7: Despesas | C7: =SUM(M6:M11) -> 0 | E7: 1834 | F7: JHONY LUCKIS | G7: DN | H7: 40.5 | I7: 0.5 | R7: =IF(vend5[[#This Row],[Nº Venda]]>1,1,0) -> 1
B8: Total entrada | C8: =SUM(C6:C7) -> 200.5 | R8: =IF(vend5[[#This Row],[Nº Venda]]>1,1,0) -> 0
R9: =IF(vend5[[#This Row],[Nº Venda]]>1,1,0) -> 0
B10: Tipos de Pagtos | R10: =IF(vend5[[#This Row],[Nº Venda]]>1,1,0) -> 0
B11: DN | C11: =(SUMIF($G$2:$G$31,B11,$I$2:$I$31))+(SUMIF($G$35:$G$41,B11,$H$35:$H$41)) -> 0.5 | O11: =IF(C16=0,0,1) -> 1 | R11: =IF(vend5[[#This Row],[Nº Venda]]>1,1,0) -> 0
B12: CTD | C12: =(SUMIF($G$2:$G$31,B12,$I$2:$I$31))+(SUMIF($G$35:$G$41,B12,$H$35:$H$41)) -> 200 | R12: =IF(vend5[[#This Row],[Nº Venda]]>1,1,0) -> 0
B13: CTC | C13: =(SUMIF($G$2:$G$31,B13,$I$2:$I$31))+(SUMIF($G$35:$G$41,B13,$H$35:$H$41)) -> 0 | K13: OS Entregue no Dia | R13: =IF(vend5[[#This Row],[Nº Venda]]>1,1,0) -> 0
B14: PCTC | C14: =(SUMIF($G$2:$G$31,B14,$I$2:$I$31))+(SUMIF($G$35:$G$41,B14,$H$35:$H$41)) -> 0 | K14: OS | L14: Vendedor | M14: CARNE | R14: =IF(vend5[[#This Row],[Nº Venda]]>1,1,0) -> 0
B15: PIX | C15: =(SUMIF($G$2:$G$31,B15,$I$2:$I$31))+(SUMIF($G$35:$G$41,B15,$H$35:$H$41)) -> 0 | K15: 1810 | L15: Wevilly | M15: Sim | R15: =IF(vend5[[#This Row],[Nº Venda]]>1,1,0) -> 0
B16: Total | C16: =SUM(C11:C15) -> 200.5 | K16: 1811 | L16: Wevilly | M16: Sim | R16: =IF(vend5[[#This Row],[Nº Venda]]>1,1,0) -> 0
K17: 1812 | L17: Wevilly | M17: Sim | R17: =IF(vend5[[#This Row],[Nº Venda]]>1,1,0) -> 0
B18: Entrega de Carne | K18: 1813 | L18: Wevilly | M18: Sim | R18: =IF(vend5[[#This Row],[Nº Venda]]>1,1,0) -> 0
B19: =COUNT(entr_carn5[OS]) -> 4 | C19: =SUM(entr_carn5[Valor Total]) -> 2261 | R19: =IF(vend5[[#This Row],[Nº Venda]]>1,1,0) -> 0
B20: Total | C20: =SUM(C19:C19) -> 2261 | R20: =IF(vend5[[#This Row],[Nº Venda]]>1,1,0) -> 0
B22: Venda | C22: =C5 -> 40.5
E24: Restante Entrada
E25: Nº Venda | F25: Cliente | G25: Forma de Pgto | H25: Valor Venda | I25: Entrada
E26: 1811 | F26: LEONOR DE LIMA | G26: CTD | I26: 100
E27: 1813 | F27: JULIETA DE LIMA | G27: CTD | I27: 100
E33: Recebimento de Carnê | K33: Entrega de Carne
E34: OS | F34: Cliente | G34: Forma de Pgto | H34: Valor Parcela | I34: Nº Parcela | K34: OS | L34: Parcelas | M34: Valor Total
K35: 1810 | L35: 8 | M35: 600
K36: 1811 | L36: 7 | M36: 1393
K37: 1812 | L37: 6 | M37: 169
K38: 1813 | L38: 6 | M38: 99
Q40: Total de OS | R40: =SUM(R6:R21) -> 2

Sheet 06
B1: ='05'!B1+1 -> 45266
B2: Fechamento Diário do Caixa
B4: Saldo Inicial | C4: 0 | E4: Vendas | K4: Despesas
B5: Vendas | C5: =SUMIF(I6:I31,">0",H6:H31) -> 450 | E5: Nº Venda | F5: Cliente | G5: Forma de Pgto | H5: Valor Venda | I5: Entrada | K5: Descrição | L5: Tipo de Pagto | M5: Valor
B6: Entrada | C6: =SUM(I6:I41) -> 450 | E6: 1836 | F6: LEONARDO GUIDINO DE OLIVEIRA | G6: PCTC | H6: 450 | I6: 450 | R6: =IF(vend[[#This Row],[Nº Venda]]>1,1,0) -> 1
B7: Despesas | C7: =SUM(M6:M11) -> 0 | R7: =IF(vend[[#This Row],[Nº Venda]]>1,1,0) -> 0
B8: Total entrada | C8: =SUM(C6:C7) -> 450 | R8: =IF(vend[[#This Row],[Nº Venda]]>1,1,0) -> 0
R9: =IF(vend[[#This Row],[Nº Venda]]>1,1,0) -> 0
B10: Tipos de Pagtos | R10: =IF(vend[[#This Row],[Nº Venda]]>1,1,0) -> 0
B11: DN | C11: =(SUMIF($G$2:$G$31,B11,$I$2:$I$31))+(SUMIF($G$35:$G$41,B11,$H$35:$H$41)) -> 0 | O11: =IF(C16=0,0,1) -> 1 | R11: =IF(vend[[#This Row],[Nº Venda]]>1,1,0) -> 0
B12: CTD | C12: =(SUMIF($G$2:$G$31,B12,$I$2:$I$31))+(SUMIF($G$35:$G$41,B12,$H$35:$H$41)) -> 0 | R12: =IF(vend[[#This Row],[Nº Venda]]>1,1,0) -> 0
B13: CTC | C13: =(SUMIF($G$2:$G$31,B13,$I$2:$I$31))+(SUMIF($G$35:$G$41,B13,$H$35:$H$41)) -> 0 | K13: OS Entregue no Dia | R13: =IF(vend[[#This Row],[Nº Venda]]>1,1,0) -> 0
B14: PCTC | C14: =(SUMIF($G$2:$G$31,B14,$I$2:$I$31))+(SUMIF($G$35:$G$41,B14,$H$35:$H$41)) -> 450 | K14: OS | L14: Vendedor | M14: CARNE | R14: =IF(vend[[#This Row],[Nº Venda]]>1,1,0) -> 0
B15: PIX | C15: =(SUMIF($G$2:$G$31,B15,$I$2:$I$31))+(SUMIF($G$35:$G$41,B15,$H$35:$H$41)) -> 0 | R15: =IF(vend[[#This Row],[Nº Venda]]>1,1,0) -> 0
B16: Total | C16: =SUM(C11:C15) -> 450 | R16: =IF(vend[[#This Row],[Nº Venda]]>1,1,0) -> 0
R17: =IF(vend[[#This Row],[Nº Venda]]>1,1,0) -> 0
B18: Entrega de Carne | R18: =IF(vend[[#This Row],[Nº Venda]]>1,1,0) -> 0
B19: =COUNT(entr_carn6[OS]) -> 0 | C19: =SUM(entr_carn6[Valor Total]) -> 0 | R19: =IF(vend[[#This Row],[Nº Venda]]>1,1,0) -> 0
B20: Total | C20: =SUM(C19:C19) -> 0 | R20: =IF(vend[[#This Row],[Nº Venda]]>1,1,0) -> 0
B22: Venda | C22: =C5 -> 450
E24: Restante Entrada
E25: Nº Venda | F25: Cliente | G25: Forma de Pgto | H25: Valor Venda | I25: Entrada
E33: Recebimento de Carnê | K33: Entrega de Carne
E34: OS | F34: Cliente | G34: Forma de Pgto | H34: Valor Parcela | I34: Nº Parcela | K34: OS | L34: Parcelas | M34: Valor Total
Q40: Total de OS | R40: =SUM(R6:R21) -> 1

Sheet 07
B1: ='06'!B1+1 -> 45267
B2: Fechamento Diário do Caixa
B4: Saldo Inicial | C4: 0 | E4: Vendas | K4: Despesas
B5: Vendas | C5: =SUMIF(I6:I31,">0",H6:H31) -> 1250 | E5: Nº Venda | F5: Cliente | G5: Forma de Pgto | H5: Valor Venda | I5: Entrada | K5: Descrição | L5: Tipo de Pagto | M5: Valor
B6: Entrada | C6: =SUM(I6:I41) -> 1300 | E6: 1837 | F6: NANCY H | G6: SS | H6: GARANTIA | I6: 0 | K6: AGUA | L6: CTD | M6: 22.5 | R6: =IF(vend7[[#This Row],[Nº Venda]]>1,1,0) -> 1
B7: Despesas | C7: =SUM(M6:M11) -> 22.5 | E7: 1838 | F7: DAIANE MARTINS | G7: DN | H7: 1250 | I7: 950 | R7: =IF(vend7[[#This Row],[Nº Venda]]>1,1,0) -> 1
B8: Total entrada | C8: =SUM(C6:C7) -> 1322.5 | R8: =IF(vend7[[#This Row],[Nº Venda]]>1,1,0) -> 0
R9: =IF(vend7[[#This Row],[Nº Venda]]>1,1,0) -> 0
B10: Tipos de Pagtos | R10: =IF(vend7[[#This Row],[Nº Venda]]>1,1,0) -> 0
B11: DN | C11: =(SUMIF($G$2:$G$31,B11,$I$2:$I$31))+(SUMIF($G$35:$G$41,B11,$H$35:$H$41)) -> 950 | O11: =IF(C16=0,0,1) -> 1 | R11: =IF(vend7[[#This Row],[Nº Venda]]>1,1,0) -> 0
B12: CTD | C12: =(SUMIF($G$2:$G$31,B12,$I$2:$I$31))+(SUMIF($G$35:$G$41,B12,$H$35:$H$41)) -> 137.5 | R12: =IF(vend7[[#This Row],[Nº Venda]]>1,1,0) -> 0
B13: CTC | C13: =(SUMIF($G$2:$G$31,B13,$I$2:$I$31))+(SUMIF($G$35:$G$41,B13,$H$35:$H$41)) -> 0 | K13: OS Entregue no Dia | R13: =IF(vend7[[#This Row],[Nº Venda]]>1,1,0) -> 0
B14: PCTC | C14: =(SUMIF($G$2:$G$31,B14,$I$2:$I$31))+(SUMIF($G$35:$G$41,B14,$H$35:$H$41)) -> 350 | K14: OS | L14: Vendedor | M14: CARNE | R14: =IF(vend7[[#This Row],[Nº Venda]]>1,1,0) -> 0
B15: PIX | C15: =(SUMIF($G$2:$G$31,B15,$I$2:$I$31))+(SUMIF($G$35:$G$41,B15,$H$35:$H$41)) -> 0 | K15: 1823 | L15: Taty | M15: Não | R15: =IF(vend7[[#This Row],[Nº Venda]]>1,1,0) -> 0
B16: Total | C16: =SUM(C11:C15) -> 1437.5 | K16: 1818 | L16: Wevilly | M16: Não | R16: =IF(vend7[[#This Row],[Nº Venda]]>1,1,0) -> 0
R17: =IF(vend7[[#This Row],[Nº Venda]]>1,1,0) -> 0
B18: Entrega de Carne | R18: =IF(vend7[[#This Row],[Nº Venda]]>1,1,0) -> 0
B19: =COUNT(entr_carn7[OS]) -> 0 | C19: =SUM(entr_carn7[Valor Total]) -> 0 | R19: =IF(vend7[[#This Row],[Nº Venda]]>1,1,0) -> 0
B20: Total | C20: =SUM(C19:C19) -> 0 | R20: =IF(vend7[[#This Row],[Nº Venda]]>1,1,0) -> 0
B22: Venda | C22: =C5 -> 1250
E24: Restante Entrada
E25: Nº Venda | F25: Cliente | G25: Forma de Pgto | H25: Valor Venda | I25: Entrada
E26: 1818 | F26: MARIA REGINA G | G26: PCTC | I26: 350
E33: Recebimento de Carnê | K33: Entrega de Carne
E34: OS | F34: Cliente | G34: Forma de Pgto | H34: Valor Parcela | I34: Nº Parcela | K34: OS | L34: Parcelas | M34: Valor Total
E35: 1580 | F35: JOSENEIDE PAULINO | G35: CTD | H35: 137.5 | I35: PARC. 4/8
Q40: Total de OS | R40: =SUM(R6:R21) -> 2

Sheet 08
B1: ='07'!B1+1 -> 45268
B2: Fechamento Diário do Caixa
B4: Saldo Inicial | C4: 0 | E4: Vendas | K4: Despesas
B5: Vendas | C5: =SUMIF(I6:I31,">0",H6:H31) -> 1739 | E5: Nº Venda | F5: Cliente | G5: Forma de Pgto | H5: Valor Venda | I5: Entrada | K5: Descrição | L5: Tipo de Pagto | M5: Valor
B6: Entrada | C6: =SUM(I6:I41) -> 1729 | E6: 1839 | F6: MARIA APARECIDA | G6: CTD | H6: 839 | I6: 80 | K6: ANA C | L6: DN | M6: 950 | R6: =IF(vend8[[#This Row],[Nº Venda]]>1,1,0) -> 1
B7: Despesas | C7: =SUM(M6:M11) -> 950 | E7: 1840 | F7: MARIA NAZARE | G7: CTD | H7: 400 | I7: 80 | R7: =IF(vend8[[#This Row],[Nº Venda]]>1,1,0) -> 1
B8: Total entrada | C8: =SUM(C6:C7) -> 2679 | E8: 1841 | F8: MARIA NAZARE | G8: CTD | H8: 500 | I8: 79 | R8: =IF(vend8[[#This Row],[Nº Venda]]>1,1,0) -> 1
R9: =IF(vend8[[#This Row],[Nº Venda]]>1,1,0) -> 0
B10: Tipos de Pagtos | R10: =IF(vend8[[#This Row],[Nº Venda]]>1,1,0) -> 0
B11: DN | C11: =(SUMIF($G$2:$G$31,B11,$I$2:$I$31))+(SUMIF($G$35:$G$41,B11,$H$35:$H$41)) -> 670 | O11: =IF(C16=0,0,1) -> 1 | R11: =IF(vend8[[#This Row],[Nº Venda]]>1,1,0) -> 0
B12: CTD | C12: =(SUMIF($G$2:$G$31,B12,$I$2:$I$31))+(SUMIF($G$35:$G$41,B12,$H$35:$H$41)) -> 239 | R12: =IF(vend8[[#This Row],[Nº Venda]]>1,1,0) -> 0
B13: CTC | C13: =(SUMIF($G$2:$G$31,B13,$I$2:$I$31))+(SUMIF($G$35:$G$41,B13,$H$35:$H$41)) -> 0 | K13: OS Entregue no Dia | R13: =IF(vend8[[#This Row],[Nº Venda]]>1,1,0) -> 0
B14: PCTC | C14: =(SUMIF($G$2:$G$31,B14,$I$2:$I$31))+(SUMIF($G$35:$G$41,B14,$H$35:$H$41)) -> 500 | K14: OS | L14: Vendedor | M14: CARNE | R14: =IF(vend8[[#This Row],[Nº Venda]]>1,1,0) -> 0
B15: PIX | C15: =(SUMIF($G$2:$G$31,B15,$I$2:$I$31))+(SUMIF($G$35:$G$41,B15,$H$35:$H$41)) -> 425 | K15: 1524 | L15: Taty | M15: Não | R15: =IF(vend8[[#This Row],[Nº Venda]]>1,1,0) -> 0
B16: Total | C16: =SUM(C11:C15) -> 1834 | R16: =IF(vend8[[#This Row],[Nº Venda]]>1,1,0) -> 0
R17: =IF(vend8[[#This Row],[Nº Venda]]>1,1,0) -> 0
B18: Entrega de Carne | R18: =IF(vend8[[#This Row],[Nº Venda]]>1,1,0) -> 0
B19: =COUNT(entr_carn8[OS]) -> 0 | C19: =SUM(entr_carn8[Valor Total]) -> 0 | R19: =IF(vend8[[#This Row],[Nº Venda]]>1,1,0) -> 0
B20: Total | C20: =SUM(C19:C19) -> 0 | R20: =IF(vend8[[#This Row],[Nº Venda]]>1,1,0) -> 0
B22: Venda | C22: =C5 -> 1739
E24: Restante Entrada
E25: Nº Venda | F25: Cliente | G25: Forma de Pgto | H25: Valor Venda | I25: Entrada
E26: 1822 | F26: KAROLAYNE MATIAS | G26: PCTC | I26: 500
E27: 1802 | F27: DANIELE SILVA | G27: PIX | I27: 160
E28: 1804 | F28: THAYLA REIS | G28: PIX | I28: 160
E29: 1783 | F29: GENI GUERATO | G29: DN | I29: 670
E33: Recebimento de Carnê | K33: Entrega de Carne
E34: OS | F34: Cliente | G34: Forma de Pgto | H34: Valor Parcela | I34: Nº Parcela | K34: OS | L34: Parcelas | M34: Valor Total
E35: 1636 | F35: ELIAS MARTINS | G35: PIX | H35: 75 | I35: PARC. 4/10
E36: 1776 | F36: DANIELE SILVA | G36: PIX | H36: 30 | I36: PARC. 1/3
Q40: Total de OS | R40: =SUM(R6:R21) -> 3

Sheet 09
B1: ='08'!B1+1 -> 45269
B2: Fechamento Diário do Caixa
B4: Saldo Inicial | C4: 0 | E4: Vendas | K4: Despesas
B5: Vendas | C5: =SUMIF(I6:I31,">0",H6:H31) -> 1159.99 | E5: Nº Venda | F5: Cliente | G5: Forma de Pgto | H5: Valor Venda | I5: Entrada | K5: Descrição | L5: Tipo de Pagto | M5: Valor
B6: Entrada | C6: =SUM(I6:I41) -> 759.99 | E6: 1843 | F6: LEONARDO DE SOUZA | G6: PCTC | H6: 400 | I6: 100 | R6: =IF(vend9[[#This Row],[Nº Venda]]>1,1,0) -> 1
B7: Despesas | C7: =SUM(M6:M11) -> 0 | E7: 1844 | F7: LEONARDO DE SOUZA | G7: PCTC | H7: 300 | I7: 100 | R7: =IF(vend9[[#This Row],[Nº Venda]]>1,1,0) -> 1
B8: Total entrada | C8: =SUM(C6:C7) -> 759.99 | E8: 1845 | F8: LEONARDO DE SOUZA | G8: PCTC | H8: 300 | I8: 100 | R8: =IF(vend9[[#This Row],[Nº Venda]]>1,1,0) -> 1
E9: 1842 | F9: TATYANE BARBOSA SANTOS | G9: PCTC | H9: 159.99 | I9: 159.99 | R9: =IF(vend9[[#This Row],[Nº Venda]]>1,1,0) -> 1
B10: Tipos de Pagtos | R10: =IF(vend9[[#This Row],[Nº Venda]]>1,1,0) -> 0
B11: DN | C11: =(SUMIF($G$2:$G$31,B11,$I$2:$I$31))+(SUMIF($G$35:$G$41,B11,$H$35:$H$41)) -> 0 | O11: =IF(C16=0,0,1) -> 1 | R11: =IF(vend9[[#This Row],[Nº Venda]]>1,1,0) -> 0
B12: CTD | C12: =(SUMIF($G$2:$G$31,B12,$I$2:$I$31))+(SUMIF($G$35:$G$41,B12,$H$35:$H$41)) -> 558.39 | R12: =IF(vend9[[#This Row],[Nº Venda]]>1,1,0) -> 0
B13: CTC | C13: =(SUMIF($G$2:$G$31,B13,$I$2:$I$31))+(SUMIF($G$35:$G$41,B13,$H$35:$H$41)) -> 0 | K13: OS Entregue no Dia | R13: =IF(vend9[[#This Row],[Nº Venda]]>1,1,0) -> 0
B14: PCTC | C14: =(SUMIF($G$2:$G$31,B14,$I$2:$I$31))+(SUMIF($G$35:$G$41,B14,$H$35:$H$41)) -> 459.99 | K14: OS | L14: Vendedor | M14: CARNE | R14: =IF(vend9[[#This Row],[Nº Venda]]>1,1,0) -> 0
B15: PIX | C15: =(SUMIF($G$2:$G$31,B15,$I$2:$I$31))+(SUMIF($G$35:$G$41,B15,$H$35:$H$41)) -> 0 | K15: 1816 | L15: WEVILLY | M15: Não | R15: =IF(vend9[[#This Row],[Nº Venda]]>1,1,0) -> 0
B16: Total | C16: =SUM(C11:C15) -> 1018.38 | K16: 1807 | L16: WEVILLY | M16: Não | R16: =IF(vend9[[#This Row],[Nº Venda]]>1,1,0) -> 0
R17: =IF(vend9[[#This Row],[Nº Venda]]>1,1,0) -> 0
B18: Entrega de Carne | R18: =IF(vend9[[#This Row],[Nº Venda]]>1,1,0) -> 0
B19: =COUNT(entr_carn9[OS]) -> 0 | C19: =SUM(entr_carn9[Valor Total]) -> 0 | R19: =IF(vend9[[#This Row],[Nº Venda]]>1,1,0) -> 0
B20: Total | C20: =SUM(C19:C19) -> 0 | R20: =IF(vend9[[#This Row],[Nº Venda]]>1,1,0) -> 0
B22: Venda | C22: =C5 -> 1159.99
E24: Restante Entrada
E25: Nº Venda | F25: Cliente | G25: Forma de Pgto | H25: Valor Venda | I25: Entrada
E26: 1807 | F26: PAULA ALVES | G26: CTD | I26: 300
E33: Recebimento de Carnê | K33: Entrega de Carne
E34: OS | F34: Cliente | G34: Forma de Pgto | H34: Valor Parcela | I34: Nº Parcela | K34: OS | L34: Parcelas | M34: Valor Total
E35: 1724 | F35: AURINO FILHO | G35: CTD | H35: 83.39 | I35: PARC. 2/6
E36: 1754 | F36: IVONE SIMPLICIO | G36: CTD | H36: 175 | I36: PARC. 2/2
Q40: Total de OS | R40: =SUM(R6:R21) -> 4

Sheet 10
B1: ='09'!B1+1 -> 45270
B2: Fechamento Diário do Caixa
B4: Saldo Inicial | C4: 0 | E4: Vendas | K4: Despesas
B5: Vendas | C5: =SUMIF(I6:I31,">0",H6:H31) -> 0 | E5: Nº Venda | F5: Cliente | G5: Forma de Pgto | H5: Valor Venda | I5: Entrada | K5: Descrição | L5: Tipo de Pagto | M5: Valor
B6: Entrada | C6: =SUM(I6:I41) -> 0 | R6: =IF(vend10[[#This Row],[Nº Venda]]>1,1,0) -> 0
B7: Despesas | C7: =SUM(M6:M11) -> 0 | R7: =IF(vend10[[#This Row],[Nº Venda]]>1,1,0) -> 0
B8: Total entrada | C8: =SUM(C6:C7) -> 0 | R8: =IF(vend10[[#This Row],[Nº Venda]]>1,1,0) -> 0
R9: =IF(vend10[[#This Row],[Nº Venda]]>1,1,0) -> 0
B10: Tipos de Pagtos | R10: =IF(vend10[[#This Row],[Nº Venda]]>1,1,0) -> 0
B11: DN | C11: =(SUMIF($G$2:$G$31,B11,$I$2:$I$31))+(SUMIF($G$35:$G$41,B11,$H$35:$H$41)) -> 0 | O11: =IF(C16=0,0,1) -> 0 | R11: =IF(vend10[[#This Row],[Nº Venda]]>1,1,0) -> 0
B12: CTD | C12: =(SUMIF($G$2:$G$31,B12,$I$2:$I$31))+(SUMIF($G$35:$G$41,B12,$H$35:$H$41)) -> 0 | R12: =IF(vend10[[#This Row],[Nº Venda]]>1,1,0) -> 0
B13: CTC | C13: =(SUMIF($G$2:$G$31,B13,$I$2:$I$31))+(SUMIF($G$35:$G$41,B13,$H$35:$H$41)) -> 0 | K13: OS Entregue no Dia | R13: =IF(vend10[[#This Row],[Nº Venda]]>1,1,0) -> 0
B14: PCTC | C14: =(SUMIF($G$2:$G$31,B14,$I$2:$I$31))+(SUMIF($G$35:$G$41,B14,$H$35:$H$41)) -> 0 | K14: OS | L14: Vendedor | M14: CARNE | R14: =IF(vend10[[#This Row],[Nº Venda]]>1,1,0) -> 0
B15: PIX | C15: =(SUMIF($G$2:$G$31,B15,$I$2:$I$31))+(SUMIF($G$35:$G$41,B15,$H$35:$H$41)) -> 0 | R15: =IF(vend10[[#This Row],[Nº Venda]]>1,1,0) -> 0
B16: Total | C16: =SUM(C11:C15) -> 0 | R16: =IF(vend10[[#This Row],[Nº Venda]]>1,1,0) -> 0
R17: =IF(vend10[[#This Row],[Nº Venda]]>1,1,0) -> 0
B18: Entrega de Carne | R18: =IF(vend10[[#This Row],[Nº Venda]]>1,1,0) -> 0
B19: =COUNT(entr_carn10[OS]) -> 0 | C19: =SUM(entr_carn10[Valor Total]) -> 0 | R19: =IF(vend10[[#This Row],[Nº Venda]]>1,1,0) -> 0
B20: Total | C20: =SUM(C19:C19) -> 0 | R20: =IF(vend10[[#This Row],[Nº Venda]]>1,1,0) -> 0
B22: Venda | C22: =C5 -> 0
E24: Restante Entrada
E25: Nº Venda | F25: Cliente | G25: Forma de Pgto | H25: Valor Venda | I25: Entrada
E33: Recebimento de Carnê | K33: Entrega de Carne
E34: OS | F34: Cliente | G34: Forma de Pgto | H34: Valor Parcela | I34: Nº Parcela | K34: OS | L34: Parcelas | M34: Valor Total
Q40: Total de OS | R40: =SUM(R6:R21) -> 0

Sheet 11
B1: ='10'!B1+1 -> 45271
B2: Fechamento Diário do Caixa
B4: Saldo Inicial | C4: 0 | E4: Vendas | K4: Despesas
B5: Vendas | C5: =SUMIF(I6:I31,">0",H6:H31) -> 1399.99 | E5: Nº Venda | F5: Cliente | G5: Forma de Pgto | H5: Valor Venda | I5: Entrada | K5: Descrição | L5: Tipo de Pagto | M5: Valor
B6: Entrada | C6: =SUM(I6:I41) -> 2329.99 | E6: 1846 | F6: JAILSON BRAGA | G6: PCTC | H6: 1399.99 | I6: 1399.99 | R6: =IF(vend11[[#This Row],[Nº Venda]]>1,1,0) -> 1
B7: Despesas | C7: =SUM(M6:M11) -> 0 | R7: =IF(vend11[[#This Row],[Nº Venda]]>1,1,0) -> 0
B8: Total entrada | C8: =SUM(C6:C7) -> 2329.99 | R8: =IF(vend11[[#This Row],[Nº Venda]]>1,1,0) -> 0
R9: =IF(vend11[[#This Row],[Nº Venda]]>1,1,0) -> 0
B10: Tipos de Pagtos | R10: =IF(vend11[[#This Row],[Nº Venda]]>1,1,0) -> 0
B11: DN | C11: =(SUMIF($G$2:$G$31,B11,$I$2:$I$31))+(SUMIF($G$35:$G$41,B11,$H$35:$H$41)) -> 450 | O11: =IF(C16=0,0,1) -> 1 | R11: =IF(vend11[[#This Row],[Nº Venda]]>1,1,0) -> 0
B12: CTD | C12: =(SUMIF($G$2:$G$31,B12,$I$2:$I$31))+(SUMIF($G$35:$G$41,B12,$H$35:$H$41)) -> 30 | R12: =IF(vend11[[#This Row],[Nº Venda]]>1,1,0) -> 0
B13: CTC | C13: =(SUMIF($G$2:$G$31,B13,$I$2:$I$31))+(SUMIF($G$35:$G$41,B13,$H$35:$H$41)) -> 0 | K13: OS Entregue no Dia | R13: =IF(vend11[[#This Row],[Nº Venda]]>1,1,0) -> 0
B14: PCTC | C14: =(SUMIF($G$2:$G$31,B14,$I$2:$I$31))+(SUMIF($G$35:$G$41,B14,$H$35:$H$41)) -> 1849.99 | K14: OS | L14: Vendedor | M14: CARNE | R14: =IF(vend11[[#This Row],[Nº Venda]]>1,1,0) -> 0
B15: PIX | C15: =(SUMIF($G$2:$G$31,B15,$I$2:$I$31))+(SUMIF($G$35:$G$41,B15,$H$35:$H$41)) -> 265 | R15: =IF(vend11[[#This Row],[Nº Venda]]>1,1,0) -> 0
B16: Total | C16: =SUM(C11:C15) -> 2594.99 | R16: =IF(vend11[[#This Row],[Nº Venda]]>1,1,0) -> 0
R17: =IF(vend11[[#This Row],[Nº Venda]]>1,1,0) -> 0
B18: Entrega de Carne | R18: =IF(vend11[[#This Row],[Nº Venda]]>1,1,0) -> 0
B19: =COUNT(entr_carn11[OS]) -> 0 | C19: =SUM(entr_carn11[Valor Total]) -> 0 | R19: =IF(vend11[[#This Row],[Nº Venda]]>1,1,0) -> 0
B20: Total | C20: =SUM(C19:C19) -> 0 | R20: =IF(vend11[[#This Row],[Nº Venda]]>1,1,0) -> 0
B22: Venda | C22: =C5 -> 1399.99
E24: Restante Entrada
E25: Nº Venda | F25: Cliente | G25: Forma de Pgto | H25: Valor Venda | I25: Entrada
E26: 1831 | F26: DIEGO ANDRADE | G26: PCTC | I26: 150
E27: 1831 | F27: DIEGO ANDRADE | G27: PCTC | I27: 300
E28: 1808 | F28: DAMIANA MARIA | G28: DN | I28: 450
E29: 1832 | F29: MARI NEIDE | G29: CTD | I29: 30
E33: Recebimento de Carnê | K33: Entrega de Carne
E34: OS | F34: Cliente | G34: Forma de Pgto | H34: Valor Parcela | I34: Nº Parcela | K34: OS | L34: Parcelas | M34: Valor Total
E35: 1467 | F35: JESSICA CRISTINA | G35: PIX | H35: 75 | I35: PARC. 5/5
E36: 1704 | F36: ROSILENE REGINA | G36: PIX | H36: 105 | I36: PARC. 2/10
E37: 1704 | F37: ROSILENE REGINA | G37: PIX | H37: 85 | I37: PARC. 3/10
Q40: Total de OS | R40: =SUM(R6:R21) -> 1

Sheet 12
B1: ='11'!B1+1 -> 45272
B2: Fechamento Diário do Caixa
B4: Saldo Inicial | C4: 0 | E4: Vendas | K4: Despesas
B5: Vendas | C5: =SUMIF(I6:I31,">0",H6:H31) -> 1440 | E5: Nº Venda | F5: Cliente | G5: Forma de Pgto | H5: Valor Venda | I5: Entrada | K5: Descrição | L5: Tipo de Pagto | M5: Valor
B6: Entrada | C6: =SUM(I6:I41) -> 1020 | E6: 1747 | F6: RICARDO RIBEIRO | G6: SS | H6: 150 | I6: 0 | R6: =IF(vend12[[#This Row],[Nº Venda]]>1,1,0) -> 1
B7: Despesas | C7: =SUM(M6:M11) -> 0 | E7: 1748 | F7: RAFAEL DANIEL | G7: DN | H7: 240 | I7: 215 | R7: =IF(vend12[[#This Row],[Nº Venda]]>1,1,0) -> 1
B8: Total entrada | C8: =SUM(C6:C7) -> 1020 | E8: 1848 | F8: RAFAEL DANIEL | G8: CTD | H8: 0 | I8: 25 | R8: =IF(vend12[[#This Row],[Nº Venda]]>1,1,0) -> 1
E9: 1849 | F9: ELAINE DIAS | G9: PCTC | H9: 320 | I9: 320 | R9: =IF(vend12[[#This Row],[Nº Venda]]>1,1,0) -> 1
B10: Tipos de Pagtos | E10: 1850 | F10: RAIMUNDA MARIA | G10: SS | H10: GARANTIA | I10: 0 | R10: =IF(vend12[[#This Row],[Nº Venda]]>1,1,0) -> 1
B11: DN | C11: =(SUMIF($G$2:$G$31,B11,$I$2:$I$31))+(SUMIF($G$35:$G$41,B11,$H$35:$H$41)) -> 235 | E11: 1851 | F11: MARIA ELISA | G11: DN | H11: 880 | I11: 20 | O11: =IF(C16=0,0,1) -> 1 | R11: =IF(vend12[[#This Row],[Nº Venda]]>1,1,0) -> 1
B12: CTD | C12: =(SUMIF($G$2:$G$31,B12,$I$2:$I$31))+(SUMIF($G$35:$G$41,B12,$H$35:$H$41)) -> 465 | R12: =IF(vend12[[#This Row],[Nº Venda]]>1,1,0) -> 0
B13: CTC | C13: =(SUMIF($G$2:$G$31,B13,$I$2:$I$31))+(SUMIF($G$35:$G$41,B13,$H$35:$H$41)) -> 59.8 | K13: OS Entregue no Dia | R13: =IF(vend12[[#This Row],[Nº Venda]]>1,1,0) -> 0
B14: PCTC | C14: =(SUMIF($G$2:$G$31,B14,$I$2:$I$31))+(SUMIF($G$35:$G$41,B14,$H$35:$H$41)) -> 320 | K14: OS | L14: Vendedor | M14: CARNE | R14: =IF(vend12[[#This Row],[Nº Venda]]>1,1,0) -> 0
B15: PIX | C15: =(SUMIF($G$2:$G$31,B15,$I$2:$I$31))+(SUMIF($G$35:$G$41,B15,$H$35:$H$41)) -> 0 | K15: 1717 | L15: WEVILLY | M15: Não | R15: =IF(vend12[[#This Row],[Nº Venda]]>1,1,0) -> 0
B16: Total | C16: =SUM(C11:C15) -> 1079.8 | K16: 1819 | L16: WEVILLY | M16: Não | R16: =IF(vend12[[#This Row],[Nº Venda]]>1,1,0) -> 0
K17: 1813 | L17: WEVILLY | M17: Sim | R17: =IF(vend12[[#This Row],[Nº Venda]]>1,1,0) -> 0
B18: Entrega de Carne | K18: 1815 | L18: MARIA | M18: Não | R18: =IF(vend12[[#This Row],[Nº Venda]]>1,1,0) -> 0
B19: =COUNT(entr_carn12[OS]) -> 1 | C19: =SUM(entr_carn12[Valor Total]) -> 590 | R19: =IF(vend12[[#This Row],[Nº Venda]]>1,1,0) -> 0
B20: Total | C20: =SUM(C19:C19) -> 590 | R20: =IF(vend12[[#This Row],[Nº Venda]]>1,1,0) -> 0
B22: Venda | C22: =C5 -> 1440
E24: Restante Entrada
E25: Nº Venda | F25: Cliente | G25: Forma de Pgto | H25: Valor Venda | I25: Entrada
E26: 1815 | F26: ALONSO PEDRO | G26: CTD | I26: 440
E33: Recebimento de Carnê | K33: Entrega de Carne
E34: OS | F34: Cliente | G34: Forma de Pgto | H34: Valor Parcela | I34: Nº Parcela | K34: OS | L34: Parcelas | M34: Valor Total
E35: 1633 | F35: EIDELI PEREIRA | G35: CTC | H35: 29.9 | I35: PARC. 2/8 | K35: 1813 | L35: 6 | M35: 590
E36: 1633 | F36: EIDELI PEREIRA | G36: CTC | H36: 29.9 | I36: PARC. 3/8
Q40: Total de OS | R40: =SUM(R6:R21) -> 6

Sheet 13
B1: ='12'!B1+1 -> 45273
B2: Fechamento Diário do Caixa
B4: Saldo Inicial | C4: 0 | E4: Vendas | K4: Despesas
B5: Vendas | C5: =SUMIF(I6:I31,">0",H6:H31) -> 0 | E5: Nº Venda | F5: Cliente | G5: Forma de Pgto | H5: Valor Venda | I5: Entrada | K5: Descrição | L5: Tipo de Pagto | M5: Valor
B6: Entrada | C6: =SUM(I6:I41) -> 0 | R6: =IF(vend13[[#This Row],[Nº Venda]]>1,1,0) -> 0
B7: Despesas | C7: =SUM(M6:M11) -> 0 | R7: =IF(vend13[[#This Row],[Nº Venda]]>1,1,0) -> 0
B8: Total entrada | C8: =SUM(C6:C7) -> 0 | R8: =IF(vend13[[#This Row],[Nº Venda]]>1,1,0) -> 0
R9: =IF(vend13[[#This Row],[Nº Venda]]>1,1,0) -> 0
B10: Tipos de Pagtos | R10: =IF(vend13[[#This Row],[Nº Venda]]>1,1,0) -> 0
B11: DN | C11: =(SUMIF($G$2:$G$31,B11,$I$2:$I$31))+(SUMIF($G$35:$G$41,B11,$H$35:$H$41)) -> 0 | O11: =IF(C16=0,0,1) -> 0 | R11: =IF(vend13[[#This Row],[Nº Venda]]>1,1,0) -> 0
B12: CTD | C12: =(SUMIF($G$2:$G$31,B12,$I$2:$I$31))+(SUMIF($G$35:$G$41,B12,$H$35:$H$41)) -> 0 | R12: =IF(vend13[[#This Row],[Nº Venda]]>1,1,0) -> 0
B13: CTC | C13: =(SUMIF($G$2:$G$31,B13,$I$2:$I$31))+(SUMIF($G$35:$G$41,B13,$H$35:$H$41)) -> 0 | K13: OS Entregue no Dia | R13: =IF(vend13[[#This Row],[Nº Venda]]>1,1,0) -> 0
B14: PCTC | C14: =(SUMIF($G$2:$G$31,B14,$I$2:$I$31))+(SUMIF($G$35:$G$41,B14,$H$35:$H$41)) -> 0 | K14: OS | L14: Vendedor | M14: CARNE | R14: =IF(vend13[[#This Row],[Nº Venda]]>1,1,0) -> 0
B15: PIX | C15: =(SUMIF($G$2:$G$31,B15,$I$2:$I$31))+(SUMIF($G$35:$G$41,B15,$H$35:$H$41)) -> 0 | R15: =IF(vend13[[#This Row],[Nº Venda]]>1,1,0) -> 0
B16: Total | C16: =SUM(C11:C15) -> 0 | R16: =IF(vend13[[#This Row],[Nº Venda]]>1,1,0) -> 0
R17: =IF(vend13[[#This Row],[Nº Venda]]>1,1,0) -> 0
B18: Entrega de Carne | R18: =IF(vend13[[#This Row],[Nº Venda]]>1,1,0) -> 0
B19: =COUNT(entr_carn13[OS]) -> 0 | C19: =SUM(entr_carn13[Valor Total]) -> 0 | R19: =IF(vend13[[#This Row],[Nº Venda]]>1,1,0) -> 0
B20: Total | C20: =SUM(C19:C19) -> 0 | R20: =IF(vend13[[#This Row],[Nº Venda]]>1,1,0) -> 0
B22: Venda | C22: =C5 -> 0
E24: Restante Entrada
E25: Nº Venda | F25: Cliente | G25: Forma de Pgto | H25: Valor Venda | I25: Entrada
E33: Recebimento de Carnê | K33: Entrega de Carne
E34: OS | F34: Cliente | G34: Forma de Pgto | H34: Valor Parcela | I34: Nº Parcela | K34: OS | L34: Parcelas | M34: Valor Total
B35: 3
Q40: Total de OS | R40: =SUM(R6:R21) -> 0

Sheet 14
B1: ='13'!B1+1 -> 45274
B2: Fechamento Diário do Caixa
B4: Saldo Inicial | C4: 0 | E4: Vendas | K4: Despesas
B5: Vendas | C5: =SUMIF(I6:I31,">0",H6:H31) -> 0 | E5: Nº Venda | F5: Cliente | G5: Forma de Pgto | H5: Valor Venda | I5: Entrada | K5: Descrição | L5: Tipo de Pagto | M5: Valor
B6: Entrada | C6: =SUM(I6:I41) -> 0 | R6: =IF(vend14[[#This Row],[Nº Venda]]>1,1,0) -> 0
B7: Despesas | C7: =SUM(M6:M11) -> 0 | R7: =IF(vend14[[#This Row],[Nº Venda]]>1,1,0) -> 0
B8: Total entrada | C8: =SUM(C6:C7) -> 0 | R8: =IF(vend14[[#This Row],[Nº Venda]]>1,1,0) -> 0
R9: =IF(vend14[[#This Row],[Nº Venda]]>1,1,0) -> 0
B10: Tipos de Pagtos | R10: =IF(vend14[[#This Row],[Nº Venda]]>1,1,0) -> 0
B11: DN | C11: =(SUMIF($G$2:$G$31,B11,$I$2:$I$31))+(SUMIF($G$35:$G$41,B11,$H$35:$H$41)) -> 0 | O11: =IF(C16=0,0,1) -> 0 | R11: =IF(vend14[[#This Row],[Nº Venda]]>1,1,0) -> 0
B12: CTD | C12: =(SUMIF($G$2:$G$31,B12,$I$2:$I$31))+(SUMIF($G$35:$G$41,B12,$H$35:$H$41)) -> 0 | R12: =IF(vend14[[#This Row],[Nº Venda]]>1,1,0) -> 0
B13: CTC | C13: =(SUMIF($G$2:$G$31,B13,$I$2:$I$31))+(SUMIF($G$35:$G$41,B13,$H$35:$H$41)) -> 0 | K13: OS Entregue no Dia | R13: =IF(vend14[[#This Row],[Nº Venda]]>1,1,0) -> 0
B14: PCTC | C14: =(SUMIF($G$2:$G$31,B14,$I$2:$I$31))+(SUMIF($G$35:$G$41,B14,$H$35:$H$41)) -> 0 | K14: OS | L14: Vendedor | M14: CARNE | R14: =IF(vend14[[#This Row],[Nº Venda]]>1,1,0) -> 0
B15: PIX | C15: =(SUMIF($G$2:$G$31,B15,$I$2:$I$31))+(SUMIF($G$35:$G$41,B15,$H$35:$H$41)) -> 0 | R15: =IF(vend14[[#This Row],[Nº Venda]]>1,1,0) -> 0
B16: Total | C16: =SUM(C11:C15) -> 0 | R16: =IF(vend14[[#This Row],[Nº Venda]]>1,1,0) -> 0
R17: =IF(vend14[[#This Row],[Nº Venda]]>1,1,0) -> 0
B18: Entrega de Carne | R18: =IF(vend14[[#This Row],[Nº Venda]]>1,1,0) -> 0
B19: =COUNT(entr_carn14[OS]) -> 0 | C19: =SUM(entr_carn14[Valor Total]) -> 0 | R19: =IF(vend14[[#This Row],[Nº Venda]]>1,1,0) -> 0
B20: Total | C20: =SUM(C19:C19) -> 0 | R20: =IF(vend14[[#This Row],[Nº Venda]]>1,1,0) -> 0
B22: Venda | C22: =C5 -> 0
E24: Restante Entrada
E25: Nº Venda | F25: Cliente | G25: Forma de Pgto | H25: Valor Venda | I25: Entrada
E33: Recebimento de Carnê | K33: Entrega de Carne
E34: OS | F34: Cliente | G34: Forma de Pgto | H34: Valor Parcela | I34: Nº Parcela | K34: OS | L34: Parcelas | M34: Valor Total
Q40: Total de OS | R40: =SUM(R6:R21) -> 0

Sheet 15
B1: ='14'!B1+1 -> 45275
B2: Fechamento Diário do Caixa
B4: Saldo Inicial | C4: 0 | E4: Vendas | K4: Despesas
B5: Vendas | C5: =SUMIF(I6:I31,">0",H6:H31) -> 1998.99 | E5: Nº Venda | F5: Cliente | G5: Forma de Pgto | H5: Valor Venda | I5: Entrada | K5: Descrição | L5: Tipo de Pagto | M5: Valor
B6: Entrada | C6: =SUM(I6:I41) -> 1538.99 | E6: 1852 | F6: ALEX SANDER CARVALHO | G6: PIX | H6: 899 | I6: 899 | R6: =IF(vend15[[#This Row],[Nº Venda]]>1,1,0) -> 1
B7: Despesas | C7: =SUM(M6:M11) -> 0 | E7: 1854 | F7: ALINE DA SILVA | G7: CTD | H7: 199.99 | I7: 199.99 | R7: =IF(vend15[[#This Row],[Nº Venda]]>1,1,0) -> 1
B8: Total entrada | C8: =SUM(C6:C7) -> 1538.99 | E8: 1853 | F8: AMISADAI DA SILVA | G8: CTD | H8: 200 | I8: 200 | R8: =IF(vend15[[#This Row],[Nº Venda]]>1,1,0) -> 1
E9: 1854 | F9: DENISE PALMEIRA | G9: CTD | H9: 700 | I9: 40 | R9: =IF(vend15[[#This Row],[Nº Venda]]>1,1,0) -> 1
B10: Tipos de Pagtos | R10: =IF(vend15[[#This Row],[Nº Venda]]>1,1,0) -> 0
B11: DN | C11: =(SUMIF($G$2:$G$31,B11,$I$2:$I$31))+(SUMIF($G$35:$G$41,B11,$H$35:$H$41)) -> 0 | O11: =IF(C16=0,0,1) -> 1 | R11: =IF(vend15[[#This Row],[Nº Venda]]>1,1,0) -> 0
B12: CTD | C12: =(SUMIF($G$2:$G$31,B12,$I$2:$I$31))+(SUMIF($G$35:$G$41,B12,$H$35:$H$41)) -> 639.99 | R12: =IF(vend15[[#This Row],[Nº Venda]]>1,1,0) -> 0
B13: CTC | C13: =(SUMIF($G$2:$G$31,B13,$I$2:$I$31))+(SUMIF($G$35:$G$41,B13,$H$35:$H$41)) -> 0 | K13: OS Entregue no Dia | R13: =IF(vend15[[#This Row],[Nº Venda]]>1,1,0) -> 0
B14: PCTC | C14: =(SUMIF($G$2:$G$31,B14,$I$2:$I$31))+(SUMIF($G$35:$G$41,B14,$H$35:$H$41)) -> 0 | K14: OS | L14: Vendedor | M14: CARNE | R14: =IF(vend15[[#This Row],[Nº Venda]]>1,1,0) -> 0
B15: PIX | C15: =(SUMIF($G$2:$G$31,B15,$I$2:$I$31))+(SUMIF($G$35:$G$41,B15,$H$35:$H$41)) -> 899 | R15: =IF(vend15[[#This Row],[Nº Venda]]>1,1,0) -> 0
B16: Total | C16: =SUM(C11:C15) -> 1538.99 | R16: =IF(vend15[[#This Row],[Nº Venda]]>1,1,0) -> 0
R17: =IF(vend15[[#This Row],[Nº Venda]]>1,1,0) -> 0
B18: Entrega de Carne | R18: =IF(vend15[[#This Row],[Nº Venda]]>1,1,0) -> 0
B19: =COUNT(entr_carn15[OS]) -> 0 | C19: =SUM(entr_carn15[Valor Total]) -> 0 | R19: =IF(vend15[[#This Row],[Nº Venda]]>1,1,0) -> 0
B20: Total | C20: =SUM(C19:C19) -> 0 | R20: =IF(vend15[[#This Row],[Nº Venda]]>1,1,0) -> 0
B22: Venda | C22: =C5 -> 1998.99
E24: Restante Entrada
E25: Nº Venda | F25: Cliente | G25: Forma de Pgto | H25: Valor Venda | I25: Entrada
E26: 1830 | F26: CLAUDICEIA SOARES | G26: CTD | I26: 200
E33: Recebimento de Carnê | K33: Entrega de Carne
E34: OS | F34: Cliente | G34: Forma de Pgto | H34: Valor Parcela | I34: Nº Parcela | K34: OS | L34: Parcelas | M34: Valor Total
Q40: Total de OS | R40: =SUM(R6:R21) -> 4

Sheet 16
B1: ='15'!B1+1 -> 45276
B2: Fechamento Diário do Caixa
B4: Saldo Inicial | C4: 0 | E4: Vendas | K4: Despesas
B5: Vendas | C5: =SUMIF(I6:I31,">0",H6:H31) -> 3109.99 | E5: Nº Venda | F5: Cliente | G5: Forma de Pgto | H5: Valor Venda | I5: Entrada | K5: Descrição | L5: Tipo de Pagto | M5: Valor
B6: Entrada | C6: =SUM(I6:I41) -> 1461.49 | E6: 1856 | F6: NELSON BONATO | G6: PCTC | H6: 324.99 | I6: 224.99 | R6: =IF(vend16[[#This Row],[Nº Venda]]>1,1,0) -> 1
B7: Despesas | C7: =SUM(M6:M11) -> 0 | E7: 1856 | F7: NELSON BONATO | G7: DN | H7: 0 | I7: 100 | R7: =IF(vend16[[#This Row],[Nº Venda]]>1,1,0) -> 1
B8: Total entrada | C8: =SUM(C6:C7) -> 1461.49 | E8: 1857 | F8: SANDRA APARECIDA S | G8: CTD | H8: 700 | I8: 100 | R8: =IF(vend16[[#This Row],[Nº Venda]]>1,1,0) -> 1
E9: 1858 | F9: DESUITA APARECIDA | G9: PIX | H9: 690 | I9: 500 | R9: =IF(vend16[[#This Row],[Nº Venda]]>1,1,0) -> 1
B10: Tipos de Pagtos | E10: 1858 | F10: DESUITA APARECIDA | G10: PCTC | H10: 0 | I10: 190 | R10: =IF(vend16[[#This Row],[Nº Venda]]>1,1,0) -> 1
B11: DN | C11: =(SUMIF($G$2:$G$31,B11,$I$2:$I$31))+(SUMIF($G$35:$G$41,B11,$H$35:$H$41)) -> 101.5 | E11: 1859 | F11: NELSON BONATO | G11: PCTC | H11: 325 | I11: 325 | O11: =IF(C16=0,0,1) -> 1 | R11: =IF(vend16[[#This Row],[Nº Venda]]>1,1,0) -> 1
B12: CTD | C12: =(SUMIF($G$2:$G$31,B12,$I$2:$I$31))+(SUMIF($G$35:$G$41,B12,$H$35:$H$41)) -> 120 | E12: 1860 | F12: EVALDO CESAR | G12: SS | H12: GARANTIA | I12: 0 | R12: =IF(vend16[[#This Row],[Nº Venda]]>1,1,0) -> 1
B13: CTC | C13: =(SUMIF($G$2:$G$31,B13,$I$2:$I$31))+(SUMIF($G$35:$G$41,B13,$H$35:$H$41)) -> 0 | E13: 1861 | F13: ANTONIO BENEDITO | G13: DN | H13: 325 | I13: 1 | K13: OS Entregue no Dia | R13: =IF(vend16[[#This Row],[Nº Venda]]>1,1,0) -> 1
B14: PCTC | C14: =(SUMIF($G$2:$G$31,B14,$I$2:$I$31))+(SUMIF($G$35:$G$41,B14,$H$35:$H$41)) -> 739.99 | E14: 1862 | F14: JOHNNY ARAUJO PERES | G14: DN | H14: 325 | I14: 0.5 | K14: OS | L14: Vendedor | M14: CARNE | R14: =IF(vend16[[#This Row],[Nº Venda]]>1,1,0) -> 1
B15: PIX | C15: =(SUMIF($G$2:$G$31,B15,$I$2:$I$31))+(SUMIF($G$35:$G$41,B15,$H$35:$H$41)) -> 500 | E15: 1863 | F15: ANTONIO OZORIO | G15: CTD | H15: 420 | I15: 20 | R15: =IF(vend16[[#This Row],[Nº Venda]]>1,1,0) -> 1
B16: Total | C16: =SUM(C11:C15) -> 1461.49 | R16: =IF(vend16[[#This Row],[Nº Venda]]>1,1,0) -> 0
R17: =IF(vend16[[#This Row],[Nº Venda]]>1,1,0) -> 0
B18: Entrega de Carne | R18: =IF(vend16[[#This Row],[Nº Venda]]>1,1,0) -> 0
B19: =COUNT(entr_carn16[OS]) -> 0 | C19: =SUM(entr_carn16[Valor Total]) -> 0 | R19: =IF(vend16[[#This Row],[Nº Venda]]>1,1,0) -> 0
B20: Total | C20: =SUM(C19:C19) -> 0 | R20: =IF(vend16[[#This Row],[Nº Venda]]>1,1,0) -> 0
B22: Venda | C22: =C5 -> 3109.99
E24: Restante Entrada
E25: Nº Venda | F25: Cliente | G25: Forma de Pgto | H25: Valor Venda | I25: Entrada
E33: Recebimento de Carnê | K33: Entrega de Carne
E34: OS | F34: Cliente | G34: Forma de Pgto | H34: Valor Parcela | I34: Nº Parcela | K34: OS | L34: Parcelas | M34: Valor Total
Q40: Total de OS | R40: =SUM(R6:R21) -> 10

Sheet 17
B1: ='16'!B1+1 -> 45277
B2: Fechamento Diário do Caixa
B4: Saldo Inicial | C4: 0 | E4: Vendas | K4: Despesas
B5: Vendas | C5: =SUMIF(I6:I31,">0",H6:H31) -> 0 | E5: Nº Venda | F5: Cliente | G5: Forma de Pgto | H5: Valor Venda | I5: Entrada | K5: Descrição | L5: Tipo de Pagto | M5: Valor
B6: Entrada | C6: =SUM(I6:I41) -> 0 | R6: =IF(vend17[[#This Row],[Nº Venda]]>1,1,0) -> 0
B7: Despesas | C7: =SUM(M6:M11) -> 0 | R7: =IF(vend17[[#This Row],[Nº Venda]]>1,1,0) -> 0
B8: Total entrada | C8: =SUM(C6:C7) -> 0 | R8: =IF(vend17[[#This Row],[Nº Venda]]>1,1,0) -> 0
R9: =IF(vend17[[#This Row],[Nº Venda]]>1,1,0) -> 0
B10: Tipos de Pagtos | R10: =IF(vend17[[#This Row],[Nº Venda]]>1,1,0) -> 0
B11: DN | C11: =(SUMIF($G$2:$G$31,B11,$I$2:$I$31))+(SUMIF($G$35:$G$41,B11,$H$35:$H$41)) -> 0 | O11: =IF(C16=0,0,1) -> 0 | R11: =IF(vend17[[#This Row],[Nº Venda]]>1,1,0) -> 0
B12: CTD | C12: =(SUMIF($G$2:$G$31,B12,$I$2:$I$31))+(SUMIF($G$35:$G$41,B12,$H$35:$H$41)) -> 0 | R12: =IF(vend17[[#This Row],[Nº Venda]]>1,1,0) -> 0
B13: CTC | C13: =(SUMIF($G$2:$G$31,B13,$I$2:$I$31))+(SUMIF($G$35:$G$41,B13,$H$35:$H$41)) -> 0 | K13: OS Entregue no Dia | R13: =IF(vend17[[#This Row],[Nº Venda]]>1,1,0) -> 0
B14: PCTC | C14: =(SUMIF($G$2:$G$31,B14,$I$2:$I$31))+(SUMIF($G$35:$G$41,B14,$H$35:$H$41)) -> 0 | K14: OS | L14: Vendedor | M14: CARNE | R14: =IF(vend17[[#This Row],[Nº Venda]]>1,1,0) -> 0
B15: PIX | C15: =(SUMIF($G$2:$G$31,B15,$I$2:$I$31))+(SUMIF($G$35:$G$41,B15,$H$35:$H$41)) -> 0 | R15: =IF(vend17[[#This Row],[Nº Venda]]>1,1,0) -> 0
B16: Total | C16: =SUM(C11:C15) -> 0 | R16: =IF(vend17[[#This Row],[Nº Venda]]>1,1,0) -> 0
R17: =IF(vend17[[#This Row],[Nº Venda]]>1,1,0) -> 0
B18: Entrega de Carne | R18: =IF(vend17[[#This Row],[Nº Venda]]>1,1,0) -> 0
B19: =COUNT(entr_carn17[OS]) -> 0 | C19: =SUM(entr_carn17[Valor Total]) -> 0 | R19: =IF(vend17[[#This Row],[Nº Venda]]>1,1,0) -> 0
B20: Total | C20: =SUM(C19:C19) -> 0 | R20: =IF(vend17[[#This Row],[Nº Venda]]>1,1,0) -> 0
B22: Venda | C22: =C5 -> 0
E24: Restante Entrada
E25: Nº Venda | F25: Cliente | G25: Forma de Pgto | H25: Valor Venda | I25: Entrada
E33: Recebimento de Carnê | K33: Entrega de Carne
E34: OS | F34: Cliente | G34: Forma de Pgto | H34: Valor Parcela | I34: Nº Parcela | K34: OS | L34: Parcelas | M34: Valor Total
Q40: Total de OS | R40: =SUM(R6:R21) -> 0

Sheet 18
B1: ='17'!B1+1 -> 45278
B2: Fechamento Diário do Caixa
B4: Saldo Inicial | C4: 0 | E4: Vendas | K4: Despesas
B5: Vendas | C5: =SUMIF(I6:I31,">0",H6:H31) -> 0 | E5: Nº Venda | F5: Cliente | G5: Forma de Pgto | H5: Valor Venda | I5: Entrada | K5: Descrição | L5: Tipo de Pagto | M5: Valor
B6: Entrada | C6: =SUM(I6:I41) -> 0 | R6: =IF(vend18[[#This Row],[Nº Venda]]>1,1,0) -> 0
B7: Despesas | C7: =SUM(M6:M11) -> 0 | R7: =IF(vend18[[#This Row],[Nº Venda]]>1,1,0) -> 0
B8: Total entrada | C8: =SUM(C6:C7) -> 0 | R8: =IF(vend18[[#This Row],[Nº Venda]]>1,1,0) -> 0
R9: =IF(vend18[[#This Row],[Nº Venda]]>1,1,0) -> 0
B10: Tipos de Pagtos | R10: =IF(vend18[[#This Row],[Nº Venda]]>1,1,0) -> 0
B11: DN | C11: =(SUMIF($G$2:$G$31,B11,$I$2:$I$31))+(SUMIF($G$35:$G$41,B11,$H$35:$H$41)) -> 0 | O11: =IF(C16=0,0,1) -> 0 | R11: =IF(vend18[[#This Row],[Nº Venda]]>1,1,0) -> 0
B12: CTD | C12: =(SUMIF($G$2:$G$31,B12,$I$2:$I$31))+(SUMIF($G$35:$G$41,B12,$H$35:$H$41)) -> 0 | R12: =IF(vend18[[#This Row],[Nº Venda]]>1,1,0) -> 0
B13: CTC | C13: =(SUMIF($G$2:$G$31,B13,$I$2:$I$31))+(SUMIF($G$35:$G$41,B13,$H$35:$H$41)) -> 0 | K13: OS Entregue no Dia | R13: =IF(vend18[[#This Row],[Nº Venda]]>1,1,0) -> 0
B14: PCTC | C14: =(SUMIF($G$2:$G$31,B14,$I$2:$I$31))+(SUMIF($G$35:$G$41,B14,$H$35:$H$41)) -> 0 | K14: OS | L14: Vendedor | M14: CARNE | R14: =IF(vend18[[#This Row],[Nº Venda]]>1,1,0) -> 0
B15: PIX | C15: =(SUMIF($G$2:$G$31,B15,$I$2:$I$31))+(SUMIF($G$35:$G$41,B15,$H$35:$H$41)) -> 0 | R15: =IF(vend18[[#This Row],[Nº Venda]]>1,1,0) -> 0
B16: Total | C16: =SUM(C11:C15) -> 0 | R16: =IF(vend18[[#This Row],[Nº Venda]]>1,1,0) -> 0
R17: =IF(vend18[[#This Row],[Nº Venda]]>1,1,0) -> 0
B18: Entrega de Carne | R18: =IF(vend18[[#This Row],[Nº Venda]]>1,1,0) -> 0
B19: =COUNT(entr_carn18[OS]) -> 0 | C19: =SUM(entr_carn18[Valor Total]) -> 0 | R19: =IF(vend18[[#This Row],[Nº Venda]]>1,1,0) -> 0
B20: Total | C20: =SUM(C19:C19) -> 0 | R20: =IF(vend18[[#This Row],[Nº Venda]]>1,1,0) -> 0
B22: Venda | C22: =C5 -> 0
E24: Restante Entrada
E25: Nº Venda | F25: Cliente | G25: Forma de Pgto | H25: Valor Venda | I25: Entrada
E33: Recebimento de Carnê | K33: Entrega de Carne
E34: OS | F34: Cliente | G34: Forma de Pgto | H34: Valor Parcela | I34: Nº Parcela | K34: OS | L34: Parcelas | M34: Valor Total
Q40: Total de OS | R40: =SUM(R6:R21) -> 0

Sheet 19
B1: ='18'!B1+1 -> 45279
B2: Fechamento Diário do Caixa
B4: Saldo Inicial | C4: 0 | E4: Vendas | K4: Despesas
B5: Vendas | C5: =SUMIF(I6:I31,">0",H6:H31) -> 0 | E5: Nº Venda | F5: Cliente | G5: Forma de Pgto | H5: Valor Venda | I5: Entrada | K5: Descrição | L5: Tipo de Pagto | M5: Valor
B6: Entrada | C6: =SUM(I6:I41) -> 0 | R6: =IF(vend19[[#This Row],[Nº Venda]]>1,1,0) -> 0
B7: Despesas | C7: =SUM(M6:M11) -> 0 | R7: =IF(vend19[[#This Row],[Nº Venda]]>1,1,0) -> 0
B8: Total entrada | C8: =SUM(C6:C7) -> 0 | R8: =IF(vend19[[#This Row],[Nº Venda]]>1,1,0) -> 0
R9: =IF(vend19[[#This Row],[Nº Venda]]>1,1,0) -> 0
B10: Tipos de Pagtos | R10: =IF(vend19[[#This Row],[Nº Venda]]>1,1,0) -> 0
B11: DN | C11: =(SUMIF($G$2:$G$31,B11,$I$2:$I$31))+(SUMIF($G$35:$G$41,B11,$H$35:$H$41)) -> 0 | O11: =IF(C16=0,0,1) -> 1 | R11: =IF(vend19[[#This Row],[Nº Venda]]>1,1,0) -> 0
B12: CTD | C12: =(SUMIF($G$2:$G$31,B12,$I$2:$I$31))+(SUMIF($G$35:$G$41,B12,$H$35:$H$41)) -> 0 | R12: =IF(vend19[[#This Row],[Nº Venda]]>1,1,0) -> 0
B13: CTC | C13: =(SUMIF($G$2:$G$31,B13,$I$2:$I$31))+(SUMIF($G$35:$G$41,B13,$H$35:$H$41)) -> 0 | K13: OS Entregue no Dia | R13: =IF(vend19[[#This Row],[Nº Venda]]>1,1,0) -> 0
B14: PCTC | C14: =(SUMIF($G$2:$G$31,B14,$I$2:$I$31))+(SUMIF($G$35:$G$41,B14,$H$35:$H$41)) -> 0 | K14: OS | L14: Vendedor | M14: CARNE | R14: =IF(vend19[[#This Row],[Nº Venda]]>1,1,0) -> 0
B15: PIX | C15: =(SUMIF($G$2:$G$31,B15,$I$2:$I$31))+(SUMIF($G$35:$G$41,B15,$H$35:$H$41)) -> 60 | R15: =IF(vend19[[#This Row],[Nº Venda]]>1,1,0) -> 0
B16: Total | C16: =SUM(C11:C15) -> 60 | R16: =IF(vend19[[#This Row],[Nº Venda]]>1,1,0) -> 0
R17: =IF(vend19[[#This Row],[Nº Venda]]>1,1,0) -> 0
B18: Entrega de Carne | R18: =IF(vend19[[#This Row],[Nº Venda]]>1,1,0) -> 0
B19: =COUNT(entr_carn19[OS]) -> 0 | C19: =SUM(entr_carn19[Valor Total]) -> 0 | R19: =IF(vend19[[#This Row],[Nº Venda]]>1,1,0) -> 0
B20: Total | C20: =SUM(C19:C19) -> 0 | R20: =IF(vend19[[#This Row],[Nº Venda]]>1,1,0) -> 0
B22: Venda | C22: =C5 -> 0
E24: Restante Entrada
E25: Nº Venda | F25: Cliente | G25: Forma de Pgto | H25: Valor Venda | I25: Entrada
E33: Recebimento de Carnê | K33: Entrega de Carne
E34: OS | F34: Cliente | G34: Forma de Pgto | H34: Valor Parcela | I34: Nº Parcela | K34: OS | L34: Parcelas | M34: Valor Total
E35: 1791 | F35: SARAH V | G35: PIX | H35: 60 | I35: PARC. 1/3
Q40: Total de OS | R40: =SUM(R6:R21) -> 0

Sheet 20
B1: ='19'!B1+1 -> 45280
B2: Fechamento Diário do Caixa
B4: Saldo Inicial | C4: 0 | E4: Vendas | K4: Despesas
B5: Vendas | C5: =SUMIF(I6:I31,">0",H6:H31) -> 150 | E5: Nº Venda | F5: Cliente | G5: Forma de Pgto | H5: Valor Venda | I5: Entrada | K5: Descrição | L5: Tipo de Pagto | M5: Valor
B6: Entrada | C6: =SUM(I6:I41) -> 150 | R6: =IF(vend20[[#This Row],[Nº Venda]]>1,1,0) -> 0
B7: Despesas | C7: =SUM(M6:M11) -> 0 | R7: =IF(vend20[[#This Row],[Nº Venda]]>1,1,0) -> 0
B8: Total entrada | C8: =SUM(C6:C7) -> 150 | R8: =IF(vend20[[#This Row],[Nº Venda]]>1,1,0) -> 0
R9: =IF(vend20[[#This Row],[Nº Venda]]>1,1,0) -> 0
B10: Tipos de Pagtos | R10: =IF(vend20[[#This Row],[Nº Venda]]>1,1,0) -> 0
B11: DN | C11: =(SUMIF($G$2:$G$31,B11,$I$2:$I$31))+(SUMIF($G$35:$G$41,B11,$H$35:$H$41)) -> 0 | O11: =IF(C16=0,0,1) -> 1 | R11: =IF(vend20[[#This Row],[Nº Venda]]>1,1,0) -> 0
B12: CTD | C12: =(SUMIF($G$2:$G$31,B12,$I$2:$I$31))+(SUMIF($G$35:$G$41,B12,$H$35:$H$41)) -> 250 | R12: =IF(vend20[[#This Row],[Nº Venda]]>1,1,0) -> 0
B13: CTC | C13: =(SUMIF($G$2:$G$31,B13,$I$2:$I$31))+(SUMIF($G$35:$G$41,B13,$H$35:$H$41)) -> 0 | K13: OS Entregue no Dia | R13: =IF(vend20[[#This Row],[Nº Venda]]>1,1,0) -> 0
B14: PCTC | C14: =(SUMIF($G$2:$G$31,B14,$I$2:$I$31))+(SUMIF($G$35:$G$41,B14,$H$35:$H$41)) -> 150 | K14: OS | L14: Vendedor | M14: CARNE | R14: =IF(vend20[[#This Row],[Nº Venda]]>1,1,0) -> 0
B15: PIX | C15: =(SUMIF($G$2:$G$31,B15,$I$2:$I$31))+(SUMIF($G$35:$G$41,B15,$H$35:$H$41)) -> 0 | K15: 1836 | L15: WEVILLY | M15: Não | R15: =IF(vend20[[#This Row],[Nº Venda]]>1,1,0) -> 0
B16: Total | C16: =SUM(C11:C15) -> 400 | L16: 1 | R16: =IF(vend20[[#This Row],[Nº Venda]]>1,1,0) -> 0
R17: =IF(vend20[[#This Row],[Nº Venda]]>1,1,0) -> 0
B18: Entrega de Carne | R18: =IF(vend20[[#This Row],[Nº Venda]]>1,1,0) -> 0
B19: =COUNT(entr_carn20[OS]) -> 0 | C19: =SUM(entr_carn20[Valor Total]) -> 0 | R19: =IF(vend20[[#This Row],[Nº Venda]]>1,1,0) -> 0
B20: Total | C20: =SUM(C19:C19) -> 0 | R20: =IF(vend20[[#This Row],[Nº Venda]]>1,1,0) -> 0
B22: Venda | C22: =C5 -> 150
E24: Restante Entrada
E25: Nº Venda | F25: Cliente | G25: Forma de Pgto | H25: Valor Venda | I25: Entrada
E26: 1847 | F26: RICARDO RIBEIRO | G26: PCTC | H26: 150 | I26: 150
E33: Recebimento de Carnê | K33: Entrega de Carne
E34: OS | F34: Cliente | G34: Forma de Pgto | H34: Valor Parcela | I34: Nº Parcela | K34: OS | L34: Parcelas | M34: Valor Total
E35: 1754 | F35: MARCOS A | G35: CTD | H35: 250 | I35: PARC. 1/2
Q40: Total de OS | R40: =SUM(R6:R21) -> 0

Sheet 21
B1: ='20'!B1+1 -> 45281
B2: Fechamento Diário do Caixa
B4: Saldo Inicial | C4: 0 | E4: Vendas | K4: Despesas
B5: Vendas | C5: =SUMIF(I6:I31,">0",H6:H31) -> 561 | E5: Nº Venda | F5: Cliente | G5: Forma de Pgto | H5: Valor Venda | I5: Entrada | K5: Descrição | L5: Tipo de Pagto | M5: Valor
B6: Entrada | C6: =SUM(I6:I41) -> 1221 | E6: 1866 | F6: SUELY DE ALMEIDA | G6: PCTC | H6: 381 | I6: 381 | R6: =IF(vend21[[#This Row],[Nº Venda]]>1,1,0) -> 1
B7: Despesas | C7: =SUM(M6:M11) -> 0 | E7: 1865 | F7: RONIE VON | G7: CTD | H7: 180 | I7: 180 | R7: =IF(vend21[[#This Row],[Nº Venda]]>1,1,0) -> 1
B8: Total entrada | C8: =SUM(C6:C7) -> 1221 | E8: 1864 | F8: IVONE SIMPLICIO | G8: SS | H8: GARANTIA | I8: 0 | R8: =IF(vend21[[#This Row],[Nº Venda]]>1,1,0) -> 1
R9: =IF(vend21[[#This Row],[Nº Venda]]>1,1,0) -> 0
B10: Tipos de Pagtos | R10: =IF(vend21[[#This Row],[Nº Venda]]>1,1,0) -> 0
B11: DN | C11: =(SUMIF($G$2:$G$31,B11,$I$2:$I$31))+(SUMIF($G$35:$G$41,B11,$H$35:$H$41)) -> 0 | O11: =IF(C16=0,0,1) -> 1 | R11: =IF(vend21[[#This Row],[Nº Venda]]>1,1,0) -> 0
B12: CTD | C12: =(SUMIF($G$2:$G$31,B12,$I$2:$I$31))+(SUMIF($G$35:$G$41,B12,$H$35:$H$41)) -> 180 | R12: =IF(vend21[[#This Row],[Nº Venda]]>1,1,0) -> 0
B13: CTC | C13: =(SUMIF($G$2:$G$31,B13,$I$2:$I$31))+(SUMIF($G$35:$G$41,B13,$H$35:$H$41)) -> 0 | K13: OS Entregue no Dia | R13: =IF(vend21[[#This Row],[Nº Venda]]>1,1,0) -> 0
B14: PCTC | C14: =(SUMIF($G$2:$G$31,B14,$I$2:$I$31))+(SUMIF($G$35:$G$41,B14,$H$35:$H$41)) -> 1041 | K14: OS | L14: Vendedor | M14: CARNE | R14: =IF(vend21[[#This Row],[Nº Venda]]>1,1,0) -> 0
B15: PIX | C15: =(SUMIF($G$2:$G$31,B15,$I$2:$I$31))+(SUMIF($G$35:$G$41,B15,$H$35:$H$41)) -> 0 | K15: 1847 | L15: WEVILLY | M15: Não | R15: =IF(vend21[[#This Row],[Nº Venda]]>1,1,0) -> 0
B16: Total | C16: =SUM(C11:C15) -> 1221 | R16: =IF(vend21[[#This Row],[Nº Venda]]>1,1,0) -> 0
R17: =IF(vend21[[#This Row],[Nº Venda]]>1,1,0) -> 0
B18: Entrega de Carne | R18: =IF(vend21[[#This Row],[Nº Venda]]>1,1,0) -> 0
B19: =COUNT(entr_carn21[OS]) -> 0 | C19: =SUM(entr_carn21[Valor Total]) -> 0 | R19: =IF(vend21[[#This Row],[Nº Venda]]>1,1,0) -> 0
B20: Total | C20: =SUM(C19:C19) -> 0 | R20: =IF(vend21[[#This Row],[Nº Venda]]>1,1,0) -> 0
B22: Venda | C22: =C5 -> 561
E24: Restante Entrada
E25: Nº Venda | F25: Cliente | G25: Forma de Pgto | H25: Valor Venda | I25: Entrada
E26: 1855 | F26: LENISE PALMEIRA | G26: PCTC | I26: 660
E33: Recebimento de Carnê | K33: Entrega de Carne
E34: OS | F34: Cliente | G34: Forma de Pgto | H34: Valor Parcela | I34: Nº Parcela | K34: OS | L34: Parcelas | M34: Valor Total
Q40: Total de OS | R40: =SUM(R6:R21) -> 3

Sheet 23
B1: ='22'!B1+1 -> 45283
B2: Fechamento Diário do Caixa
B4: Saldo Inicial | C4: 0 | E4: Vendas | K4: Despesas
B5: Vendas | C5: =SUMIF(I6:I31,">0",H6:H31) -> 0 | E5: Nº Venda | F5: Cliente | G5: Forma de Pgto | H5: Valor Venda | I5: Entrada | K5: Descrição | L5: Tipo de Pagto | M5: Valor
B6: Entrada | C6: =SUM(I6:I41) -> 1800 | R6: =IF(vend23[[#This Row],[Nº Venda]]>1,1,0) -> 0
B7: Despesas | C7: =SUM(M6:M11) -> 0 | R7: =IF(vend23[[#This Row],[Nº Venda]]>1,1,0) -> 0
B8: Total entrada | C8: =SUM(C6:C7) -> 1800 | R8: =IF(vend23[[#This Row],[Nº Venda]]>1,1,0) -> 0
R9: =IF(vend23[[#This Row],[Nº Venda]]>1,1,0) -> 0
B10: Tipos de Pagtos | R10: =IF(vend23[[#This Row],[Nº Venda]]>1,1,0) -> 0
B11: DN | C11: =(SUMIF($G$2:$G$31,B11,$I$2:$I$31))+(SUMIF($G$35:$G$41,B11,$H$35:$H$41)) -> 0 | O11: =IF(C16=0,0,1) -> 1 | R11: =IF(vend23[[#This Row],[Nº Venda]]>1,1,0) -> 0
B12: CTD | C12: =(SUMIF($G$2:$G$31,B12,$I$2:$I$31))+(SUMIF($G$35:$G$41,B12,$H$35:$H$41)) -> 300 | R12: =IF(vend23[[#This Row],[Nº Venda]]>1,1,0) -> 0
B13: CTC | C13: =(SUMIF($G$2:$G$31,B13,$I$2:$I$31))+(SUMIF($G$35:$G$41,B13,$H$35:$H$41)) -> 0 | K13: OS Entregue no Dia | R13: =IF(vend23[[#This Row],[Nº Venda]]>1,1,0) -> 0
B14: PCTC | C14: =(SUMIF($G$2:$G$31,B14,$I$2:$I$31))+(SUMIF($G$35:$G$41,B14,$H$35:$H$41)) -> 1500 | K14: OS | L14: Vendedor | M14: CARNE | R14: =IF(vend23[[#This Row],[Nº Venda]]>1,1,0) -> 0
B15: PIX | C15: =(SUMIF($G$2:$G$31,B15,$I$2:$I$31))+(SUMIF($G$35:$G$41,B15,$H$35:$H$41)) -> 0 | R15: =IF(vend23[[#This Row],[Nº Venda]]>1,1,0) -> 0
B16: Total | C16: =SUM(C11:C15) -> 1800 | R16: =IF(vend23[[#This Row],[Nº Venda]]>1,1,0) -> 0
R17: =IF(vend23[[#This Row],[Nº Venda]]>1,1,0) -> 0
B18: Entrega de Carne | R18: =IF(vend23[[#This Row],[Nº Venda]]>1,1,0) -> 0
B19: =COUNT(entr_carn23[OS]) -> 0 | C19: =SUM(entr_carn23[Valor Total]) -> 0 | R19: =IF(vend23[[#This Row],[Nº Venda]]>1,1,0) -> 0
B20: Total | C20: =SUM(C19:C19) -> 0 | R20: =IF(vend23[[#This Row],[Nº Venda]]>1,1,0) -> 0
B22: Venda | C22: =C5 -> 0
E24: Restante Entrada
E25: Nº Venda | F25: Cliente | G25: Forma de Pgto | H25: Valor Venda | I25: Entrada
E26: 1841 | F26: MARIA NAZARÉ | G26: PCTC | I26: 421
E27: 1839 | F27: MARIA APARECIDA | G27: PCTC | I27: 759
E28: 1840 | F28: MARIA NAZARÉ | G28: PCTC | I28: 320
E29: 1838 | F29: DAIANE MARTINS | G29: CTD | I29: 300
E33: Recebimento de Carnê | K33: Entrega de Carne
E34: OS | F34: Cliente | G34: Forma de Pgto | H34: Valor Parcela | I34: Nº Parcela | K34: OS | L34: Parcelas | M34: Valor Total
Q40: Total de OS | R40: =SUM(R6:R21) -> 0

Sheet 22
B1: ='21'!B1+1 -> 45282
B2: Fechamento Diário do Caixa
B4: Saldo Inicial | C4: 0 | E4: Vendas | K4: Despesas
B5: Vendas | C5: =SUMIF(I6:I31,">0",H6:H31) -> 0 | E5: Nº Venda | F5: Cliente | G5: Forma de Pgto | H5: Valor Venda | I5: Entrada | K5: Descrição | L5: Tipo de Pagto | M5: Valor
B6: Entrada | C6: =SUM(I6:I41) -> 0 | R6: =IF(vend22[[#This Row],[Nº Venda]]>1,1,0) -> 0
