Workbook

Sheet resumo_cx
P1: Colaboradores
A2: Saldo Inicial | B2: 0 | P2: ROGÉRIO
A3: Vendas | B3: =SUM('01'!C5,'02'!C5,'03'!C5,'04'!C5,'05'!C5,'06'!C5,'07'!C5,'08'!C5,'09'!C5,'10'!C5,'11'!C5,'12'!C5,'13'!C5,'14'!C5,'15'!C5,'16'!C5,'17'!C5,'18'!C5,'19'!C5,'20'!C5,'21'!C5,'22'!C5,'23'!C5,'24'!C5,'25'!C5,'26'!C5,'27'!C5,'28'!C5,'29'!C5,'30'!C5,'31'!C5) -> 86581.98 | P3: JOCY
A4: Entrada | B4: =SUM('01'!C6,'02'!C6,'03'!C6,'04'!C6,'05'!C6,'06'!C6,'07'!C6,'08'!C6,'09'!C6,'10'!C6,'11'!C6,'12'!C6,'13'!C6,'14'!C6,'15'!C6,'16'!C6,'17'!C6,'18'!C6,'19'!C6,'20'!C6,'21'!C6,'22'!C6,'23'!C6,'24'!C6,'25'!C6,'26'!C6,'27'!C6,'28'!C6,'29'!C6,'30'!C6,'31'!C6) -> 76493.5 | P4: MARIA
A5: Despesas | B5: =SUM('01'!C7,'02'!C7,'03'!C7,'04'!C7,'05'!C7,'06'!C7,'07'!C7,'08'!C7,'09'!C7,'10'!C7,'11'!C7,'12'!C7,'13'!C7,'14'!C7,'15'!C7,'16'!C7,'17'!C7,'18'!C7,'19'!C7,'20'!C7,'21'!C7,'22'!C7,'23'!C7,'24'!C7,'25'!C7,'26'!C7,'27'!C7,'28'!C7,'29'!C7,'30'!C7,'31'!C7) -> 1691.3 | P5: WEVILLY
A6: Entr_Desp | B6: =SUM(B4:B5) -> 78184.8 | P6: BETH
P7: ARIANI
A8: Tipos de Pagtos | P8: ROSÂNGELA
A9: DN | B9: =SUM('01'!C11,'02'!C11,'03'!C11,'04'!C11,'05'!C11,'06'!C11,'07'!C11,'08'!C11,'09'!C11,'10'!C11,'11'!C11,'12'!C11,'13'!C11,'14'!C11,'15'!C11,'16'!C11,'17'!C11,'18'!C11,'19'!C11,'20'!C11,'21'!C11,'22'!C11,'23'!C11,'24'!C11,'25'!C11,'26'!C11,'27'!C11,'28'!C11,'29'!C11,'30'!C11,'31'!C11) -> 7908.07 | P9: TATY
A10: CTD | B10: =SUM('01'!C12,'02'!C12,'03'!C12,'04'!C12,'05'!C12,'06'!C12,'07'!C12,'08'!C12,'09'!C12,'10'!C12,'11'!C12,'12'!C12,'13'!C12,'14'!C12,'15'!C12,'16'!C12,'17'!C12,'18'!C12,'19'!C12,'20'!C12,'21'!C12,'22'!C12,'23'!C12,'24'!C12,'25'!C12,'26'!C12,'27'!C12,'28'!C12,'29'!C12,'30'!C12,'31'!C12) -> 10272.75 | P10: LARISSA
A11: CTC | B11: =SUM('01'!C13,'02'!C13,'03'!C13,'04'!C13,'05'!C13,'06'!C13,'07'!C13,'08'!C13,'09'!C13,'10'!C13,'11'!C13,'12'!C13,'13'!C13,'14'!C13,'15'!C13,'16'!C13,'17'!C13,'18'!C13,'19'!C13,'20'!C13,'21'!C13,'22'!C13,'23'!C13,'24'!C13,'25'!C13,'26'!C13,'27'!C13,'28'!C13,'29'!C13,'30'!C13,'31'!C13) -> 39866.99 | P11: ERIKA
A12: PCTC | B12: =SUM('01'!C14,'02'!C14,'03'!C14,'04'!C14,'05'!C14,'06'!C14,'07'!C14,'08'!C14,'09'!C14,'10'!C14,'11'!C14,'12'!C14,'13'!C14,'14'!C14,'15'!C14,'16'!C14,'17'!C14,'18'!C14,'19'!C14,'20'!C14,'21'!C14,'22'!C14,'23'!C14,'24'!C14,'25'!C14,'26'!C14,'27'!C14,'28'!C14,'29'!C14,'30'!C14,'31'!C14) -> 0 | P12: LUANA
A13: PIX | B13: =SUM('01'!C15,'02'!C15,'03'!C15,'04'!C15,'05'!C15,'06'!C15,'07'!C15,'08'!C15,'09'!C15,'10'!C15,'11'!C15,'12'!C15,'13'!C15,'14'!C15,'15'!C15,'16'!C15,'17'!C15,'18'!C15,'19'!C15,'20'!C15,'21'!C15,'22'!C15,'23'!C15,'24'!C15,'25'!C15,'26'!C15,'27'!C15,'28'!C15,'29'!C15,'30'!C15,'31'!C15) -> 27231.33 | P13: FELIPE
A14: Total | B14: =SUM(B9:B13) -> 85279.14
A16: Entrega de Carne
A17: =COUNT(#REF!) -> 0 | B17: =SUM('01'!C19,'02'!C19,'03'!C19,'04'!C19,'05'!C19,'06'!C19,'07'!C19,'08'!C19,'09'!C19,'10'!C19,'11'!C19,'12'!C19,'13'!C19,'14'!C19,'15'!C19,'16'!C19,'17'!C19,'18'!C19,'19'!C19,'20'!C19,'21'!C19,'22'!C19,'23'!C19,'24'!C19,'25'!C19,'26'!C19,'27'!C19,'28'!C19,'29'!C19,'30'!C19,'31'!C19) -> 11196.6
A18: Total | B18: =SUM(B17:B17) -> 11196.6

Sheet 01
B1: 45474
B2: Fechamento Diário do Caixa - Escritório
B4: Saldo Inicial | C4: 0 | E4: Vendas | K4: Despesas
B5: Vendas | C5: =SUMIF(I6:I31,">0",H6:H31) -> 1394 | E5: Nº Venda | F5: Cliente | G5: Forma de Pgto | H5: Valor Venda | I5: Entrada | K5: Descrição | L5: Tipo de Pagto | M5: Valor
B6: Entrada | C6: =SUM(I6:I41) -> 857 | E6: 9445 | F6: alvoro rodrigues | G6: CTC | H6: 400 | I6: 400 | R6: =IF(vend1[[#This Row],[Nº Venda]]>1,1,0) -> 1
B7: Despesas | C7: =SUM(M6:M11) -> 0 | E7: 9446 | F7: marina lucia | G7: DN | H7: 40 | I7: 40 | R7: =IF(vend1[[#This Row],[Nº Venda]]>1,1,0) -> 1
B8: Total entrada | C8: =SUM(C6:C7) -> 857 | E8: 9447 | F8: marinalva beserra | G8: DN | H8: 160 | I8: 2 | R8: =IF(vend1[[#This Row],[Nº Venda]]>1,1,0) -> 1
E9: 9448 | F9: ana maria | G9: DN | H9: 499 | I9: 120 | R9: =IF(vend1[[#This Row],[Nº Venda]]>1,1,0) -> 1
B10: Tipos de Pagtos | E10: 9449 | F10: lilian david | G10: CTC | H10: 45 | I10: 45 | R10: =IF(vend1[[#This Row],[Nº Venda]]>1,1,0) -> 1
B11: DN | C11: =(SUMIF($G$2:$G$31,B11,$I$2:$I$31))+(SUMIF($G$35:$G$41,B11,$H$35:$H$41)) -> 530.08 | E11: 9450 | F11: simone rodrigues | G11: PIX | H11: 250 | I11: 250 | O11: =IF(C16=0,0,1) -> 1 | R11: =IF(vend1[[#This Row],[Nº Venda]]>1,1,0) -> 1
B12: CTD | C12: =(SUMIF($G$2:$G$31,B12,$I$2:$I$31))+(SUMIF($G$35:$G$41,B12,$H$35:$H$41)) -> 70 | R12: =IF(vend1[[#This Row],[Nº Venda]]>1,1,0) -> 0
B13: CTC | C13: =(SUMIF($G$2:$G$31,B13,$I$2:$I$31))+(SUMIF($G$35:$G$41,B13,$H$35:$H$41)) -> 445 | K13: OS Entregue no Dia | R13: =IF(vend1[[#This Row],[Nº Venda]]>1,1,0) -> 0
B14: PCTC | C14: =(SUMIF($G$2:$G$31,B14,$I$2:$I$31))+(SUMIF($G$35:$G$41,B14,$H$35:$H$41)) -> 0 | K14: OS | L14: Vendedor | M14: CARNE | R14: =IF(vend1[[#This Row],[Nº Venda]]>1,1,0) -> 0
B15: PIX | C15: =(SUMIF($G$2:$G$31,B15,$I$2:$I$31))+(SUMIF($G$35:$G$41,B15,$H$35:$H$41)) -> 250 | K15: 9340 | L15: ARIANI | M15: Não | R15: =IF(vend1[[#This Row],[Nº Venda]]>1,1,0) -> 0
B16: Total | C16: =SUM(C11:C15) -> 1295.08 | K16: 9352 | L16: JOCY | M16: Não | R16: =IF(vend1[[#This Row],[Nº Venda]]>1,1,0) -> 0
K17: 9221 | L17: TATY | M17: Não | R17: =IF(vend1[[#This Row],[Nº Venda]]>1,1,0) -> 0
B18: Entrega de Carne | R18: =IF(vend1[[#This Row],[Nº Venda]]>1,1,0) -> 0
B19: =COUNT(entr_carn31195[OS]) -> 0 | C19: =SUM(entr_carn31195[Valor Total]) -> 0 | R19: =IF(vend1[[#This Row],[Nº Venda]]>1,1,0) -> 0
B20: Total | C20: =SUM(C19:C19) -> 0 | R20: =IF(vend1[[#This Row],[Nº Venda]]>1,1,0) -> 0
B22: Venda | C22: =C5 -> 1394
E24: Restante Entrada
E25: Nº Venda | F25: Cliente | G25: Forma de Pgto | H25: Valor Venda | I25: Entrada
E33: Recebimento de Carnê | K33: Entrega de Carne
E34: OS | F34: Cliente | G34: Forma de Pgto | H34: Valor Parcela | I34: Nº Parcela | K34: OS | L34: Parcelas | M34: Valor Total
E35: 8624 | F35: marinalva beserra | G35: DN | H35: 41.42 | I35: PARC. 5/7
E36: 8328 | F36: marinalva beserra | G36: DN | H36: 50 | I36: PARC. 6/8
E37: 9330 | F37: marinalva beserra | G37: DN | H37: 50 | I37: PARC. 1/6
E38: 8999 | F38: marinalva beserra | G38: DN | H38: 60 | I38: PARC. 3/7
E39: 9305 | F39: ailton barbosa | G39: CTD | H39: 70 | I39: PARC. 1/6
E40: 9308 | F40: jaqueline dos santos | G40: DN | H40: 166.66 | I40: PARC. 1/6 | Q40: Total de OS | R40: =SUM(R6:R21) -> 6

Sheet 02
B1: ='01'!B1+1 -> 45475
B2: Fechamento Diário do Caixa
B4: Saldo Inicial | C4: 0 | E4: Vendas | K4: Despesas
B5: Vendas | C5: =SUMIF(I6:I31,">0",H6:H31) -> 600 | E5: Nº Venda | F5: Cliente | G5: Forma de Pgto | H5: Valor Venda | I5: Entrada | K5: Descrição | L5: Tipo de Pagto | M5: Valor
B6: Entrada | C6: =SUM(I6:I41) -> 350 | E6: 9451 | F6: bruna dos santos | G6: DN | H6: 600 | I6: 50 | R6: =IF(vend2[[#This Row],[Nº Venda]]>1,1,0) -> 1
B7: Despesas | C7: =SUM(M6:M11) -> 0 | R7: =IF(vend2[[#This Row],[Nº Venda]]>1,1,0) -> 0
B8: Total entrada | C8: =SUM(C6:C7) -> 350 | R8: =IF(vend2[[#This Row],[Nº Venda]]>1,1,0) -> 0
R9: =IF(vend2[[#This Row],[Nº Venda]]>1,1,0) -> 0
B10: Tipos de Pagtos | R10: =IF(vend2[[#This Row],[Nº Venda]]>1,1,0) -> 0
B11: DN | C11: =(SUMIF($G$2:$G$31,B11,$I$2:$I$31))+(SUMIF($G$35:$G$41,B11,$H$35:$H$41)) -> 688.57 | O11: =IF(C16=0,0,1) -> 1 | R11: =IF(vend2[[#This Row],[Nº Venda]]>1,1,0) -> 0
B12: CTD | C12: =(SUMIF($G$2:$G$31,B12,$I$2:$I$31))+(SUMIF($G$35:$G$41,B12,$H$35:$H$41)) -> 0 | R12: =IF(vend2[[#This Row],[Nº Venda]]>1,1,0) -> 0
B13: CTC | C13: =(SUMIF($G$2:$G$31,B13,$I$2:$I$31))+(SUMIF($G$35:$G$41,B13,$H$35:$H$41)) -> 0 | K13: OS Entregue no Dia | R13: =IF(vend2[[#This Row],[Nº Venda]]>1,1,0) -> 0
B14: PCTC | C14: =(SUMIF($G$2:$G$31,B14,$I$2:$I$31))+(SUMIF($G$35:$G$41,B14,$H$35:$H$41)) -> 0 | K14: OS | L14: Vendedor | M14: CARNE | R14: =IF(vend2[[#This Row],[Nº Venda]]>1,1,0) -> 0
B15: PIX | C15: =(SUMIF($G$2:$G$31,B15,$I$2:$I$31))+(SUMIF($G$35:$G$41,B15,$H$35:$H$41)) -> 0 | K15: 9449 | L15: JOCY | M15: Não | R15: =IF(vend2[[#This Row],[Nº Venda]]>1,1,0) -> 0
B16: Total | C16: =SUM(C11:C15) -> 688.57 | K16: 9281 | L16: JOCY | M16: Não | R16: =IF(vend2[[#This Row],[Nº Venda]]>1,1,0) -> 0
K17: 9114 | L17: JOCY | M17: Não | R17: =IF(vend2[[#This Row],[Nº Venda]]>1,1,0) -> 0
B18: Entrega de Carne | K18: 9371 | L18: JOCY | M18: Não | R18: =IF(vend2[[#This Row],[Nº Venda]]>1,1,0) -> 0
B19: =COUNT(entr_carn2[OS]) -> 0 | C19: =SUM(entr_carn2[Valor Total]) -> 0 | K19: 9439 | L19: JOCY | M19: Não | R19: =IF(vend2[[#This Row],[Nº Venda]]>1,1,0) -> 0
B20: Total | C20: =SUM(C19:C19) -> 0 | K20: 9440 | L20: JOCY | M20: Não | R20: =IF(vend2[[#This Row],[Nº Venda]]>1,1,0) -> 0
B22: Venda | C22: =C5 -> 600
E24: Restante Entrada
E25: Nº Venda | F25: Cliente | G25: Forma de Pgto | H25: Valor Venda | I25: Entrada
E26: 9390 | F26: paulo do carmo | G26: DN | H26: 0 | I26: 300
E33: Recebimento de Carnê | K33: Entrega de Carne
E34: OS | F34: Cliente | G34: Forma de Pgto | H34: Valor Parcela | I34: Nº Parcela | K34: OS | L34: Parcelas | M34: Valor Total | U34: V
E35: 8703 | F35: minalda de fatima | G35: DN | H35: 110 | I35: PARC. 3/6
E36: 8703 | F36: minalda de fatima | G36: DN | H36: 110 | I36: PARC. 4/6
E37: 8214 | F37: lilian pereira | G37: DN | H37: 118.57 | I37: PARC. 8/8
Q40: Total de OS | R40: =SUM(R6:R21) -> 1

Sheet 03
B1: ='02'!B1+1 -> 45476
B2: Fechamento Diário do Caixa
B4: Saldo Inicial | C4: 0 | E4: Vendas | K4: Despesas
B5: Vendas | C5: =SUMIF(I6:I31,">0",H6:H31) -> 1350 | E5: Nº Venda | F5: Cliente | G5: Forma de Pgto | H5: Valor Venda | I5: Entrada | K5: Descrição | L5: Tipo de Pagto | M5: Valor
B6: Entrada | C6: =SUM(I6:I41) -> 2011 | E6: 9452 | F6: THAIS HELENA | G6: DN | H6: 600 | I6: 200 | R6: =IF(vend3[[#This Row],[Nº Venda]]>1,1,0) -> 1
B7: Despesas | C7: =SUM(M6:M11) -> 0 | E7: 9453 | F7: RITA DE CASSIA | G7: DN | H7: 400 | I7: 1 | R7: =IF(vend3[[#This Row],[Nº Venda]]>1,1,0) -> 1
B8: Total entrada | C8: =SUM(C6:C7) -> 2011 | E8: 9454 | F8: RITA DE CASSIA | G8: PIX | H8: 350 | I8: 20 | R8: =IF(vend3[[#This Row],[Nº Venda]]>1,1,0) -> 1
R9: =IF(vend3[[#This Row],[Nº Venda]]>1,1,0) -> 0
B10: Tipos de Pagtos | R10: =IF(vend3[[#This Row],[Nº Venda]]>1,1,0) -> 0
B11: DN | C11: =(SUMIF($G$2:$G$31,B11,$I$2:$I$31))+(SUMIF($G$35:$G$41,B11,$H$35:$H$41)) -> 419.75 | O11: =IF(C16=0,0,1) -> 1 | R11: =IF(vend3[[#This Row],[Nº Venda]]>1,1,0) -> 0
B12: CTD | C12: =(SUMIF($G$2:$G$31,B12,$I$2:$I$31))+(SUMIF($G$35:$G$41,B12,$H$35:$H$41)) -> 106.25 | R12: =IF(vend3[[#This Row],[Nº Venda]]>1,1,0) -> 0
B13: CTC | C13: =(SUMIF($G$2:$G$31,B13,$I$2:$I$31))+(SUMIF($G$35:$G$41,B13,$H$35:$H$41)) -> 0 | K13: OS Entregue no Dia | R13: =IF(vend3[[#This Row],[Nº Venda]]>1,1,0) -> 0
B14: PCTC | C14: =(SUMIF($G$2:$G$31,B14,$I$2:$I$31))+(SUMIF($G$35:$G$41,B14,$H$35:$H$41)) -> 0 | K14: OS | L14: Vendedor | M14: CARNE | R14: =IF(vend3[[#This Row],[Nº Venda]]>1,1,0) -> 0
B15: PIX | C15: =(SUMIF($G$2:$G$31,B15,$I$2:$I$31))+(SUMIF($G$35:$G$41,B15,$H$35:$H$41)) -> 2310 | K15: 9373 | L15: TATY | M15: Não | R15: =IF(vend3[[#This Row],[Nº Venda]]>1,1,0) -> 0
B16: Total | C16: =SUM(C11:C15) -> 2836 | K16: 9392 | L16: JOCY | M16: Não | R16: =IF(vend3[[#This Row],[Nº Venda]]>1,1,0) -> 0
K17: 9353 | L17: ROGÉRIO | M17: Não | R17: =IF(vend3[[#This Row],[Nº Venda]]>1,1,0) -> 0
B18: Entrega de Carne | K18: 9407 | L18: ARIANI | M18: Não | R18: =IF(vend3[[#This Row],[Nº Venda]]>1,1,0) -> 0
B19: =COUNT(entr_carn3[OS]) -> 0 | C19: =SUM(entr_carn3[Valor Total]) -> 0 | K19: 9406 | L19: ARIANI | M19: Não | R19: =IF(vend3[[#This Row],[Nº Venda]]>1,1,0) -> 0
B20: Total | C20: =SUM(C19:C19) -> 0 | K20: 9403 | L20: TATY | M20: Não | R20: =IF(vend3[[#This Row],[Nº Venda]]>1,1,0) -> 0
K21: 9405 | L21: TATY | M21: Não
B22: Venda | C22: =C5 -> 1350 | K22: 9446 | L22: ARIANI | M22: Não
K23: 9363 | L23: ARIANI | M23: Não
E24: Restante Entrada
E25: Nº Venda | F25: Cliente | G25: Forma de Pgto | H25: Valor Venda | I25: Entrada
E26: 9392 | F26: MARIA ALVES | G26: DN | H26: 0 | I26: 100
E27: 9357 | F27: UEIDE DE SOUZA | G27: PIX | H27: 0 | I27: 1690
E33: Recebimento de Carnê | K33: Entrega de Carne
E34: OS | F34: Cliente | G34: Forma de Pgto | H34: Valor Parcela | I34: Nº Parcela | K34: OS | L34: Parcelas | M34: Valor Total
E35: 8619 | F35: CARLOS APARECIDO | G35: CTD | H35: 106.25 | I35: PARC. 3/8
E36: 9118 | F36: LILIAN CRISTINA | G36: DN | H36: 118.75 | I36: PARC. 2/8
E37: 8754 | F37: SELMA DA SILVA | G37: PIX | H37: 237.5 | I37: PARC. 2/8
E38: 8754 | F38: SELMA DA SILVA | G38: PIX | H38: 237.5 | I38: PARC. 3/8
E39: 9068 | F39: FERNANDO JOAO | G39: PIX | H39: 125 | I39: PARC. 2/7
Q40: Total de OS | R40: =SUM(R6:R21) -> 3

Sheet 04
B1: ='03'!B1+1 -> 45477
B2: Fechamento Diário do Caixa
B4: Saldo Inicial | C4: 0 | E4: Vendas | K4: Despesas
B5: Vendas | C5: =SUMIF(I6:I31,">0",H6:H31) -> 669 | E5: Nº Venda | F5: Cliente | G5: Forma de Pgto | H5: Valor Venda | I5: Entrada | K5: Descrição | L5: Tipo de Pagto | M5: Valor
B6: Entrada | C6: =SUM(I6:I41) -> 1119 | E6: 9455 | F6: SILVANA REGANE | G6: DN | H6: 400 | I6: 80 | R6: =IF(vend4[[#This Row],[Nº Venda]]>1,1,0) -> 1
B7: Despesas | C7: =SUM(M6:M11) -> 0 | E7: 9456 | F7: CAROLINA SETTI | G7: PIX | H7: 39 | I7: 39 | R7: =IF(vend4[[#This Row],[Nº Venda]]>1,1,0) -> 1
B8: Total entrada | C8: =SUM(C6:C7) -> 1119 | E8: 9457 | F8: DIOGO FERREIRA | G8: SS | R8: =IF(vend4[[#This Row],[Nº Venda]]>1,1,0) -> 1
E9: 9458 | F9: ILDA SOPARES | G9: GARANTIA | R9: =IF(vend4[[#This Row],[Nº Venda]]>1,1,0) -> 1
B10: Tipos de Pagtos | E10: 9459 | F10: ILDA SOPARES | G10: GARANTIA | R10: =IF(vend4[[#This Row],[Nº Venda]]>1,1,0) -> 1
B11: DN | C11: =(SUMIF($G$2:$G$31,B11,$I$2:$I$31))+(SUMIF($G$35:$G$41,B11,$H$35:$H$41)) -> 180 | E11: 9460 | F11: JOSIMAR FERNANDO | G11: SS | O11: =IF(C16=0,0,1) -> 1 | R11: =IF(vend4[[#This Row],[Nº Venda]]>1,1,0) -> 1
B12: CTD | C12: =(SUMIF($G$2:$G$31,B12,$I$2:$I$31))+(SUMIF($G$35:$G$41,B12,$H$35:$H$41)) -> 700 | E12: 9461 | F12: JOSE DONIZETE | G12: CTD | H12: 230 | I12: 230 | R12: =IF(vend4[[#This Row],[Nº Venda]]>1,1,0) -> 1
B13: CTC | C13: =(SUMIF($G$2:$G$31,B13,$I$2:$I$31))+(SUMIF($G$35:$G$41,B13,$H$35:$H$41)) -> 0 | K13: OS Entregue no Dia | R13: =IF(vend4[[#This Row],[Nº Venda]]>1,1,0) -> 0
B14: PCTC | C14: =(SUMIF($G$2:$G$31,B14,$I$2:$I$31))+(SUMIF($G$35:$G$41,B14,$H$35:$H$41)) -> 0 | K14: OS | L14: Vendedor | M14: CARNE | R14: =IF(vend4[[#This Row],[Nº Venda]]>1,1,0) -> 0
B15: PIX | C15: =(SUMIF($G$2:$G$31,B15,$I$2:$I$31))+(SUMIF($G$35:$G$41,B15,$H$35:$H$41)) -> 239 | K15: 9375 | L15: JOCY | M15: Sim | R15: =IF(vend4[[#This Row],[Nº Venda]]>1,1,0) -> 0
B16: Total | C16: =SUM(C11:C15) -> 1119 | K16: 9372 | L16: JOCY | M16: Sim | R16: =IF(vend4[[#This Row],[Nº Venda]]>1,1,0) -> 0
K17: 9436 | L17: TATY | M17: Sim | R17: =IF(vend4[[#This Row],[Nº Venda]]>1,1,0) -> 0
B18: Entrega de Carne | K18: 9426 | L18: ARIANI | M18: Não | R18: =IF(vend4[[#This Row],[Nº Venda]]>1,1,0) -> 0
B19: =COUNT(entr_carn4[OS]) -> 5 | C19: =SUM(entr_carn4[Valor Total]) -> 3720 | K19: 9418 | L19: ARIANI | M19: Não | R19: =IF(vend4[[#This Row],[Nº Venda]]>1,1,0) -> 0
B20: Total | C20: =SUM(C19:C19) -> 3720 | K20: 9428 | L20: TATY | M20: Não | R20: =IF(vend4[[#This Row],[Nº Venda]]>1,1,0) -> 0
K21: 9374 | L21: TATY | M21: Sim
B22: Venda | C22: =C5 -> 669 | K22: 9456 | L22: JOCY | M22: Não
K23: 9370 | L23: TATY | M23: Sim
E24: Restante Entrada | K24: 9461 | L24: JOCY | M24: Não
E25: Nº Venda | F25: Cliente | G25: Forma de Pgto | H25: Valor Venda | I25: Entrada
E26: 9436 | F26: luiza jaqueline | G26: CTD | H26: 0 | I26: 200
E27: 9428 | F27: cicero francisco | G27: CTD | H27: 0 | I27: 170
E28: 9374 | F28: sara de quadros | G28: DN | H28: 0 | I28: 100
E29: 9018 | F29: ilda soares | G29: CTD | H29: 0 | I29: 100
E30: 9370 | F30: marisa de araujo | G30: PIX | H30: 0 | I30: 200
E33: Recebimento de Carnê | K33: Entrega de Carne
E34: OS | F34: Cliente | G34: Forma de Pgto | H34: Valor Parcela | I34: Nº Parcela | K34: OS | L34: Parcelas | M34: Valor Total
K35: 9375 | L35: 8 | M35: 881
K36: 9372 | L36: 1 | M36: 900
K37: 9436 | L37: 8 | M37: 999
K38: 9374 | L38: 6 | M38: 290
K39: 9370 | L39: 6 | M39: 650
Q40: Total de OS | R40: =SUM(R6:R21) -> 7

Sheet 05
B1: ='04'!B1+1 -> 45478
B2: Fechamento Diário do Caixa
B4: Saldo Inicial | C4: 0 | E4: Vendas | K4: Despesas
B5: Vendas | C5: =SUMIF(I6:I31,">0",H6:H31) -> 9299 | E5: Nº Venda | F5: Cliente | G5: Forma de Pgto | H5: Valor Venda | I5: Entrada | K5: Descrição | L5: Tipo de Pagto | M5: Valor
B6: Entrada | C6: =SUM(I6:I41) -> 9479 | E6: 9462 | F6: emidio francisco | G6: CTD | H6: 3150 | I6: 1575 | K6: pagamento debora | L6: dinheiro | M6: 1056.53 | R6: =IF(vend5[[#This Row],[Nº Venda]]>1,1,0) -> 1
B7: Despesas | C7: =SUM(M6:M11) -> 1549 | G7: CTC | H7: 0 | I7: 1575 | K7: pagamento joci | L7: dinheiro | M7: 492.47 | R7: =IF(vend5[[#This Row],[Nº Venda]]>1,1,0) -> 0
B8: Total entrada | C8: =SUM(C6:C7) -> 11028 | E8: 9463 | F8: emidio francisco | G8: CTC | H8: 150 | I8: 75 | R8: =IF(vend5[[#This Row],[Nº Venda]]>1,1,0) -> 1
G9: CTD | H9: 0 | I9: 75 | R9: =IF(vend5[[#This Row],[Nº Venda]]>1,1,0) -> 0
B10: Tipos de Pagtos | E10: 9464 | F10: rosa maria | G10: CTD | H10: 450 | I10: 225 | R10: =IF(vend5[[#This Row],[Nº Venda]]>1,1,0) -> 1
B11: DN | C11: =(SUMIF($G$2:$G$31,B11,$I$2:$I$31))+(SUMIF($G$35:$G$41,B11,$H$35:$H$41)) -> 1549 | G11: CTC | H11: 0 | I11: 225 | O11: =IF(C16=0,0,1) -> 1 | R11: =IF(vend5[[#This Row],[Nº Venda]]>1,1,0) -> 0
B12: CTD | C12: =(SUMIF($G$2:$G$31,B12,$I$2:$I$31))+(SUMIF($G$35:$G$41,B12,$H$35:$H$41)) -> 1875 | E12: 9465 | F12: gilvanison jacinto | G12: PIX | H12: 600 | I12: 30 | R12: =IF(vend5[[#This Row],[Nº Venda]]>1,1,0) -> 1
B13: CTC | C13: =(SUMIF($G$2:$G$31,B13,$I$2:$I$31))+(SUMIF($G$35:$G$41,B13,$H$35:$H$41)) -> 3875 | E13: 9466 | F13: martinha de jesus | G13: CTC | H13: 2599 | I13: 2000 | K13: OS Entregue no Dia | R13: =IF(vend5[[#This Row],[Nº Venda]]>1,1,0) -> 1
B14: PCTC | C14: =(SUMIF($G$2:$G$31,B14,$I$2:$I$31))+(SUMIF($G$35:$G$41,B14,$H$35:$H$41)) -> 0 | G14: DN | H14: 0 | I14: 599 | K14: OS | L14: Vendedor | M14: CARNE | R14: =IF(vend5[[#This Row],[Nº Venda]]>1,1,0) -> 0
B15: PIX | C15: =(SUMIF($G$2:$G$31,B15,$I$2:$I$31))+(SUMIF($G$35:$G$41,B15,$H$35:$H$41)) -> 2664.51 | E15: 9467 | F15: martinha de jesus | G15: SS | H15: 0 | I15: 0 | K15: 9275 | L15: JOCY | M15: Não | R15: =IF(vend5[[#This Row],[Nº Venda]]>1,1,0) -> 1
B16: Total | C16: =SUM(C11:C15) -> 9963.51 | E16: 9468 | F16: monica magalhoes | G16: PIX | H16: 900 | I16: 900 | K16: 9385 | L16: ARIANI | M16: Não | R16: =IF(vend5[[#This Row],[Nº Venda]]>1,1,0) -> 1
E17: 9469 | F17: monica magalhoes | G17: PIX | H17: 1450 | I17: 1450 | K17: 9065 | L17: JOCY | M17: Não | R17: =IF(vend5[[#This Row],[Nº Venda]]>1,1,0) -> 1
B18: Entrega de Carne | K18: 9409 | L18: JOCY | M18: Não | R18: =IF(vend5[[#This Row],[Nº Venda]]>1,1,0) -> 0
B19: =COUNT(entr_carn5[OS]) -> 0 | C19: =SUM(entr_carn5[Valor Total]) -> 0 | K19: 9398 | L19: JOCY | M19: Não | R19: =IF(vend5[[#This Row],[Nº Venda]]>1,1,0) -> 0
B20: Total | C20: =SUM(C19:C19) -> 0 | R20: =IF(vend5[[#This Row],[Nº Venda]]>1,1,0) -> 0
B22: Venda | C22: =C5 -> 9299
E24: Restante Entrada
E25: Nº Venda | F25: Cliente | G25: Forma de Pgto | H25: Valor Venda | I25: Entrada
E26: 9385 | F26: shirlei facunde | G26: DN | I26: 250
E27: 9398 | F27: ivaldo carvalho | G27: DN | I27: 500
E33: Recebimento de Carnê | K33: Entrega de Carne
E34: OS | F34: Cliente | G34: Forma de Pgto | H34: Valor Parcela | I34: Nº Parcela | K34: OS | L34: Parcelas | M34: Valor Total
E35: 8907 | F35: jose carlos | G35: DN | H35: 50 | I35: PARC. 3/4
E36: 9222 | F36: quezia de almeida | G36: DN | H36: 150 | I36: PARC. 2/3
E37: 9307 | F37: edneusa aparecida | G37: PIX | H37: 116.66 | I37: PARC. 1/6
E38: 9285 | F38: hellen vitoria | G38: PIX | H38: 92.85 | I38: PARC. 5/7
E39: 9262 | F39: silvia maria | G39: PIX | H39: 75 | I39: PARC. 1/6
Q40: Total de OS | R40: =SUM(R6:R21) -> 8

Sheet 07
B1: ='06'!B1+1 -> 45480
B2: Fechamento Diário do Caixa
B4: Saldo Inicial | C4: 0 | E4: Vendas | K4: Despesas | U4: 0
B5: Vendas | C5: =SUMIF(I6:I31,">0",H6:H31) -> 0 | E5: Nº Venda | F5: Cliente | G5: Forma de Pgto | H5: Valor Venda | I5: Entrada | K5: Descrição | L5: Tipo de Pagto | M5: Valor
B6: Entrada | C6: =SUM(I6:I41) -> 0 | R6: =IF(vend7[[#This Row],[Nº Venda]]>1,1,0) -> 0
B7: Despesas | C7: =SUM(M6:M11) -> 0 | R7: =IF(vend7[[#This Row],[Nº Venda]]>1,1,0) -> 0
B8: Total entrada | C8: =SUM(C6:C7) -> 0 | R8: =IF(vend7[[#This Row],[Nº Venda]]>1,1,0) -> 0
R9: =IF(vend7[[#This Row],[Nº Venda]]>1,1,0) -> 0
B10: Tipos de Pagtos | R10: =IF(vend7[[#This Row],[Nº Venda]]>1,1,0) -> 0
B11: DN | C11: =(SUMIF($G$2:$G$31,B11,$I$2:$I$31))+(SUMIF($G$35:$G$41,B11,$H$35:$H$41)) -> 0 | O11: =IF(C16=0,0,1) -> 0 | R11: =IF(vend7[[#This Row],[Nº Venda]]>1,1,0) -> 0
B12: CTD | C12: =(SUMIF($G$2:$G$31,B12,$I$2:$I$31))+(SUMIF($G$35:$G$41,B12,$H$35:$H$41)) -> 0 | R12: =IF(vend7[[#This Row],[Nº Venda]]>1,1,0) -> 0
B13: CTC | C13: =(SUMIF($G$2:$G$31,B13,$I$2:$I$31))+(SUMIF($G$35:$G$41,B13,$H$35:$H$41)) -> 0 | K13: OS Entregue no Dia | R13: =IF(vend7[[#This Row],[Nº Venda]]>1,1,0) -> 0
B14: PCTC | C14: =(SUMIF($G$2:$G$31,B14,$I$2:$I$31))+(SUMIF($G$35:$G$41,B14,$H$35:$H$41)) -> 0 | K14: OS | L14: Vendedor | M14: CARNE | R14: =IF(vend7[[#This Row],[Nº Venda]]>1,1,0) -> 0
B15: PIX | C15: =(SUMIF($G$2:$G$31,B15,$I$2:$I$31))+(SUMIF($G$35:$G$41,B15,$H$35:$H$41)) -> 0 | R15: =IF(vend7[[#This Row],[Nº Venda]]>1,1,0) -> 0
B16: Total | C16: =SUM(C11:C15) -> 0 | R16: =IF(vend7[[#This Row],[Nº Venda]]>1,1,0) -> 0
R17: =IF(vend7[[#This Row],[Nº Venda]]>1,1,0) -> 0
B18: Entrega de Carne | R18: =IF(vend7[[#This Row],[Nº Venda]]>1,1,0) -> 0
B19: =COUNT(entr_carn7[OS]) -> 0 | C19: =SUM(entr_carn7[Valor Total]) -> 0 | R19: =IF(vend7[[#This Row],[Nº Venda]]>1,1,0) -> 0
B20: Total | C20: =SUM(C19:C19) -> 0 | R20: =IF(vend7[[#This Row],[Nº Venda]]>1,1,0) -> 0
B22: Venda | C22: =C5 -> 0
E24: Restante Entrada
E25: Nº Venda | F25: Cliente | G25: Forma de Pgto | H25: Valor Venda | I25: Entrada
E33: Recebimento de Carnê | K33: Entrega de Carne
E34: OS | F34: Cliente | G34: Forma de Pgto | H34: Valor Parcela | I34: Nº Parcela | K34: OS | L34: Parcelas | M34: Valor Total
Q40: Total de OS | R40: =SUM(R6:R21) -> 0

Sheet 06
B1: ='05'!B1+1 -> 45479
B2: Fechamento Diário do Caixa
B4: Saldo Inicial | C4: 0 | E4: Vendas | K4: Despesas
B5: Vendas | C5: =SUMIF(I6:I36,">0",H6:H36) -> 3857 | E5: Nº Venda | F5: Cliente | G5: Forma de Pgto | H5: Valor Venda | I5: Entrada | K5: Descrição | L5: Tipo de Pagto | M5: Valor
B6: Entrada | C6: =SUM(I6:I47) -> 3868 | E6: 9470 | F6: neusa lima | G6: CTD | H6: 790 | I6: 20 | K6: TATY RETIROU | L6: DINHEIRO | M6: 100 | R6: =IF(vend[[#This Row],[Nº Venda]]>1,1,0) -> 1
B7: Despesas | C7: =SUM(M6:M11) -> 100 | E7: 9471 | F7: maria ivani | G7: CTD | H7: 899 | I7: 50 | R7: =IF(vend[[#This Row],[Nº Venda]]>1,1,0) -> 1
B8: Total entrada | C8: =SUM(C6:C7) -> 3968 | E8: 9472 | F8: ilda soares | G8: DN | H8: 400 | I8: 50 | R8: =IF(vend[[#This Row],[Nº Venda]]>1,1,0) -> 1
E9: 9473 | F9: larissa segura | G9: PIX | H9: 569 | I9: 569 | R9: =IF(vend[[#This Row],[Nº Venda]]>1,1,0) -> 1
B10: Tipos de Pagtos | E10: 9474 | F10: larissa segura | G10: PIX | H10: 200 | I10: 200 | R10: =IF(vend[[#This Row],[Nº Venda]]>1,1,0) -> 1
B11: DN | C11: =(SUMIF($G$2:$G$36,B11,$I$2:$I$36))+(SUMIF($G$41:$G$47,B11,$H$41:$H$47)) -> 540 | O11: =IF(C16=0,0,1) -> 1 | R11: =IF(vend[[#This Row],[Nº Venda]]>1,1,0) -> 0
B12: CTD | C12: =(SUMIF($G$2:$G$36,B12,$I$2:$I$36))+(SUMIF($G$41:$G$47,B12,$H$41:$H$47)) -> 390 | R12: =IF(vend[[#This Row],[Nº Venda]]>1,1,0) -> 0
B13: CTC | C13: =(SUMIF($G$2:$G$36,B13,$I$2:$I$36))+(SUMIF($G$41:$G$47,B13,$H$41:$H$47)) -> 1099 | K13: OS Entregue no Dia | R13: =IF(vend[[#This Row],[Nº Venda]]>1,1,0) -> 0
B14: PCTC | C14: =(SUMIF($G$2:$G$36,B14,$I$2:$I$36))+(SUMIF($G$41:$G$47,B14,$H$41:$H$47)) -> 0 | K14: OS | L14: Vendedor | M14: CARNE | R14: =IF(vend[[#This Row],[Nº Venda]]>1,1,0) -> 0
B15: PIX | C15: =(SUMIF($G$2:$G$36,B15,$I$2:$I$36))+(SUMIF($G$41:$G$47,B15,$H$41:$H$47)) -> 2040.42 | K15: 9396 | L15: JOCY | M15: Sim | R15: =IF(vend[[#This Row],[Nº Venda]]>1,1,0) -> 0
B16: Total | C16: =SUM(C11:C15) -> 4069.42 | K16: 9435 | L16: JOCY | M16: Não | R16: =IF(vend[[#This Row],[Nº Venda]]>1,1,0) -> 0
K17: 9444 | L17: TATY | M17: Não | R17: =IF(vend[[#This Row],[Nº Venda]]>1,1,0) -> 0
B18: Entrega de Carne | K18: 9417 | L18: ARIANI | M18: Não | R18: =IF(vend[[#This Row],[Nº Venda]]>1,1,0) -> 0
B19: =COUNT(entr_carn6[OS]) -> 3 | C19: =SUM(entr_carn6[Valor Total]) -> 1578.6 | K19: 9450 | L19: JOCY | M19: Não | R19: =IF(vend[[#This Row],[Nº Venda]]>1,1,0) -> 0
B20: Total | C20: =SUM(C19:C19) -> 1578.6 | K20: 9410 | L20: ARIANI | M20: Não | R20: =IF(vend[[#This Row],[Nº Venda]]>1,1,0) -> 0
K21: 9289 | L21: ARIANI | M21: Sim
B22: Venda | C22: =C5 -> 3857 | K22: 9425 | L22: ARIANI | M22: Sim
K23: 9437 | L23: TATY | M23: Sim
E24: Restante Entrada
E25: Nº Venda | F25: Cliente | G25: Forma de Pgto | H25: Valor Venda | I25: Entrada
E26: 9018 | F26: ilda soares | G26: DN | H26: 0 | I26: 50
E27: 8957 | F27: pricila goncalves | G27: PIX | H27: 0 | I27: 270
E28: 9396 | F28: alercio serafim | G28: PIX | H28: 0 | I28: 300
E29: 9435 | F29: stefany aparecida | G29: PIX | H29: 300 | I29: 300
E30: 9455 | F30: silvana rejane | G30: CTD | H30: 0 | I30: 320
E31: 9453 | F31: rita de cassia | G31: CTC | H31: 0 | I31: 400
E32: 9026 | F32: iris dos santos | G32: DN | H32: 0 | I32: 140
E33: 9425 | F33: andrea alves | G33: PIX | H33: 0 | I33: 200 | K33: Entrega de Carne
E34: 9289 | F34: julcimara aparecida | G34: DN | H34: 0 | I34: 300 | K34: OS | L34: Parcelas | M34: Valor Total
E35: 9460 | F35: josimar fernando | G35: CTC | H35: 699 | I35: 699 | K35: 9396 | L35: 1 | M35: 400
K36: 9289 | L36: 6 | M36: 549.6
K37: 9425 | L37: 6 | M37: 629
E39: Recebimento de Carnê
E40: OS | F40: Cliente | G40: Forma de Pgto | H40: Valor Parcela | I40: Nº Parcela | Q40: Total de OS | R40: =SUM(R6:R21) -> 5
E41: 9857 | F41: aparecida maria | G41: PIX | H41: 98.57 | I41: PARC. 5/7
E42: 8847 | F42: jose santos | G42: PIX | H42: 102.85 | I42: PARC. 3/7

Sheet 08
B1: ='07'!B1+1 -> 45481
B2: Fechamento Diário do Caixa
B4: Saldo Inicial | C4: 0 | E4: Vendas | K4: Despesas
B5: Vendas | C5: =SUMIF(I6:I31,">0",H6:H31) -> 0 | E5: Nº Venda | F5: Cliente | G5: Forma de Pgto | H5: Valor Venda | I5: Entrada | K5: Descrição | L5: Tipo de Pagto | M5: Valor
B6: Entrada | C6: =SUM(I6:I41) -> 770 | E6: 9475 | F6: simara luciano | G6: SS | H6: 40 | R6: =IF(vend8[[#This Row],[Nº Venda]]>1,1,0) -> 1
B7: Despesas | C7: =SUM(M6:M11) -> 0 | R7: =IF(vend8[[#This Row],[Nº Venda]]>1,1,0) -> 0
B8: Total entrada | C8: =SUM(C6:C7) -> 770 | R8: =IF(vend8[[#This Row],[Nº Venda]]>1,1,0) -> 0
R9: =IF(vend8[[#This Row],[Nº Venda]]>1,1,0) -> 0
B10: Tipos de Pagtos | R10: =IF(vend8[[#This Row],[Nº Venda]]>1,1,0) -> 0
B11: DN | C11: =(SUMIF($G$2:$G$31,B11,$I$2:$I$31))+(SUMIF($G$35:$G$42,B11,$H$35:$H$42)) -> 0 | O11: =IF(C16=0,0,1) -> 1 | R11: =IF(vend8[[#This Row],[Nº Venda]]>1,1,0) -> 0
B12: CTD | C12: =(SUMIF($G$2:$G$31,B12,$I$2:$I$31))+(SUMIF($G$35:$G$42,B12,$H$35:$H$42)) -> 0 | R12: =IF(vend8[[#This Row],[Nº Venda]]>1,1,0) -> 0
B13: CTC | C13: =(SUMIF($G$2:$G$31,B13,$I$2:$I$31))+(SUMIF($G$35:$G$42,B13,$H$35:$H$42)) -> 770 | K13: OS Entregue no Dia | R13: =IF(vend8[[#This Row],[Nº Venda]]>1,1,0) -> 0
B14: PCTC | C14: =(SUMIF($G$2:$G$31,B14,$I$2:$I$31))+(SUMIF($G$35:$G$42,B14,$H$35:$H$42)) -> 0 | K14: OS | L14: Vendedor | M14: CARNE | R14: =IF(vend8[[#This Row],[Nº Venda]]>1,1,0) -> 0
B15: PIX | C15: =(SUMIF($G$2:$G$31,B15,$I$2:$I$31))+(SUMIF($G$35:$G$42,B15,$H$35:$H$42)) -> 163.8 | K15: 9431 | L15: JOCY | M15: Não | R15: =IF(vend8[[#This Row],[Nº Venda]]>1,1,0) -> 0
B16: Total | C16: =SUM(C11:C15) -> 933.8 | K16: 8957 | L16: ARIANI | M16: Não | R16: =IF(vend8[[#This Row],[Nº Venda]]>1,1,0) -> 0
R17: =IF(vend8[[#This Row],[Nº Venda]]>1,1,0) -> 0
B18: Entrega de Carne | R18: =IF(vend8[[#This Row],[Nº Venda]]>1,1,0) -> 0
B19: =COUNT(entr_carn8[OS]) -> 0 | C19: =SUM(entr_carn8[Valor Total]) -> 0 | R19: =IF(vend8[[#This Row],[Nº Venda]]>1,1,0) -> 0
B20: Total | C20: =SUM(C19:C19) -> 0 | R20: =IF(vend8[[#This Row],[Nº Venda]]>1,1,0) -> 0
B22: Venda | C22: =C5 -> 0
E24: Restante Entrada
E25: Nº Venda | F25: Cliente | G25: Forma de Pgto | H25: Valor Venda | I25: Entrada
E26: 9470 | F26: neusa lima de souza | G26: CTC | I26: 770
E33: Recebimento de Carnê | K33: Entrega de Carne
E34: OS | F34: Cliente | G34: Forma de Pgto | H34: Valor Parcela | I34: Nº Parcela | K34: OS | L34: Parcelas | M34: Valor Total
E35: 9104 | F35: fabiana de souza | G35: PIX | H35: 57.14 | I35: PARC. 2/7
E36: 8669 | F36: sandra fernandes | G36: PIX | H36: 106.66 | I36: PARC. 5/6
Q40: Total de OS | R40: =SUM(R6:R21) -> 1

Sheet 09
B1: ='08'!B1+1 -> 45482
B2: Fechamento Diário do Caixa
B4: Saldo Inicial | C4: 0 | E4: Vendas | K4: Despesas
B5: Vendas | C5: =SUMIF(I6:I31,">0",H6:H31) -> 0 | E5: Nº Venda | F5: Cliente | G5: Forma de Pgto | H5: Valor Venda | I5: Entrada | K5: Descrição | L5: Tipo de Pagto | M5: Valor
B6: Entrada | C6: =SUM(I6:I41) -> 0 | R6: =IF(vend9[[#This Row],[Nº Venda]]>1,1,0) -> 0
B7: Despesas | C7: =SUM(M6:M11) -> 0 | R7: =IF(vend9[[#This Row],[Nº Venda]]>1,1,0) -> 0
B8: Total entrada | C8: =SUM(C6:C7) -> 0 | R8: =IF(vend9[[#This Row],[Nº Venda]]>1,1,0) -> 0
R9: =IF(vend9[[#This Row],[Nº Venda]]>1,1,0) -> 0
B10: Tipos de Pagtos | R10: =IF(vend9[[#This Row],[Nº Venda]]>1,1,0) -> 0
B11: DN | C11: =(SUMIF($G$2:$G$31,B11,$I$2:$I$31))+(SUMIF($G$35:$G$41,B11,$H$35:$H$41)) -> 0 | O11: =IF(C16=0,0,1) -> 0 | R11: =IF(vend9[[#This Row],[Nº Venda]]>1,1,0) -> 0
B12: CTD | C12: =(SUMIF($G$2:$G$31,B12,$I$2:$I$31))+(SUMIF($G$35:$G$41,B12,$H$35:$H$41)) -> 0 | R12: =IF(vend9[[#This Row],[Nº Venda]]>1,1,0) -> 0 | V12: 0
B13: CTC | C13: =(SUMIF($G$2:$G$31,B13,$I$2:$I$31))+(SUMIF($G$35:$G$41,B13,$H$35:$H$41)) -> 0 | K13: OS Entregue no Dia | R13: =IF(vend9[[#This Row],[Nº Venda]]>1,1,0) -> 0
B14: PCTC | C14: =(SUMIF($G$2:$G$31,B14,$I$2:$I$31))+(SUMIF($G$35:$G$41,B14,$H$35:$H$41)) -> 0 | K14: OS | L14: Vendedor | M14: CARNE | R14: =IF(vend9[[#This Row],[Nº Venda]]>1,1,0) -> 0
B15: PIX | C15: =(SUMIF($G$2:$G$31,B15,$I$2:$I$31))+(SUMIF($G$35:$G$41,B15,$H$35:$H$41)) -> 0 | R15: =IF(vend9[[#This Row],[Nº Venda]]>1,1,0) -> 0
B16: Total | C16: =SUM(C11:C15) -> 0 | R16: =IF(vend9[[#This Row],[Nº Venda]]>1,1,0) -> 0
R17: =IF(vend9[[#This Row],[Nº Venda]]>1,1,0) -> 0
B18: Entrega de Carne | R18: =IF(vend9[[#This Row],[Nº Venda]]>1,1,0) -> 0
B19: =COUNT(entr_carn9[OS]) -> 0 | C19: =SUM(entr_carn9[Valor Total]) -> 0 | R19: =IF(vend9[[#This Row],[Nº Venda]]>1,1,0) -> 0
B20: Total | C20: =SUM(C19:C19) -> 0 | R20: =IF(vend9[[#This Row],[Nº Venda]]>1,1,0) -> 0
B22: Venda | C22: =C5 -> 0
E24: Restante Entrada
E25: Nº Venda | F25: Cliente | G25: Forma de Pgto | H25: Valor Venda | I25: Entrada
E33: Recebimento de Carnê | K33: Entrega de Carne
E34: OS | F34: Cliente | G34: Forma de Pgto | H34: Valor Parcela | I34: Nº Parcela | K34: OS | L34: Parcelas | M34: Valor Total
Q40: Total de OS | R40: =SUM(R6:R21) -> 0

Sheet 10
B1: ='09'!B1+1 -> 45483
B2: Fechamento Diário do Caixa
B4: Saldo Inicial | C4: 0 | E4: Vendas | K4: Despesas
B5: Vendas | C5: =SUMIF(I6:I32,">0",H6:H32) -> 4460 | E5: Nº Venda | F5: Cliente | G5: Forma de Pgto | H5: Valor Venda | I5: Entrada | K5: Descrição | L5: Tipo de Pagto | M5: Valor
B6: Entrada | C6: =SUM(I6:I49) -> 5580 | E6: 9476 | F6: cleide josefa | G6: CTD | H6: 700 | I6: 700 | R6: =IF(vend10[[#This Row],[Nº Venda]]>1,1,0) -> 1
B7: Despesas | C7: =SUM(M6:M11) -> 0 | E7: 9477 | F7: edson ferreira | G7: CTC | H7: 490 | I7: 490 | R7: =IF(vend10[[#This Row],[Nº Venda]]>1,1,0) -> 1
B8: Total entrada | C8: =SUM(C6:C7) -> 5580 | E8: 9478 | F8: jaidinhilda martins | G8: CTC | H8: 2600 | I8: 2600 | R8: =IF(vend10[[#This Row],[Nº Venda]]>1,1,0) -> 1
E9: 9479 | F9: gilmar lopes | G9: DN | H9: 600 | I9: 20 | R9: =IF(vend10[[#This Row],[Nº Venda]]>1,1,0) -> 1
B10: Tipos de Pagtos | E10: 9480 | F10: JOSIMAR FERNANDO | G10: CTD | H10: 70 | I10: 70 | R10: =IF(vend10[[#This Row],[Nº Venda]]>1,1,0) -> 1
B11: DN | C11: =(SUMIF($G$2:$G$32,B11,$I$2:$I$32))+(SUMIF($G$36:$G$49,B11,$H$36:$H$49)) -> 20 | O11: =IF(C16=0,0,1) -> 1 | R11: =IF(vend10[[#This Row],[Nº Venda]]>1,1,0) -> 0
B12: CTD | C12: =(SUMIF($G$2:$G$32,B12,$I$2:$I$32))+(SUMIF($G$36:$G$49,B12,$H$36:$H$49)) -> 1220 | R12: =IF(vend10[[#This Row],[Nº Venda]]>1,1,0) -> 0
B13: CTC | C13: =(SUMIF($G$2:$G$32,B13,$I$2:$I$32))+(SUMIF($G$36:$G$49,B13,$H$36:$H$49)) -> 4340 | K13: OS Entregue no Dia | R13: =IF(vend10[[#This Row],[Nº Venda]]>1,1,0) -> 0
B14: PCTC | C14: =(SUMIF($G$2:$G$32,B14,$I$2:$I$32))+(SUMIF($G$36:$G$49,B14,$H$36:$H$49)) -> 0 | K14: OS | L14: Vendedor | M14: CARNE | R14: =IF(vend10[[#This Row],[Nº Venda]]>1,1,0) -> 0
B15: PIX | C15: =(SUMIF($G$2:$G$32,B15,$I$2:$I$32))+(SUMIF($G$36:$G$49,B15,$H$36:$H$49)) -> 795.99 | K15: 9394 | L15: TATY | M15: Não | R15: =IF(vend10[[#This Row],[Nº Venda]]>1,1,0) -> 0
B16: Total | C16: =SUM(C11:C15) -> 6375.99 | K16: 9283 | L16: ARIANI | M16: NÃO | R16: =IF(vend10[[#This Row],[Nº Venda]]>1,1,0) -> 0
K17: 9473 | L17: TATY | M17: Não | R17: =IF(vend10[[#This Row],[Nº Venda]]>1,1,0) -> 0
B18: Entrega de Carne | K18: 9284 | L18: ARIANI | M18: Não | R18: =IF(vend10[[#This Row],[Nº Venda]]>1,1,0) -> 0
B19: =COUNT(entr_carn10[OS]) -> 2 | C19: =SUM(entr_carn10[Valor Total]) -> 3850 | K19: 9391 | L19: JOCY | M19: Não | R19: =IF(vend10[[#This Row],[Nº Venda]]>1,1,0) -> 0
B20: Total | C20: =SUM(C19:C19) -> 3850 | K20: 9393 | L20: JOCY | M20: Sim | R20: =IF(vend10[[#This Row],[Nº Venda]]>1,1,0) -> 0
K21: 9438 | L21: TATY | M21: Não
B22: Venda | C22: =C5 -> 4460 | K22: 9328 | L22: JOCY | M22: Não
K23: 9441 | L23: JOCY | M23: Sim
E24: Restante Entrada | K24: 9442 | L24: JOCY | M24: Não
E25: Nº Venda | F25: Cliente | G25: Forma de Pgto | H25: Valor Venda | I25: Entrada | K25: 9480 | L25: JOCY | M25: Não
E26: 9394 | F26: carlos alberto | G26: CTC | H26: 0 | I26: 1099
E27: 9395 | F27: carlos alberto | G27: CTC | H27: 0 | I27: 151
E28: 9441 | F28: gilmar lopes | G28: CTD | H28: 0 | I28: 450
K33: Entrega de Carne
E34: Recebimento de Carnê | K34: OS | L34: Parcelas | M34: Valor Total
E35: OS | F35: Cliente | G35: Forma de Pgto | H35: Valor Parcela | I35: Nº Parcela | K35: 9393 | L35: 8 | M35: 1000
E36: 9342 | F36: FABIANA ALVES | G36: PIX | H36: 58.33 | I36: PARC. 1/6 | K36: 9441 | L36: 8 | M36: 2850
E37: 9102 | F37: ELLEN CRISTINA | G37: PIX | H37: 60 | I37: PARC. 2/5
E38: 8781 | F38: ROZILEIDE BRITO | G38: PIX | H38: 99.83 | I38: PARC. 3/6
E39: 8781 | F39: ROZILEIDE BRITO | G39: PIX | H39: 99.83 | I39: PARC. 4/6
E40: 8660 | F40: maria da conceição | G40: PIX | H40: 55.6 | I40: PARC. 1/5 | Q40: Total de OS | R40: =SUM(R6:R21) -> 5
E41: 8660 | F41: maria da conceição | G41: PIX | H41: 55.6 | I41: PARC. 2/5
E42: 8660 | F42: maria da conceição | G42: PIX | H42: 55.6 | I42: PARC. 3/5
E43: 8660 | F43: maria da conceição | G43: PIX | H43: 55.6 | I43: PARC. 4/5
E44: 8660 | F44: maria da conceição | G44: PIX | H44: 55.6 | I44: PARC. 5/5
E45: 8943 | F45: samuel de melo | G45: PIX | H45: 200 | I45: PARC. 1/9

Sheet 11
B1: ='10'!B1+1 -> 45484
B2: Fechamento Diário do Caixa
B4: Saldo Inicial | C4: 0 | E4: Vendas | K4: Despesas
B5: Vendas | C5: =SUMIF(I6:I31,">0",H6:H31) -> 2150 | E5: Nº Venda | F5: Cliente | G5: Forma de Pgto | H5: Valor Venda | I5: Entrada | K5: Descrição | L5: Tipo de Pagto | M5: Valor
B6: Entrada | C6: =SUM(I6:I41) -> 2675 | E6: 9481 | F6: renata paula | G6: GARANTIA | K6: papel contact | L6: dinheiro | M6: 27 | R6: =IF(vend11[[#This Row],[Nº Venda]]>1,1,0) -> 1
B7: Despesas | C7: =SUM(M6:M11) -> 27 | E7: 9482 | F7: fernando cardoso | G7: PIX | H7: 1600 | I7: 1500 | R7: =IF(vend11[[#This Row],[Nº Venda]]>1,1,0) -> 1
B8: Total entrada | C8: =SUM(C6:C7) -> 2702 | E8: 9483 | F8: julcimara aparecida | G8: GARANTIA | R8: =IF(vend11[[#This Row],[Nº Venda]]>1,1,0) -> 1
E9: 9484 | F9: julio cesar | G9: PIX | H9: 550 | I9: 275 | R9: =IF(vend11[[#This Row],[Nº Venda]]>1,1,0) -> 1
B10: Tipos de Pagtos | R10: =IF(vend11[[#This Row],[Nº Venda]]>1,1,0) -> 0
B11: DN | C11: =(SUMIF($G$2:$G$31,B11,$I$2:$I$31))+(SUMIF($G$35:$G$41,B11,$H$35:$H$41)) -> 431.5 | O11: =IF(C16=0,0,1) -> 1 | R11: =IF(vend11[[#This Row],[Nº Venda]]>1,1,0) -> 0
B12: CTD | C12: =(SUMIF($G$2:$G$31,B12,$I$2:$I$31))+(SUMIF($G$35:$G$41,B12,$H$35:$H$41)) -> 120 | R12: =IF(vend11[[#This Row],[Nº Venda]]>1,1,0) -> 0
B13: CTC | C13: =(SUMIF($G$2:$G$31,B13,$I$2:$I$31))+(SUMIF($G$35:$G$41,B13,$H$35:$H$41)) -> 570 | K13: OS Entregue no Dia | R13: =IF(vend11[[#This Row],[Nº Venda]]>1,1,0) -> 0
B14: PCTC | C14: =(SUMIF($G$2:$G$31,B14,$I$2:$I$31))+(SUMIF($G$35:$G$41,B14,$H$35:$H$41)) -> 0 | K14: OS | L14: Vendedor | M14: CARNE | R14: =IF(vend11[[#This Row],[Nº Venda]]>1,1,0) -> 0
B15: PIX | C15: =(SUMIF($G$2:$G$31,B15,$I$2:$I$31))+(SUMIF($G$35:$G$41,B15,$H$35:$H$41)) -> 2079 | K15: 9454 | L15: JOCY | M15: Não | R15: =IF(vend11[[#This Row],[Nº Venda]]>1,1,0) -> 0
B16: Total | C16: =SUM(C11:C15) -> 3200.5 | K16: 9402 | L16: TATY | M16: Não | R16: =IF(vend11[[#This Row],[Nº Venda]]>1,1,0) -> 0
K17: 9365 | L17: JOCY | M17: Não | R17: =IF(vend11[[#This Row],[Nº Venda]]>1,1,0) -> 0
B18: Entrega de Carne | K18: 9429 | L18: ARIANI | M18: Não | R18: =IF(vend11[[#This Row],[Nº Venda]]>1,1,0) -> 0
B19: =COUNT(entr_carn11[OS]) -> 1 | C19: =SUM(entr_carn11[Valor Total]) -> 400 | K19: 9430 | L19: ARIANI | M19: Não | R19: =IF(vend11[[#This Row],[Nº Venda]]>1,1,0) -> 0
B20: Total | C20: =SUM(C19:C19) -> 400 | K20: 9452 | L20: ARIANI | M20: Sim | R20: =IF(vend11[[#This Row],[Nº Venda]]>1,1,0) -> 0
K21: 8967 | L21: JOCY | M21: Não
B22: Venda | C22: =C5 -> 2150 | K22: 9224 | L22: ARIANI | M22: Não
E24: Restante Entrada
E25: Nº Venda | F25: Cliente | G25: Forma de Pgto | H25: Valor Venda | I25: Entrada
E26: 9465 | F26: gilvanilson jacinto | G26: CTC | H26: 0 | I26: 570
E27: 9454 | F27: rita de cassia | G27: DN | H27: 0 | I27: 210
E28: 9454 | F28: rita de cassia | G28: CTD | H28: 0 | I28: 120
E33: Recebimento de Carnê | K33: Entrega de Carne
E34: OS | F34: Cliente | G34: Forma de Pgto | H34: Valor Parcela | I34: Nº Parcela | K34: OS | L34: Parcelas | M34: Valor Total
E35: 8985 | F35: cleide ana melo | G35: PIX | H35: 100 | I35: PARC. 2/4 | K35: 9452 | L35: 6 | M35: 400
E36: 8790 | F36: maria aparecida | G36: DN | H36: 55 | I36: PARC. 4/7
E37: 8260 | F37: welber anderson | G37: DN | H37: 100 | I37: PARC. 7/7
E38: 8504 | F38: izabel dos santos | G38: PIX | H38: 115 | I38: PARC. 6/6
E39: 9156 | F39: simone ignacio | G39: DN | H39: 66.5 | I39: PARC. 2/6
E40: 9166 | F40: izildinha aparecida | G40: PIX | H40: 89 | I40: PARC. 2/8 | Q40: Total de OS | R40: =SUM(R6:R21) -> 4

Sheet 12
B1: ='11'!B1+1 -> 45485
B2: Fechamento Diário do Caixa
B4: Saldo Inicial | C4: 0 | E4: Vendas | K4: Despesas
B5: Vendas | C5: =SUMIF(I6:I31,">0",H6:H31) -> 7390 | E5: Nº Venda | F5: Cliente | G5: Forma de Pgto | H5: Valor Venda | I5: Entrada | K5: Descrição | L5: Tipo de Pagto | M5: Valor
B6: Entrada | C6: =SUM(I6:I41) -> 3909.5 | E6: 9485 | F6: ana celia | G6: CTC | H6: 450 | I6: 450 | R6: =IF(vend12[[#This Row],[Nº Venda]]>1,1,0) -> 1
B7: Despesas | C7: =SUM(M6:M11) -> 0 | E7: 9486 | F7: ana celia | G7: CTC | H7: 350 | I7: 350 | R7: =IF(vend12[[#This Row],[Nº Venda]]>1,1,0) -> 1
B8: Total entrada | C8: =SUM(C6:C7) -> 3909.5 | E8: 9487 | F8: ana celia | G8: CTC | H8: 450 | I8: 450 | R8: =IF(vend12[[#This Row],[Nº Venda]]>1,1,0) -> 1
E9: 9488 | F9: julia gomes | G9: CTC | H9: 350 | I9: 350 | R9: =IF(vend12[[#This Row],[Nº Venda]]>1,1,0) -> 1
B10: Tipos de Pagtos | E10: 9489 | F10: su yo ting | G10: DN | H10: 250 | I10: 20 | R10: =IF(vend12[[#This Row],[Nº Venda]]>1,1,0) -> 1
B11: DN | C11: =(SUMIF($G$2:$G$31,B11,$I$2:$I$31))+(SUMIF($G$35:$G$41,B11,$H$35:$H$41)) -> 259.5 | E11: 9490 | F11: everaldo serafim | G11: PIX | H11: 1900 | I11: 900 | O11: =IF(C16=0,0,1) -> 1 | R11: =IF(vend12[[#This Row],[Nº Venda]]>1,1,0) -> 1
B12: CTD | C12: =(SUMIF($G$2:$G$31,B12,$I$2:$I$31))+(SUMIF($G$35:$G$41,B12,$H$35:$H$41)) -> 125.72 | E12: 9491 | F12: everaldo serafim | G12: PIX | H12: 100 | I12: 100 | R12: =IF(vend12[[#This Row],[Nº Venda]]>1,1,0) -> 1
B13: CTC | C13: =(SUMIF($G$2:$G$31,B13,$I$2:$I$31))+(SUMIF($G$35:$G$41,B13,$H$35:$H$41)) -> 1650 | E13: 9492 | F13: everaldo serafim | G13: PIX | H13: 1690 | I13: 900 | K13: OS Entregue no Dia | R13: =IF(vend12[[#This Row],[Nº Venda]]>1,1,0) -> 1
B14: PCTC | C14: =(SUMIF($G$2:$G$31,B14,$I$2:$I$31))+(SUMIF($G$35:$G$41,B14,$H$35:$H$41)) -> 0 | E14: 9493 | F14: everaldo serafim | G14: PIX | H14: 100 | I14: 100 | K14: OS | L14: Vendedor | M14: CARNE | R14: =IF(vend12[[#This Row],[Nº Venda]]>1,1,0) -> 1
B15: PIX | C15: =(SUMIF($G$2:$G$31,B15,$I$2:$I$31))+(SUMIF($G$35:$G$41,B15,$H$35:$H$41)) -> 2443.33 | E15: 9494 | F15: mariana rosa | G15: DN | H15: 1200 | I15: 50 | K15: 9427 | L15: ARIANI | M15: Não | R15: =IF(vend12[[#This Row],[Nº Venda]]>1,1,0) -> 1
B16: Total | C16: =SUM(C11:C15) -> 4478.55 | E16: 9495 | F16: thaynara de jesus | G16: CTC | H16: 550 | I16: 50 | R16: =IF(vend12[[#This Row],[Nº Venda]]>1,1,0) -> 1
R17: =IF(vend12[[#This Row],[Nº Venda]]>1,1,0) -> 0
B18: Entrega de Carne | R18: =IF(vend12[[#This Row],[Nº Venda]]>1,1,0) -> 0
B19: =COUNT(entr_carn12[OS]) -> 0 | C19: =SUM(entr_carn12[Valor Total]) -> 0 | R19: =IF(vend12[[#This Row],[Nº Venda]]>1,1,0) -> 0
B20: Total | C20: =SUM(C19:C19) -> 0 | R20: =IF(vend12[[#This Row],[Nº Venda]]>1,1,0) -> 0
B22: Venda | C22: =C5 -> 7390
E24: Restante Entrada
E25: Nº Venda | F25: Cliente | G25: Forma de Pgto | H25: Valor Venda | I25: Entrada
E26: 9448 | F26: ana maria | G26: DN | H26: 0 | I26: 189.5
E33: Recebimento de Carnê | K33: Entrega de Carne
E34: OS | F34: Cliente | G34: Forma de Pgto | H34: Valor Parcela | I34: Nº Parcela | K34: OS | L34: Parcelas | M34: Valor Total
E35: 9072 | F35: marilu candida | G35: PIX | H35: 168.33 | I35: PARC. 2/6
E36: 8153 | F36: valdineia molina | G36: PIX | H36: 50 | I36: PARC. 7/8
E37: 9012 | F37: silas diego | G37: PIX | H37: 225 | I37: PARC. 2/8
E38: 8472 | F38: arlete vieira | G38: CTD | H38: 125.72 | I38: PARC. 6/7
Q40: Total de OS | R40: =SUM(R6:R21) -> 11

Sheet 13
B1: ='12'!B1+1 -> 45486
B2: Fechamento Diário do Caixa
B4: Saldo Inicial | C4: 0 | E4: Vendas | K4: Despesas
B5: Vendas | C5: =SUMIF(I6:I36,">0",H6:H36) -> 6188.98 | E5: Nº Venda | F5: Cliente | G5: Forma de Pgto | H5: Valor Venda | I5: Entrada | K5: Descrição | L5: Tipo de Pagto | M5: Valor
B6: Entrada | C6: =SUM(I6:I47) -> 7465 | E6: 9496 | F6: ELAINE CRISTINA | G6: DN | H6: 89 | I6: 40 | R6: =IF(vend13[[#This Row],[Nº Venda]]>1,1,0) -> 1
B7: Despesas | C7: =SUM(M6:M11) -> 0 | E7: 9497 | F7: RAIMUNDO OLIVEIRA | G7: CTC | H7: 148 | I7: 148 | R7: =IF(vend13[[#This Row],[Nº Venda]]>1,1,0) -> 1
B8: Total entrada | C8: =SUM(C6:C7) -> 7465 | E8: 9498 | F8: RAIMUNDO OLIVEIRA | G8: CTC | H8: 851.99 | I8: 851.99 | R8: =IF(vend13[[#This Row],[Nº Venda]]>1,1,0) -> 1
E9: 9499 | F9: GERALDA APARECIDA | G9: CTC | H9: 899.99 | I9: 899.99 | R9: =IF(vend13[[#This Row],[Nº Venda]]>1,1,0) -> 1
B10: Tipos de Pagtos | E10: 9500 | F10: FABIO GOMES | G10: CTC | H10: 2000 | I10: 2000 | R10: =IF(vend13[[#This Row],[Nº Venda]]>1,1,0) -> 1
B11: DN | C11: =(SUMIF($G$2:$G$37,B11,$I$2:$I$37))+(SUMIF($G$41:$G$47,B11,$H$41:$H$47)) -> 66 | E11: 9501 | F11: ISRAEL COSME | G11: CTC | H11: 600 | I11: 600 | O11: =IF(C16=0,0,1) -> 1 | R11: =IF(vend13[[#This Row],[Nº Venda]]>1,1,0) -> 1
B12: CTD | C12: =(SUMIF($G$2:$G$37,B12,$I$2:$I$37))+(SUMIF($G$41:$G$47,B12,$H$41:$H$47)) -> 1311.25 | E12: 9502 | F12: ISRAEL COSME | G12: CTC | H12: 600 | I12: 400 | R12: =IF(vend13[[#This Row],[Nº Venda]]>1,1,0) -> 1
B13: CTC | C13: =(SUMIF($G$2:$G$37,B13,$I$2:$I$37))+(SUMIF($G$41:$G$47,B13,$H$41:$H$47)) -> 6200 | E13: 9502 | F13: ISRAEL COSME | G13: CTD | H13: 200 | I13: 200 | K13: OS Entregue no Dia | R13: =IF(vend13[[#This Row],[Nº Venda]]>1,1,0) -> 1
B14: PCTC | C14: =(SUMIF($G$2:$G$37,B14,$I$2:$I$37))+(SUMIF($G$41:$G$47,B14,$H$41:$H$47)) -> 0 | E14: 9503 | F14: SHEILA RIBEIRO | G14: SS | H14: 99 | K14: OS | L14: Vendedor | M14: CARNE | R14: =IF(vend13[[#This Row],[Nº Venda]]>1,1,0) -> 1
B15: PIX | C15: =(SUMIF($G$2:$G$36,B15,$I$2:$I$36))+(SUMIF($G$41:$G$47,B15,$H$41:$H$47)) -> 49 | E15: 9504 | F15: SINARA GOMES | G15: CTD | H15: 600 | I15: 600 | K15: 9356 | L15: JOCY | M15: Não | R15: =IF(vend13[[#This Row],[Nº Venda]]>1,1,0) -> 1
B16: Total | C16: =SUM(C11:C15) -> 7626.25 | E16: 9505 | F16: FABIO GOMES | G16: CTC | H16: 100 | I16: 100 | K16: 9496 | L16: TATY | M16: Não | R16: =IF(vend13[[#This Row],[Nº Venda]]>1,1,0) -> 1
E17: 9506 | F17: FABIO GOMES | G17: CTC | H17: 100 | I17: 100 | K17: 9481 | L17: ARIANI | M17: Não | R17: =IF(vend13[[#This Row],[Nº Venda]]>1,1,0) -> 1
B18: Entrega de Carne | K18: 9291 | L18: ARIANI | M18: Não | R18: =IF(vend13[[#This Row],[Nº Venda]]>1,1,0) -> 0
B19: =COUNT(entr_carn13[OS]) -> 0 | C19: =SUM(entr_carn13[Valor Total]) -> 0 | K19: 9292 | L19: ARIANI | M19: Não | R19: =IF(vend13[[#This Row],[Nº Venda]]>1,1,0) -> 0
B20: Total | C20: =SUM(C19:C19) -> 0 | K20: 9293 | L20: ARIANI | M20: Não | R20: =IF(vend13[[#This Row],[Nº Venda]]>1,1,0) -> 0
K21: 9378 | L21: ARIANI | M21: Não
B22: Venda | C22: =C5 -> 6188.98 | K22: 9473 | L22: TATY | M22: Não
E24: Restante Entrada
E25: Nº Venda | F25: Cliente | G25: Forma de Pgto | H25: Valor Venda | I25: Entrada
E26: 9496 | F26: ELAINE CRISTINA | G26: PIX | H26: 0 | I26: 49
E27: 9356 | F27: ELENICE ALVES | G27: CTD | H27: 0 | I27: 150
E28: 9291 | F28: ELIANE DA SILVA | G28: CTC | H28: 0 | I28: 965.34
E29: 9292 | F29: ELIANE DA SILVA | G29: CTC | H29: 0 | I29: 80.34
E30: 9293 | F30: ELIANE DA SILVA | G30: CTC | H30: 0 | I30: 54.34
E31: 9293 | F31: ELIANE DA SILVA | G31: DN | H31: 0 | I31: 26
E32: 9378 | F32: LUIZ DE ARAUJO | G32: CTD | H32: 0 | I32: 200
K33: Entrega de Carne
K34: OS | L34: Parcelas | M34: Valor Total
E39: Recebimento de Carnê
E40: OS | F40: Cliente | G40: Forma de Pgto | H40: Valor Parcela | I40: Nº Parcela | Q40: Total de OS | R40: =SUM(R6:R21) -> 12
E41: 9116 | F41: JOSE DE ARAUJO | G41: CTD | H41: 161.25 | I41: PARC. 2/8

Sheet 14
B1: ='13'!B1+1 -> 45487
B2: Fechamento Diário do Caixa
B4: Saldo Inicial | C4: 0 | E4: Vendas | K4: Despesas
B5: Vendas | C5: =SUMIF(I6:I31,">0",H6:H31) -> 0 | E5: Nº Venda | F5: Cliente | G5: Forma de Pgto | H5: Valor Venda | I5: Entrada | K5: Descrição | L5: Tipo de Pagto | M5: Valor
B6: Entrada | C6: =SUM(I6:I41) -> 0 | R6: =IF(vend14[[#This Row],[Nº Venda]]>1,1,0) -> 0
B7: Despesas | C7: =SUM(M6:M11) -> 0 | R7: =IF(vend14[[#This Row],[Nº Venda]]>1,1,0) -> 0
B8: Total entrada | C8: =SUM(C6:C7) -> 0 | R8: =IF(vend14[[#This Row],[Nº Venda]]>1,1,0) -> 0
R9: =IF(vend14[[#This Row],[Nº Venda]]>1,1,0) -> 0
B10: Tipos de Pagtos | R10: =IF(vend14[[#This Row],[Nº Venda]]>1,1,0) -> 0
B11: DN | C11: =(SUMIF($G$2:$G$31,B11,$I$2:$I$31))+(SUMIF($G$35:$G$41,B11,$H$35:$H$41)) -> 0 | O11: =IF(C16=0,0,1) -> 0 | R11: =IF(vend14[[#This Row],[Nº Venda]]>1,1,0) -> 0
B12: CTD | C12: =(SUMIF($G$2:$G$31,B12,$I$2:$I$31))+(SUMIF($G$35:$G$41,B12,$H$35:$H$41)) -> 0 | R12: =IF(vend14[[#This Row],[Nº Venda]]>1,1,0) -> 0
B13: CTC | C13: =(SUMIF($G$2:$G$31,B13,$I$2:$I$31))+(SUMIF($G$35:$G$41,B13,$H$35:$H$41)) -> 0 | K13: OS Entregue no Dia | R13: =IF(vend14[[#This Row],[Nº Venda]]>1,1,0) -> 0
B14: PCTC | C14: =(SUMIF($G$2:$G$31,B14,$I$2:$I$31))+(SUMIF($G$35:$G$41,B14,$H$35:$H$41)) -> 0 | K14: OS | L14: Vendedor | M14: CARNE | R14: =IF(vend14[[#This Row],[Nº Venda]]>1,1,0) -> 0
B15: PIX | C15: =(SUMIF($G$2:$G$31,B15,$I$2:$I$31))+(SUMIF($G$35:$G$41,B15,$H$35:$H$41)) -> 0 | R15: =IF(vend14[[#This Row],[Nº Venda]]>1,1,0) -> 0
B16: Total | C16: =SUM(C11:C15) -> 0 | R16: =IF(vend14[[#This Row],[Nº Venda]]>1,1,0) -> 0
R17: =IF(vend14[[#This Row],[Nº Venda]]>1,1,0) -> 0
B18: Entrega de Carne | R18: =IF(vend14[[#This Row],[Nº Venda]]>1,1,0) -> 0
B19: =COUNT(entr_carn14[OS]) -> 0 | C19: =SUM(entr_carn14[Valor Total]) -> 0 | R19: =IF(vend14[[#This Row],[Nº Venda]]>1,1,0) -> 0
B20: Total | C20: =SUM(C19:C19) -> 0 | R20: =IF(vend14[[#This Row],[Nº Venda]]>1,1,0) -> 0
B22: Venda | C22: =C5 -> 0
E24: Restante Entrada
E25: Nº Venda | F25: Cliente | G25: Forma de Pgto | H25: Valor Venda | I25: Entrada
E33: Recebimento de Carnê | K33: Entrega de Carne
E34: OS | F34: Cliente | G34: Forma de Pgto | H34: Valor Parcela | I34: Nº Parcela | K34: OS | L34: Parcelas | M34: Valor Total
Q40: Total de OS | R40: =SUM(R6:R21) -> 0

Sheet 15
B1: ='14'!B1+1 -> 45488
B2: Fechamento Diário do Caixa
B4: Saldo Inicial | C4: 0 | E4: Vendas | K4: Despesas
B5: Vendas | C5: =SUMIF(I6:I31,">0",H6:H31) -> 7159 | E5: Nº Venda | F5: Cliente | G5: Forma de Pgto | H5: Valor Venda | I5: Entrada | K5: Descrição | L5: Tipo de Pagto | M5: Valor
B6: Entrada | C6: =SUM(I6:I41) -> 5640 | E6: 9507 | F6: maria do carmo | G6: PIX | H6: 530 | I6: 30 | R6: =IF(vend15[[#This Row],[Nº Venda]]>1,1,0) -> 1
B7: Despesas | C7: =SUM(M6:M11) -> 0 | E7: 9508 | F7: sarah regina | G7: DN | H7: 499 | I7: 20 | R7: =IF(vend15[[#This Row],[Nº Venda]]>1,1,0) -> 1
B8: Total entrada | C8: =SUM(C6:C7) -> 5640 | E8: 9508 | F8: sarah regina | G8: CTD | I8: 10 | R8: =IF(vend15[[#This Row],[Nº Venda]]>1,1,0) -> 1
E9: 9509 | F9: pedro vieira | G9: GARANTIA | R9: =IF(vend15[[#This Row],[Nº Venda]]>1,1,0) -> 1
B10: Tipos de Pagtos | E10: 9510 | F10: luiz garcia | G10: CTC | H10: 1600 | I10: 1600 | R10: =IF(vend15[[#This Row],[Nº Venda]]>1,1,0) -> 1
B11: DN | C11: =(SUMIF($G$2:$G$31,B11,$I$2:$I$31))+(SUMIF($G$35:$G$41,B11,$H$35:$H$41)) -> 20 | E11: 9511 | F11: luiz garcia | G11: GARANTIA | O11: =IF(C16=0,0,1) -> 1 | R11: =IF(vend15[[#This Row],[Nº Venda]]>1,1,0) -> 1
B12: CTD | C12: =(SUMIF($G$2:$G$31,B12,$I$2:$I$31))+(SUMIF($G$35:$G$41,B12,$H$35:$H$41)) -> 10 | E12: 9512 | F12: rogerio alves | G12: PIX | H12: 2500 | I12: 2500 | R12: =IF(vend15[[#This Row],[Nº Venda]]>1,1,0) -> 1
B13: CTC | C13: =(SUMIF($G$2:$G$31,B13,$I$2:$I$31))+(SUMIF($G$35:$G$41,B13,$H$35:$H$41)) -> 1600 | E13: 9513 | F13: rogerio alves | G13: SS | K13: OS Entregue no Dia | R13: =IF(vend15[[#This Row],[Nº Venda]]>1,1,0) -> 1
B14: PCTC | C14: =(SUMIF($G$2:$G$31,B14,$I$2:$I$31))+(SUMIF($G$35:$G$41,B14,$H$35:$H$41)) -> 0 | E14: 9514 | F14: rogerio alves | G14: PIX | H14: 1400 | I14: 1400 | K14: OS | L14: Vendedor | M14: CARNE | R14: =IF(vend15[[#This Row],[Nº Venda]]>1,1,0) -> 1
B15: PIX | C15: =(SUMIF($G$2:$G$31,B15,$I$2:$I$31))+(SUMIF($G$35:$G$41,B15,$H$35:$H$41)) -> 4010 | E15: 9515 | F15: rogerio alves | G15: SS | K15: 9457 | L15: JOCY | M15: Não | R15: =IF(vend15[[#This Row],[Nº Venda]]>1,1,0) -> 1
B16: Total | C16: =SUM(C11:C15) -> 5640 | E16: 9516 | F16: diogoo ferreira | G16: PIX | H16: 590 | I16: 40 | K16: 9497 | L16: TATY | M16: Não | R16: =IF(vend15[[#This Row],[Nº Venda]]>1,1,0) -> 1
E17: 9517 | F17: bianca candida | G17: SS | H17: 1000 | R17: =IF(vend15[[#This Row],[Nº Venda]]>1,1,0) -> 1
B18: Entrega de Carne | R18: =IF(vend15[[#This Row],[Nº Venda]]>1,1,0) -> 0
B19: =COUNT(entr_carn15[OS]) -> 0 | C19: =SUM(entr_carn15[Valor Total]) -> 0 | R19: =IF(vend15[[#This Row],[Nº Venda]]>1,1,0) -> 0
B20: Total | C20: =SUM(C19:C19) -> 0 | R20: =IF(vend15[[#This Row],[Nº Venda]]>1,1,0) -> 0
B22: Venda | C22: =C5 -> 7159
E24: Restante Entrada
E25: Nº Venda | F25: Cliente | G25: Forma de Pgto | H25: Valor Venda | I25: Entrada
E26: 9457 | F26: diogo ferreira | G26: PIX | H26: 40 | I26: 40
E33: Recebimento de Carnê | K33: Entrega de Carne
E34: OS | F34: Cliente | G34: Forma de Pgto | H34: Valor Parcela | I34: Nº Parcela | K34: OS | L34: Parcelas | M34: Valor Total
Q40: Total de OS | R40: =SUM(R6:R21) -> 12

Sheet 16
B1: ='15'!B1+1 -> 45489
B2: Fechamento Diário do Caixa
B4: Saldo Inicial | C4: 0 | E4: Vendas | K4: Despesas
B5: Vendas | C5: =SUMIF(I6:I31,">0",H6:H31) -> 2287 | E5: Nº Venda | F5: Cliente | G5: Forma de Pgto | H5: Valor Venda | I5: Entrada | K5: Descrição | L5: Tipo de Pagto | M5: Valor
B6: Entrada | C6: =SUM(I6:I41) -> 1317 | E6: 9518 | F6: VERA LUCIA | G6: CTC | H6: 99 | I6: 99 | R6: =IF(vend16[[#This Row],[Nº Venda]]>1,1,0) -> 1
B7: Despesas | C7: =SUM(M6:M11) -> 0 | E7: 9519 | F7: SUZETE LOPES | G7: CTC | H7: 800 | I7: 800 | R7: =IF(vend16[[#This Row],[Nº Venda]]>1,1,0) -> 1
B8: Total entrada | C8: =SUM(C6:C7) -> 1317 | E8: 9520 | F8: VERONICA | G8: CTD | H8: 199 | I8: 199 | R8: =IF(vend16[[#This Row],[Nº Venda]]>1,1,0) -> 1
E9: 9521 | F9: MANUEL | G9: GARANTIA | R9: =IF(vend16[[#This Row],[Nº Venda]]>1,1,0) -> 1
B10: Tipos de Pagtos | E10: 9522 | F10: DAVID R MACRE | G10: PIX | H10: 90 | I10: 90 | R10: =IF(vend16[[#This Row],[Nº Venda]]>1,1,0) -> 1
B11: DN | C11: =(SUMIF($G$2:$G$31,B11,$I$2:$I$31))+(SUMIF($G$35:$G$41,B11,$H$35:$H$41)) -> 0 | O11: =IF(C16=0,0,1) -> 1 | R11: =IF(vend16[[#This Row],[Nº Venda]]>1,1,0) -> 0
B12: CTD | C12: =(SUMIF($G$2:$G$31,B12,$I$2:$I$31))+(SUMIF($G$35:$G$41,B12,$H$35:$H$41)) -> 199 | R12: =IF(vend16[[#This Row],[Nº Venda]]>1,1,0) -> 0
B13: CTC | C13: =(SUMIF($G$2:$G$31,B13,$I$2:$I$31))+(SUMIF($G$35:$G$41,B13,$H$35:$H$41)) -> 998 | K13: OS Entregue no Dia | R13: =IF(vend16[[#This Row],[Nº Venda]]>1,1,0) -> 0
B14: PCTC | C14: =(SUMIF($G$2:$G$31,B14,$I$2:$I$31))+(SUMIF($G$35:$G$41,B14,$H$35:$H$41)) -> 0 | K14: OS | L14: Vendedor | M14: CARNE | R14: =IF(vend16[[#This Row],[Nº Venda]]>1,1,0) -> 0
B15: PIX | C15: =(SUMIF($G$2:$G$31,B15,$I$2:$I$31))+(SUMIF($G$35:$G$41,B15,$H$35:$H$41)) -> 120 | K15: 9503 | L15: TATY | M15: Sim | R15: =IF(vend16[[#This Row],[Nº Venda]]>1,1,0) -> 0
B16: Total | C16: =SUM(C11:C15) -> 1317 | K16: 9387 | L16: JOCY | M16: Sim | R16: =IF(vend16[[#This Row],[Nº Venda]]>1,1,0) -> 0
R17: =IF(vend16[[#This Row],[Nº Venda]]>1,1,0) -> 0
B18: Entrega de Carne | R18: =IF(vend16[[#This Row],[Nº Venda]]>1,1,0) -> 0
B19: =COUNT(entr_carn16[OS]) -> 0 | C19: =SUM(entr_carn16[Valor Total]) -> 0 | R19: =IF(vend16[[#This Row],[Nº Venda]]>1,1,0) -> 0
B20: Total | C20: =SUM(C19:C19) -> 0 | R20: =IF(vend16[[#This Row],[Nº Venda]]>1,1,0) -> 0
B22: Venda | C22: =C5 -> 2287
E24: Restante Entrada
E25: Nº Venda | F25: Cliente | G25: Forma de Pgto | H25: Valor Venda | I25: Entrada
E26: 9517 | F26: BIANCA CANDIDA | G26: PIX | H26: 1000 | I26: 30
E27: 9503 | F27: SHEILA RIBEIRO | G27: CTC | H27: 99 | I27: 99
E33: Recebimento de Carnê | K33: Entrega de Carne
E34: OS | F34: Cliente | G34: Forma de Pgto | H34: Valor Parcela | I34: Nº Parcela | K34: OS | L34: Parcelas | M34: Valor Total
Q40: Total de OS | R40: =SUM(R6:R21) -> 5

Sheet 17
B1: ='16'!B1+1 -> 45490
B2: Fechamento Diário do Caixa
B4: Saldo Inicial | C4: 0 | E4: Vendas | K4: Despesas
B5: Vendas | C5: =SUMIF(I6:I31,">0",H6:H31) -> 4290 | E5: Nº Venda | F5: Cliente | G5: Forma de Pgto | H5: Valor Venda | I5: Entrada | K5: Descrição | L5: Tipo de Pagto | M5: Valor
B6: Entrada | C6: =SUM(I6:I41) -> 4360 | E6: 9523 | F6: helena aparecida | G6: CTC | H6: 890 | I6: 890 | R6: =IF(vend17[[#This Row],[Nº Venda]]>1,1,0) -> 1
B7: Despesas | C7: =SUM(M6:M11) -> 0 | E7: 9524 | F7: aurivaldo antonio | G7: CTC | H7: 3400 | I7: 3400 | R7: =IF(vend17[[#This Row],[Nº Venda]]>1,1,0) -> 1
B8: Total entrada | C8: =SUM(C6:C7) -> 4360 | E8: 9525 | F8: aurivaldo antonio | G8: SS | R8: =IF(vend17[[#This Row],[Nº Venda]]>1,1,0) -> 1
R9: =IF(vend17[[#This Row],[Nº Venda]]>1,1,0) -> 0
B10: Tipos de Pagtos | R10: =IF(vend17[[#This Row],[Nº Venda]]>1,1,0) -> 0
B11: DN | C11: =(SUMIF($G$2:$G$31,B11,$I$2:$I$31))+(SUMIF($G$35:$G$41,B11,$H$35:$H$41)) -> 20 | O11: =IF(C16=0,0,1) -> 1 | R11: =IF(vend17[[#This Row],[Nº Venda]]>1,1,0) -> 0
B12: CTD | C12: =(SUMIF($G$2:$G$31,B12,$I$2:$I$31))+(SUMIF($G$35:$G$41,B12,$H$35:$H$41)) -> 50 | R12: =IF(vend17[[#This Row],[Nº Venda]]>1,1,0) -> 0
B13: CTC | C13: =(SUMIF($G$2:$G$31,B13,$I$2:$I$31))+(SUMIF($G$35:$G$41,B13,$H$35:$H$41)) -> 4290 | K13: OS Entregue no Dia | R13: =IF(vend17[[#This Row],[Nº Venda]]>1,1,0) -> 0
B14: PCTC | C14: =(SUMIF($G$2:$G$31,B14,$I$2:$I$31))+(SUMIF($G$35:$G$41,B14,$H$35:$H$41)) -> 0 | K14: OS | L14: Vendedor | M14: CARNE | R14: =IF(vend17[[#This Row],[Nº Venda]]>1,1,0) -> 0
B15: PIX | C15: =(SUMIF($G$2:$G$31,B15,$I$2:$I$31))+(SUMIF($G$35:$G$41,B15,$H$35:$H$41)) -> 0 | K15: 9447 | L15: JOCY | M15: Sim | R15: =IF(vend17[[#This Row],[Nº Venda]]>1,1,0) -> 0
B16: Total | C16: =SUM(C11:C15) -> 4360 | K16: 9018 | L16: ARIANI | M16: Sim | R16: =IF(vend17[[#This Row],[Nº Venda]]>1,1,0) -> 0
K17: 9477 | L17: ARIANI | M17: Não | R17: =IF(vend17[[#This Row],[Nº Venda]]>1,1,0) -> 0
B18: Entrega de Carne | K18: 9462 | L18: JOCY | M18: Não | R18: =IF(vend17[[#This Row],[Nº Venda]]>1,1,0) -> 0
B19: =COUNT(entr_carn17[OS]) -> 2 | C19: =SUM(entr_carn17[Valor Total]) -> 640 | K19: 9468 | L19: JOCY | M19: Não | R19: =IF(vend17[[#This Row],[Nº Venda]]>1,1,0) -> 0
B20: Total | C20: =SUM(C19:C19) -> 640 | K20: 9459 | L20: ARIANI | M20: Não | R20: =IF(vend17[[#This Row],[Nº Venda]]>1,1,0) -> 0
K21: 9458 | L21: ARIANI | M21: Não
B22: Venda | C22: =C5 -> 4290
E24: Restante Entrada
E25: Nº Venda | F25: Cliente | G25: Forma de Pgto | H25: Valor Venda | I25: Entrada
E26: 9447 | F26: marinalva beserra | G26: DN | H26: 0 | I26: 20
E28: 9018 | F28: ilda soares | G28: CTD | H28: 0 | I28: 50
E33: Recebimento de Carnê | K33: Entrega de Carne
E34: OS | F34: Cliente | G34: Forma de Pgto | H34: Valor Parcela | I34: Nº Parcela | K34: OS | L34: Parcelas | M34: Valor Total
K35: 9447 | L35: 7 | M35: 140
K36: 9018 | L36: 5 | M36: 500
Q40: Total de OS | R40: =SUM(R6:R21) -> 3

Sheet 18
B1: ='17'!B1+1 -> 45491
B2: Fechamento Diário do Caixa
B4: Saldo Inicial | C4: 0 | E4: Vendas | K4: Despesas
B5: Vendas | C5: =SUMIF(I6:I31,">0",H6:H31) -> 2980 | E5: Nº Venda | F5: Cliente | G5: Forma de Pgto | H5: Valor Venda | I5: Entrada | K5: Descrição | L5: Tipo de Pagto | M5: Valor
B6: Entrada | C6: =SUM(I6:I41) -> 1900 | E6: 9526 | F6: aline cunha | G6: PIX | H6: 300 | I6: 300 | R6: =IF(vend18[[#This Row],[Nº Venda]]>1,1,0) -> 1
B7: Despesas | C7: =SUM(M6:M11) -> 0 | E7: 9527 | F7: wesley da silva | G7: PIX | H7: 2500 | I7: 600 | R7: =IF(vend18[[#This Row],[Nº Venda]]>1,1,0) -> 1
B8: Total entrada | C8: =SUM(C6:C7) -> 1900 | E8: 9528 | F8: claudionor | G8: PIX | H8: 180 | I8: 50 | R8: =IF(vend18[[#This Row],[Nº Venda]]>1,1,0) -> 1
R9: =IF(vend18[[#This Row],[Nº Venda]]>1,1,0) -> 0
B10: Tipos de Pagtos | R10: =IF(vend18[[#This Row],[Nº Venda]]>1,1,0) -> 0
B11: DN | C11: =(SUMIF($G$2:$G$31,B11,$I$2:$I$31))+(SUMIF($G$35:$G$41,B11,$H$35:$H$41)) -> 0 | O11: =IF(C16=0,0,1) -> 1 | R11: =IF(vend18[[#This Row],[Nº Venda]]>1,1,0) -> 0
B12: CTD | C12: =(SUMIF($G$2:$G$31,B12,$I$2:$I$31))+(SUMIF($G$35:$G$41,B12,$H$35:$H$41)) -> 0 | R12: =IF(vend18[[#This Row],[Nº Venda]]>1,1,0) -> 0
B13: CTC | C13: =(SUMIF($G$2:$G$31,B13,$I$2:$I$31))+(SUMIF($G$35:$G$41,B13,$H$35:$H$41)) -> 700 | K13: OS Entregue no Dia | R13: =IF(vend18[[#This Row],[Nº Venda]]>1,1,0) -> 0
B14: PCTC | C14: =(SUMIF($G$2:$G$31,B14,$I$2:$I$31))+(SUMIF($G$35:$G$41,B14,$H$35:$H$41)) -> 0 | K14: OS | L14: Vendedor | M14: CARNE | R14: =IF(vend18[[#This Row],[Nº Venda]]>1,1,0) -> 0
B15: PIX | C15: =(SUMIF($G$2:$G$31,B15,$I$2:$I$31))+(SUMIF($G$35:$G$41,B15,$H$35:$H$41)) -> 1200 | K15: 9401 | L15: ARIANI | M15: Não | R15: =IF(vend18[[#This Row],[Nº Venda]]>1,1,0) -> 0
B16: Total | C16: =SUM(C11:C15) -> 1900 | K16: 9299 | L16: ARIANI | M16: Não | R16: =IF(vend18[[#This Row],[Nº Venda]]>1,1,0) -> 0
K17: 9453 | L17: JOCY | M17: Não | R17: =IF(vend18[[#This Row],[Nº Venda]]>1,1,0) -> 0
B18: Entrega de Carne | K18: 9455 | L18: ARIANI | M18: Não | R18: =IF(vend18[[#This Row],[Nº Venda]]>1,1,0) -> 0
B19: =COUNT(entr_carn18[OS]) -> 0 | C19: =SUM(entr_carn18[Valor Total]) -> 0 | K19: 9026 | L19: JOCY | M19: Não | R19: =IF(vend18[[#This Row],[Nº Venda]]>1,1,0) -> 0
B20: Total | C20: =SUM(C19:C19) -> 0 | R20: =IF(vend18[[#This Row],[Nº Venda]]>1,1,0) -> 0
B22: Venda | C22: =C5 -> 2980
E24: Restante Entrada
E25: Nº Venda | F25: Cliente | G25: Forma de Pgto | H25: Valor Venda | I25: Entrada
E26: 9401 | F26: silvia regina | G26: CTC | I26: 700
E27: 9471 | F27: maria ivani | G27: PIX | I27: 150
E28: 9026 | F28: ires dos santos | G28: PIX | I28: 100
E33: Recebimento de Carnê | K33: Entrega de Carne
