Workbook

Sheet resumo_cx
P1: Colaboradores
A2: Saldo Inicial | B2: 0 | P2: ROGÉRIO
A3: Vendas | B3: =SUM('01'!C5,'02'!C5,'03'!C5,'04'!C5,'05'!C5,'06'!C5,'07'!C5,'08'!C5,'09'!C5,'10'!C5,'11'!C5,'12'!C5,'13'!C5,'14'!C5,'15'!C5,'16'!C5,'17'!C5,'18'!C5,'19'!C5,'20'!C5,'21'!C5,'22'!C5,'23'!C5,'24'!C5,'25'!C5,'26'!C5,'27'!C5,'28'!C5,'29'!C5,'30'!C5,'31'!C5) -> 75719 | P3: JOCY
A4: Entrada | B4: =SUM('01'!C6,'02'!C6,'03'!C6,'04'!C6,'05'!C6,'06'!C6,'07'!C6,'08'!C6,'09'!C6,'10'!C6,'11'!C6,'12'!C6,'13'!C6,'14'!C6,'15'!C6,'16'!C6,'17'!C6,'18'!C6,'19'!C6,'20'!C6,'21'!C6,'22'!C6,'23'!C6,'24'!C6,'25'!C6,'26'!C6,'27'!C6,'28'!C6,'29'!C6,'30'!C6,'31'!C6) -> 70210 | P4: MARIA
A5: Despesas | B5: =SUM('01'!C7,'02'!C7,'03'!C7,'04'!C7,'05'!C7,'06'!C7,'07'!C7,'08'!C7,'09'!C7,'10'!C7,'11'!C7,'12'!C7,'13'!C7,'14'!C7,'15'!C7,'16'!C7,'17'!C7,'18'!C7,'19'!C7,'20'!C7,'21'!C7,'22'!C7,'23'!C7,'24'!C7,'25'!C7,'26'!C7,'27'!C7,'28'!C7,'29'!C7,'30'!C7,'31'!C7) -> 1161 | P5: WEVILLY
A6: Entr_Desp | B6: =SUM(B4:B5) -> 71371 | P6: BETH
P7: ARIANI
A8: Tipos de Pagtos | P8: ROSÂNGELA
A9: DN | B9: =SUM('01'!C11,'02'!C11,'03'!C11,'04'!C11,'05'!C11,'06'!C11,'07'!C11,'08'!C11,'09'!C11,'10'!C11,'11'!C11,'12'!C11,'13'!C11,'14'!C11,'15'!C11,'16'!C11,'17'!C11,'18'!C11,'19'!C11,'20'!C11,'21'!C11,'22'!C11,'23'!C11,'24'!C11,'25'!C11,'26'!C11,'27'!C11,'28'!C11,'29'!C11,'30'!C11,'31'!C11) -> 8839.98 | P9: TATY
A10: CTD | B10: =SUM('01'!C12,'02'!C12,'03'!C12,'04'!C12,'05'!C12,'06'!C12,'07'!C12,'08'!C12,'09'!C12,'10'!C12,'11'!C12,'12'!C12,'13'!C12,'14'!C12,'15'!C12,'16'!C12,'17'!C12,'18'!C12,'19'!C12,'20'!C12,'21'!C12,'22'!C12,'23'!C12,'24'!C12,'25'!C12,'26'!C12,'27'!C12,'28'!C12,'29'!C12,'30'!C12,'31'!C12) -> 13905.47 | P10: LARISSA
A11: CTC | B11: =SUM('01'!C13,'02'!C13,'03'!C13,'04'!C13,'05'!C13,'06'!C13,'07'!C13,'08'!C13,'09'!C13,'10'!C13,'11'!C13,'12'!C13,'13'!C13,'14'!C13,'15'!C13,'16'!C13,'17'!C13,'18'!C13,'19'!C13,'20'!C13,'21'!C13,'22'!C13,'23'!C13,'24'!C13,'25'!C13,'26'!C13,'27'!C13,'28'!C13,'29'!C13,'30'!C13,'31'!C13) -> 44613 | P11: ERIKA
A12: PCTC | B12: =SUM('01'!C14,'02'!C14,'03'!C14,'04'!C14,'05'!C14,'06'!C14,'07'!C14,'08'!C14,'09'!C14,'10'!C14,'11'!C14,'12'!C14,'13'!C14,'14'!C14,'15'!C14,'16'!C14,'17'!C14,'18'!C14,'19'!C14,'20'!C14,'21'!C14,'22'!C14,'23'!C14,'24'!C14,'25'!C14,'26'!C14,'27'!C14,'28'!C14,'29'!C14,'30'!C14,'31'!C14) -> 0 | P12: LUANA
A13: PIX | B13: =SUM('01'!C15,'02'!C15,'03'!C15,'04'!C15,'05'!C15,'06'!C15,'07'!C15,'08'!C15,'09'!C15,'10'!C15,'11'!C15,'12'!C15,'13'!C15,'14'!C15,'15'!C15,'16'!C15,'17'!C15,'18'!C15,'19'!C15,'20'!C15,'21'!C15,'22'!C15,'23'!C15,'24'!C15,'25'!C15,'26'!C15,'27'!C15,'28'!C15,'29'!C15,'30'!C15,'31'!C15) -> 13324.91 | P13: FELIPE
A14: Total | B14: =SUM(B9:B13) -> 80683.36
A16: Entrega de Carne
A17: =COUNT(#REF!) -> 0 | B17: =SUM('01'!C19,'02'!C19,'03'!C19,'04'!C19,'05'!C19,'06'!C19,'07'!C19,'08'!C19,'09'!C19,'10'!C19,'11'!C19,'12'!C19,'13'!C19,'14'!C19,'15'!C19,'16'!C19,'17'!C19,'18'!C19,'19'!C19,'20'!C19,'21'!C19,'22'!C19,'23'!C19,'24'!C19,'25'!C19,'26'!C19,'27'!C19,'28'!C19,'29'!C19,'30'!C19,'31'!C19) -> 11231
A18: Total | B18: =SUM(B17:B17) -> 11231

Sheet 01
B1: 45566
B2: Fechamento Diário do Caixa - Escritório
B4: Saldo Inicial | C4: 0 | E4: Vendas | K4: Despesas
B5: Vendas | C5: =SUMIF(I6:I31,">0",H6:H31) -> 5115 | E5: Nº Venda | F5: Cliente | G5: Forma de Pgto | H5: Valor Venda | I5: Entrada | K5: Descrição | L5: Tipo de Pagto | M5: Valor
B6: Entrada | C6: =SUM(I6:I41) -> 4815 | E6: 9854 | F6: reginaldo francisco | G6: DN | H6: 45 | I6: 45 | R6: =IF(vend1[[#This Row],[Nº Venda]]>1,1,0) -> 1
B7: Despesas | C7: =SUM(M6:M11) -> 0 | E7: 9855 | F7: jose ernesto | G7: DN | H7: 500 | I7: 200 | R7: =IF(vend1[[#This Row],[Nº Venda]]>1,1,0) -> 1
B8: Total entrada | C8: =SUM(C6:C7) -> 4815 | E8: 9856 | F8: elson rodrigues | G8: CTC | H8: 1380 | I8: 1380 | R8: =IF(vend1[[#This Row],[Nº Venda]]>1,1,0) -> 1
E9: 9857 | F9: roseli oblasser | G9: CTD | H9: 2850 | I9: 2850 | R9: =IF(vend1[[#This Row],[Nº Venda]]>1,1,0) -> 1
B10: Tipos de Pagtos | E10: 9858 | F10: roseli oblasser | G10: CTD | H10: 340 | I10: 340 | R10: =IF(vend1[[#This Row],[Nº Venda]]>1,1,0) -> 1
B11: DN | C11: =(SUMIF($G$2:$G$31,B11,$I$2:$I$31))+(SUMIF($G$35:$G$41,B11,$H$35:$H$41)) -> 1175 | E11: 9859 | F11: roseli oblasser | G11: CTC | H11: ss | O11: =IF(C16=0,0,1) -> 1 | R11: =IF(vend1[[#This Row],[Nº Venda]]>1,1,0) -> 1
B12: CTD | C12: =(SUMIF($G$2:$G$31,B12,$I$2:$I$31))+(SUMIF($G$35:$G$41,B12,$H$35:$H$41)) -> 3190 | R12: =IF(vend1[[#This Row],[Nº Venda]]>1,1,0) -> 0
B13: CTC | C13: =(SUMIF($G$2:$G$31,B13,$I$2:$I$31))+(SUMIF($G$35:$G$41,B13,$H$35:$H$41)) -> 1380 | K13: OS Entregue no Dia | R13: =IF(vend1[[#This Row],[Nº Venda]]>1,1,0) -> 0
B14: PCTC | C14: =(SUMIF($G$2:$G$31,B14,$I$2:$I$31))+(SUMIF($G$35:$G$41,B14,$H$35:$H$41)) -> 0 | K14: OS | L14: Vendedor | M14: CARNE | R14: =IF(vend1[[#This Row],[Nº Venda]]>1,1,0) -> 0
B15: PIX | C15: =(SUMIF($G$2:$G$31,B15,$I$2:$I$31))+(SUMIF($G$35:$G$41,B15,$H$35:$H$41)) -> 166.66 | K15: 9788 | L15: JOCY | M15: Não | R15: =IF(vend1[[#This Row],[Nº Venda]]>1,1,0) -> 0
B16: Total | C16: =SUM(C11:C15) -> 5911.66 | K16: 9835 | L16: JOCY | M16: Não | R16: =IF(vend1[[#This Row],[Nº Venda]]>1,1,0) -> 0
K17: 9854 | L17: ARIANI | M17: Não | R17: =IF(vend1[[#This Row],[Nº Venda]]>1,1,0) -> 0
B18: Entrega de Carne | K18: 9849 | L18: ARIANI | M18: Não | R18: =IF(vend1[[#This Row],[Nº Venda]]>1,1,0) -> 0
B19: =COUNT(entr_carn31195[OS]) -> 0 | C19: =SUM(entr_carn31195[Valor Total]) -> 0 | R19: =IF(vend1[[#This Row],[Nº Venda]]>1,1,0) -> 0
B20: Total | C20: =SUM(C19:C19) -> 0 | R20: =IF(vend1[[#This Row],[Nº Venda]]>1,1,0) -> 0
B22: Venda | C22: =C5 -> 5115
E24: Restante Entrada
E25: Nº Venda | F25: Cliente | G25: Forma de Pgto | H25: Valor Venda | I25: Entrada
E33: Recebimento de Carnê | K33: Entrega de Carne
E34: OS | F34: Cliente | G34: Forma de Pgto | H34: Valor Parcela | I34: Nº Parcela | K34: OS | L34: Parcelas | M34: Valor Total
E35: 6336 | F35: edna madalena | G35: DN | H35: 155 | I35: PARC. 1/6
E36: 6336 | F36: edna madalena | G36: DN | H36: 155 | I36: PARC. 2/6
E37: 6336 | F37: edna madalena | G37: DN | H37: 155 | I37: PARC. 3/6
E38: 6336 | F38: edna madalena | G38: DN | H38: 155 | I38: PARC. 4/6
E39: 6336 | F39: edna madalena | G39: DN | H39: 155 | I39: PARC. 5/6
E40: 6336 | F40: edna madalena | G40: DN | H40: 155 | I40: PARC. 6/6 | Q40: Total de OS | R40: =SUM(R6:R21) -> 6
E41: 9308 | F41: jaqueline dos santos | G41: PIX | H41: 166.66 | I41: PARC. 2/6

Sheet 02
B1: ='01'!B1+1 -> 45567
B2: Fechamento Diário do Caixa
B4: Saldo Inicial | C4: 0 | E4: Vendas | K4: Despesas
B5: Vendas | C5: =SUMIF(I6:I31,">0",H6:H31) -> 2150 | E5: Nº Venda | F5: Cliente | G5: Forma de Pgto | H5: Valor Venda | I5: Entrada | K5: Descrição | L5: Tipo de Pagto | M5: Valor
B6: Entrada | C6: =SUM(I6:I41) -> 2085 | E6: 9860 | F6: adriana aparecida | G6: PIX | H6: 800 | I6: 125 | R6: =IF(vend2[[#This Row],[Nº Venda]]>1,1,0) -> 1
B7: Despesas | C7: =SUM(M6:M11) -> 0 | E7: 9861 | F7: neuma carvalho | G7: CTC | H7: 900 | I7: 900 | R7: =IF(vend2[[#This Row],[Nº Venda]]>1,1,0) -> 1
B8: Total entrada | C8: =SUM(C6:C7) -> 2085 | E8: 9862 | F8: karen francine | G8: CTC | H8: 450 | I8: 450 | R8: =IF(vend2[[#This Row],[Nº Venda]]>1,1,0) -> 1
R9: =IF(vend2[[#This Row],[Nº Venda]]>1,1,0) -> 0
B10: Tipos de Pagtos | R10: =IF(vend2[[#This Row],[Nº Venda]]>1,1,0) -> 0
B11: DN | C11: =(SUMIF($G$2:$G$31,B11,$I$2:$I$31))+(SUMIF($G$35:$G$44,B11,$H$35:$H$44)) -> 100 | O11: =IF(C16=0,0,1) -> 1 | R11: =IF(vend2[[#This Row],[Nº Venda]]>1,1,0) -> 0
B12: CTD | C12: =(SUMIF($G$2:$G$31,B12,$I$2:$I$31))+(SUMIF($G$35:$G$44,B12,$H$35:$H$44)) -> 403.2 | R12: =IF(vend2[[#This Row],[Nº Venda]]>1,1,0) -> 0
B13: CTC | C13: =(SUMIF($G$2:$G$31,B13,$I$2:$I$31))+(SUMIF($G$35:$G$44,B13,$H$35:$H$44)) -> 1350 | K13: OS Entregue no Dia | R13: =IF(vend2[[#This Row],[Nº Venda]]>1,1,0) -> 0
B14: PCTC | C14: =(SUMIF($G$2:$G$31,B14,$I$2:$I$31))+(SUMIF($G$35:$G$44,B14,$H$35:$H$44)) -> 0 | K14: OS | L14: Vendedor | M14: CARNE | R14: =IF(vend2[[#This Row],[Nº Venda]]>1,1,0) -> 0
B15: PIX | C15: =(SUMIF($G$2:$G$31,B15,$I$2:$I$31))+(SUMIF($G$35:$G$44,B15,$H$35:$H$44)) -> 1312.84 | K15: 9813 | L15: JOCY | M15: Não | R15: =IF(vend2[[#This Row],[Nº Venda]]>1,1,0) -> 0
B16: Total | C16: =SUM(C11:C15) -> 3166.04 | K16: 9808 | L16: ARIANI | M16: Não | R16: =IF(vend2[[#This Row],[Nº Venda]]>1,1,0) -> 0
K17: 9817 | L17: ARIANI | M17: Não | R17: =IF(vend2[[#This Row],[Nº Venda]]>1,1,0) -> 0
B18: Entrega de Carne | K18: 9734 | L18: JOCY | M18: Não | R18: =IF(vend2[[#This Row],[Nº Venda]]>1,1,0) -> 0
B19: =COUNT(entr_carn2[OS]) -> 1 | C19: =SUM(entr_carn2[Valor Total]) -> 1080 | K19: 9758 | L19: JOCY | M19: Sim | R19: =IF(vend2[[#This Row],[Nº Venda]]>1,1,0) -> 0
B20: Total | C20: =SUM(C19:C19) -> 1080 | K20: 9757 | L20: JOCY | M20: Sim | R20: =IF(vend2[[#This Row],[Nº Venda]]>1,1,0) -> 0
B22: Venda | C22: =C5 -> 2150
E24: Restante Entrada
E25: Nº Venda | F25: Cliente | G25: Forma de Pgto | H25: Valor Venda | I25: Entrada
E26: 9817 | F26: ulisses roberto | G26: PIX | I26: 250
E27: 9757 | F27: carlinhos ferreira | G27: PIX | I27: 200
E28: 9758 | F28: carlinhos ferreira | G28: PIX | I28: 160
E33: Recebimento de Carnê | K33: Entrega de Carne
E34: OS | F34: Cliente | G34: Forma de Pgto | H34: Valor Parcela | I34: Nº Parcela | K34: OS | L34: Parcelas | M34: Valor Total | U34: V
E35: 9494 | F35: mariana rosa | G35: CTD | H35: 150 | I35: PARC. 2/6 | K35: 9757 | L35: 6 | M35: 1080
E36: 8104 | F36: marilu senziali | G36: PIX | H36: 170 | I36: PARC. 4/7
E37: 8479 | F37: kawany chaves | G37: PIX | H37: 145 | I37: PARC. 1/3
E38: 9305 | F38: ailton barbosa | G38: CTD | H38: 70 | I38: PARC. 4/6
E39: 9436 | F39: luiza jaqueline | G39: CTD | H39: 124.87 | I39: PARC. 3/8
B40: 98 | E40: 9093 | F40: veraci eloisa | G40: CTD | H40: 58.33 | I40: PARC. 4/6 | Q40: Total de OS | R40: =SUM(R6:R21) -> 3
E41: 9104 | F41: fabiana de souza | G41: PIX | H41: 57.14 | I41: PARC. 5/7
E42: 8847 | F42: jose santos | G42: PIX | H42: 102.85 | I42: PARC. 6/7
E43: 8847 | F43: jose santos | G43: PIX | H43: 102.85 | I43: PARC. 7/7
E44: 9289 | F44: julcimara aparecida | G44: DN | H44: 100 | I44: PARC. 3/6

Sheet 03
B1: ='02'!B1+1 -> 45568
B2: Fechamento Diário do Caixa
B4: Saldo Inicial | C4: 0 | E4: Vendas | K4: Despesas
B5: Vendas | C5: =SUMIF(I6:I31,">0",H6:H31) -> 2170 | E5: Nº Venda | F5: Cliente | G5: Forma de Pgto | H5: Valor Venda | I5: Entrada | K5: Descrição | L5: Tipo de Pagto | M5: Valor
B6: Entrada | C6: =SUM(I6:I41) -> 2470 | E6: 9863 | F6: antonio carmo | G6: DN | H6: 1000 | I6: 200 | R6: =IF(vend3[[#This Row],[Nº Venda]]>1,1,0) -> 1
B7: Despesas | C7: =SUM(M6:M11) -> 0 | E7: 9864 | F7: fernanda de souza | G7: CTC | H7: 700 | I7: 700 | R7: =IF(vend3[[#This Row],[Nº Venda]]>1,1,0) -> 1
B8: Total entrada | C8: =SUM(C6:C7) -> 2470 | E8: 9865 | F8: ildeni macena | G8: CTC | H8: 350 | I8: 350 | R8: =IF(vend3[[#This Row],[Nº Venda]]>1,1,0) -> 1
E9: 9866 | F9: sela regina | G9: CTC | H9: 120 | I9: 120 | R9: =IF(vend3[[#This Row],[Nº Venda]]>1,1,0) -> 1
B10: Tipos de Pagtos | R10: =IF(vend3[[#This Row],[Nº Venda]]>1,1,0) -> 0
B11: DN | C11: =(SUMIF($G$2:$G$31,B11,$I$2:$I$31))+(SUMIF($G$35:$G$41,B11,$H$35:$H$41)) -> 1098 | O11: =IF(C16=0,0,1) -> 1 | R11: =IF(vend3[[#This Row],[Nº Venda]]>1,1,0) -> 0
B12: CTD | C12: =(SUMIF($G$2:$G$31,B12,$I$2:$I$31))+(SUMIF($G$35:$G$41,B12,$H$35:$H$41)) -> 0 | R12: =IF(vend3[[#This Row],[Nº Venda]]>1,1,0) -> 0
B13: CTC | C13: =(SUMIF($G$2:$G$31,B13,$I$2:$I$31))+(SUMIF($G$35:$G$41,B13,$H$35:$H$41)) -> 1270 | K13: OS Entregue no Dia | R13: =IF(vend3[[#This Row],[Nº Venda]]>1,1,0) -> 0
B14: PCTC | C14: =(SUMIF($G$2:$G$31,B14,$I$2:$I$31))+(SUMIF($G$35:$G$41,B14,$H$35:$H$41)) -> 0 | K14: OS | L14: Vendedor | M14: CARNE | R14: =IF(vend3[[#This Row],[Nº Venda]]>1,1,0) -> 0
B15: PIX | C15: =(SUMIF($G$2:$G$31,B15,$I$2:$I$31))+(SUMIF($G$35:$G$41,B15,$H$35:$H$41)) -> 212.12 | K15: 9742 | L15: JOCY | M15: Não | R15: =IF(vend3[[#This Row],[Nº Venda]]>1,1,0) -> 0
B16: Total | C16: =SUM(C11:C15) -> 2580.12 | K16: 9838 | L16: TATY | M16: Não | R16: =IF(vend3[[#This Row],[Nº Venda]]>1,1,0) -> 0
K17: 9824 | L17: ARIANI | M17: Não | R17: =IF(vend3[[#This Row],[Nº Venda]]>1,1,0) -> 0
B18: Entrega de Carne | K18: 9840 | L18: TATY | M18: Não | R18: =IF(vend3[[#This Row],[Nº Venda]]>1,1,0) -> 0
B19: =COUNT(entr_carn3[OS]) -> 0 | C19: =SUM(entr_carn3[Valor Total]) -> 0 | K19: 9794 | L19: ARIANI | M19: Não | R19: =IF(vend3[[#This Row],[Nº Venda]]>1,1,0) -> 0
B20: Total | C20: =SUM(C19:C19) -> 0 | R20: =IF(vend3[[#This Row],[Nº Venda]]>1,1,0) -> 0
B22: Venda | C22: =C5 -> 2170
E24: Restante Entrada
E25: Nº Venda | F25: Cliente | G25: Forma de Pgto | H25: Valor Venda | I25: Entrada
E26: 9840 | F26: pedro augusto | G26: DN | I26: 298
E27: 9840 | F27: pedro augusto | G27: PIX | I27: 102
E28: 9838 | F28: celia cristina | G28: DN | I28: 150
E29: 9838 | F29: celia cristina | G29: CTC | I29: 100
E30: 9742 | F30: carol vieira | G30: DN | I30: 450
E33: Recebimento de Carnê | K33: Entrega de Carne
E34: OS | F34: Cliente | G34: Forma de Pgto | H34: Valor Parcela | I34: Nº Parcela | K34: OS | L34: Parcelas | M34: Valor Total
E35: 9375 | F35: carmelina da conceição | G35: PIX | H35: 110.12 | I35: PARC. 3/8
Q40: Total de OS | R40: =SUM(R6:R21) -> 4

Sheet 04
B1: ='03'!B1+1 -> 45569
B2: Fechamento Diário do Caixa
B4: Saldo Inicial | C4: 0 | E4: Vendas | K4: Despesas
B5: Vendas | C5: =SUMIF(I6:I31,">0",H6:H31) -> 5277 | E5: Nº Venda | F5: Cliente | G5: Forma de Pgto | H5: Valor Venda | I5: Entrada | K5: Descrição | L5: Tipo de Pagto | M5: Valor
B6: Entrada | C6: =SUM(I6:I41) -> 4478 | E6: 9867 | F6: luciana teixeira | G6: SS | H6: 699 | K6: junior | L6: dn | M6: 11 | R6: =IF(vend4[[#This Row],[Nº Venda]]>1,1,0) -> 1
B7: Despesas | C7: =SUM(M6:M11) -> 11 | E7: 9868 | F7: victor kunika | G7: CTD | H7: 489 | I7: 489 | R7: =IF(vend4[[#This Row],[Nº Venda]]>1,1,0) -> 1
B8: Total entrada | C8: =SUM(C6:C7) -> 4489 | E8: 9869 | F8: inacio jose | G8: CTC | H8: 450 | I8: 450 | R8: =IF(vend4[[#This Row],[Nº Venda]]>1,1,0) -> 1
E9: 9870 | F9: douglas | G9: CTC | H9: 189 | I9: 189 | R9: =IF(vend4[[#This Row],[Nº Venda]]>1,1,0) -> 1
B10: Tipos de Pagtos | E10: 9871 | F10: paloma cristina | G10: SS | H10: 1400 | R10: =IF(vend4[[#This Row],[Nº Venda]]>1,1,0) -> 1
B11: DN | C11: =(SUMIF($G$2:$G$31,B11,$I$2:$I$31))+(SUMIF($G$35:$G$41,B11,$H$35:$H$41)) -> 148.33 | E11: 9872 | F11: marcos cesar | G11: CTC | H11: 500 | I11: 500 | O11: =IF(C16=0,0,1) -> 1 | R11: =IF(vend4[[#This Row],[Nº Venda]]>1,1,0) -> 1
B12: CTD | C12: =(SUMIF($G$2:$G$31,B12,$I$2:$I$31))+(SUMIF($G$35:$G$41,B12,$H$35:$H$41)) -> 489 | E12: 9873 | F12: marcos cesar | G12: CTC | H12: 500 | I12: 500 | R12: =IF(vend4[[#This Row],[Nº Venda]]>1,1,0) -> 1
B13: CTC | C13: =(SUMIF($G$2:$G$31,B13,$I$2:$I$31))+(SUMIF($G$35:$G$41,B13,$H$35:$H$41)) -> 3989 | E13: 9874 | F13: elza dias | G13: CTC | H13: 899 | I13: 100 | K13: OS Entregue no Dia | R13: =IF(vend4[[#This Row],[Nº Venda]]>1,1,0) -> 1
B14: PCTC | C14: =(SUMIF($G$2:$G$31,B14,$I$2:$I$31))+(SUMIF($G$35:$G$41,B14,$H$35:$H$41)) -> 0 | E14: 9875 | F14: andreia de oliveira | G14: CTC | H14: 1900 | I14: 1900 | K14: OS | L14: Vendedor | M14: CARNE | R14: =IF(vend4[[#This Row],[Nº Venda]]>1,1,0) -> 1
B15: PIX | C15: =(SUMIF($G$2:$G$31,B15,$I$2:$I$31))+(SUMIF($G$35:$G$41,B15,$H$35:$H$41)) -> 649.82 | E15: 9876 | F15: andreia de oliveira | G15: SS | H15: 0 | I15: 0 | K15: 9741 | L15: JOCY | M15: Não | R15: =IF(vend4[[#This Row],[Nº Venda]]>1,1,0) -> 1
B16: Total | C16: =SUM(C11:C15) -> 5276.15 | E16: 9877 | F16: aline da silva | G16: CTC | H16: 350 | I16: 350 | K16: 9829 | L16: TATY | M16: Não | R16: =IF(vend4[[#This Row],[Nº Venda]]>1,1,0) -> 1
K17: 9853 | L17: ARIANI | M17: Não | R17: =IF(vend4[[#This Row],[Nº Venda]]>1,1,0) -> 0
B18: Entrega de Carne | K18: 9851 | L18: ARIANI | M18: Não | R18: =IF(vend4[[#This Row],[Nº Venda]]>1,1,0) -> 0
B19: =COUNT(entr_carn4[OS]) -> 0 | C19: =SUM(entr_carn4[Valor Total]) -> 0 | R19: =IF(vend4[[#This Row],[Nº Venda]]>1,1,0) -> 0
B20: Total | C20: =SUM(C19:C19) -> 0 | R20: =IF(vend4[[#This Row],[Nº Venda]]>1,1,0) -> 0
B22: Venda | C22: =C5 -> 5277
E24: Restante Entrada
E25: Nº Venda | F25: Cliente | G25: Forma de Pgto | H25: Valor Venda | I25: Entrada
E33: Recebimento de Carnê | K33: Entrega de Carne
E34: OS | F34: Cliente | G34: Forma de Pgto | H34: Valor Parcela | I34: Nº Parcela | K34: OS | L34: Parcelas | M34: Valor Total
E35: 9645 | F35: diego perez | G35: PIX | H35: 166.66 | I35: PARC. 2/6
E36: 9725 | F36: ana paula | G36: PIX | H36: 166.5 | I36: PARC. 1/6
E37: 9018 | F37: ilda soares | G37: DN | H37: 100 | I37: PARC. 2/5
E38: 9374 | F38: sara de quadros | G38: DN | H38: 48.33 | I38: PARC. 1/6
E39: 9723 | F39: darci alice | G39: PIX | H39: 91.66 | I39: PARC. 1/6
E40: 9012 | F40: silas diego | G40: PIX | H40: 225 | I40: PARC. 5/6 | Q40: Total de OS | R40: =SUM(R6:R21) -> 11

Sheet 05
B1: ='04'!B1+1 -> 45570
B2: Fechamento Diário do Caixa
B4: Saldo Inicial | C4: 0 | E4: Vendas | K4: Despesas
B5: Vendas | C5: =SUMIF(I6:I31,">0",H6:H31) -> 6044 | E5: Nº Venda | F5: Cliente | G5: Forma de Pgto | H5: Valor Venda | I5: Entrada | K5: Descrição | L5: Tipo de Pagto | M5: Valor
B6: Entrada | C6: =SUM(I6:I41) -> 6044 | E6: 9878 | F6: denise adriane | G6: CTC | H6: 2000 | I6: 1350 | R6: =IF(vend5[[#This Row],[Nº Venda]]>1,1,0) -> 1
B7: Despesas | C7: =SUM(M6:M11) -> 0 | E7: 9878 | F7: denise adriane | G7: CTD | I7: 650 | R7: =IF(vend5[[#This Row],[Nº Venda]]>1,1,0) -> 1
B8: Total entrada | C8: =SUM(C6:C7) -> 6044 | E8: 9879 | F8: denise adriane | G8: CTD | H8: 150 | I8: 150 | R8: =IF(vend5[[#This Row],[Nº Venda]]>1,1,0) -> 1
E9: 9880 | F9: denise adriane | G9: CTC | H9: 500 | I9: 500 | R9: =IF(vend5[[#This Row],[Nº Venda]]>1,1,0) -> 1
B10: Tipos de Pagtos | E10: 9881 | F10: maria helena | G10: CTD | H10: 509 | I10: 509 | R10: =IF(vend5[[#This Row],[Nº Venda]]>1,1,0) -> 1
B11: DN | C11: =(SUMIF($G$2:$G$31,B11,$I$2:$I$31))+(SUMIF($G$35:$G$41,B11,$H$35:$H$41)) -> 83 | E11: 9882 | F11: maria helena | G11: CTD | H11: 400 | I11: 400 | O11: =IF(C16=0,0,1) -> 1 | R11: =IF(vend5[[#This Row],[Nº Venda]]>1,1,0) -> 1
B12: CTD | C12: =(SUMIF($G$2:$G$31,B12,$I$2:$I$31))+(SUMIF($G$35:$G$41,B12,$H$35:$H$41)) -> 1709 | E12: 9883 | F12: maria do socorro | G12: CTC | H12: 900 | I12: 900 | R12: =IF(vend5[[#This Row],[Nº Venda]]>1,1,0) -> 1
B13: CTC | C13: =(SUMIF($G$2:$G$31,B13,$I$2:$I$31))+(SUMIF($G$35:$G$41,B13,$H$35:$H$41)) -> 4285 | E13: 9884 | F13: paulo colombo | G13: DN | H13: 900 | I13: 50 | K13: OS Entregue no Dia | R13: =IF(vend5[[#This Row],[Nº Venda]]>1,1,0) -> 1
B14: PCTC | C14: =(SUMIF($G$2:$G$31,B14,$I$2:$I$31))+(SUMIF($G$35:$G$41,B14,$H$35:$H$41)) -> 0 | E14: 9885 | F14: ricardo martins | G14: CTC | H14: 685 | I14: 685 | K14: OS | L14: Vendedor | M14: CARNE | R14: =IF(vend5[[#This Row],[Nº Venda]]>1,1,0) -> 1
B15: PIX | C15: =(SUMIF($G$2:$G$31,B15,$I$2:$I$31))+(SUMIF($G$35:$G$41,B15,$H$35:$H$41)) -> 0 | K15: 9816 | L15: ARIANI | M15: não | R15: =IF(vend5[[#This Row],[Nº Venda]]>1,1,0) -> 0
B16: Total | C16: =SUM(C11:C15) -> 6077 | K16: 9870 | L16: TATY | M16: não | R16: =IF(vend5[[#This Row],[Nº Venda]]>1,1,0) -> 0
R17: =IF(vend5[[#This Row],[Nº Venda]]>1,1,0) -> 0
B18: Entrega de Carne | R18: =IF(vend5[[#This Row],[Nº Venda]]>1,1,0) -> 0
B19: =COUNT(entr_carn5[OS]) -> 0 | C19: =SUM(entr_carn5[Valor Total]) -> 0 | R19: =IF(vend5[[#This Row],[Nº Venda]]>1,1,0) -> 0
B20: Total | C20: =SUM(C19:C19) -> 0 | R20: =IF(vend5[[#This Row],[Nº Venda]]>1,1,0) -> 0
B22: Venda | C22: =C5 -> 6044
E24: Restante Entrada
E25: Nº Venda | F25: Cliente | G25: Forma de Pgto | H25: Valor Venda | I25: Entrada
E26: 9787 | F26: paulo colombo | G26: CTC | I26: 850
E33: Recebimento de Carnê | K33: Entrega de Carne
E34: OS | F34: Cliente | G34: Forma de Pgto | H34: Valor Parcela | I34: Nº Parcela | K34: OS | L34: Parcelas | M34: Valor Total
E35: 9811 | F35: zuleide maria | G35: DN | H35: 33 | I35: PARC. 1/3
Q40: Total de OS | R40: =SUM(R6:R21) -> 9

Sheet 06
B1: ='05'!B1+1 -> 45571
B2: Fechamento Diário do Caixa
B4: Saldo Inicial | C4: 0 | E4: Vendas | K4: Despesas
B5: Vendas | C5: =SUMIF(I6:I31,">0",H6:H31) -> 0 | E5: Nº Venda | F5: Cliente | G5: Forma de Pgto | H5: Valor Venda | I5: Entrada | K5: Descrição | L5: Tipo de Pagto | M5: Valor
B6: Entrada | C6: =SUM(I6:I41) -> 0 | R6: =IF(vend[[#This Row],[Nº Venda]]>1,1,0) -> 0
B7: Despesas | C7: =SUM(M6:M11) -> 0 | R7: =IF(vend[[#This Row],[Nº Venda]]>1,1,0) -> 0
B8: Total entrada | C8: =SUM(C6:C7) -> 0 | R8: =IF(vend[[#This Row],[Nº Venda]]>1,1,0) -> 0
R9: =IF(vend[[#This Row],[Nº Venda]]>1,1,0) -> 0
B10: Tipos de Pagtos | R10: =IF(vend[[#This Row],[Nº Venda]]>1,1,0) -> 0
B11: DN | C11: =(SUMIF($G$2:$G$31,B11,$I$2:$I$31))+(SUMIF($G$35:$G$41,B11,$H$35:$H$41)) -> 0 | O11: =IF(C16=0,0,1) -> 0 | R11: =IF(vend[[#This Row],[Nº Venda]]>1,1,0) -> 0
B12: CTD | C12: =(SUMIF($G$2:$G$31,B12,$I$2:$I$31))+(SUMIF($G$35:$G$41,B12,$H$35:$H$41)) -> 0 | R12: =IF(vend[[#This Row],[Nº Venda]]>1,1,0) -> 0
B13: CTC | C13: =(SUMIF($G$2:$G$31,B13,$I$2:$I$31))+(SUMIF($G$35:$G$41,B13,$H$35:$H$41)) -> 0 | K13: OS Entregue no Dia | R13: =IF(vend[[#This Row],[Nº Venda]]>1,1,0) -> 0
B14: PCTC | C14: =(SUMIF($G$2:$G$31,B14,$I$2:$I$31))+(SUMIF($G$35:$G$41,B14,$H$35:$H$41)) -> 0 | K14: OS | L14: Vendedor | M14: CARNE | R14: =IF(vend[[#This Row],[Nº Venda]]>1,1,0) -> 0
B15: PIX | C15: =(SUMIF($G$2:$G$31,B15,$I$2:$I$31))+(SUMIF($G$35:$G$41,B15,$H$35:$H$41)) -> 0 | R15: =IF(vend[[#This Row],[Nº Venda]]>1,1,0) -> 0
B16: Total | C16: =SUM(C11:C15) -> 0 | R16: =IF(vend[[#This Row],[Nº Venda]]>1,1,0) -> 0
R17: =IF(vend[[#This Row],[Nº Venda]]>1,1,0) -> 0
B18: Entrega de Carne | R18: =IF(vend[[#This Row],[Nº Venda]]>1,1,0) -> 0
B19: =COUNT(entr_carn6[OS]) -> 0 | C19: =SUM(entr_carn6[Valor Total]) -> 0 | R19: =IF(vend[[#This Row],[Nº Venda]]>1,1,0) -> 0
B20: Total | C20: =SUM(C19:C19) -> 0 | R20: =IF(vend[[#This Row],[Nº Venda]]>1,1,0) -> 0
B22: Venda | C22: =C5 -> 0
E24: Restante Entrada
E25: Nº Venda | F25: Cliente | G25: Forma de Pgto | H25: Valor Venda | I25: Entrada
E33: Recebimento de Carnê | K33: Entrega de Carne
E34: OS | F34: Cliente | G34: Forma de Pgto | H34: Valor Parcela | I34: Nº Parcela | K34: OS | L34: Parcelas | M34: Valor Total
Q40: Total de OS | R40: =SUM(R6:R21) -> 0

Sheet 07
B1: ='06'!B1+1 -> 45572
B2: Fechamento Diário do Caixa
B4: Saldo Inicial | C4: 0 | E4: Vendas | K4: Despesas | U4: 0
B5: Vendas | C5: =SUMIF(I6:I31,">0",H6:H31) -> 4049 | E5: Nº Venda | F5: Cliente | G5: Forma de Pgto | H5: Valor Venda | I5: Entrada | K5: Descrição | L5: Tipo de Pagto | M5: Valor
B6: Entrada | C6: =SUM(I6:I41) -> 1660 | E6: 9886 | F6: ana lucia | G6: CTD | H6: 899 | I6: 240 | R6: =IF(vend7[[#This Row],[Nº Venda]]>1,1,0) -> 1
B7: Despesas | C7: =SUM(M6:M11) -> 0 | E7: 9887 | F7: aline santana | G7: PIX | H7: 750 | I7: 250 | R7: =IF(vend7[[#This Row],[Nº Venda]]>1,1,0) -> 1
B8: Total entrada | C8: =SUM(C6:C7) -> 1660 | E8: 9888 | F8: yasmin cristina | G8: GARANTIA | R8: =IF(vend7[[#This Row],[Nº Venda]]>1,1,0) -> 1
E9: 9889 | F9: ronailly lourenco | G9: DN | H9: 300 | I9: 20 | R9: =IF(vend7[[#This Row],[Nº Venda]]>1,1,0) -> 1
B10: Tipos de Pagtos | E10: 9890 | F10: ana lucia | G10: CTD | H10: 1300 | I10: 400 | R10: =IF(vend7[[#This Row],[Nº Venda]]>1,1,0) -> 1
B11: DN | C11: =(SUMIF($G$2:$G$31,B11,$I$2:$I$31))+(SUMIF($G$35:$G$41,B11,$H$35:$H$41)) -> 198.33 | E11: 9891 | F11: ana lucia | G11: CTD | H11: 800 | I11: 300 | O11: =IF(C16=0,0,1) -> 1 | R11: =IF(vend7[[#This Row],[Nº Venda]]>1,1,0) -> 1
B12: CTD | C12: =(SUMIF($G$2:$G$31,B12,$I$2:$I$31))+(SUMIF($G$35:$G$41,B12,$H$35:$H$41)) -> 1306.66 | R12: =IF(vend7[[#This Row],[Nº Venda]]>1,1,0) -> 0
B13: CTC | C13: =(SUMIF($G$2:$G$31,B13,$I$2:$I$31))+(SUMIF($G$35:$G$41,B13,$H$35:$H$41)) -> 0 | K13: OS Entregue no Dia | R13: =IF(vend7[[#This Row],[Nº Venda]]>1,1,0) -> 0
B14: PCTC | C14: =(SUMIF($G$2:$G$31,B14,$I$2:$I$31))+(SUMIF($G$35:$G$41,B14,$H$35:$H$41)) -> 0 | K14: OS | L14: Vendedor | M14: CARNE | R14: =IF(vend7[[#This Row],[Nº Venda]]>1,1,0) -> 0
B15: PIX | C15: =(SUMIF($G$2:$G$31,B15,$I$2:$I$31))+(SUMIF($G$35:$G$41,B15,$H$35:$H$41)) -> 1166.5 | K15: 9833 | L15: JOCY | M15: Não | R15: =IF(vend7[[#This Row],[Nº Venda]]>1,1,0) -> 0
B16: Total | C16: =SUM(C11:C15) -> 2671.49 | K16: 9837 | L16: JOCY | M16: Não | R16: =IF(vend7[[#This Row],[Nº Venda]]>1,1,0) -> 0
R17: =IF(vend7[[#This Row],[Nº Venda]]>1,1,0) -> 0
B18: Entrega de Carne | R18: =IF(vend7[[#This Row],[Nº Venda]]>1,1,0) -> 0
B19: =COUNT(entr_carn7[OS]) -> 0 | C19: =SUM(entr_carn7[Valor Total]) -> 0 | R19: =IF(vend7[[#This Row],[Nº Venda]]>1,1,0) -> 0
B20: Total | C20: =SUM(C19:C19) -> 0 | R20: =IF(vend7[[#This Row],[Nº Venda]]>1,1,0) -> 0
B22: Venda | C22: =C5 -> 4049
E24: Restante Entrada
E25: Nº Venda | F25: Cliente | G25: Forma de Pgto | H25: Valor Venda | I25: Entrada
E26: 9837 | F26: ana lucia | G26: CTD | I26: 250
E27: 8531 | F27: maria das dores | G27: DN | I27: 100
E28: 9684 | F28: wesley da silva | G28: PIX | I28: 100
E33: Recebimento de Carnê | K33: Entrega de Carne
E34: OS | F34: Cliente | G34: Forma de Pgto | H34: Valor Parcela | I34: Nº Parcela | K34: OS | L34: Parcelas | M34: Valor Total
E35: 9565 | F35: vitoria nhoque | G35: PIX | H35: 100 | I35: PARC. 2/8
E36: 9615 | F36: cicero ferreira | G36: DN | H36: 78.33 | I36: PARC. 1/6
E37: 9784 | F37: magno figueira | G37: CTD | H37: 116.66 | I37: PARC. 1/3
E38: 9716 | F38: ronivaldo pereira | G38: PIX | H38: 120 | I38: PARC. 1/6
E39: 9728 | F39: eliel duarte | G39: PIX | H39: 162.5 | I39: PARC. 2/8
E40: 8885 | F40: zenilda augusta | G40: PIX | H40: 300 | I40: PARC. 5/5 | Q40: Total de OS | R40: =SUM(R6:R21) -> 6
E41: 9538 | F41: zenilda augusta | G41: PIX | H41: 134 | I41: PARC. 2/2

Sheet 08
B1: ='07'!B1+1 -> 45573
B2: Fechamento Diário do Caixa
B4: Saldo Inicial | C4: 0 | E4: Vendas | K4: Despesas
B5: Vendas | C5: =SUMIF(I6:I31,">0",H6:H31) -> 3470 | E5: Nº Venda | F5: Cliente | G5: Forma de Pgto | H5: Valor Venda | I5: Entrada | K5: Descrição | L5: Tipo de Pagto | M5: Valor
B6: Entrada | C6: =SUM(I6:I41) -> 1739 | E6: 9892 | F6: claudia cristina | G6: DN | H6: 80 | I6: 80 | R6: =IF(vend8[[#This Row],[Nº Venda]]>1,1,0) -> 1
B7: Despesas | C7: =SUM(M6:M11) -> 0 | E7: 9893 | F7: camila pacini | G7: GARANTIA | R7: =IF(vend8[[#This Row],[Nº Venda]]>1,1,0) -> 1
B8: Total entrada | C8: =SUM(C6:C7) -> 1739 | E8: 9894 | F8: antonio marim | G8: PIX | H8: 1100 | I8: 270 | R8: =IF(vend8[[#This Row],[Nº Venda]]>1,1,0) -> 1
E9: 9895 | F9: dhiego souza | G9: CTC | H9: 400 | I9: 400 | R9: =IF(vend8[[#This Row],[Nº Venda]]>1,1,0) -> 1
B10: Tipos de Pagtos | E10: 9896 | F10: dhiego souza | G10: CTC | H10: 490 | I10: 490 | R10: =IF(vend8[[#This Row],[Nº Venda]]>1,1,0) -> 1
B11: DN | C11: =(SUMIF($G$2:$G$31,B11,$I$2:$I$31))+(SUMIF($G$35:$G$42,B11,$H$35:$H$42)) -> 439 | E11: 9897 | F11: airton acacio | G11: CTD | H11: 1400 | I11: 200 | O11: =IF(C16=0,0,1) -> 1 | R11: =IF(vend8[[#This Row],[Nº Venda]]>1,1,0) -> 1
B12: CTD | C12: =(SUMIF($G$2:$G$31,B12,$I$2:$I$31))+(SUMIF($G$35:$G$42,B12,$H$35:$H$42)) -> 200 | R12: =IF(vend8[[#This Row],[Nº Venda]]>1,1,0) -> 0
B13: CTC | C13: =(SUMIF($G$2:$G$31,B13,$I$2:$I$31))+(SUMIF($G$35:$G$42,B13,$H$35:$H$42)) -> 890 | K13: OS Entregue no Dia | R13: =IF(vend8[[#This Row],[Nº Venda]]>1,1,0) -> 0
B14: PCTC | C14: =(SUMIF($G$2:$G$31,B14,$I$2:$I$31))+(SUMIF($G$35:$G$42,B14,$H$35:$H$42)) -> 0 | K14: OS | L14: Vendedor | M14: CARNE | R14: =IF(vend8[[#This Row],[Nº Venda]]>1,1,0) -> 0
B15: PIX | C15: =(SUMIF($G$2:$G$31,B15,$I$2:$I$31))+(SUMIF($G$35:$G$42,B15,$H$35:$H$42)) -> 336.33 | K15: 9892 | L15: JOCY | M15: Não | R15: =IF(vend8[[#This Row],[Nº Venda]]>1,1,0) -> 0
B16: Total | C16: =SUM(C11:C15) -> 1865.33 | K16: 9831 | L16: JOCY | M16: Não | R16: =IF(vend8[[#This Row],[Nº Venda]]>1,1,0) -> 0
K17: 9844 | L17: ARIANI | M17: Não | R17: =IF(vend8[[#This Row],[Nº Venda]]>1,1,0) -> 0
B18: Entrega de Carne | R18: =IF(vend8[[#This Row],[Nº Venda]]>1,1,0) -> 0
B19: =COUNT(entr_carn8[OS]) -> 0 | C19: =SUM(entr_carn8[Valor Total]) -> 0 | R19: =IF(vend8[[#This Row],[Nº Venda]]>1,1,0) -> 0
B20: Total | C20: =SUM(C19:C19) -> 0 | R20: =IF(vend8[[#This Row],[Nº Venda]]>1,1,0) -> 0
B22: Venda | C22: =C5 -> 3470
E24: Restante Entrada
E25: Nº Venda | F25: Cliente | G25: Forma de Pgto | H25: Valor Venda | I25: Entrada
E26: 9844 | F26: rafaela mendes | G26: DN | I26: 299
E33: Recebimento de Carnê | K33: Entrega de Carne
E34: OS | F34: Cliente | G34: Forma de Pgto | H34: Valor Parcela | I34: Nº Parcela | K34: OS | L34: Parcelas | M34: Valor Total
E35: 8999 | F35: marinalva beserra | G35: DN | H35: 60 | I35: PARC. 6/7
E36: 9208 | F36: patricia paulino | G36: PIX | H36: 66.33 | I36: ='15'!E69922 -> 0
Q40: Total de OS | R40: =SUM(R6:R21) -> 6

Sheet 09
B1: ='08'!B1+1 -> 45574
B2: Fechamento Diário do Caixa
B4: Saldo Inicial | C4: 0 | E4: Vendas | K4: Despesas
B5: Vendas | C5: =SUMIF(I6:I31,">0",H6:H31) -> 4730 | E5: Nº Venda | F5: Cliente | G5: Forma de Pgto | H5: Valor Venda | I5: Entrada | K5: Descrição | L5: Tipo de Pagto | M5: Valor
B6: Entrada | C6: =SUM(I6:I41) -> 5830 | E6: 9898 | F6: ANDRE LUIZ | G6: CTC | H6: 1600 | I6: 1600 | R6: =IF(vend9[[#This Row],[Nº Venda]]>1,1,0) -> 1
B7: Despesas | C7: =SUM(M6:M11) -> 0 | E7: 9899 | F7: EVALDO CORDEIRO | G7: CTC | H7: 500 | I7: 500 | R7: =IF(vend9[[#This Row],[Nº Venda]]>1,1,0) -> 1
B8: Total entrada | C8: =SUM(C6:C7) -> 5830 | E8: 9900 | F8: EVALDO CORDEIRO | G8: CTC | H8: 500 | I8: 500 | R8: =IF(vend9[[#This Row],[Nº Venda]]>1,1,0) -> 1
E9: 9901 | F9: EVALDO CORDEIRO | G9: CTC | H9: 300 | I9: 300 | R9: =IF(vend9[[#This Row],[Nº Venda]]>1,1,0) -> 1
B10: Tipos de Pagtos | E10: 9902 | F10: EVALDO CORDEIRO | G10: CTC | H10: 700 | I10: 700 | R10: =IF(vend9[[#This Row],[Nº Venda]]>1,1,0) -> 1
B11: DN | C11: =(SUMIF($G$2:$G$31,B11,$I$2:$I$31))+(SUMIF($G$35:$G$41,B11,$H$35:$H$41)) -> 96.66 | E11: 9903 | F11: KATIANA SANTANA | G11: CTD | H11: 1100 | I11: 550 | O11: =IF(C16=0,0,1) -> 1 | R11: =IF(vend9[[#This Row],[Nº Venda]]>1,1,0) -> 1
B12: CTD | C12: =(SUMIF($G$2:$G$31,B12,$I$2:$I$31))+(SUMIF($G$35:$G$41,B12,$H$35:$H$41)) -> 550 | E12: 9903 | F12: KATIANA SANTANA | G12: CTC | I12: 550 | R12: =IF(vend9[[#This Row],[Nº Venda]]>1,1,0) -> 1 | V12: 0
B13: CTC | C13: =(SUMIF($G$2:$G$31,B13,$I$2:$I$31))+(SUMIF($G$35:$G$41,B13,$H$35:$H$41)) -> 5250 | K13: OS Entregue no Dia | R13: =IF(vend9[[#This Row],[Nº Venda]]>1,1,0) -> 0
B14: PCTC | C14: =(SUMIF($G$2:$G$31,B14,$I$2:$I$31))+(SUMIF($G$35:$G$41,B14,$H$35:$H$41)) -> 0 | K14: OS | L14: Vendedor | M14: CARNE | R14: =IF(vend9[[#This Row],[Nº Venda]]>1,1,0) -> 0
B15: PIX | C15: =(SUMIF($G$2:$G$31,B15,$I$2:$I$31))+(SUMIF($G$35:$G$41,B15,$H$35:$H$41)) -> 334.83 | K15: 9815 | L15: ARIANI | M15: Não | R15: =IF(vend9[[#This Row],[Nº Venda]]>1,1,0) -> 0
B16: Total | C16: =SUM(C11:C15) -> 6231.49 | K16: 9513 | L16: JOCY | M16: Não | R16: =IF(vend9[[#This Row],[Nº Venda]]>1,1,0) -> 0
R17: =IF(vend9[[#This Row],[Nº Venda]]>1,1,0) -> 0
B18: Entrega de Carne | R18: =IF(vend9[[#This Row],[Nº Venda]]>1,1,0) -> 0
B19: =COUNT(entr_carn9[OS]) -> 0 | C19: =SUM(entr_carn9[Valor Total]) -> 0 | R19: =IF(vend9[[#This Row],[Nº Venda]]>1,1,0) -> 0
B20: Total | C20: =SUM(C19:C19) -> 0 | R20: =IF(vend9[[#This Row],[Nº Venda]]>1,1,0) -> 0
B22: Venda | C22: =C5 -> 4730
E24: Restante Entrada
E25: Nº Venda | F25: Cliente | G25: Forma de Pgto | H25: Valor Venda | I25: Entrada
E26: 9815 | F26: MARIA DAS GRACAS | G26: CTC | I26: 1100
E27: 9888 | F27: YASMIN CRISTINA | G27: DN | H27: 30 | I27: 30
E33: Recebimento de Carnê | K33: Entrega de Carne
E34: OS | F34: Cliente | G34: Forma de Pgto | H34: Valor Parcela | I34: Nº Parcela | K34: OS | L34: Parcelas | M34: Valor Total
E35: 9342 | F35: FABIANA | G35: PIX | H35: 58.33 | I35: PARC. 3/6
E36: 9150 | F36: ELZA DE PAULA | G36: PIX | H36: 130 | I36: PARC. 5/5
E37: 9452 | F37: THAIS HELENA | G37: DN | H37: 66.66 | I37: PARC. 3/6
E38: 9699 | F38: HENRIQUE LIMA | G38: PIX | H38: 80 | I38: PARC. 1/6
E39: 9156 | F39: simone ignacio | G39: PIX | H39: 66.5 | I39: PARC. 5/6
Q40: Total de OS | R40: =SUM(R6:R21) -> 7

Sheet 10
B1: ='09'!B1+1 -> 45575
B2: Fechamento Diário do Caixa
B4: Saldo Inicial | C4: 0 | E4: Vendas | K4: Despesas
B5: Vendas | C5: =SUMIF(I6:I32,">0",H6:H32) -> 5098 | E5: Nº Venda | F5: Cliente | G5: Forma de Pgto | H5: Valor Venda | I5: Entrada | K5: Descrição | L5: Tipo de Pagto | M5: Valor
B6: Entrada | C6: =SUM(I6:I42) -> 4898 | E6: 9904 | F6: erika aparecida | G6: CTC | H6: 600 | I6: 600 | K6: wendell porta | L6: dn | M6: 30 | R6: =IF(vend10[[#This Row],[Nº Venda]]>1,1,0) -> 1
B7: Despesas | C7: =SUM(M6:M11) -> 30 | E7: 9905 | F7: erika aparecida | G7: CTC | H7: 300 | I7: 300 | R7: =IF(vend10[[#This Row],[Nº Venda]]>1,1,0) -> 1
B8: Total entrada | C8: =SUM(C6:C7) -> 4928 | E8: 9906 | F8: renata aparecida | G8: CTC | H8: 900 | I8: 450 | R8: =IF(vend10[[#This Row],[Nº Venda]]>1,1,0) -> 1
E9: 9906 | F9: renata aparecida | G9: CTC | I9: 450 | R9: =IF(vend10[[#This Row],[Nº Venda]]>1,1,0) -> 1
B10: Tipos de Pagtos | E10: 9907 | F10: vera lucia | G10: CTD | H10: 250 | I10: 50 | R10: =IF(vend10[[#This Row],[Nº Venda]]>1,1,0) -> 1
B11: DN | C11: =(SUMIF($G$2:$G$32,B11,$I$2:$I$32))+(SUMIF($G$36:$G$42,B11,$H$36:$H$42)) -> 100 | E11: 9908 | F11: erick kenzo | G11: SS | H11: 35 | I11: 0 | O11: =IF(C16=0,0,1) -> 1 | R11: =IF(vend10[[#This Row],[Nº Venda]]>1,1,0) -> 1
B12: CTD | C12: =(SUMIF($G$2:$G$32,B12,$I$2:$I$32))+(SUMIF($G$36:$G$42,B12,$H$36:$H$42)) -> 50 | E12: 9909 | F12: ana cleia vieira | G12: CTC | H12: 908 | I12: 908 | R12: =IF(vend10[[#This Row],[Nº Venda]]>1,1,0) -> 1
B13: CTC | C13: =(SUMIF($G$2:$G$32,B13,$I$2:$I$32))+(SUMIF($G$36:$G$42,B13,$H$36:$H$42)) -> 4848 | E13: 9910 | F13: ana cleia vieira | G13: CTC | H13: 250 | I13: 250 | K13: OS Entregue no Dia | R13: =IF(vend10[[#This Row],[Nº Venda]]>1,1,0) -> 1
B14: PCTC | C14: =(SUMIF($G$2:$G$32,B14,$I$2:$I$32))+(SUMIF($G$36:$G$42,B14,$H$36:$H$42)) -> 0 | E14: 9911 | F14: adriana leal | G14: CTC | H14: 1799 | I14: 1799 | K14: OS | L14: Vendedor | M14: CARNE | R14: =IF(vend10[[#This Row],[Nº Venda]]>1,1,0) -> 1
B15: PIX | C15: =(SUMIF($G$2:$G$32,B15,$I$2:$I$32))+(SUMIF($G$36:$G$42,B15,$H$36:$H$42)) -> 794.83 | E15: 9912 | F15: adriana leal | G15: CTC | H15: 91 | I15: 91 | K15: 9869 | L15: TATY | M15: Não | R15: =IF(vend10[[#This Row],[Nº Venda]]>1,1,0) -> 1
B16: Total | C16: =SUM(C11:C15) -> 5792.83 | K16: 9846 | L16: ARIANI | M16: Sim | R16: =IF(vend10[[#This Row],[Nº Venda]]>1,1,0) -> 0
K17: 9845 | L17: ARIANI | M17: Sim | R17: =IF(vend10[[#This Row],[Nº Venda]]>1,1,0) -> 0
B18: Entrega de Carne | K18: 9834 | L18: JOCY | M18: Não | R18: =IF(vend10[[#This Row],[Nº Venda]]>1,1,0) -> 0
B19: =COUNT(entr_carn10[OS]) -> 1 | C19: =SUM(entr_carn10[Valor Total]) -> 580 | R19: =IF(vend10[[#This Row],[Nº Venda]]>1,1,0) -> 0
B20: Total | C20: =SUM(C19:C19) -> 580 | R20: =IF(vend10[[#This Row],[Nº Venda]]>1,1,0) -> 0
B22: Venda | C22: =C5 -> 5098
E24: Restante Entrada
E25: Nº Venda | F25: Cliente | G25: Forma de Pgto | H25: Valor Venda | I25: Entrada
K33: Entrega de Carne
E34: Recebimento de Carnê | K34: OS | L34: Parcelas | M34: Valor Total
E35: OS | F35: Cliente | G35: Forma de Pgto | H35: Valor Parcela | I35: Nº Parcela | K35: 9845 | L35: 8 | M35: 580
E36: 9704 | F36: maria jose | G36: DN | H36: 100 | I36: PARC. 1/7
E37: 9711 | F37: andreza souza | G37: PIX | H37: 100 | I37: PARC. 1/8
E38: 9495 | F38: thaynara de jesus | G38: PIX | H38: 350 | I38: PARC. 1/1
E39: 9424 | F39: julio cesar | G39: PIX | H39: 104.83 | I39: PARC. 3/6
E40: 8817 | F40: catia carvalho | G40: PIX | H40: 180 | I40: PARC. 6/8 | Q40: Total de OS | R40: =SUM(R6:R21) -> 10
E41: 9102 | F41: ellen cristina | G41: PIX | H41: 60 | I41: PARC. 5/5

Sheet 11
B1: ='10'!B1+1 -> 45576
B2: Fechamento Diário do Caixa
B4: Saldo Inicial | C4: 0 | E4: Vendas | K4: Despesas
B5: Vendas | C5: =SUMIF(I6:I31,">0",H6:H31) -> 1310 | E5: Nº Venda | F5: Cliente | G5: Forma de Pgto | H5: Valor Venda | I5: Entrada | K5: Descrição | L5: Tipo de Pagto | M5: Valor
B6: Entrada | C6: =SUM(I6:I41) -> 900 | E6: 9913 | F6: GISLENE ELOISA | G6: GARANTIA | R6: =IF(vend11[[#This Row],[Nº Venda]]>1,1,0) -> 1
B7: Despesas | C7: =SUM(M6:M11) -> 0 | E7: 9914 | F7: SIDNEY DEGRIE | G7: CTD | H7: 770 | I7: 70 | R7: =IF(vend11[[#This Row],[Nº Venda]]>1,1,0) -> 1
B8: Total entrada | C8: =SUM(C6:C7) -> 900 | E8: 9915 | F8: ARTHUR HENRIQUE | G8: CTD | H8: 540 | I8: 30 | R8: =IF(vend11[[#This Row],[Nº Venda]]>1,1,0) -> 1
R9: =IF(vend11[[#This Row],[Nº Venda]]>1,1,0) -> 0
B10: Tipos de Pagtos | R10: =IF(vend11[[#This Row],[Nº Venda]]>1,1,0) -> 0
B11: DN | C11: =(SUMIF($G$2:$G$31,B11,$I$2:$I$31))+(SUMIF($G$35:$G$41,B11,$H$35:$H$41)) -> 178.33 | O11: =IF(C16=0,0,1) -> 1 | R11: =IF(vend11[[#This Row],[Nº Venda]]>1,1,0) -> 0
B12: CTD | C12: =(SUMIF($G$2:$G$31,B12,$I$2:$I$31))+(SUMIF($G$35:$G$41,B12,$H$35:$H$41)) -> 900 | R12: =IF(vend11[[#This Row],[Nº Venda]]>1,1,0) -> 0
B13: CTC | C13: =(SUMIF($G$2:$G$31,B13,$I$2:$I$31))+(SUMIF($G$35:$G$41,B13,$H$35:$H$41)) -> 0 | K13: OS Entregue no Dia | R13: =IF(vend11[[#This Row],[Nº Venda]]>1,1,0) -> 0
B14: PCTC | C14: =(SUMIF($G$2:$G$31,B14,$I$2:$I$31))+(SUMIF($G$35:$G$41,B14,$H$35:$H$41)) -> 0 | K14: OS | L14: Vendedor | M14: CARNE | R14: =IF(vend11[[#This Row],[Nº Venda]]>1,1,0) -> 0
B15: PIX | C15: =(SUMIF($G$2:$G$31,B15,$I$2:$I$31))+(SUMIF($G$35:$G$41,B15,$H$35:$H$41)) -> 110 | K15: 9863 | L15: ARIANI | M15: Não | R15: =IF(vend11[[#This Row],[Nº Venda]]>1,1,0) -> 0
B16: Total | C16: =SUM(C11:C15) -> 1188.33 | K16: 9862 | L16: JOCY | M16: Não | R16: =IF(vend11[[#This Row],[Nº Venda]]>1,1,0) -> 0
K17: 9857 | L17: TATY | M17: Não | R17: =IF(vend11[[#This Row],[Nº Venda]]>1,1,0) -> 0
B18: Entrega de Carne | K18: 9820 | L18: JOCY | M18: Não | R18: =IF(vend11[[#This Row],[Nº Venda]]>1,1,0) -> 0
B19: =COUNT(entr_carn11[OS]) -> 0 | C19: =SUM(entr_carn11[Valor Total]) -> 0 | K19: 9859 | L19: TATY | M19: Não | R19: =IF(vend11[[#This Row],[Nº Venda]]>1,1,0) -> 0
B20: Total | C20: =SUM(C19:C19) -> 0 | R20: =IF(vend11[[#This Row],[Nº Venda]]>1,1,0) -> 0
B22: Venda | C22: =C5 -> 1310
E24: Restante Entrada
E25: Nº Venda | F25: Cliente | G25: Forma de Pgto | H25: Valor Venda | I25: Entrada
E26: 9863 | F26: ANTONIO CARMO | G26: CTD | I26: 800
E33: Recebimento de Carnê | K33: Entrega de Carne
E34: OS | F34: Cliente | G34: Forma de Pgto | H34: Valor Parcela | I34: Nº Parcela | K34: OS | L34: Parcelas | M34: Valor Total
E35: 9189 | F35: MARIA SANDRA | G35: PIX | H35: 100 | I35: PARC. 5/7
E36: 8790 | F36: MARIA APARECIDA | G36: DN | H36: 55 | I36: PARC. 1/7
E37: 9054 | F37: LUIZ ZACARIAS | G37: PIX | H37: 10 | I37: PARC. 3/3
E38: 9054 | F38: LUIZ ZACARIAS | G38: DN | H38: 123.33 | I38: PARC. 3/3
Q40: Total de OS | R40: =SUM(R6:R21) -> 3

Sheet 12
B1: ='11'!B1+1 -> 45577
B2: Fechamento Diário do Caixa
B4: Saldo Inicial | C4: 0 | E4: Vendas | K4: Despesas
B5: Vendas | C5: =SUMIF(I6:I31,">0",H6:H31) -> 3640 | E5: Nº Venda | F5: Cliente | G5: Forma de Pgto | H5: Valor Venda | I5: Entrada | K5: Descrição | L5: Tipo de Pagto | M5: Valor
B6: Entrada | C6: =SUM(I6:I41) -> 2500 | E6: 9916 | F6: ROSANA GLESIA | G6: PIX | H6: 1290 | I6: 50 | R6: =IF(vend12[[#This Row],[Nº Venda]]>1,1,0) -> 1
B7: Despesas | C7: =SUM(M6:M11) -> 0 | E7: 9917 | F7: CICERO CHALES | G7: PIX | H7: 1470 | I7: 1470 | R7: =IF(vend12[[#This Row],[Nº Venda]]>1,1,0) -> 1
B8: Total entrada | C8: =SUM(C6:C7) -> 2500 | E8: 9918 | F8: VERA LUCIA | G8: CTC | H8: 750 | I8: 750 | R8: =IF(vend12[[#This Row],[Nº Venda]]>1,1,0) -> 1
E9: 9919 | F9: ROSANGELA MENDES | G9: PIX | H9: 130 | I9: 30 | R9: =IF(vend12[[#This Row],[Nº Venda]]>1,1,0) -> 1
B10: Tipos de Pagtos | R10: =IF(vend12[[#This Row],[Nº Venda]]>1,1,0) -> 0
B11: DN | C11: =(SUMIF($G$2:$G$31,B11,$I$2:$I$31))+(SUMIF($G$35:$G$41,B11,$H$35:$H$41)) -> 0 | O11: =IF(C16=0,0,1) -> 1 | R11: =IF(vend12[[#This Row],[Nº Venda]]>1,1,0) -> 0
B12: CTD | C12: =(SUMIF($G$2:$G$31,B12,$I$2:$I$31))+(SUMIF($G$35:$G$41,B12,$H$35:$H$41)) -> 0 | R12: =IF(vend12[[#This Row],[Nº Venda]]>1,1,0) -> 0
B13: CTC | C13: =(SUMIF($G$2:$G$31,B13,$I$2:$I$31))+(SUMIF($G$35:$G$41,B13,$H$35:$H$41)) -> 950 | K13: OS Entregue no Dia | R13: =IF(vend12[[#This Row],[Nº Venda]]>1,1,0) -> 0
B14: PCTC | C14: =(SUMIF($G$2:$G$31,B14,$I$2:$I$31))+(SUMIF($G$35:$G$41,B14,$H$35:$H$41)) -> 0 | K14: OS | L14: Vendedor | M14: CARNE | R14: =IF(vend12[[#This Row],[Nº Venda]]>1,1,0) -> 0
B15: PIX | C15: =(SUMIF($G$2:$G$31,B15,$I$2:$I$31))+(SUMIF($G$35:$G$41,B15,$H$35:$H$41)) -> 2074.58 | K15: 9007 | L15: JOCY | M15: Não | R15: =IF(vend12[[#This Row],[Nº Venda]]>1,1,0) -> 0
B16: Total | C16: =SUM(C11:C15) -> 3024.58 | K16: 9847 | L16: JOCY | M16: Não | R16: =IF(vend12[[#This Row],[Nº Venda]]>1,1,0) -> 0
K17: 9828 | L17: TATY | M17: Não | R17: =IF(vend12[[#This Row],[Nº Venda]]>1,1,0) -> 0
B18: Entrega de Carne | K18: 9479 | L18: TATY | M18: Não | R18: =IF(vend12[[#This Row],[Nº Venda]]>1,1,0) -> 0
B19: =COUNT(entr_carn12[OS]) -> 1 | C19: =SUM(entr_carn12[Valor Total]) -> 1200 | K19: 9836 | L19: JOCY | M19: Sim | R19: =IF(vend12[[#This Row],[Nº Venda]]>1,1,0) -> 0
B20: Total | C20: =SUM(C19:C19) -> 1200 | R20: =IF(vend12[[#This Row],[Nº Venda]]>1,1,0) -> 0
B22: Venda | C22: =C5 -> 3640
E24: Restante Entrada
E25: Nº Venda | F25: Cliente | G25: Forma de Pgto | H25: Valor Venda | I25: Entrada
E26: 9907 | F26: VERA LUCIA | G26: CTC | I26: 200
E33: Recebimento de Carnê | K33: Entrega de Carne
E34: OS | F34: Cliente | G34: Forma de Pgto | H34: Valor Parcela | I34: Nº Parcela | K34: OS | L34: Parcelas | M34: Valor Total
E35: 9441 | F35: GILMAR LOPES | G35: PIX | H35: 356.25 | I35: PARC. 3/8 | K35: 9836 | L35: 8 | M35: 1200
E36: 9072 | F36: MARILU CANDIDA | G36: PIX | H36: 168.33 | I36: PARC. 5/6
Q40: Total de OS | R40: =SUM(R6:R21) -> 4

Sheet 13
B1: ='12'!B1+1 -> 45578
B2: Fechamento Diário do Caixa
B4: Saldo Inicial | C4: 0 | E4: Vendas | K4: Despesas
B5: Vendas | C5: =SUMIF(I6:I31,">0",H6:H31) -> 0 | E5: Nº Venda | F5: Cliente | G5: Forma de Pgto | H5: Valor Venda | I5: Entrada | K5: Descrição | L5: Tipo de Pagto | M5: Valor
B6: Entrada | C6: =SUM(I6:I41) -> 0 | R6: =IF(vend13[[#This Row],[Nº Venda]]>1,1,0) -> 0
B7: Despesas | C7: =SUM(M6:M11) -> 0 | R7: =IF(vend13[[#This Row],[Nº Venda]]>1,1,0) -> 0
B8: Total entrada | C8: =SUM(C6:C7) -> 0 | R8: =IF(vend13[[#This Row],[Nº Venda]]>1,1,0) -> 0
R9: =IF(vend13[[#This Row],[Nº Venda]]>1,1,0) -> 0
B10: Tipos de Pagtos | R10: =IF(vend13[[#This Row],[Nº Venda]]>1,1,0) -> 0
B11: DN | C11: =(SUMIF($G$2:$G$31,B11,$I$2:$I$31))+(SUMIF($G$35:$G$41,B11,$H$35:$H$41)) -> 0 | O11: =IF(C16=0,0,1) -> 0 | R11: =IF(vend13[[#This Row],[Nº Venda]]>1,1,0) -> 0
B12: CTD | C12: =(SUMIF($G$2:$G$31,B12,$I$2:$I$31))+(SUMIF($G$35:$G$41,B12,$H$35:$H$41)) -> 0 | R12: =IF(vend13[[#This Row],[Nº Venda]]>1,1,0) -> 0
B13: CTC | C13: =(SUMIF($G$2:$G$31,B13,$I$2:$I$31))+(SUMIF($G$35:$G$41,B13,$H$35:$H$41)) -> 0 | K13: OS Entregue no Dia | R13: =IF(vend13[[#This Row],[Nº Venda]]>1,1,0) -> 0
B14: PCTC | C14: =(SUMIF($G$2:$G$31,B14,$I$2:$I$31))+(SUMIF($G$35:$G$41,B14,$H$35:$H$41)) -> 0 | K14: OS | L14: Vendedor | M14: CARNE | R14: =IF(vend13[[#This Row],[Nº Venda]]>1,1,0) -> 0
B15: PIX | C15: =(SUMIF($G$2:$G$31,B15,$I$2:$I$31))+(SUMIF($G$35:$G$41,B15,$H$35:$H$41)) -> 0 | R15: =IF(vend13[[#This Row],[Nº Venda]]>1,1,0) -> 0
B16: Total | C16: =SUM(C11:C15) -> 0 | R16: =IF(vend13[[#This Row],[Nº Venda]]>1,1,0) -> 0
R17: =IF(vend13[[#This Row],[Nº Venda]]>1,1,0) -> 0
B18: Entrega de Carne | R18: =IF(vend13[[#This Row],[Nº Venda]]>1,1,0) -> 0
B19: =COUNT(entr_carn13[OS]) -> 0 | C19: =SUM(entr_carn13[Valor Total]) -> 0 | R19: =IF(vend13[[#This Row],[Nº Venda]]>1,1,0) -> 0
B20: Total | C20: =SUM(C19:C19) -> 0 | R20: =IF(vend13[[#This Row],[Nº Venda]]>1,1,0) -> 0
B22: Venda | C22: =C5 -> 0
E24: Restante Entrada
E25: Nº Venda | F25: Cliente | G25: Forma de Pgto | H25: Valor Venda | I25: Entrada
E33: Recebimento de Carnê | K33: Entrega de Carne
E34: OS | F34: Cliente | G34: Forma de Pgto | H34: Valor Parcela | I34: Nº Parcela | K34: OS | L34: Parcelas | M34: Valor Total
Q40: Total de OS | R40: =SUM(R6:R21) -> 0

Sheet 14
B1: ='13'!B1+1 -> 45579
B2: Fechamento Diário do Caixa
B4: Saldo Inicial | C4: 0 | E4: Vendas | K4: Despesas
B5: Vendas | C5: =SUMIF(I6:I31,">0",H6:H31) -> 2000 | E5: Nº Venda | F5: Cliente | G5: Forma de Pgto | H5: Valor Venda | I5: Entrada | K5: Descrição | L5: Tipo de Pagto | M5: Valor
B6: Entrada | C6: =SUM(I6:I41) -> 1680 | E6: 9920 | F6: jose aprigio | G6: CTD | H6: 800 | I6: 800 | R6: =IF(vend14[[#This Row],[Nº Venda]]>1,1,0) -> 1
B7: Despesas | C7: =SUM(M6:M11) -> 0 | E7: 9921 | F7: benedito vieira | G7: CTD | H7: 1200 | I7: 600 | R7: =IF(vend14[[#This Row],[Nº Venda]]>1,1,0) -> 1
B8: Total entrada | C8: =SUM(C6:C7) -> 1680 | R8: =IF(vend14[[#This Row],[Nº Venda]]>1,1,0) -> 0
R9: =IF(vend14[[#This Row],[Nº Venda]]>1,1,0) -> 0
B10: Tipos de Pagtos | R10: =IF(vend14[[#This Row],[Nº Venda]]>1,1,0) -> 0
B11: DN | C11: =(SUMIF($G$2:$G$31,B11,$I$2:$I$31))+(SUMIF($G$35:$G$41,B11,$H$35:$H$41)) -> 200 | O11: =IF(C16=0,0,1) -> 1 | R11: =IF(vend14[[#This Row],[Nº Venda]]>1,1,0) -> 0
B12: CTD | C12: =(SUMIF($G$2:$G$31,B12,$I$2:$I$31))+(SUMIF($G$35:$G$41,B12,$H$35:$H$41)) -> 1561.25 | R12: =IF(vend14[[#This Row],[Nº Venda]]>1,1,0) -> 0
B13: CTC | C13: =(SUMIF($G$2:$G$31,B13,$I$2:$I$31))+(SUMIF($G$35:$G$41,B13,$H$35:$H$41)) -> 0 | K13: OS Entregue no Dia | R13: =IF(vend14[[#This Row],[Nº Venda]]>1,1,0) -> 0
B14: PCTC | C14: =(SUMIF($G$2:$G$31,B14,$I$2:$I$31))+(SUMIF($G$35:$G$41,B14,$H$35:$H$41)) -> 0 | K14: OS | L14: Vendedor | M14: CARNE | R14: =IF(vend14[[#This Row],[Nº Venda]]>1,1,0) -> 0
B15: PIX | C15: =(SUMIF($G$2:$G$31,B15,$I$2:$I$31))+(SUMIF($G$35:$G$41,B15,$H$35:$H$41)) -> 80 | K15: 9858 | L15: TATY | M15: Não | R15: =IF(vend14[[#This Row],[Nº Venda]]>1,1,0) -> 0
B16: Total | C16: =SUM(C11:C15) -> 1841.25 | K16: 9889 | L16: JOCY | M16: Não | R16: =IF(vend14[[#This Row],[Nº Venda]]>1,1,0) -> 0
K17: 9861 | L17: ARIANI | M17: Não | R17: =IF(vend14[[#This Row],[Nº Venda]]>1,1,0) -> 0
B18: Entrega de Carne | K18: 9830 | L18: JOCY | M18: Não | R18: =IF(vend14[[#This Row],[Nº Venda]]>1,1,0) -> 0
B19: =COUNT(entr_carn14[OS]) -> 0 | C19: =SUM(entr_carn14[Valor Total]) -> 0 | K19: 9796 | L19: JOCY | M19: Não | R19: =IF(vend14[[#This Row],[Nº Venda]]>1,1,0) -> 0
B20: Total | C20: =SUM(C19:C19) -> 0 | K20: 9893 | L20: TATY | M20: Não | R20: =IF(vend14[[#This Row],[Nº Venda]]>1,1,0) -> 0
K21: 9695 | L21: JOCY | M21: Não
B22: Venda | C22: =C5 -> 2000 | K22: 9877 | L22: TATY | M22: Não
E24: Restante Entrada
E25: Nº Venda | F25: Cliente | G25: Forma de Pgto | H25: Valor Venda | I25: Entrada
E26: 9889 | F26: ronailly lourenco | G26: DN | I26: 200
E27: 9889 | F27: ronailly lourenco | G27: PIX | I27: 80
E33: Recebimento de Carnê | K33: Entrega de Carne
E34: OS | F34: Cliente | G34: Forma de Pgto | H34: Valor Parcela | I34: Nº Parcela | K34: OS | L34: Parcelas | M34: Valor Total
E35: 9116 | F35: jose de araujo | G35: CTD | H35: 161.25 | I35: PARC. 5/8
Q40: Total de OS | R40: =SUM(R6:R21) -> 2

Sheet 15
B1: ='14'!B1+1 -> 45580
B2: Fechamento Diário do Caixa
B4: Saldo Inicial | C4: 0 | E4: Vendas | K4: Despesas
B5: Vendas | C5: =SUMIF(I6:I31,">0",H6:H31) -> 3534 | E5: Nº Venda | F5: Cliente | G5: Forma de Pgto | H5: Valor Venda | I5: Entrada | K5: Descrição | L5: Tipo de Pagto | M5: Valor
B6: Entrada | C6: =SUM(I6:I41) -> 3713 | E6: 9922 | F6: JURACI PEREIRA | G6: DN | H6: 49 | I6: 49 | R6: =IF(vend15[[#This Row],[Nº Venda]]>1,1,0) -> 1
B7: Despesas | C7: =SUM(M6:M11) -> 0 | E7: 9923 | F7: AURISETE ARNALDO | G7: CTC | H7: 2790 | I7: 2790 | R7: =IF(vend15[[#This Row],[Nº Venda]]>1,1,0) -> 1
B8: Total entrada | C8: =SUM(C6:C7) -> 3713 | E8: 9824 | F8: AURISETE ARNALDO | G8: CTC | H8: 175 | I8: 175 | R8: =IF(vend15[[#This Row],[Nº Venda]]>1,1,0) -> 1
E9: 9925 | F9: JULIANA DE OLIVEIRA | G9: PIX | H9: 450 | I9: 50 | R9: =IF(vend15[[#This Row],[Nº Venda]]>1,1,0) -> 1
B10: Tipos de Pagtos | E10: 9926 | F10: BIANCA CARDOZO | G10: PIX | H10: 70 | I10: 70 | R10: =IF(vend15[[#This Row],[Nº Venda]]>1,1,0) -> 1
B11: DN | C11: =(SUMIF($G$2:$G$31,B11,$I$2:$I$31))+(SUMIF($G$35:$G$41,B11,$H$35:$H$41)) -> 49 | O11: =IF(C16=0,0,1) -> 1 | R11: =IF(vend15[[#This Row],[Nº Venda]]>1,1,0) -> 0
B12: CTD | C12: =(SUMIF($G$2:$G$31,B12,$I$2:$I$31))+(SUMIF($G$35:$G$41,B12,$H$35:$H$41)) -> 0 | R12: =IF(vend15[[#This Row],[Nº Venda]]>1,1,0) -> 0
B13: CTC | C13: =(SUMIF($G$2:$G$31,B13,$I$2:$I$31))+(SUMIF($G$35:$G$41,B13,$H$35:$H$41)) -> 3544 | K13: OS Entregue no Dia | R13: =IF(vend15[[#This Row],[Nº Venda]]>1,1,0) -> 0
B14: PCTC | C14: =(SUMIF($G$2:$G$31,B14,$I$2:$I$31))+(SUMIF($G$35:$G$41,B14,$H$35:$H$41)) -> 0 | K14: OS | L14: Vendedor | M14: CARNE | R14: =IF(vend15[[#This Row],[Nº Venda]]>1,1,0) -> 0
B15: PIX | C15: =(SUMIF($G$2:$G$31,B15,$I$2:$I$31))+(SUMIF($G$35:$G$41,B15,$H$35:$H$41)) -> 300 | K15: 9922 | L15: TATY | M15: Não | R15: =IF(vend15[[#This Row],[Nº Venda]]>1,1,0) -> 0
B16: Total | C16: =SUM(C11:C15) -> 3893 | K16: 9832 | L16: JOCY | M16: Não | R16: =IF(vend15[[#This Row],[Nº Venda]]>1,1,0) -> 0
K17: 9881 | L17: TATY | M17: Não | R17: =IF(vend15[[#This Row],[Nº Venda]]>1,1,0) -> 0
B18: Entrega de Carne | K18: 9827 | L18: JOCY | M18: Não | R18: =IF(vend15[[#This Row],[Nº Venda]]>1,1,0) -> 0
B19: =COUNT(entr_carn15[OS]) -> 0 | C19: =SUM(entr_carn15[Valor Total]) -> 0 | K19: 9795 | L19: JOCY | M19: Não | R19: =IF(vend15[[#This Row],[Nº Venda]]>1,1,0) -> 0
B20: Total | C20: =SUM(C19:C19) -> 0 | K20: 9913 | L20: JOCY | M20: Não | R20: =IF(vend15[[#This Row],[Nº Venda]]>1,1,0) -> 0
B22: Venda | C22: =C5 -> 3534
E24: Restante Entrada
E25: Nº Venda | F25: Cliente | G25: Forma de Pgto | H25: Valor Venda | I25: Entrada
E26: 9597 | F26: BIANCA DA SILVA | G26: CTC | I26: 579
E33: Recebimento de Carnê | K33: Entrega de Carne
E34: OS | F34: Cliente | G34: Forma de Pgto | H34: Valor Parcela | I34: Nº Parcela | K34: OS | L34: Parcelas | M34: Valor Total
E35: 9757 | F35: CARLINHOS FERREIRA | G35: PIX | H35: 180 | I35: PARC. 1/6
Q40: Total de OS | R40: =SUM(R6:R21) -> 5

Sheet 16
B1: ='15'!B1+1 -> 45581
B2: Fechamento Diário do Caixa
B4: Saldo Inicial | C4: 0 | E4: Vendas | K4: Despesas
B5: Vendas | C5: =SUMIF(I6:I31,">0",H6:H31) -> 3225 | E5: Nº Venda | F5: Cliente | G5: Forma de Pgto | H5: Valor Venda | I5: Entrada | K5: Descrição | L5: Tipo de Pagto | M5: Valor
B6: Entrada | C6: =SUM(I6:I41) -> 3500 | E6: 9927 | F6: ROGERIO LUIZ | G6: CTD | H6: 800 | I6: 400 | R6: =IF(vend16[[#This Row],[Nº Venda]]>1,1,0) -> 1
B7: Despesas | C7: =SUM(M6:M11) -> 0 | E7: 9928 | F7: LUCAS DA SILVA | G7: CTC | H7: 900 | I7: 900 | R7: =IF(vend16[[#This Row],[Nº Venda]]>1,1,0) -> 1
B8: Total entrada | C8: =SUM(C6:C7) -> 3500 | E8: 9929 | F8: LUCAS DA SILVA | G8: CTC | H8: 900 | I8: 900 | R8: =IF(vend16[[#This Row],[Nº Venda]]>1,1,0) -> 1
R9: =IF(vend16[[#This Row],[Nº Venda]]>1,1,0) -> 0
B10: Tipos de Pagtos | R10: =IF(vend16[[#This Row],[Nº Venda]]>1,1,0) -> 0
B11: DN | C11: =(SUMIF($G$2:$G$31,B11,$I$2:$I$31))+(SUMIF($G$35:$G$41,B11,$H$35:$H$41)) -> 550 | O11: =IF(C16=0,0,1) -> 1 | R11: =IF(vend16[[#This Row],[Nº Venda]]>1,1,0) -> 0
B12: CTD | C12: =(SUMIF($G$2:$G$31,B12,$I$2:$I$31))+(SUMIF($G$35:$G$41,B12,$H$35:$H$41)) -> 435 | R12: =IF(vend16[[#This Row],[Nº Venda]]>1,1,0) -> 0
B13: CTC | C13: =(SUMIF($G$2:$G$31,B13,$I$2:$I$31))+(SUMIF($G$35:$G$41,B13,$H$35:$H$41)) -> 2390 | K13: OS Entregue no Dia | R13: =IF(vend16[[#This Row],[Nº Venda]]>1,1,0) -> 0
B14: PCTC | C14: =(SUMIF($G$2:$G$31,B14,$I$2:$I$31))+(SUMIF($G$35:$G$41,B14,$H$35:$H$41)) -> 0 | K14: OS | L14: Vendedor | M14: CARNE | R14: =IF(vend16[[#This Row],[Nº Venda]]>1,1,0) -> 0
B15: PIX | C15: =(SUMIF($G$2:$G$31,B15,$I$2:$I$31))+(SUMIF($G$35:$G$41,B15,$H$35:$H$41)) -> 275 | K15: 9885 | L15: TATY | M15: Não | R15: =IF(vend16[[#This Row],[Nº Venda]]>1,1,0) -> 0
B16: Total | C16: =SUM(C11:C15) -> 3650 | K16: 9868 | L16: JOCY | M16: Não | R16: =IF(vend16[[#This Row],[Nº Venda]]>1,1,0) -> 0
K17: 9908 | L17: JOCY | M17: Não | R17: =IF(vend16[[#This Row],[Nº Venda]]>1,1,0) -> 0
B18: Entrega de Carne | K18: 9855 | L18: ARIANI | M18: Não | R18: =IF(vend16[[#This Row],[Nº Venda]]>1,1,0) -> 0
B19: =COUNT(entr_carn16[OS]) -> 1 | C19: =SUM(entr_carn16[Valor Total]) -> 550 | K19: 9860 | L19: ARIANI | M19: Sim | R19: =IF(vend16[[#This Row],[Nº Venda]]>1,1,0) -> 0
B20: Total | C20: =SUM(C19:C19) -> 550 | R20: =IF(vend16[[#This Row],[Nº Venda]]>1,1,0) -> 0
B22: Venda | C22: =C5 -> 3225
E24: Restante Entrada
E25: Nº Venda | F25: Cliente | G25: Forma de Pgto | H25: Valor Venda | I25: Entrada
E26: 9850 | F26: ADELAIDE MARIA | G26: DN | I26: 250
E27: 9908 | F27: ERICK KENNZO | G27: CTD | H27: 35 | I27: 35
E28: 9855 | F28: JOSE ERNESTO | G28: DN | I28: 300
E29: 9860 | F29: ADRIANA APARECIDA | G29: PIX | I29: 125
E30: 9810 | F30: TANIA CRISTINA | G30: CTC | H30: 590 | I30: 590
E33: Recebimento de Carnê | K33: Entrega de Carne
E34: OS | F34: Cliente | G34: Forma de Pgto | H34: Valor Parcela | I34: Nº Parcela | K34: OS | L34: Parcelas | M34: Valor Total
E35: 9536 | F35: VIVIAN DANTAS | G35: PIX | H35: 150 | I35: PARC. 2/6 | K35: 9860 | L35: 5 | M35: 550
Q40: Total de OS | R40: =SUM(R6:R21) -> 3

Sheet 17
B1: ='16'!B1+1 -> 45582
B2: Fechamento Diário do Caixa
B4: Saldo Inicial | C4: 0 | E4: Vendas | K4: Despesas
B5: Vendas | C5: =SUMIF(I6:I31,">0",H6:H31) -> 300 | E5: Nº Venda | F5: Cliente | G5: Forma de Pgto | H5: Valor Venda | I5: Entrada | K5: Descrição | L5: Tipo de Pagto | M5: Valor
B6: Entrada | C6: =SUM(I6:I41) -> 1230 | E6: 9930 | F6: FABIO TOSHIO | G6: DN | H6: 300 | I6: 100 | R6: =IF(vend17[[#This Row],[Nº Venda]]>1,1,0) -> 1
B7: Despesas | C7: =SUM(M6:M11) -> 0 | R7: =IF(vend17[[#This Row],[Nº Venda]]>1,1,0) -> 0
B8: Total entrada | C8: =SUM(C6:C7) -> 1230 | R8: =IF(vend17[[#This Row],[Nº Venda]]>1,1,0) -> 0
R9: =IF(vend17[[#This Row],[Nº Venda]]>1,1,0) -> 0
B10: Tipos de Pagtos | R10: =IF(vend17[[#This Row],[Nº Venda]]>1,1,0) -> 0
B11: DN | C11: =(SUMIF($G$2:$G$31,B11,$I$2:$I$31))+(SUMIF($G$35:$G$41,B11,$H$35:$H$41)) -> 500 | O11: =IF(C16=0,0,1) -> 1 | R11: =IF(vend17[[#This Row],[Nº Venda]]>1,1,0) -> 0
B12: CTD | C12: =(SUMIF($G$2:$G$31,B12,$I$2:$I$31))+(SUMIF($G$35:$G$41,B12,$H$35:$H$41)) -> 617.1 | R12: =IF(vend17[[#This Row],[Nº Venda]]>1,1,0) -> 0
B13: CTC | C13: =(SUMIF($G$2:$G$31,B13,$I$2:$I$31))+(SUMIF($G$35:$G$41,B13,$H$35:$H$41)) -> 0 | K13: OS Entregue no Dia | R13: =IF(vend17[[#This Row],[Nº Venda]]>1,1,0) -> 0
B14: PCTC | C14: =(SUMIF($G$2:$G$31,B14,$I$2:$I$31))+(SUMIF($G$35:$G$41,B14,$H$35:$H$41)) -> 0 | K14: OS | L14: Vendedor | M14: CARNE | R14: =IF(vend17[[#This Row],[Nº Venda]]>1,1,0) -> 0
B15: PIX | C15: =(SUMIF($G$2:$G$31,B15,$I$2:$I$31))+(SUMIF($G$35:$G$41,B15,$H$35:$H$41)) -> 430 | K15: 9905 | L15: JOCY | M15: Não | R15: =IF(vend17[[#This Row],[Nº Venda]]>1,1,0) -> 0
B16: Total | C16: =SUM(C11:C15) -> 1547.1 | K16: 9919 | L16: JOCY | M16: Não | R16: =IF(vend17[[#This Row],[Nº Venda]]>1,1,0) -> 0
K17: 9916 | L17: TATY | M17: Sim | R17: =IF(vend17[[#This Row],[Nº Venda]]>1,1,0) -> 0
B18: Entrega de Carne | K18: 9826 | L18: JOCY | M18: Não | R18: =IF(vend17[[#This Row],[Nº Venda]]>1,1,0) -> 0
B19: =COUNT(entr_carn17[OS]) -> 1 | C19: =SUM(entr_carn17[Valor Total]) -> 906 | R19: =IF(vend17[[#This Row],[Nº Venda]]>1,1,0) -> 0
B20: Total | C20: =SUM(C19:C19) -> 906 | R20: =IF(vend17[[#This Row],[Nº Venda]]>1,1,0) -> 0
B22: Venda | C22: =C5 -> 300
E24: Restante Entrada
E25: Nº Venda | F25: Cliente | G25: Forma de Pgto | H25: Valor Venda | I25: Entrada
E26: 9919 | F26: ROSANGELA | G26: PIX | I26: 100
E27: 9916 | F27: ROSAN GLESIA | G27: PIX | I27: 330
E28: 9826 | F28: ADENILSON SOARES | G28: DN | I28: 300
E29: 9826 | F29: ADENILSON SOARES | G29: CTD | I29: 300
E30: 9827 | F30: ADENILSON SOARES | G30: DN | I30: 100
U31: 0
E33: Recebimento de Carnê | K33: Entrega de Carne
E34: OS | F34: Cliente | G34: Forma de Pgto | H34: Valor Parcela | I34: Nº Parcela | K34: OS | L34: Parcelas | M34: Valor Total
E35: 8862 | F35: SEBASTIÃO PEREIRA | G35: CTD | H35: 158.55 | I35: PARC. 4/9 | K35: 9916 | L35: 6 | M35: 906
E36: 8862 | F36: SEBASTIÃO PEREIRA | G36: CTD | H36: 158.55 | I36: PARC. 5/9
Q40: Total de OS | R40: =SUM(R6:R21) -> 1

Sheet 18
B1: ='17'!B1+1 -> 45583
B2: Fechamento Diário do Caixa
B4: Saldo Inicial | C4: 0 | E4: Vendas | K4: Despesas
B5: Vendas | C5: =SUMIF(I6:I31,">0",H6:H31) -> 2440 | E5: Nº Venda | F5: Cliente | G5: Forma de Pgto | H5: Valor Venda | I5: Entrada | K5: Descrição | L5: Tipo de Pagto | M5: Valor
B6: Entrada | C6: =SUM(I6:I41) -> 839 | E6: 9931 | F6: BERNADETE RAMOS | G6: DN | H6: 400 | I6: 400 | R6: =IF(vend18[[#This Row],[Nº Venda]]>1,1,0) -> 1
B7: Despesas | C7: =SUM(M6:M11) -> 0 | E7: 9932 | F7: MARIA PRADO | G7: CTD | H7: 750 | I7: 50 | R7: =IF(vend18[[#This Row],[Nº Venda]]>1,1,0) -> 1
B8: Total entrada | C8: =SUM(C6:C7) -> 839 | E8: 9933 | F8: JOANA MARIA | G8: CTD | H8: 1290 | I8: 389 | R8: =IF(vend18[[#This Row],[Nº Venda]]>1,1,0) -> 1
R9: =IF(vend18[[#This Row],[Nº Venda]]>1,1,0) -> 0
B10: Tipos de Pagtos | R10: =IF(vend18[[#This Row],[Nº Venda]]>1,1,0) -> 0
B11: DN | C11: =(SUMIF($G$2:$G$31,B11,$I$2:$I$31))+(SUMIF($G$35:$G$41,B11,$H$35:$H$41)) -> 400 | O11: =IF(C16=0,0,1) -> 1 | R11: =IF(vend18[[#This Row],[Nº Venda]]>1,1,0) -> 0
B12: CTD | C12: =(SUMIF($G$2:$G$31,B12,$I$2:$I$31))+(SUMIF($G$35:$G$41,B12,$H$35:$H$41)) -> 439 | R12: =IF(vend18[[#This Row],[Nº Venda]]>1,1,0) -> 0
B13: CTC | C13: =(SUMIF($G$2:$G$31,B13,$I$2:$I$31))+(SUMIF($G$35:$G$41,B13,$H$35:$H$41)) -> 0 | K13: OS Entregue no Dia | R13: =IF(vend18[[#This Row],[Nº Venda]]>1,1,0) -> 0
B14: PCTC | C14: =(SUMIF($G$2:$G$31,B14,$I$2:$I$31))+(SUMIF($G$35:$G$41,B14,$H$35:$H$41)) -> 0 | K14: OS | L14: Vendedor | M14: CARNE | R14: =IF(vend18[[#This Row],[Nº Venda]]>1,1,0) -> 0
B15: PIX | C15: =(SUMIF($G$2:$G$31,B15,$I$2:$I$31))+(SUMIF($G$35:$G$41,B15,$H$35:$H$41)) -> 0 | K15: 9873 | L15: JOCY | M15: Não | R15: =IF(vend18[[#This Row],[Nº Venda]]>1,1,0) -> 0
B16: Total | C16: =SUM(C11:C15) -> 839 | K16: 9872 | L16: JOCY | M16: Não | R16: =IF(vend18[[#This Row],[Nº Venda]]>1,1,0) -> 0
K17: 9909 | L17: JOCY | M17: Não | R17: =IF(vend18[[#This Row],[Nº Venda]]>1,1,0) -> 0
B18: Entrega de Carne | K18: 9882 | L18: TATY | M18: Não | R18: =IF(vend18[[#This Row],[Nº Venda]]>1,1,0) -> 0
B19: =COUNT(entr_carn18[OS]) -> 0 | C19: =SUM(entr_carn18[Valor Total]) -> 0 | K19: 9926 | L19: TATY | M19: Não | R19: =IF(vend18[[#This Row],[Nº Venda]]>1,1,0) -> 0
B20: Total | C20: =SUM(C19:C19) -> 0 | K20: 9819 | L20: ARIANI | M20: Não | R20: =IF(vend18[[#This Row],[Nº Venda]]>1,1,0) -> 0
K21: 9898 | L21: JOCY | M21: Não
B22: Venda | C22: =C5 -> 2440
E24: Restante Entrada
E25: Nº Venda | F25: Cliente | G25: Forma de Pgto | H25: Valor Venda | I25: Entrada
E33: Recebimento de Carnê | K33: Entrega de Carne
E34: OS | F34: Cliente | G34: Forma de Pgto | H34: Valor Parcela | I34: Nº Parcela | K34: OS | L34: Parcelas | M34: Valor Total
Q40: Total de OS | R40: =SUM(R6:R21) -> 3

Sheet 19
B1: ='18'!B1+1 -> 45584
B2: Fechamento Diário do Caixa
B4: Saldo Inicial | C4: 0 | E4: Vendas | K4: Despesas
B5: Vendas | C5: =SUMIF(I6:I31,">0",H6:H31) -> 4548 | E5: Nº Venda | F5: Cliente | G5: Forma de Pgto | H5: Valor Venda | I5: Entrada | K5: Descrição | L5: Tipo de Pagto | M5: Valor
B6: Entrada | C6: =SUM(I6:I41) -> 3089 | E6: 9934 | F6: EDSON LUCAS | G6: CTC | H6: 300 | I6: 300 | R6: =IF(vend19[[#This Row],[Nº Venda]]>1,1,0) -> 1
B7: Despesas | C7: =SUM(M6:M11) -> 0 | E7: 9935 | F7: DIVA DE OLIVEIRA | G7: PIX | H7: 600 | I7: 50 | R7: =IF(vend19[[#This Row],[Nº Venda]]>1,1,0) -> 1
B8: Total entrada | C8: =SUM(C6:C7) -> 3089 | E8: 9936 | F8: RODRIGO BISPO | G8: PIX | H8: 699 | I8: 40 | R8: =IF(vend19[[#This Row],[Nº Venda]]>1,1,0) -> 1
E9: 9937 | F9: DIRCE GABRIELLE | G9: PIX | H9: 400 | I9: 200 | R9: =IF(vend19[[#This Row],[Nº Venda]]>1,1,0) -> 1
B10: Tipos de Pagtos | E10: 9938 | F10: ERICA TAMIRES | G10: PIX | H10: 600 | I10: 300 | R10: =IF(vend19[[#This Row],[Nº Venda]]>1,1,0) -> 1
