Workbook

Sheet resumo_cx
P1: Colaboradores
A2: Saldo Inicial | B2: 0 | P2: ROGÉRIO
A3: Vendas | B3: =SUM('01'!C5,'02'!C5,'03'!C5,'04'!C5,'05'!C5,'06'!C5,'07'!C5,'08'!C5,'09'!C5,'10'!C5,'11'!C5,'12'!C5,'13'!C5,'14'!C5,'15'!C5,'16'!C5,'17'!C5,'18'!C5,'19'!C5,'20'!C5,'21'!C5,'22'!C5,'23'!C5,'24'!C5,'25'!C5,'26'!C5,'27'!C5,'28'!C5,'29'!C5,'30'!C5,'31'!C5) -> 27321 | P3: JOCY
A4: Entrada | B4: =SUM('01'!C6,'02'!C6,'03'!C6,'04'!C6,'05'!C6,'06'!C6,'07'!C6,'08'!C6,'09'!C6,'10'!C6,'11'!C6,'12'!C6,'13'!C6,'14'!C6,'15'!C6,'16'!C6,'17'!C6,'18'!C6,'19'!C6,'20'!C6,'21'!C6,'22'!C6,'23'!C6,'24'!C6,'25'!C6,'26'!C6,'27'!C6,'28'!C6,'29'!C6,'30'!C6,'31'!C6) -> 24776 | P4: MARIA
A5: Despesas | B5: =SUM('01'!C7,'02'!C7,'03'!C7,'04'!C7,'05'!C7,'06'!C7,'07'!C7,'08'!C7,'09'!C7,'10'!C7,'11'!C7,'12'!C7,'13'!C7,'14'!C7,'15'!C7,'16'!C7,'17'!C7,'18'!C7,'19'!C7,'20'!C7,'21'!C7,'22'!C7,'23'!C7,'24'!C7,'25'!C7,'26'!C7,'27'!C7,'28'!C7,'29'!C7,'30'!C7,'31'!C7) -> 381 | P5: WEVILLY
A6: Entr_Desp | B6: =SUM(B4:B5) -> 25157 | P6: BETH
P7: ARIANI
A8: Tipos de Pagtos | P8: ROSÂNGELA
A9: DN | B9: =SUM('01'!C11,'02'!C11,'03'!C11,'04'!C11,'05'!C11,'06'!C11,'07'!C11,'08'!C11,'09'!C11,'10'!C11,'11'!C11,'12'!C11,'13'!C11,'14'!C11,'15'!C11,'16'!C11,'17'!C11,'18'!C11,'19'!C11,'20'!C11,'21'!C11,'22'!C11,'23'!C11,'24'!C11,'25'!C11,'26'!C11,'27'!C11,'28'!C11,'29'!C11,'30'!C11,'31'!C11) -> 2532 | P9: TATY
A10: CTD | B10: =SUM('01'!C12,'02'!C12,'03'!C12,'04'!C12,'05'!C12,'06'!C12,'07'!C12,'08'!C12,'09'!C12,'10'!C12,'11'!C12,'12'!C12,'13'!C12,'14'!C12,'15'!C12,'16'!C12,'17'!C12,'18'!C12,'19'!C12,'20'!C12,'21'!C12,'22'!C12,'23'!C12,'24'!C12,'25'!C12,'26'!C12,'27'!C12,'28'!C12,'29'!C12,'30'!C12,'31'!C12) -> 1867 | P10: LARISSA
A11: CTC | B11: =SUM('01'!C13,'02'!C13,'03'!C13,'04'!C13,'05'!C13,'06'!C13,'07'!C13,'08'!C13,'09'!C13,'10'!C13,'11'!C13,'12'!C13,'13'!C13,'14'!C13,'15'!C13,'16'!C13,'17'!C13,'18'!C13,'19'!C13,'20'!C13,'21'!C13,'22'!C13,'23'!C13,'24'!C13,'25'!C13,'26'!C13,'27'!C13,'28'!C13,'29'!C13,'30'!C13,'31'!C13) -> 17794 | P11: ERIKA
A12: PCTC | B12: =SUM('01'!C14,'02'!C14,'03'!C14,'04'!C14,'05'!C14,'06'!C14,'07'!C14,'08'!C14,'09'!C14,'10'!C14,'11'!C14,'12'!C14,'13'!C14,'14'!C14,'15'!C14,'16'!C14,'17'!C14,'18'!C14,'19'!C14,'20'!C14,'21'!C14,'22'!C14,'23'!C14,'24'!C14,'25'!C14,'26'!C14,'27'!C14,'28'!C14,'29'!C14,'30'!C14,'31'!C14) -> 0 | P12: LUANA
A13: PIX | B13: =SUM('01'!C15,'02'!C15,'03'!C15,'04'!C15,'05'!C15,'06'!C15,'07'!C15,'08'!C15,'09'!C15,'10'!C15,'11'!C15,'12'!C15,'13'!C15,'14'!C15,'15'!C15,'16'!C15,'17'!C15,'18'!C15,'19'!C15,'20'!C15,'21'!C15,'22'!C15,'23'!C15,'24'!C15,'25'!C15,'26'!C15,'27'!C15,'28'!C15,'29'!C15,'30'!C15,'31'!C15) -> 3171 | P13: FELIPE
A14: Total | B14: =SUM(B9:B13) -> 25364
A16: Entrega de Carne
A17: =COUNT(#REF!) -> 0 | B17: =SUM('01'!C19,'02'!C19,'03'!C19,'04'!C19,'05'!C19,'06'!C19,'07'!C19,'08'!C19,'09'!C19,'10'!C19,'11'!C19,'12'!C19,'13'!C19,'14'!C19,'15'!C19,'16'!C19,'17'!C19,'18'!C19,'19'!C19,'20'!C19,'21'!C19,'22'!C19,'23'!C19,'24'!C19,'25'!C19,'26'!C19,'27'!C19,'28'!C19,'29'!C19,'30'!C19,'31'!C19) -> 0
A18: Total | B18: =SUM(B17:B17) -> 0

Sheet 01
B1: 45536
B2: Fechamento Diário do Caixa - Escritório
B4: Saldo Inicial | C4: 0 | E4: Vendas | K4: Despesas
B5: Vendas | C5: =SUMIF(I6:I31,">0",H6:H31) -> 0 | E5: Nº Venda | F5: Cliente | G5: Forma de Pgto | H5: Valor Venda | I5: Entrada | K5: Descrição | L5: Tipo de Pagto | M5: Valor
B6: Entrada | C6: =SUM(I6:I41) -> 0 | R6: =IF(vend1[[#This Row],[Nº Venda]]>1,1,0) -> 0
B7: Despesas | C7: =SUM(M6:M11) -> 0 | R7: =IF(vend1[[#This Row],[Nº Venda]]>1,1,0) -> 0
B8: Total entrada | C8: =SUM(C6:C7) -> 0 | R8: =IF(vend1[[#This Row],[Nº Venda]]>1,1,0) -> 0
R9: =IF(vend1[[#This Row],[Nº Venda]]>1,1,0) -> 0
B10: Tipos de Pagtos | R10: =IF(vend1[[#This Row],[Nº Venda]]>1,1,0) -> 0
B11: DN | C11: =(SUMIF($G$2:$G$31,B11,$I$2:$I$31))+(SUMIF($G$35:$G$41,B11,$H$35:$H$41)) -> 0 | O11: =IF(C16=0,0,1) -> 0 | R11: =IF(vend1[[#This Row],[Nº Venda]]>1,1,0) -> 0
B12: CTD | C12: =(SUMIF($G$2:$G$31,B12,$I$2:$I$31))+(SUMIF($G$35:$G$41,B12,$H$35:$H$41)) -> 0 | R12: =IF(vend1[[#This Row],[Nº Venda]]>1,1,0) -> 0
B13: CTC | C13: =(SUMIF($G$2:$G$31,B13,$I$2:$I$31))+(SUMIF($G$35:$G$41,B13,$H$35:$H$41)) -> 0 | K13: OS Entregue no Dia | R13: =IF(vend1[[#This Row],[Nº Venda]]>1,1,0) -> 0
B14: PCTC | C14: =(SUMIF($G$2:$G$31,B14,$I$2:$I$31))+(SUMIF($G$35:$G$41,B14,$H$35:$H$41)) -> 0 | K14: OS | L14: Vendedor | M14: CARNE | R14: =IF(vend1[[#This Row],[Nº Venda]]>1,1,0) -> 0
B15: PIX | C15: =(SUMIF($G$2:$G$31,B15,$I$2:$I$31))+(SUMIF($G$35:$G$41,B15,$H$35:$H$41)) -> 0 | R15: =IF(vend1[[#This Row],[Nº Venda]]>1,1,0) -> 0
B16: Total | C16: =SUM(C11:C15) -> 0 | R16: =IF(vend1[[#This Row],[Nº Venda]]>1,1,0) -> 0
R17: =IF(vend1[[#This Row],[Nº Venda]]>1,1,0) -> 0
B18: Entrega de Carne | R18: =IF(vend1[[#This Row],[Nº Venda]]>1,1,0) -> 0
B19: =COUNT(entr_carn31195[OS]) -> 0 | C19: =SUM(entr_carn31195[Valor Total]) -> 0 | R19: =IF(vend1[[#This Row],[Nº Venda]]>1,1,0) -> 0
B20: Total | C20: =SUM(C19:C19) -> 0 | R20: =IF(vend1[[#This Row],[Nº Venda]]>1,1,0) -> 0
B22: Venda | C22: =C5 -> 0
E24: Restante Entrada
E25: Nº Venda | F25: Cliente | G25: Forma de Pgto | H25: Valor Venda | I25: Entrada
E33: Recebimento de Carnê | K33: Entrega de Carne
E34: OS | F34: Cliente | G34: Forma de Pgto | H34: Valor Parcela | I34: Nº Parcela | K34: OS | L34: Parcelas | M34: Valor Total
Q40: Total de OS | R40: =SUM(R6:R21) -> 0

Sheet 02
B1: ='01'!B1+1 -> 45537
B2: Fechamento Diário do Caixa
B4: Saldo Inicial | C4: 0 | E4: Vendas | K4: Despesas
B5: Vendas | C5: =SUMIF(I6:I31,">0",H6:H31) -> 0 | E5: Nº Venda | F5: Cliente | G5: Forma de Pgto | H5: Valor Venda | I5: Entrada | K5: Descrição | L5: Tipo de Pagto | M5: Valor
B6: Entrada | C6: =SUM(I6:I41) -> 499 | R6: =IF(vend2[[#This Row],[Nº Venda]]>1,1,0) -> 0
B7: Despesas | C7: =SUM(M6:M11) -> 0 | R7: =IF(vend2[[#This Row],[Nº Venda]]>1,1,0) -> 0
B8: Total entrada | C8: =SUM(C6:C7) -> 499 | R8: =IF(vend2[[#This Row],[Nº Venda]]>1,1,0) -> 0
R9: =IF(vend2[[#This Row],[Nº Venda]]>1,1,0) -> 0
B10: Tipos de Pagtos | R10: =IF(vend2[[#This Row],[Nº Venda]]>1,1,0) -> 0
B11: DN | C11: =(SUMIF($G$2:$G$31,B11,$I$2:$I$31))+(SUMIF($G$35:$G$41,B11,$H$35:$H$41)) -> 0 | O11: =IF(C16=0,0,1) -> 1 | R11: =IF(vend2[[#This Row],[Nº Venda]]>1,1,0) -> 0
B12: CTD | C12: =(SUMIF($G$2:$G$31,B12,$I$2:$I$31))+(SUMIF($G$35:$G$41,B12,$H$35:$H$41)) -> 0 | R12: =IF(vend2[[#This Row],[Nº Venda]]>1,1,0) -> 0
B13: CTC | C13: =(SUMIF($G$2:$G$31,B13,$I$2:$I$31))+(SUMIF($G$35:$G$41,B13,$H$35:$H$41)) -> 450 | K13: OS Entregue no Dia | R13: =IF(vend2[[#This Row],[Nº Venda]]>1,1,0) -> 0
B14: PCTC | C14: =(SUMIF($G$2:$G$31,B14,$I$2:$I$31))+(SUMIF($G$35:$G$41,B14,$H$35:$H$41)) -> 0 | K14: OS | L14: Vendedor | M14: CARNE | R14: =IF(vend2[[#This Row],[Nº Venda]]>1,1,0) -> 0
B15: PIX | C15: =(SUMIF($G$2:$G$31,B15,$I$2:$I$31))+(SUMIF($G$35:$G$41,B15,$H$35:$H$41)) -> 49 | K15: 3705 | L15: ROGÉRIO | M15: Não | R15: =IF(vend2[[#This Row],[Nº Venda]]>1,1,0) -> 0
B16: Total | C16: =SUM(C11:C15) -> 499 | K16: 3704 | L16: ROGÉRIO | M16: Não | R16: =IF(vend2[[#This Row],[Nº Venda]]>1,1,0) -> 0
K17: 3701 | L17: ROGÉRIO | M17: Não | R17: =IF(vend2[[#This Row],[Nº Venda]]>1,1,0) -> 0
B18: Entrega de Carne | R18: =IF(vend2[[#This Row],[Nº Venda]]>1,1,0) -> 0
B19: =COUNT(entr_carn2[OS]) -> 0 | C19: =SUM(entr_carn2[Valor Total]) -> 0 | R19: =IF(vend2[[#This Row],[Nº Venda]]>1,1,0) -> 0
B20: Total | C20: =SUM(C19:C19) -> 0 | R20: =IF(vend2[[#This Row],[Nº Venda]]>1,1,0) -> 0
B22: Venda | C22: =C5 -> 0
E24: Restante Entrada
E25: Nº Venda | F25: Cliente | G25: Forma de Pgto | H25: Valor Venda | I25: Entrada
E26: 3705 | F26: william dos santos | G26: CTC | I26: 450
E27: 3705 | F27: william dos santos | G27: PIX | I27: 49
E33: Recebimento de Carnê | K33: Entrega de Carne
E34: OS | F34: Cliente | G34: Forma de Pgto | H34: Valor Parcela | I34: Nº Parcela | K34: OS | L34: Parcelas | M34: Valor Total | U34: V
Q40: Total de OS | R40: =SUM(R6:R21) -> 0

Sheet 03
B1: ='02'!B1+1 -> 45538
B2: Fechamento Diário do Caixa
B4: Saldo Inicial | C4: 0 | E4: Vendas | K4: Despesas
B5: Vendas | C5: =SUMIF(I6:I31,">0",H6:H31) -> 0 | E5: Nº Venda | F5: Cliente | G5: Forma de Pgto | H5: Valor Venda | I5: Entrada | K5: Descrição | L5: Tipo de Pagto | M5: Valor
B6: Entrada | C6: =SUM(I6:I41) -> 415 | R6: =IF(vend3[[#This Row],[Nº Venda]]>1,1,0) -> 0
B7: Despesas | C7: =SUM(M6:M11) -> 0 | R7: =IF(vend3[[#This Row],[Nº Venda]]>1,1,0) -> 0
B8: Total entrada | C8: =SUM(C6:C7) -> 415 | R8: =IF(vend3[[#This Row],[Nº Venda]]>1,1,0) -> 0
R9: =IF(vend3[[#This Row],[Nº Venda]]>1,1,0) -> 0
B10: Tipos de Pagtos | R10: =IF(vend3[[#This Row],[Nº Venda]]>1,1,0) -> 0
B11: DN | C11: =(SUMIF($G$2:$G$31,B11,$I$2:$I$31))+(SUMIF($G$35:$G$41,B11,$H$35:$H$41)) -> 250 | O11: =IF(C16=0,0,1) -> 1 | R11: =IF(vend3[[#This Row],[Nº Venda]]>1,1,0) -> 0
B12: CTD | C12: =(SUMIF($G$2:$G$31,B12,$I$2:$I$31))+(SUMIF($G$35:$G$41,B12,$H$35:$H$41)) -> 165 | R12: =IF(vend3[[#This Row],[Nº Venda]]>1,1,0) -> 0
B13: CTC | C13: =(SUMIF($G$2:$G$31,B13,$I$2:$I$31))+(SUMIF($G$35:$G$41,B13,$H$35:$H$41)) -> 0 | K13: OS Entregue no Dia | R13: =IF(vend3[[#This Row],[Nº Venda]]>1,1,0) -> 0
B14: PCTC | C14: =(SUMIF($G$2:$G$31,B14,$I$2:$I$31))+(SUMIF($G$35:$G$41,B14,$H$35:$H$41)) -> 0 | K14: OS | L14: Vendedor | M14: CARNE | R14: =IF(vend3[[#This Row],[Nº Venda]]>1,1,0) -> 0
B15: PIX | C15: =(SUMIF($G$2:$G$31,B15,$I$2:$I$31))+(SUMIF($G$35:$G$41,B15,$H$35:$H$41)) -> 0 | K15: 3614 | L15: ROGÉRIO | M15: Não | R15: =IF(vend3[[#This Row],[Nº Venda]]>1,1,0) -> 0
B16: Total | C16: =SUM(C11:C15) -> 415 | K16: 3703 | L16: ROGÉRIO | M16: Não | R16: =IF(vend3[[#This Row],[Nº Venda]]>1,1,0) -> 0
R17: =IF(vend3[[#This Row],[Nº Venda]]>1,1,0) -> 0
B18: Entrega de Carne | R18: =IF(vend3[[#This Row],[Nº Venda]]>1,1,0) -> 0
B19: =COUNT(entr_carn3[OS]) -> 0 | C19: =SUM(entr_carn3[Valor Total]) -> 0 | R19: =IF(vend3[[#This Row],[Nº Venda]]>1,1,0) -> 0
B20: Total | C20: =SUM(C19:C19) -> 0 | R20: =IF(vend3[[#This Row],[Nº Venda]]>1,1,0) -> 0
B22: Venda | C22: =C5 -> 0
E24: Restante Entrada
E25: Nº Venda | F25: Cliente | G25: Forma de Pgto | H25: Valor Venda | I25: Entrada
E26: 3614 | F26: CHRISLENE CARVALHO | G26: DN | I26: 250
E27: 3703 | F27: LIRIAH PENNA | G27: CTD | I27: 165
E33: Recebimento de Carnê | K33: Entrega de Carne
E34: OS | F34: Cliente | G34: Forma de Pgto | H34: Valor Parcela | I34: Nº Parcela | K34: OS | L34: Parcelas | M34: Valor Total
Q40: Total de OS | R40: =SUM(R6:R21) -> 0

Sheet 04
B1: ='03'!B1+1 -> 45539
B2: Fechamento Diário do Caixa
B4: Saldo Inicial | C4: 0 | E4: Vendas | K4: Despesas
B5: Vendas | C5: =SUMIF(I6:I31,">0",H6:H31) -> 2191 | E5: Nº Venda | F5: Cliente | G5: Forma de Pgto | H5: Valor Venda | I5: Entrada | K5: Descrição | L5: Tipo de Pagto | M5: Valor
B6: Entrada | C6: =SUM(I6:I41) -> 2191 | E6: 3710 | F6: MARIA VALERIA | G6: CTC | H6: 930 | I6: 800 | R6: =IF(vend4[[#This Row],[Nº Venda]]>1,1,0) -> 1
B7: Despesas | C7: =SUM(M6:M11) -> 0 | E7: 3710 | F7: MARIA VALERIA | G7: DN | I7: 100 | R7: =IF(vend4[[#This Row],[Nº Venda]]>1,1,0) -> 1
B8: Total entrada | C8: =SUM(C6:C7) -> 2191 | E8: 3710 | F8: MARIA VALERIA | G8: PIX | I8: 30 | R8: =IF(vend4[[#This Row],[Nº Venda]]>1,1,0) -> 1
E9: 3711 | F9: MARILENA LOURENÇO | G9: CTC | H9: 862 | I9: 862 | R9: =IF(vend4[[#This Row],[Nº Venda]]>1,1,0) -> 1
B10: Tipos de Pagtos | E10: 3712 | F10: ALESSANDRA LOURENÇO | G10: CTC | H10: 399 | I10: 399 | R10: =IF(vend4[[#This Row],[Nº Venda]]>1,1,0) -> 1
B11: DN | C11: =(SUMIF($G$2:$G$31,B11,$I$2:$I$31))+(SUMIF($G$35:$G$41,B11,$H$35:$H$41)) -> 267 | O11: =IF(C16=0,0,1) -> 1 | R11: =IF(vend4[[#This Row],[Nº Venda]]>1,1,0) -> 0
B12: CTD | C12: =(SUMIF($G$2:$G$31,B12,$I$2:$I$31))+(SUMIF($G$35:$G$41,B12,$H$35:$H$41)) -> 0 | R12: =IF(vend4[[#This Row],[Nº Venda]]>1,1,0) -> 0
B13: CTC | C13: =(SUMIF($G$2:$G$31,B13,$I$2:$I$31))+(SUMIF($G$35:$G$41,B13,$H$35:$H$41)) -> 2061 | K13: OS Entregue no Dia | R13: =IF(vend4[[#This Row],[Nº Venda]]>1,1,0) -> 0
B14: PCTC | C14: =(SUMIF($G$2:$G$31,B14,$I$2:$I$31))+(SUMIF($G$35:$G$41,B14,$H$35:$H$41)) -> 0 | K14: OS | L14: Vendedor | M14: CARNE | R14: =IF(vend4[[#This Row],[Nº Venda]]>1,1,0) -> 0
B15: PIX | C15: =(SUMIF($G$2:$G$31,B15,$I$2:$I$31))+(SUMIF($G$35:$G$41,B15,$H$35:$H$41)) -> 30 | K15: 3617 | L15: ROSÂNGELA | M15: Não | R15: =IF(vend4[[#This Row],[Nº Venda]]>1,1,0) -> 0
B16: Total | C16: =SUM(C11:C15) -> 2358 | R16: =IF(vend4[[#This Row],[Nº Venda]]>1,1,0) -> 0
R17: =IF(vend4[[#This Row],[Nº Venda]]>1,1,0) -> 0
B18: Entrega de Carne | R18: =IF(vend4[[#This Row],[Nº Venda]]>1,1,0) -> 0
B19: =COUNT(entr_carn4[OS]) -> 0 | C19: =SUM(entr_carn4[Valor Total]) -> 0 | R19: =IF(vend4[[#This Row],[Nº Venda]]>1,1,0) -> 0
B20: Total | C20: =SUM(C19:C19) -> 0 | R20: =IF(vend4[[#This Row],[Nº Venda]]>1,1,0) -> 0
B22: Venda | C22: =C5 -> 2191
E24: Restante Entrada
E25: Nº Venda | F25: Cliente | G25: Forma de Pgto | H25: Valor Venda | I25: Entrada
E33: Recebimento de Carnê | K33: Entrega de Carne
E34: OS | F34: Cliente | G34: Forma de Pgto | H34: Valor Parcela | I34: Nº Parcela | K34: OS | L34: Parcelas | M34: Valor Total
E35: 3611 | F35: EDNALVA BATISTA ALMEIDA | G35: DN | H35: 167 | I35: PARC. 2/5
Q40: Total de OS | R40: =SUM(R6:R21) -> 5

Sheet 05
B1: ='04'!B1+1 -> 45540
B2: Fechamento Diário do Caixa
B4: Saldo Inicial | C4: 0 | E4: Vendas | K4: Despesas
B5: Vendas | C5: =SUMIF(I6:I31,">0",H6:H31) -> 0 | E5: Nº Venda | F5: Cliente | G5: Forma de Pgto | H5: Valor Venda | I5: Entrada | K5: Descrição | L5: Tipo de Pagto | M5: Valor
B6: Entrada | C6: =SUM(I6:I41) -> 0 | R6: =IF(vend5[[#This Row],[Nº Venda]]>1,1,0) -> 0
B7: Despesas | C7: =SUM(M6:M11) -> 0 | R7: =IF(vend5[[#This Row],[Nº Venda]]>1,1,0) -> 0
B8: Total entrada | C8: =SUM(C6:C7) -> 0 | R8: =IF(vend5[[#This Row],[Nº Venda]]>1,1,0) -> 0
R9: =IF(vend5[[#This Row],[Nº Venda]]>1,1,0) -> 0
B10: Tipos de Pagtos | R10: =IF(vend5[[#This Row],[Nº Venda]]>1,1,0) -> 0
B11: DN | C11: =(SUMIF($G$2:$G$31,B11,$I$2:$I$31))+(SUMIF($G$35:$G$41,B11,$H$35:$H$41)) -> 0 | O11: =IF(C16=0,0,1) -> 0 | R11: =IF(vend5[[#This Row],[Nº Venda]]>1,1,0) -> 0
B12: CTD | C12: =(SUMIF($G$2:$G$31,B12,$I$2:$I$31))+(SUMIF($G$35:$G$41,B12,$H$35:$H$41)) -> 0 | R12: =IF(vend5[[#This Row],[Nº Venda]]>1,1,0) -> 0
B13: CTC | C13: =(SUMIF($G$2:$G$31,B13,$I$2:$I$31))+(SUMIF($G$35:$G$41,B13,$H$35:$H$41)) -> 0 | K13: OS Entregue no Dia | R13: =IF(vend5[[#This Row],[Nº Venda]]>1,1,0) -> 0
B14: PCTC | C14: =(SUMIF($G$2:$G$31,B14,$I$2:$I$31))+(SUMIF($G$35:$G$41,B14,$H$35:$H$41)) -> 0 | K14: OS | L14: Vendedor | M14: CARNE | R14: =IF(vend5[[#This Row],[Nº Venda]]>1,1,0) -> 0
B15: PIX | C15: =(SUMIF($G$2:$G$31,B15,$I$2:$I$31))+(SUMIF($G$35:$G$41,B15,$H$35:$H$41)) -> 0 | R15: =IF(vend5[[#This Row],[Nº Venda]]>1,1,0) -> 0
B16: Total | C16: =SUM(C11:C15) -> 0 | R16: =IF(vend5[[#This Row],[Nº Venda]]>1,1,0) -> 0
R17: =IF(vend5[[#This Row],[Nº Venda]]>1,1,0) -> 0
B18: Entrega de Carne | R18: =IF(vend5[[#This Row],[Nº Venda]]>1,1,0) -> 0
B19: =COUNT(entr_carn5[OS]) -> 0 | C19: =SUM(entr_carn5[Valor Total]) -> 0 | R19: =IF(vend5[[#This Row],[Nº Venda]]>1,1,0) -> 0
B20: Total | C20: =SUM(C19:C19) -> 0 | R20: =IF(vend5[[#This Row],[Nº Venda]]>1,1,0) -> 0
B22: Venda | C22: =C5 -> 0
E24: Restante Entrada
E25: Nº Venda | F25: Cliente | G25: Forma de Pgto | H25: Valor Venda | I25: Entrada
X27: 0
E33: Recebimento de Carnê | K33: Entrega de Carne
E34: OS | F34: Cliente | G34: Forma de Pgto | H34: Valor Parcela | I34: Nº Parcela | K34: OS | L34: Parcelas | M34: Valor Total
I35: PARC. 1/1
Q40: Total de OS | R40: =SUM(R6:R21) -> 0

Sheet 06
B1: ='05'!B1+1 -> 45541
B2: Fechamento Diário do Caixa
B4: Saldo Inicial | C4: 0 | E4: Vendas | K4: Despesas
B5: Vendas | C5: =SUMIF(I6:I31,">0",H6:H31) -> 1490 | E5: Nº Venda | F5: Cliente | G5: Forma de Pgto | H5: Valor Venda | I5: Entrada | K5: Descrição | L5: Tipo de Pagto | M5: Valor
B6: Entrada | C6: =SUM(I6:I41) -> 1099 | E6: 3713 | F6: CRISTINA FERREIRA BRITO | G6: PIX | H6: 1490 | I6: 350 | K6: ROGERIO | L6: DN | M6: 280 | R6: =IF(vend[[#This Row],[Nº Venda]]>1,1,0) -> 1
B7: Despesas | C7: =SUM(M6:M11) -> 280 | E7: 3713 | F7: CRISTINA FERREIRA BRITO | G7: CTD | I7: 50 | R7: =IF(vend[[#This Row],[Nº Venda]]>1,1,0) -> 1
B8: Total entrada | C8: =SUM(C6:C7) -> 1379 | E8: 3713 | F8: CRISTINA FERREIRA BRITO | G8: DN | I8: 100 | R8: =IF(vend[[#This Row],[Nº Venda]]>1,1,0) -> 1
R9: =IF(vend[[#This Row],[Nº Venda]]>1,1,0) -> 0
B10: Tipos de Pagtos | R10: =IF(vend[[#This Row],[Nº Venda]]>1,1,0) -> 0
B11: DN | C11: =(SUMIF($G$2:$G$31,B11,$I$2:$I$31))+(SUMIF($G$35:$G$41,B11,$H$35:$H$41)) -> 280 | O11: =IF(C16=0,0,1) -> 1 | R11: =IF(vend[[#This Row],[Nº Venda]]>1,1,0) -> 0
B12: CTD | C12: =(SUMIF($G$2:$G$31,B12,$I$2:$I$31))+(SUMIF($G$35:$G$41,B12,$H$35:$H$41)) -> 649 | R12: =IF(vend[[#This Row],[Nº Venda]]>1,1,0) -> 0
B13: CTC | C13: =(SUMIF($G$2:$G$31,B13,$I$2:$I$31))+(SUMIF($G$35:$G$41,B13,$H$35:$H$41)) -> 0 | K13: OS Entregue no Dia | R13: =IF(vend[[#This Row],[Nº Venda]]>1,1,0) -> 0
B14: PCTC | C14: =(SUMIF($G$2:$G$31,B14,$I$2:$I$31))+(SUMIF($G$35:$G$41,B14,$H$35:$H$41)) -> 0 | K14: OS | L14: Vendedor | M14: CARNE | R14: =IF(vend[[#This Row],[Nº Venda]]>1,1,0) -> 0
B15: PIX | C15: =(SUMIF($G$2:$G$31,B15,$I$2:$I$31))+(SUMIF($G$35:$G$41,B15,$H$35:$H$41)) -> 350 | K15: 3698 | L15: ROGÉRIO | M15: Não | R15: =IF(vend[[#This Row],[Nº Venda]]>1,1,0) -> 0
B16: Total | C16: =SUM(C11:C15) -> 1279 | R16: =IF(vend[[#This Row],[Nº Venda]]>1,1,0) -> 0
R17: =IF(vend[[#This Row],[Nº Venda]]>1,1,0) -> 0
B18: Entrega de Carne | R18: =IF(vend[[#This Row],[Nº Venda]]>1,1,0) -> 0
B19: =COUNT(entr_carn6[OS]) -> 0 | C19: =SUM(entr_carn6[Valor Total]) -> 0 | R19: =IF(vend[[#This Row],[Nº Venda]]>1,1,0) -> 0
B20: Total | C20: =SUM(C19:C19) -> 0 | R20: =IF(vend[[#This Row],[Nº Venda]]>1,1,0) -> 0
B22: Venda | C22: =C5 -> 1490
E24: Restante Entrada
E25: Nº Venda | F25: Cliente | G25: Forma de Pgto | H25: Valor Venda | I25: Entrada
E26: 3698 | F26: RICARDO ANTERO | G26: CTD | I26: 599
E33: Recebimento de Carnê | K33: Entrega de Carne
E34: OS | F34: Cliente | G34: Forma de Pgto | H34: Valor Parcela | I34: Nº Parcela | K34: OS | L34: Parcelas | M34: Valor Total
E35: 3592 | F35: GENESIO DOS SANTOS | G35: DN | H35: 180 | I35: PARC. 2/5
Q40: Total de OS | R40: =SUM(R6:R21) -> 3

Sheet 07
B1: ='06'!B1+1 -> 45542
B2: Fechamento Diário do Caixa
B4: Saldo Inicial | C4: 0 | E4: Vendas | K4: Despesas
B5: Vendas | C5: =SUMIF(I6:I31,">0",H6:H31) -> 3895 | E5: Nº Venda | F5: Cliente | G5: Forma de Pgto | H5: Valor Venda | I5: Entrada | K5: Descrição | L5: Tipo de Pagto | M5: Valor
B6: Entrada | C6: =SUM(I6:I41) -> 2547 | E6: 3714 | F6: JUCELINO SILVA LIMA | G6: CTC | H6: 1999 | I6: 1999 | R6: =IF(vend7[[#This Row],[Nº Venda]]>1,1,0) -> 1
B7: Despesas | C7: =SUM(M6:M11) -> 0 | E7: 3715 | F7: MARIA APARECIDA | G7: DN | H7: 699 | I7: 25 | R7: =IF(vend7[[#This Row],[Nº Venda]]>1,1,0) -> 1
B8: Total entrada | C8: =SUM(C6:C7) -> 2547 | E8: 3716 | F8: JORGE NISHIRA | G8: DN | H8: 699 | I8: 25 | R8: =IF(vend7[[#This Row],[Nº Venda]]>1,1,0) -> 1
E9: 3717 | F9: MISLENE | G9: PIX | H9: 498 | I9: 498 | R9: =IF(vend7[[#This Row],[Nº Venda]]>1,1,0) -> 1
B10: Tipos de Pagtos | R10: =IF(vend7[[#This Row],[Nº Venda]]>1,1,0) -> 0
B11: DN | C11: =(SUMIF($G$2:$G$31,B11,$I$2:$I$31))+(SUMIF($G$35:$G$41,B11,$H$35:$H$41)) -> 50 | O11: =IF(C16=0,0,1) -> 1 | R11: =IF(vend7[[#This Row],[Nº Venda]]>1,1,0) -> 0
B12: CTD | C12: =(SUMIF($G$2:$G$31,B12,$I$2:$I$31))+(SUMIF($G$35:$G$41,B12,$H$35:$H$41)) -> 0 | R12: =IF(vend7[[#This Row],[Nº Venda]]>1,1,0) -> 0
B13: CTC | C13: =(SUMIF($G$2:$G$31,B13,$I$2:$I$31))+(SUMIF($G$35:$G$41,B13,$H$35:$H$41)) -> 1999 | K13: OS Entregue no Dia | R13: =IF(vend7[[#This Row],[Nº Venda]]>1,1,0) -> 0
B14: PCTC | C14: =(SUMIF($G$2:$G$31,B14,$I$2:$I$31))+(SUMIF($G$35:$G$41,B14,$H$35:$H$41)) -> 0 | K14: OS | L14: Vendedor | M14: CARNE | R14: =IF(vend7[[#This Row],[Nº Venda]]>1,1,0) -> 0
B15: PIX | C15: =(SUMIF($G$2:$G$31,B15,$I$2:$I$31))+(SUMIF($G$35:$G$41,B15,$H$35:$H$41)) -> 498 | R15: =IF(vend7[[#This Row],[Nº Venda]]>1,1,0) -> 0
B16: Total | C16: =SUM(C11:C15) -> 2547 | R16: =IF(vend7[[#This Row],[Nº Venda]]>1,1,0) -> 0
R17: =IF(vend7[[#This Row],[Nº Venda]]>1,1,0) -> 0
B18: Entrega de Carne | R18: =IF(vend7[[#This Row],[Nº Venda]]>1,1,0) -> 0
B19: =COUNT(entr_carn7[OS]) -> 0 | C19: =SUM(entr_carn7[Valor Total]) -> 0 | R19: =IF(vend7[[#This Row],[Nº Venda]]>1,1,0) -> 0
B20: Total | C20: =SUM(C19:C19) -> 0 | R20: =IF(vend7[[#This Row],[Nº Venda]]>1,1,0) -> 0
B22: Venda | C22: =C5 -> 3895
E24: Restante Entrada
E25: Nº Venda | F25: Cliente | G25: Forma de Pgto | H25: Valor Venda | I25: Entrada
E33: Recebimento de Carnê | K33: Entrega de Carne
E34: OS | F34: Cliente | G34: Forma de Pgto | H34: Valor Parcela | I34: Nº Parcela | K34: OS | L34: Parcelas | M34: Valor Total
Q40: Total de OS | R40: =SUM(R6:R21) -> 4

Sheet 08
B1: ='07'!B1+1 -> 45543
B2: Fechamento Diário do Caixa
B4: Saldo Inicial | C4: 0 | E4: Vendas | K4: Despesas
B5: Vendas | C5: =SUMIF(I6:I31,">0",H6:H31) -> 0 | E5: Nº Venda | F5: Cliente | G5: Forma de Pgto | H5: Valor Venda | I5: Entrada | K5: Descrição | L5: Tipo de Pagto | M5: Valor
B6: Entrada | C6: =SUM(I6:I41) -> 0 | R6: =IF(vend8[[#This Row],[Nº Venda]]>1,1,0) -> 0
B7: Despesas | C7: =SUM(M6:M11) -> 0 | R7: =IF(vend8[[#This Row],[Nº Venda]]>1,1,0) -> 0
B8: Total entrada | C8: =SUM(C6:C7) -> 0 | R8: =IF(vend8[[#This Row],[Nº Venda]]>1,1,0) -> 0
R9: =IF(vend8[[#This Row],[Nº Venda]]>1,1,0) -> 0
B10: Tipos de Pagtos | R10: =IF(vend8[[#This Row],[Nº Venda]]>1,1,0) -> 0
B11: DN | C11: =(SUMIF($G$2:$G$31,B11,$I$2:$I$31))+(SUMIF($G$35:$G$42,B11,$H$35:$H$42)) -> 0 | O11: =IF(C16=0,0,1) -> 0 | R11: =IF(vend8[[#This Row],[Nº Venda]]>1,1,0) -> 0
B12: CTD | C12: =(SUMIF($G$2:$G$31,B12,$I$2:$I$31))+(SUMIF($G$35:$G$42,B12,$H$35:$H$42)) -> 0 | R12: =IF(vend8[[#This Row],[Nº Venda]]>1,1,0) -> 0
B13: CTC | C13: =(SUMIF($G$2:$G$31,B13,$I$2:$I$31))+(SUMIF($G$35:$G$42,B13,$H$35:$H$42)) -> 0 | K13: OS Entregue no Dia | R13: =IF(vend8[[#This Row],[Nº Venda]]>1,1,0) -> 0
B14: PCTC | C14: =(SUMIF($G$2:$G$31,B14,$I$2:$I$31))+(SUMIF($G$35:$G$42,B14,$H$35:$H$42)) -> 0 | K14: OS | L14: Vendedor | M14: CARNE | R14: =IF(vend8[[#This Row],[Nº Venda]]>1,1,0) -> 0
B15: PIX | C15: =(SUMIF($G$2:$G$31,B15,$I$2:$I$31))+(SUMIF($G$35:$G$42,B15,$H$35:$H$42)) -> 0 | R15: =IF(vend8[[#This Row],[Nº Venda]]>1,1,0) -> 0
B16: Total | C16: =SUM(C11:C15) -> 0 | R16: =IF(vend8[[#This Row],[Nº Venda]]>1,1,0) -> 0
R17: =IF(vend8[[#This Row],[Nº Venda]]>1,1,0) -> 0
B18: Entrega de Carne | R18: =IF(vend8[[#This Row],[Nº Venda]]>1,1,0) -> 0
B19: =COUNT(entr_carn8[OS]) -> 0 | C19: =SUM(entr_carn8[Valor Total]) -> 0 | R19: =IF(vend8[[#This Row],[Nº Venda]]>1,1,0) -> 0
B20: Total | C20: =SUM(C19:C19) -> 0 | R20: =IF(vend8[[#This Row],[Nº Venda]]>1,1,0) -> 0
B22: Venda | C22: =C5 -> 0
E24: Restante Entrada
E25: Nº Venda | F25: Cliente | G25: Forma de Pgto | H25: Valor Venda | I25: Entrada
E33: Recebimento de Carnê | K33: Entrega de Carne
E34: OS | F34: Cliente | G34: Forma de Pgto | H34: Valor Parcela | I34: Nº Parcela | K34: OS | L34: Parcelas | M34: Valor Total
Q40: Total de OS | R40: =SUM(R6:R21) -> 0

Sheet 09
B1: ='08'!B1+1 -> 45544
B2: Fechamento Diário do Caixa
B4: Saldo Inicial | C4: 0 | E4: Vendas | K4: Despesas
B5: Vendas | C5: =SUMIF(I6:I31,">0",H6:H31) -> 690 | E5: Nº Venda | F5: Cliente | G5: Forma de Pgto | H5: Valor Venda | I5: Entrada | K5: Descrição | L5: Tipo de Pagto | M5: Valor
B6: Entrada | C6: =SUM(I6:I41) -> 690 | E6: 3718 | F6: JENIFER SILVA VIEIRA | G6: CTC | H6: 690 | I6: 690 | R6: =IF(vend9[[#This Row],[Nº Venda]]>1,1,0) -> 1
B7: Despesas | C7: =SUM(M6:M11) -> 0 | R7: =IF(vend9[[#This Row],[Nº Venda]]>1,1,0) -> 0
B8: Total entrada | C8: =SUM(C6:C7) -> 690 | R8: =IF(vend9[[#This Row],[Nº Venda]]>1,1,0) -> 0
R9: =IF(vend9[[#This Row],[Nº Venda]]>1,1,0) -> 0
B10: Tipos de Pagtos | R10: =IF(vend9[[#This Row],[Nº Venda]]>1,1,0) -> 0
B11: DN | C11: =(SUMIF($G$2:$G$31,B11,$I$2:$I$31))+(SUMIF($G$35:$G$41,B11,$H$35:$H$41)) -> 0 | O11: =IF(C16=0,0,1) -> 1 | R11: =IF(vend9[[#This Row],[Nº Venda]]>1,1,0) -> 0
B12: CTD | C12: =(SUMIF($G$2:$G$31,B12,$I$2:$I$31))+(SUMIF($G$35:$G$41,B12,$H$35:$H$41)) -> 0 | R12: =IF(vend9[[#This Row],[Nº Venda]]>1,1,0) -> 0 | V12: 0
B13: CTC | C13: =(SUMIF($G$2:$G$31,B13,$I$2:$I$31))+(SUMIF($G$35:$G$41,B13,$H$35:$H$41)) -> 690 | K13: OS Entregue no Dia | R13: =IF(vend9[[#This Row],[Nº Venda]]>1,1,0) -> 0
B14: PCTC | C14: =(SUMIF($G$2:$G$31,B14,$I$2:$I$31))+(SUMIF($G$35:$G$41,B14,$H$35:$H$41)) -> 0 | K14: OS | L14: Vendedor | M14: CARNE | R14: =IF(vend9[[#This Row],[Nº Venda]]>1,1,0) -> 0
B15: PIX | C15: =(SUMIF($G$2:$G$31,B15,$I$2:$I$31))+(SUMIF($G$35:$G$41,B15,$H$35:$H$41)) -> 0 | K15: 3717 | L15: ROSÂNGELA | M15: Não | R15: =IF(vend9[[#This Row],[Nº Venda]]>1,1,0) -> 0
B16: Total | C16: =SUM(C11:C15) -> 690 | R16: =IF(vend9[[#This Row],[Nº Venda]]>1,1,0) -> 0
R17: =IF(vend9[[#This Row],[Nº Venda]]>1,1,0) -> 0
B18: Entrega de Carne | R18: =IF(vend9[[#This Row],[Nº Venda]]>1,1,0) -> 0
B19: =COUNT(entr_carn9[OS]) -> 0 | C19: =SUM(entr_carn9[Valor Total]) -> 0 | R19: =IF(vend9[[#This Row],[Nº Venda]]>1,1,0) -> 0
B20: Total | C20: =SUM(C19:C19) -> 0 | R20: =IF(vend9[[#This Row],[Nº Venda]]>1,1,0) -> 0
B22: Venda | C22: =C5 -> 690
E24: Restante Entrada
E25: Nº Venda | F25: Cliente | G25: Forma de Pgto | H25: Valor Venda | I25: Entrada
E33: Recebimento de Carnê | K33: Entrega de Carne
E34: OS | F34: Cliente | G34: Forma de Pgto | H34: Valor Parcela | I34: Nº Parcela | K34: OS | L34: Parcelas | M34: Valor Total
Q40: Total de OS | R40: =SUM(R6:R21) -> 1

Sheet 10
B1: ='09'!B1+1 -> 45545
B2: Fechamento Diário do Caixa
B4: Saldo Inicial | C4: 0 | E4: Vendas | K4: Despesas
B5: Vendas | C5: =SUMIF(I6:I32,">0",H6:H32) -> 2028 | E5: Nº Venda | F5: Cliente | G5: Forma de Pgto | H5: Valor Venda | I5: Entrada | K5: Descrição | L5: Tipo de Pagto | M5: Valor
B6: Entrada | C6: =SUM(I6:I42) -> 1903.5 | E6: 3719 | F6: JORGE R. DE O. PINTO | G6: GARANTIA | H6: 0 | I6: 0 | R6: =IF(vend10[[#This Row],[Nº Venda]]>1,1,0) -> 1
B7: Despesas | C7: =SUM(M6:M11) -> 0 | E7: 3720 | F7: LUCA SANTOS | G7: DN | H7: 799 | I7: 200 | R7: =IF(vend10[[#This Row],[Nº Venda]]>1,1,0) -> 1
B8: Total entrada | C8: =SUM(C6:C7) -> 1903.5 | E8: 3720 | F8: LUCA SANTOS | G8: CTC | I8: 599 | R8: =IF(vend10[[#This Row],[Nº Venda]]>1,1,0) -> 1
E9: 3721 | F9: SELMA LUCIA PINHEIRO | G9: CTC | H9: 260 | I9: 260 | R9: =IF(vend10[[#This Row],[Nº Venda]]>1,1,0) -> 1
B10: Tipos de Pagtos | E10: 3722 | F10: VANESSA | G10: PIX | H10: 249 | I10: 124.5 | R10: =IF(vend10[[#This Row],[Nº Venda]]>1,1,0) -> 1
B11: DN | C11: =(SUMIF($G$2:$G$32,B11,$I$2:$I$32))+(SUMIF($G$36:$G$42,B11,$H$36:$H$42)) -> 200 | E11: 3723 | F11: GEOVANA SILVA | G11: CTC | H11: 720 | I11: 720 | O11: =IF(C16=0,0,1) -> 1 | R11: =IF(vend10[[#This Row],[Nº Venda]]>1,1,0) -> 1
B12: CTD | C12: =(SUMIF($G$2:$G$32,B12,$I$2:$I$32))+(SUMIF($G$36:$G$42,B12,$H$36:$H$42)) -> 0 | R12: =IF(vend10[[#This Row],[Nº Venda]]>1,1,0) -> 0
B13: CTC | C13: =(SUMIF($G$2:$G$32,B13,$I$2:$I$32))+(SUMIF($G$36:$G$42,B13,$H$36:$H$42)) -> 1579 | K13: OS Entregue no Dia | R13: =IF(vend10[[#This Row],[Nº Venda]]>1,1,0) -> 0
B14: PCTC | C14: =(SUMIF($G$2:$G$32,B14,$I$2:$I$32))+(SUMIF($G$36:$G$42,B14,$H$36:$H$42)) -> 0 | K14: OS | L14: Vendedor | M14: CARNE | R14: =IF(vend10[[#This Row],[Nº Venda]]>1,1,0) -> 0
B15: PIX | C15: =(SUMIF($G$2:$G$32,B15,$I$2:$I$32))+(SUMIF($G$36:$G$42,B15,$H$36:$H$42)) -> 124.5 | K15: 3721 | L15: ROSÂNGELA | M15: Não | R15: =IF(vend10[[#This Row],[Nº Venda]]>1,1,0) -> 0
B16: Total | C16: =SUM(C11:C15) -> 1903.5 | K16: 3706 | L16: ROGÉRIO | M16: Não | R16: =IF(vend10[[#This Row],[Nº Venda]]>1,1,0) -> 0
R17: =IF(vend10[[#This Row],[Nº Venda]]>1,1,0) -> 0
B18: Entrega de Carne | R18: =IF(vend10[[#This Row],[Nº Venda]]>1,1,0) -> 0
B19: =COUNT(entr_carn10[OS]) -> 0 | C19: =SUM(entr_carn10[Valor Total]) -> 0 | R19: =IF(vend10[[#This Row],[Nº Venda]]>1,1,0) -> 0
B20: Total | C20: =SUM(C19:C19) -> 0 | R20: =IF(vend10[[#This Row],[Nº Venda]]>1,1,0) -> 0
B22: Venda | C22: =C5 -> 2028
E24: Restante Entrada
E25: Nº Venda | F25: Cliente | G25: Forma de Pgto | H25: Valor Venda | I25: Entrada
K33: Entrega de Carne
E34: Recebimento de Carnê | K34: OS | L34: Parcelas | M34: Valor Total
E35: OS | F35: Cliente | G35: Forma de Pgto | H35: Valor Parcela | I35: Nº Parcela
Q40: Total de OS | R40: =SUM(R6:R21) -> 6

Sheet 11
B1: ='10'!B1+1 -> 45546
B2: Fechamento Diário do Caixa
B4: Saldo Inicial | C4: 0 | E4: Vendas | K4: Despesas
B5: Vendas | C5: =SUMIF(I6:I31,">0",H6:H31) -> 0 | E5: Nº Venda | F5: Cliente | G5: Forma de Pgto | H5: Valor Venda | I5: Entrada | K5: Descrição | L5: Tipo de Pagto | M5: Valor
B6: Entrada | C6: =SUM(I6:I41) -> 0 | K6: COPIA DE CHAVE | L6: PIX | M6: 25 | R6: =IF(vend11[[#This Row],[Nº Venda]]>1,1,0) -> 0
B7: Despesas | C7: =SUM(M6:M11) -> 25 | R7: =IF(vend11[[#This Row],[Nº Venda]]>1,1,0) -> 0
B8: Total entrada | C8: =SUM(C6:C7) -> 25 | R8: =IF(vend11[[#This Row],[Nº Venda]]>1,1,0) -> 0
R9: =IF(vend11[[#This Row],[Nº Venda]]>1,1,0) -> 0
B10: Tipos de Pagtos | R10: =IF(vend11[[#This Row],[Nº Venda]]>1,1,0) -> 0
B11: DN | C11: =(SUMIF($G$2:$G$31,B11,$I$2:$I$31))+(SUMIF($G$35:$G$41,B11,$H$35:$H$41)) -> 0 | O11: =IF(C16=0,0,1) -> 1 | R11: =IF(vend11[[#This Row],[Nº Venda]]>1,1,0) -> 0
B12: CTD | C12: =(SUMIF($G$2:$G$31,B12,$I$2:$I$31))+(SUMIF($G$35:$G$41,B12,$H$35:$H$41)) -> 0 | R12: =IF(vend11[[#This Row],[Nº Venda]]>1,1,0) -> 0
B13: CTC | C13: =(SUMIF($G$2:$G$31,B13,$I$2:$I$31))+(SUMIF($G$35:$G$41,B13,$H$35:$H$41)) -> 0 | K13: OS Entregue no Dia | R13: =IF(vend11[[#This Row],[Nº Venda]]>1,1,0) -> 0
B14: PCTC | C14: =(SUMIF($G$2:$G$31,B14,$I$2:$I$31))+(SUMIF($G$35:$G$41,B14,$H$35:$H$41)) -> 0 | K14: OS | L14: Vendedor | M14: CARNE | R14: =IF(vend11[[#This Row],[Nº Venda]]>1,1,0) -> 0
B15: PIX | C15: =(SUMIF($G$2:$G$31,B15,$I$2:$I$31))+(SUMIF($G$35:$G$41,B15,$H$35:$H$41)) -> 133 | R15: =IF(vend11[[#This Row],[Nº Venda]]>1,1,0) -> 0
B16: Total | C16: =SUM(C11:C15) -> 133 | R16: =IF(vend11[[#This Row],[Nº Venda]]>1,1,0) -> 0
R17: =IF(vend11[[#This Row],[Nº Venda]]>1,1,0) -> 0
B18: Entrega de Carne | R18: =IF(vend11[[#This Row],[Nº Venda]]>1,1,0) -> 0
B19: =COUNT(entr_carn11[OS]) -> 0 | C19: =SUM(entr_carn11[Valor Total]) -> 0 | R19: =IF(vend11[[#This Row],[Nº Venda]]>1,1,0) -> 0
B20: Total | C20: =SUM(C19:C19) -> 0 | R20: =IF(vend11[[#This Row],[Nº Venda]]>1,1,0) -> 0
B22: Venda | C22: =C5 -> 0
E24: Restante Entrada
E25: Nº Venda | F25: Cliente | G25: Forma de Pgto | H25: Valor Venda | I25: Entrada
E33: Recebimento de Carnê | K33: Entrega de Carne
E34: OS | F34: Cliente | G34: Forma de Pgto | H34: Valor Parcela | I34: Nº Parcela | K34: OS | L34: Parcelas | M34: Valor Total
E35: 3624 | F35: SAMIRA DE OLIVEIRA | G35: PIX | H35: 133 | I35: PARC. 2/3
Q40: Total de OS | R40: =SUM(R6:R21) -> 0

Sheet 12
B1: ='11'!B1+1 -> 45547
B2: Fechamento Diário do Caixa
B4: Saldo Inicial | C4: 0 | E4: Vendas | K4: Despesas
B5: Vendas | C5: =SUMIF(I6:I31,">0",H6:H31) -> 0 | E5: Nº Venda | F5: Cliente | G5: Forma de Pgto | H5: Valor Venda | I5: Entrada | K5: Descrição | L5: Tipo de Pagto | M5: Valor
B6: Entrada | C6: =SUM(I6:I41) -> 0 | R6: =IF(vend12[[#This Row],[Nº Venda]]>1,1,0) -> 0
B7: Despesas | C7: =SUM(M6:M11) -> 0 | R7: =IF(vend12[[#This Row],[Nº Venda]]>1,1,0) -> 0
B8: Total entrada | C8: =SUM(C6:C7) -> 0 | R8: =IF(vend12[[#This Row],[Nº Venda]]>1,1,0) -> 0
R9: =IF(vend12[[#This Row],[Nº Venda]]>1,1,0) -> 0
B10: Tipos de Pagtos | R10: =IF(vend12[[#This Row],[Nº Venda]]>1,1,0) -> 0
B11: DN | C11: =(SUMIF($G$2:$G$31,B11,$I$2:$I$31))+(SUMIF($G$35:$G$41,B11,$H$35:$H$41)) -> 0 | O11: =IF(C16=0,0,1) -> 0 | R11: =IF(vend12[[#This Row],[Nº Venda]]>1,1,0) -> 0
B12: CTD | C12: =(SUMIF($G$2:$G$31,B12,$I$2:$I$31))+(SUMIF($G$35:$G$41,B12,$H$35:$H$41)) -> 0 | R12: =IF(vend12[[#This Row],[Nº Venda]]>1,1,0) -> 0
B13: CTC | C13: =(SUMIF($G$2:$G$31,B13,$I$2:$I$31))+(SUMIF($G$35:$G$41,B13,$H$35:$H$41)) -> 0 | K13: OS Entregue no Dia | R13: =IF(vend12[[#This Row],[Nº Venda]]>1,1,0) -> 0
B14: PCTC | C14: =(SUMIF($G$2:$G$31,B14,$I$2:$I$31))+(SUMIF($G$35:$G$41,B14,$H$35:$H$41)) -> 0 | K14: OS | L14: Vendedor | M14: CARNE | R14: =IF(vend12[[#This Row],[Nº Venda]]>1,1,0) -> 0
B15: PIX | C15: =(SUMIF($G$2:$G$31,B15,$I$2:$I$31))+(SUMIF($G$35:$G$41,B15,$H$35:$H$41)) -> 0 | K15: 3709 | L15: ROGÉRIO | M15: Não | R15: =IF(vend12[[#This Row],[Nº Venda]]>1,1,0) -> 0
B16: Total | C16: =SUM(C11:C15) -> 0 | R16: =IF(vend12[[#This Row],[Nº Venda]]>1,1,0) -> 0
R17: =IF(vend12[[#This Row],[Nº Venda]]>1,1,0) -> 0
B18: Entrega de Carne | R18: =IF(vend12[[#This Row],[Nº Venda]]>1,1,0) -> 0
B19: =COUNT(entr_carn12[OS]) -> 0 | C19: =SUM(entr_carn12[Valor Total]) -> 0 | R19: =IF(vend12[[#This Row],[Nº Venda]]>1,1,0) -> 0
B20: Total | C20: =SUM(C19:C19) -> 0 | R20: =IF(vend12[[#This Row],[Nº Venda]]>1,1,0) -> 0
B22: Venda | C22: =C5 -> 0
E24: Restante Entrada
E25: Nº Venda | F25: Cliente | G25: Forma de Pgto | H25: Valor Venda | I25: Entrada
E33: Recebimento de Carnê | K33: Entrega de Carne
E34: OS | F34: Cliente | G34: Forma de Pgto | H34: Valor Parcela | I34: Nº Parcela | K34: OS | L34: Parcelas | M34: Valor Total
Q40: Total de OS | R40: =SUM(R6:R21) -> 0

Sheet 13
B1: ='12'!B1+1 -> 45548
B2: Fechamento Diário do Caixa
B4: Saldo Inicial | C4: 0 | E4: Vendas | K4: Despesas
B5: Vendas | C5: =SUMIF(I6:I31,">0",H6:H31) -> 0 | E5: Nº Venda | F5: Cliente | G5: Forma de Pgto | H5: Valor Venda | I5: Entrada | K5: Descrição | L5: Tipo de Pagto | M5: Valor
B6: Entrada | C6: =SUM(I6:I41) -> 124.5 | K6: CHIP C/ RECARGA | L6: PIX | M6: 28 | R6: =IF(vend13[[#This Row],[Nº Venda]]>1,1,0) -> 0
B7: Despesas | C7: =SUM(M6:M11) -> 56 | K7: AGUA | L7: PIX | M7: 28 | R7: =IF(vend13[[#This Row],[Nº Venda]]>1,1,0) -> 0
B8: Total entrada | C8: =SUM(C6:C7) -> 180.5 | R8: =IF(vend13[[#This Row],[Nº Venda]]>1,1,0) -> 0
R9: =IF(vend13[[#This Row],[Nº Venda]]>1,1,0) -> 0
B10: Tipos de Pagtos | R10: =IF(vend13[[#This Row],[Nº Venda]]>1,1,0) -> 0
B11: DN | C11: =(SUMIF($G$2:$G$31,B11,$I$2:$I$31))+(SUMIF($G$35:$G$41,B11,$H$35:$H$41)) -> 0 | O11: =IF(C16=0,0,1) -> 1 | R11: =IF(vend13[[#This Row],[Nº Venda]]>1,1,0) -> 0
B12: CTD | C12: =(SUMIF($G$2:$G$31,B12,$I$2:$I$31))+(SUMIF($G$35:$G$41,B12,$H$35:$H$41)) -> 0 | R12: =IF(vend13[[#This Row],[Nº Venda]]>1,1,0) -> 0
B13: CTC | C13: =(SUMIF($G$2:$G$31,B13,$I$2:$I$31))+(SUMIF($G$35:$G$41,B13,$H$35:$H$41)) -> 0 | K13: OS Entregue no Dia | R13: =IF(vend13[[#This Row],[Nº Venda]]>1,1,0) -> 0
B14: PCTC | C14: =(SUMIF($G$2:$G$31,B14,$I$2:$I$31))+(SUMIF($G$35:$G$41,B14,$H$35:$H$41)) -> 0 | K14: OS | L14: Vendedor | M14: CARNE | R14: =IF(vend13[[#This Row],[Nº Venda]]>1,1,0) -> 0
B15: PIX | C15: =(SUMIF($G$2:$G$31,B15,$I$2:$I$31))+(SUMIF($G$35:$G$41,B15,$H$35:$H$41)) -> 124.5 | K15: 3708 | L15: ROGÉRIO | M15: Não | R15: =IF(vend13[[#This Row],[Nº Venda]]>1,1,0) -> 0
B16: Total | C16: =SUM(C11:C15) -> 124.5 | K16: 3722 | L16: ROSÂNGELA | M16: Não | R16: =IF(vend13[[#This Row],[Nº Venda]]>1,1,0) -> 0
R17: =IF(vend13[[#This Row],[Nº Venda]]>1,1,0) -> 0
B18: Entrega de Carne | R18: =IF(vend13[[#This Row],[Nº Venda]]>1,1,0) -> 0
B19: =COUNT(entr_carn13[OS]) -> 0 | C19: =SUM(entr_carn13[Valor Total]) -> 0 | R19: =IF(vend13[[#This Row],[Nº Venda]]>1,1,0) -> 0
B20: Total | C20: =SUM(C19:C19) -> 0 | R20: =IF(vend13[[#This Row],[Nº Venda]]>1,1,0) -> 0
B22: Venda | C22: =C5 -> 0
E24: Restante Entrada
E25: Nº Venda | F25: Cliente | G25: Forma de Pgto | H25: Valor Venda | I25: Entrada
E26: 3722 | F26: vanessa | G26: PIX | I26: 124.5
E33: Recebimento de Carnê | K33: Entrega de Carne
E34: OS | F34: Cliente | G34: Forma de Pgto | H34: Valor Parcela | I34: Nº Parcela | K34: OS | L34: Parcelas | M34: Valor Total
Q40: Total de OS | R40: =SUM(R6:R21) -> 0

Sheet 14
B1: ='13'!B1+1 -> 45549
B2: Fechamento Diário do Caixa
B4: Saldo Inicial | C4: 0 | E4: Vendas | K4: Despesas
B5: Vendas | C5: =SUMIF(I6:I31,">0",H6:H31) -> 0 | E5: Nº Venda | F5: Cliente | G5: Forma de Pgto | H5: Valor Venda | I5: Entrada | K5: Descrição | L5: Tipo de Pagto | M5: Valor
B6: Entrada | C6: =SUM(I6:I41) -> 0 | R6: =IF(vend14[[#This Row],[Nº Venda]]>1,1,0) -> 0
B7: Despesas | C7: =SUM(M6:M11) -> 0 | R7: =IF(vend14[[#This Row],[Nº Venda]]>1,1,0) -> 0
B8: Total entrada | C8: =SUM(C6:C7) -> 0 | R8: =IF(vend14[[#This Row],[Nº Venda]]>1,1,0) -> 0
R9: =IF(vend14[[#This Row],[Nº Venda]]>1,1,0) -> 0
B10: Tipos de Pagtos | R10: =IF(vend14[[#This Row],[Nº Venda]]>1,1,0) -> 0
B11: DN | C11: =(SUMIF($G$2:$G$31,B11,$I$2:$I$31))+(SUMIF($G$35:$G$41,B11,$H$35:$H$41)) -> 0 | O11: =IF(C16=0,0,1) -> 0 | R11: =IF(vend14[[#This Row],[Nº Venda]]>1,1,0) -> 0
B12: CTD | C12: =(SUMIF($G$2:$G$31,B12,$I$2:$I$31))+(SUMIF($G$35:$G$41,B12,$H$35:$H$41)) -> 0 | R12: =IF(vend14[[#This Row],[Nº Venda]]>1,1,0) -> 0
B13: CTC | C13: =(SUMIF($G$2:$G$31,B13,$I$2:$I$31))+(SUMIF($G$35:$G$41,B13,$H$35:$H$41)) -> 0 | K13: OS Entregue no Dia | R13: =IF(vend14[[#This Row],[Nº Venda]]>1,1,0) -> 0
B14: PCTC | C14: =(SUMIF($G$2:$G$31,B14,$I$2:$I$31))+(SUMIF($G$35:$G$41,B14,$H$35:$H$41)) -> 0 | K14: OS | L14: Vendedor | M14: CARNE | R14: =IF(vend14[[#This Row],[Nº Venda]]>1,1,0) -> 0
B15: PIX | C15: =(SUMIF($G$2:$G$31,B15,$I$2:$I$31))+(SUMIF($G$35:$G$41,B15,$H$35:$H$41)) -> 0 | K15: 3718 | L15: ROSÂNGELA | M15: Não | R15: =IF(vend14[[#This Row],[Nº Venda]]>1,1,0) -> 0
B16: Total | C16: =SUM(C11:C15) -> 0 | R16: =IF(vend14[[#This Row],[Nº Venda]]>1,1,0) -> 0
R17: =IF(vend14[[#This Row],[Nº Venda]]>1,1,0) -> 0
B18: Entrega de Carne | R18: =IF(vend14[[#This Row],[Nº Venda]]>1,1,0) -> 0
B19: =COUNT(entr_carn14[OS]) -> 0 | C19: =SUM(entr_carn14[Valor Total]) -> 0 | R19: =IF(vend14[[#This Row],[Nº Venda]]>1,1,0) -> 0
B20: Total | C20: =SUM(C19:C19) -> 0 | R20: =IF(vend14[[#This Row],[Nº Venda]]>1,1,0) -> 0
B22: Venda | C22: =C5 -> 0
E24: Restante Entrada
E25: Nº Venda | F25: Cliente | G25: Forma de Pgto | H25: Valor Venda | I25: Entrada
E33: Recebimento de Carnê | K33: Entrega de Carne
E34: OS | F34: Cliente | G34: Forma de Pgto | H34: Valor Parcela | I34: Nº Parcela | K34: OS | L34: Parcelas | M34: Valor Total
Q40: Total de OS | R40: =SUM(R6:R21) -> 0

Sheet 15
B1: ='14'!B1+1 -> 45550
B2: Fechamento Diário do Caixa
B4: Saldo Inicial | C4: 0 | E4: Vendas | K4: Despesas
B5: Vendas | C5: =SUMIF(I6:I31,">0",H6:H31) -> 0 | E5: Nº Venda | F5: Cliente | G5: Forma de Pgto | H5: Valor Venda | I5: Entrada | K5: Descrição | L5: Tipo de Pagto | M5: Valor
B6: Entrada | C6: =SUM(I6:I41) -> 0 | R6: =IF(vend15[[#This Row],[Nº Venda]]>1,1,0) -> 0
B7: Despesas | C7: =SUM(M6:M11) -> 0 | R7: =IF(vend15[[#This Row],[Nº Venda]]>1,1,0) -> 0
B8: Total entrada | C8: =SUM(C6:C7) -> 0 | R8: =IF(vend15[[#This Row],[Nº Venda]]>1,1,0) -> 0
R9: =IF(vend15[[#This Row],[Nº Venda]]>1,1,0) -> 0
B10: Tipos de Pagtos | R10: =IF(vend15[[#This Row],[Nº Venda]]>1,1,0) -> 0
B11: DN | C11: =(SUMIF($G$2:$G$31,B11,$I$2:$I$31))+(SUMIF($G$35:$G$41,B11,$H$35:$H$41)) -> 0 | O11: =IF(C16=0,0,1) -> 0 | R11: =IF(vend15[[#This Row],[Nº Venda]]>1,1,0) -> 0
B12: CTD | C12: =(SUMIF($G$2:$G$31,B12,$I$2:$I$31))+(SUMIF($G$35:$G$41,B12,$H$35:$H$41)) -> 0 | R12: =IF(vend15[[#This Row],[Nº Venda]]>1,1,0) -> 0
B13: CTC | C13: =(SUMIF($G$2:$G$31,B13,$I$2:$I$31))+(SUMIF($G$35:$G$41,B13,$H$35:$H$41)) -> 0 | K13: OS Entregue no Dia | R13: =IF(vend15[[#This Row],[Nº Venda]]>1,1,0) -> 0
B14: PCTC | C14: =(SUMIF($G$2:$G$31,B14,$I$2:$I$31))+(SUMIF($G$35:$G$41,B14,$H$35:$H$41)) -> 0 | K14: OS | L14: Vendedor | M14: CARNE | R14: =IF(vend15[[#This Row],[Nº Venda]]>1,1,0) -> 0
B15: PIX | C15: =(SUMIF($G$2:$G$31,B15,$I$2:$I$31))+(SUMIF($G$35:$G$41,B15,$H$35:$H$41)) -> 0 | R15: =IF(vend15[[#This Row],[Nº Venda]]>1,1,0) -> 0
B16: Total | C16: =SUM(C11:C15) -> 0 | R16: =IF(vend15[[#This Row],[Nº Venda]]>1,1,0) -> 0
R17: =IF(vend15[[#This Row],[Nº Venda]]>1,1,0) -> 0
B18: Entrega de Carne | R18: =IF(vend15[[#This Row],[Nº Venda]]>1,1,0) -> 0
B19: =COUNT(entr_carn15[OS]) -> 0 | C19: =SUM(entr_carn15[Valor Total]) -> 0 | R19: =IF(vend15[[#This Row],[Nº Venda]]>1,1,0) -> 0
B20: Total | C20: =SUM(C19:C19) -> 0 | R20: =IF(vend15[[#This Row],[Nº Venda]]>1,1,0) -> 0
B22: Venda | C22: =C5 -> 0
E24: Restante Entrada
E25: Nº Venda | F25: Cliente | G25: Forma de Pgto | H25: Valor Venda | I25: Entrada
E33: Recebimento de Carnê | K33: Entrega de Carne
E34: OS | F34: Cliente | G34: Forma de Pgto | H34: Valor Parcela | I34: Nº Parcela | K34: OS | L34: Parcelas | M34: Valor Total
Q40: Total de OS | R40: =SUM(R6:R21) -> 0

Sheet 16
B1: ='15'!B1+1 -> 45551
B2: Fechamento Diário do Caixa
B4: Saldo Inicial | C4: 0 | E4: Vendas | K4: Despesas
B5: Vendas | C5: =SUMIF(I6:I31,">0",H6:H31) -> 0 | E5: Nº Venda | F5: Cliente | G5: Forma de Pgto | H5: Valor Venda | I5: Entrada | K5: Descrição | L5: Tipo de Pagto | M5: Valor
B6: Entrada | C6: =SUM(I6:I41) -> 0 | R6: =IF(vend16[[#This Row],[Nº Venda]]>1,1,0) -> 0
B7: Despesas | C7: =SUM(M6:M11) -> 0 | R7: =IF(vend16[[#This Row],[Nº Venda]]>1,1,0) -> 0
B8: Total entrada | C8: =SUM(C6:C7) -> 0 | R8: =IF(vend16[[#This Row],[Nº Venda]]>1,1,0) -> 0
R9: =IF(vend16[[#This Row],[Nº Venda]]>1,1,0) -> 0
B10: Tipos de Pagtos | R10: =IF(vend16[[#This Row],[Nº Venda]]>1,1,0) -> 0
B11: DN | C11: =(SUMIF($G$2:$G$31,B11,$I$2:$I$31))+(SUMIF($G$35:$G$41,B11,$H$35:$H$41)) -> 0 | O11: =IF(C16=0,0,1) -> 0 | R11: =IF(vend16[[#This Row],[Nº Venda]]>1,1,0) -> 0
B12: CTD | C12: =(SUMIF($G$2:$G$31,B12,$I$2:$I$31))+(SUMIF($G$35:$G$41,B12,$H$35:$H$41)) -> 0 | R12: =IF(vend16[[#This Row],[Nº Venda]]>1,1,0) -> 0
B13: CTC | C13: =(SUMIF($G$2:$G$31,B13,$I$2:$I$31))+(SUMIF($G$35:$G$41,B13,$H$35:$H$41)) -> 0 | K13: OS Entregue no Dia | R13: =IF(vend16[[#This Row],[Nº Venda]]>1,1,0) -> 0
B14: PCTC | C14: =(SUMIF($G$2:$G$31,B14,$I$2:$I$31))+(SUMIF($G$35:$G$41,B14,$H$35:$H$41)) -> 0 | K14: OS | L14: Vendedor | M14: CARNE | R14: =IF(vend16[[#This Row],[Nº Venda]]>1,1,0) -> 0
B15: PIX | C15: =(SUMIF($G$2:$G$31,B15,$I$2:$I$31))+(SUMIF($G$35:$G$41,B15,$H$35:$H$41)) -> 0 | K15: 3689 | L15: ROSÂNGELA | M15: Não | R15: =IF(vend16[[#This Row],[Nº Venda]]>1,1,0) -> 0
B16: Total | C16: =SUM(C11:C15) -> 0 | K16: 3719 | L16: ROGÉRIO | M16: Não | R16: =IF(vend16[[#This Row],[Nº Venda]]>1,1,0) -> 0
K17: 3712 | L17: ROGÉRIO | M17: Não | R17: =IF(vend16[[#This Row],[Nº Venda]]>1,1,0) -> 0
B18: Entrega de Carne | K18: 3711 | L18: ROGÉRIO | M18: Não | R18: =IF(vend16[[#This Row],[Nº Venda]]>1,1,0) -> 0
B19: =COUNT(entr_carn16[OS]) -> 0 | C19: =SUM(entr_carn16[Valor Total]) -> 0 | R19: =IF(vend16[[#This Row],[Nº Venda]]>1,1,0) -> 0
B20: Total | C20: =SUM(C19:C19) -> 0 | R20: =IF(vend16[[#This Row],[Nº Venda]]>1,1,0) -> 0
B22: Venda | C22: =C5 -> 0
E24: Restante Entrada
E25: Nº Venda | F25: Cliente | G25: Forma de Pgto | H25: Valor Venda | I25: Entrada
E33: Recebimento de Carnê | K33: Entrega de Carne
E34: OS | F34: Cliente | G34: Forma de Pgto | H34: Valor Parcela | I34: Nº Parcela | K34: OS | L34: Parcelas | M34: Valor Total
Q40: Total de OS | R40: =SUM(R6:R21) -> 0

Sheet 17
B1: ='16'!B1+1 -> 45552
B2: Fechamento Diário do Caixa
B4: Saldo Inicial | C4: 0 | E4: Vendas | K4: Despesas
B5: Vendas | C5: =SUMIF(I6:I31,">0",H6:H31) -> 65 | E5: Nº Venda | F5: Cliente | G5: Forma de Pgto | H5: Valor Venda | I5: Entrada | K5: Descrição | L5: Tipo de Pagto | M5: Valor
B6: Entrada | C6: =SUM(I6:I41) -> 775 | E6: 3724 | F6: MIRELLA ALBINO | G6: CTC | H6: 65 | I6: 65 | R6: =IF(vend17[[#This Row],[Nº Venda]]>1,1,0) -> 1
B7: Despesas | C7: =SUM(M6:M11) -> 0 | R7: =IF(vend17[[#This Row],[Nº Venda]]>1,1,0) -> 0
B8: Total entrada | C8: =SUM(C6:C7) -> 775 | R8: =IF(vend17[[#This Row],[Nº Venda]]>1,1,0) -> 0
R9: =IF(vend17[[#This Row],[Nº Venda]]>1,1,0) -> 0
B10: Tipos de Pagtos | R10: =IF(vend17[[#This Row],[Nº Venda]]>1,1,0) -> 0
B11: DN | C11: =(SUMIF($G$2:$G$31,B11,$I$2:$I$31))+(SUMIF($G$35:$G$41,B11,$H$35:$H$41)) -> 0 | O11: =IF(C16=0,0,1) -> 1 | R11: =IF(vend17[[#This Row],[Nº Venda]]>1,1,0) -> 0
B12: CTD | C12: =(SUMIF($G$2:$G$31,B12,$I$2:$I$31))+(SUMIF($G$35:$G$41,B12,$H$35:$H$41)) -> 108 | R12: =IF(vend17[[#This Row],[Nº Venda]]>1,1,0) -> 0
B13: CTC | C13: =(SUMIF($G$2:$G$31,B13,$I$2:$I$31))+(SUMIF($G$35:$G$41,B13,$H$35:$H$41)) -> 575 | K13: OS Entregue no Dia | R13: =IF(vend17[[#This Row],[Nº Venda]]>1,1,0) -> 0
B14: PCTC | C14: =(SUMIF($G$2:$G$31,B14,$I$2:$I$31))+(SUMIF($G$35:$G$41,B14,$H$35:$H$41)) -> 0 | K14: OS | L14: Vendedor | M14: CARNE | R14: =IF(vend17[[#This Row],[Nº Venda]]>1,1,0) -> 0
B15: PIX | C15: =(SUMIF($G$2:$G$31,B15,$I$2:$I$31))+(SUMIF($G$35:$G$41,B15,$H$35:$H$41)) -> 200 | K15: 3714 | L15: ROGÉRIO | M15: Não | R15: =IF(vend17[[#This Row],[Nº Venda]]>1,1,0) -> 0
B16: Total | C16: =SUM(C11:C15) -> 883 | K16: 3720 | L16: ROGÉRIO | M16: Não | R16: =IF(vend17[[#This Row],[Nº Venda]]>1,1,0) -> 0
K17: 3620 | L17: ROGÉRIO | M17: Não | R17: =IF(vend17[[#This Row],[Nº Venda]]>1,1,0) -> 0
B18: Entrega de Carne | R18: =IF(vend17[[#This Row],[Nº Venda]]>1,1,0) -> 0
B19: =COUNT(entr_carn17[OS]) -> 0 | C19: =SUM(entr_carn17[Valor Total]) -> 0 | R19: =IF(vend17[[#This Row],[Nº Venda]]>1,1,0) -> 0
B20: Total | C20: =SUM(C19:C19) -> 0 | R20: =IF(vend17[[#This Row],[Nº Venda]]>1,1,0) -> 0
B22: Venda | C22: =C5 -> 65
E24: Restante Entrada
E25: Nº Venda | F25: Cliente | G25: Forma de Pgto | H25: Valor Venda | I25: Entrada
E26: 3620 | F26: NAILSON FERREIRA | G26: PIX | I26: 200
E27: 3620 | F27: NAILSON FERREIRA | G27: CTC | I27: 510
E33: Recebimento de Carnê | K33: Entrega de Carne
E34: OS | F34: Cliente | G34: Forma de Pgto | H34: Valor Parcela | I34: Nº Parcela | K34: OS | L34: Parcelas | M34: Valor Total
E35: 3637 | F35: VITOR SIMPHRONIO | G35: CTD | H35: 108 | I35: PARC. 2/5
Q40: Total de OS | R40: =SUM(R6:R21) -> 1

Sheet 18
B1: ='17'!B1+1 -> 45553
B2: Fechamento Diário do Caixa
B4: Saldo Inicial | C4: 0 | E4: Vendas | K4: Despesas
B5: Vendas | C5: =SUMIF(I6:I31,">0",H6:H31) -> 0 | E5: Nº Venda | F5: Cliente | G5: Forma de Pgto | H5: Valor Venda | I5: Entrada | K5: Descrição | L5: Tipo de Pagto | M5: Valor
B6: Entrada | C6: =SUM(I6:I41) -> 0 | R6: =IF(vend18[[#This Row],[Nº Venda]]>1,1,0) -> 0
B7: Despesas | C7: =SUM(M6:M11) -> 0 | R7: =IF(vend18[[#This Row],[Nº Venda]]>1,1,0) -> 0
B8: Total entrada | C8: =SUM(C6:C7) -> 0 | R8: =IF(vend18[[#This Row],[Nº Venda]]>1,1,0) -> 0
R9: =IF(vend18[[#This Row],[Nº Venda]]>1,1,0) -> 0
B10: Tipos de Pagtos | R10: =IF(vend18[[#This Row],[Nº Venda]]>1,1,0) -> 0
B11: DN | C11: =(SUMIF($G$2:$G$31,B11,$I$2:$I$31))+(SUMIF($G$35:$G$41,B11,$H$35:$H$41)) -> 0 | O11: =IF(C16=0,0,1) -> 0 | R11: =IF(vend18[[#This Row],[Nº Venda]]>1,1,0) -> 0
B12: CTD | C12: =(SUMIF($G$2:$G$31,B12,$I$2:$I$31))+(SUMIF($G$35:$G$41,B12,$H$35:$H$41)) -> 0 | R12: =IF(vend18[[#This Row],[Nº Venda]]>1,1,0) -> 0
B13: CTC | C13: =(SUMIF($G$2:$G$31,B13,$I$2:$I$31))+(SUMIF($G$35:$G$41,B13,$H$35:$H$41)) -> 0 | K13: OS Entregue no Dia | R13: =IF(vend18[[#This Row],[Nº Venda]]>1,1,0) -> 0
B14: PCTC | C14: =(SUMIF($G$2:$G$31,B14,$I$2:$I$31))+(SUMIF($G$35:$G$41,B14,$H$35:$H$41)) -> 0 | K14: OS | L14: Vendedor | M14: CARNE | R14: =IF(vend18[[#This Row],[Nº Venda]]>1,1,0) -> 0
B15: PIX | C15: =(SUMIF($G$2:$G$31,B15,$I$2:$I$31))+(SUMIF($G$35:$G$41,B15,$H$35:$H$41)) -> 0 | K15: 3723 | L15: ROGÉRIO | M15: Não | R15: =IF(vend18[[#This Row],[Nº Venda]]>1,1,0) -> 0
B16: Total | C16: =SUM(C11:C15) -> 0 | R16: =IF(vend18[[#This Row],[Nº Venda]]>1,1,0) -> 0
R17: =IF(vend18[[#This Row],[Nº Venda]]>1,1,0) -> 0
B18: Entrega de Carne | R18: =IF(vend18[[#This Row],[Nº Venda]]>1,1,0) -> 0
B19: =COUNT(entr_carn18[OS]) -> 0 | C19: =SUM(entr_carn18[Valor Total]) -> 0 | R19: =IF(vend18[[#This Row],[Nº Venda]]>1,1,0) -> 0
B20: Total | C20: =SUM(C19:C19) -> 0 | R20: =IF(vend18[[#This Row],[Nº Venda]]>1,1,0) -> 0
B22: Venda | C22: =C5 -> 0
E24: Restante Entrada
E25: Nº Venda | F25: Cliente | G25: Forma de Pgto | H25: Valor Venda | I25: Entrada
E33: Recebimento de Carnê | K33: Entrega de Carne
E34: OS | F34: Cliente | G34: Forma de Pgto | H34: Valor Parcela | I34: Nº Parcela | K34: OS | L34: Parcelas | M34: Valor Total
Q40: Total de OS | R40: =SUM(R6:R21) -> 0

Sheet 19
B1: ='18'!B1+1 -> 45554
B2: Fechamento Diário do Caixa
B4: Saldo Inicial | C4: 0 | E4: Vendas | K4: Despesas
B5: Vendas | C5: =SUMIF(I6:I31,">0",H6:H31) -> 495 | E5: Nº Venda | F5: Cliente | G5: Forma de Pgto | H5: Valor Venda | I5: Entrada | K5: Descrição | L5: Tipo de Pagto | M5: Valor
B6: Entrada | C6: =SUM(I6:I41) -> 774 | E6: 3725 | F6: PABLO FERREIRA | G6: PIX | H6: 495 | I6: 100 | R6: =IF(vend19[[#This Row],[Nº Venda]]>1,1,0) -> 1
B7: Despesas | C7: =SUM(M6:M11) -> 0 | R7: =IF(vend19[[#This Row],[Nº Venda]]>1,1,0) -> 0
B8: Total entrada | C8: =SUM(C6:C7) -> 774 | R8: =IF(vend19[[#This Row],[Nº Venda]]>1,1,0) -> 0
R9: =IF(vend19[[#This Row],[Nº Venda]]>1,1,0) -> 0
B10: Tipos de Pagtos | R10: =IF(vend19[[#This Row],[Nº Venda]]>1,1,0) -> 0
B11: DN | C11: =(SUMIF($G$2:$G$31,B11,$I$2:$I$31))+(SUMIF($G$35:$G$41,B11,$H$35:$H$41)) -> 0 | O11: =IF(C16=0,0,1) -> 1 | R11: =IF(vend19[[#This Row],[Nº Venda]]>1,1,0) -> 0
B12: CTD | C12: =(SUMIF($G$2:$G$31,B12,$I$2:$I$31))+(SUMIF($G$35:$G$41,B12,$H$35:$H$41)) -> 14 | R12: =IF(vend19[[#This Row],[Nº Venda]]>1,1,0) -> 0
B13: CTC | C13: =(SUMIF($G$2:$G$31,B13,$I$2:$I$31))+(SUMIF($G$35:$G$41,B13,$H$35:$H$41)) -> 660 | K13: OS Entregue no Dia | R13: =IF(vend19[[#This Row],[Nº Venda]]>1,1,0) -> 0
B14: PCTC | C14: =(SUMIF($G$2:$G$31,B14,$I$2:$I$31))+(SUMIF($G$35:$G$41,B14,$H$35:$H$41)) -> 0 | K14: OS | L14: Vendedor | M14: CARNE | R14: =IF(vend19[[#This Row],[Nº Venda]]>1,1,0) -> 0
B15: PIX | C15: =(SUMIF($G$2:$G$31,B15,$I$2:$I$31))+(SUMIF($G$35:$G$41,B15,$H$35:$H$41)) -> 100 | R15: =IF(vend19[[#This Row],[Nº Venda]]>1,1,0) -> 0
B16: Total | C16: =SUM(C11:C15) -> 774 | R16: =IF(vend19[[#This Row],[Nº Venda]]>1,1,0) -> 0
R17: =IF(vend19[[#This Row],[Nº Venda]]>1,1,0) -> 0
B18: Entrega de Carne | R18: =IF(vend19[[#This Row],[Nº Venda]]>1,1,0) -> 0
B19: =COUNT(entr_carn19[OS]) -> 0 | C19: =SUM(entr_carn19[Valor Total]) -> 0 | R19: =IF(vend19[[#This Row],[Nº Venda]]>1,1,0) -> 0
B20: Total | C20: =SUM(C19:C19) -> 0 | R20: =IF(vend19[[#This Row],[Nº Venda]]>1,1,0) -> 0
B22: Venda | C22: =C5 -> 495
E24: Restante Entrada
E25: Nº Venda | F25: Cliente | G25: Forma de Pgto | H25: Valor Venda | I25: Entrada
E26: 3716 | F26: JORGE NISHIKAWA | G26: CTC | I26: 660
E27: 3716 | F27: JORGE NISHIKAWA | G27: CTD | I27: 14
E33: Recebimento de Carnê | K33: Entrega de Carne
E34: OS | F34: Cliente | G34: Forma de Pgto | H34: Valor Parcela | I34: Nº Parcela | K34: OS | L34: Parcelas | M34: Valor Total
Q40: Total de OS | R40: =SUM(R6:R21) -> 1

Sheet 20
B1: ='19'!B1+1 -> 45555
B2: Fechamento Diário do Caixa
B4: Saldo Inicial | C4: 0 | E4: Vendas | K4: Despesas
B5: Vendas | C5: =SUMIF(I6:I31,">0",H6:H31) -> 629 | E5: Nº Venda | F5: Cliente | G5: Forma de Pgto | H5: Valor Venda | I5: Entrada | K5: Descrição | L5: Tipo de Pagto | M5: Valor
B6: Entrada | C6: =SUM(I6:I41) -> 790 | E6: 3726 | F6: JOAQUIM ANDRE | G6: PIX | H6: 629 | I6: 100 | R6: =IF(vend20[[#This Row],[Nº Venda]]>1,1,0) -> 1
B7: Despesas | C7: =SUM(M6:M11) -> 0 | R7: =IF(vend20[[#This Row],[Nº Venda]]>1,1,0) -> 0
B8: Total entrada | C8: =SUM(C6:C7) -> 790 | R8: =IF(vend20[[#This Row],[Nº Venda]]>1,1,0) -> 0
R9: =IF(vend20[[#This Row],[Nº Venda]]>1,1,0) -> 0
B10: Tipos de Pagtos | R10: =IF(vend20[[#This Row],[Nº Venda]]>1,1,0) -> 0
B11: DN | C11: =(SUMIF($G$2:$G$31,B11,$I$2:$I$31))+(SUMIF($G$35:$G$41,B11,$H$35:$H$41)) -> 500 | O11: =IF(C16=0,0,1) -> 1 | R11: =IF(vend20[[#This Row],[Nº Venda]]>1,1,0) -> 0
B12: CTD | C12: =(SUMIF($G$2:$G$31,B12,$I$2:$I$31))+(SUMIF($G$35:$G$41,B12,$H$35:$H$41)) -> 190 | R12: =IF(vend20[[#This Row],[Nº Venda]]>1,1,0) -> 0
B13: CTC | C13: =(SUMIF($G$2:$G$31,B13,$I$2:$I$31))+(SUMIF($G$35:$G$41,B13,$H$35:$H$41)) -> 0 | K13: OS Entregue no Dia | R13: =IF(vend20[[#This Row],[Nº Venda]]>1,1,0) -> 0
B14: PCTC | C14: =(SUMIF($G$2:$G$31,B14,$I$2:$I$31))+(SUMIF($G$35:$G$41,B14,$H$35:$H$41)) -> 0 | K14: OS | L14: Vendedor | M14: CARNE | R14: =IF(vend20[[#This Row],[Nº Venda]]>1,1,0) -> 0
B15: PIX | C15: =(SUMIF($G$2:$G$31,B15,$I$2:$I$31))+(SUMIF($G$35:$G$41,B15,$H$35:$H$41)) -> 100 | K15: 3710 | L15: ROGÉRIO | M15: Não | R15: =IF(vend20[[#This Row],[Nº Venda]]>1,1,0) -> 0
B16: Total | C16: =SUM(C11:C15) -> 790 | K16: 3724 | L16: ROGÉRIO | M16: Não | R16: =IF(vend20[[#This Row],[Nº Venda]]>1,1,0) -> 0
K17: 3702 | L17: ROGÉRIO | M17: Não | R17: =IF(vend20[[#This Row],[Nº Venda]]>1,1,0) -> 0
B18: Entrega de Carne | R18: =IF(vend20[[#This Row],[Nº Venda]]>1,1,0) -> 0
B19: =COUNT(entr_carn20[OS]) -> 0 | C19: =SUM(entr_carn20[Valor Total]) -> 0 | R19: =IF(vend20[[#This Row],[Nº Venda]]>1,1,0) -> 0
B20: Total | C20: =SUM(C19:C19) -> 0 | R20: =IF(vend20[[#This Row],[Nº Venda]]>1,1,0) -> 0
B22: Venda | C22: =C5 -> 629
E24: Restante Entrada
E25: Nº Venda | F25: Cliente | G25: Forma de Pgto | H25: Valor Venda | I25: Entrada
E26: 3702 | F26: DORALICE BORGES | G26: CTD | I26: 190
E27: 3702 | F27: DORALICE BORGES | G27: DN | I27: 500
E33: Recebimento de Carnê | K33: Entrega de Carne
E34: OS | F34: Cliente | G34: Forma de Pgto | H34: Valor Parcela | I34: Nº Parcela | K34: OS | L34: Parcelas | M34: Valor Total
Q40: Total de OS | R40: =SUM(R6:R21) -> 1

Sheet 21
B1: ='20'!B1+1 -> 45556
B2: Fechamento Diário do Caixa
B4: Saldo Inicial | C4: 0 | E4: Vendas | K4: Despesas
B5: Vendas | C5: =SUMIF(I6:I31,">0",H6:H31) -> 0 | E5: Nº Venda | F5: Cliente | G5: Forma de Pgto | H5: Valor Venda | I5: Entrada | K5: Descrição | L5: Tipo de Pagto | M5: Valor
B6: Entrada | C6: =SUM(I6:I41) -> 0 | R6: =IF(vend21[[#This Row],[Nº Venda]]>1,1,0) -> 0
B7: Despesas | C7: =SUM(M6:M11) -> 0 | R7: =IF(vend21[[#This Row],[Nº Venda]]>1,1,0) -> 0
B8: Total entrada | C8: =SUM(C6:C7) -> 0 | R8: =IF(vend21[[#This Row],[Nº Venda]]>1,1,0) -> 0
R9: =IF(vend21[[#This Row],[Nº Venda]]>1,1,0) -> 0
B10: Tipos de Pagtos | R10: =IF(vend21[[#This Row],[Nº Venda]]>1,1,0) -> 0
B11: DN | C11: =(SUMIF($G$2:$G$31,B11,$I$2:$I$31))+(SUMIF($G$35:$G$41,B11,$H$35:$H$41)) -> 0 | O11: =IF(C16=0,0,1) -> 0 | R11: =IF(vend21[[#This Row],[Nº Venda]]>1,1,0) -> 0
B12: CTD | C12: =(SUMIF($G$2:$G$31,B12,$I$2:$I$31))+(SUMIF($G$35:$G$41,B12,$H$35:$H$41)) -> 0 | R12: =IF(vend21[[#This Row],[Nº Venda]]>1,1,0) -> 0
B13: CTC | C13: =(SUMIF($G$2:$G$31,B13,$I$2:$I$31))+(SUMIF($G$35:$G$41,B13,$H$35:$H$41)) -> 0 | K13: OS Entregue no Dia | R13: =IF(vend21[[#This Row],[Nº Venda]]>1,1,0) -> 0
B14: PCTC | C14: =(SUMIF($G$2:$G$31,B14,$I$2:$I$31))+(SUMIF($G$35:$G$41,B14,$H$35:$H$41)) -> 0 | K14: OS | L14: Vendedor | M14: CARNE | R14: =IF(vend21[[#This Row],[Nº Venda]]>1,1,0) -> 0
B15: PIX | C15: =(SUMIF($G$2:$G$31,B15,$I$2:$I$31))+(SUMIF($G$35:$G$41,B15,$H$35:$H$41)) -> 0 | R15: =IF(vend21[[#This Row],[Nº Venda]]>1,1,0) -> 0
B16: Total | C16: =SUM(C11:C15) -> 0 | R16: =IF(vend21[[#This Row],[Nº Venda]]>1,1,0) -> 0
R17: =IF(vend21[[#This Row],[Nº Venda]]>1,1,0) -> 0
B18: Entrega de Carne | R18: =IF(vend21[[#This Row],[Nº Venda]]>1,1,0) -> 0
B19: =COUNT(entr_carn21[OS]) -> 0 | C19: =SUM(entr_carn21[Valor Total]) -> 0 | R19: =IF(vend21[[#This Row],[Nº Venda]]>1,1,0) -> 0
B20: Total | C20: =SUM(C19:C19) -> 0 | R20: =IF(vend21[[#This Row],[Nº Venda]]>1,1,0) -> 0
B22: Venda | C22: =C5 -> 0
E24: Restante Entrada
E25: Nº Venda | F25: Cliente | G25: Forma de Pgto | H25: Valor Venda | I25: Entrada
E33: Recebimento de Carnê | K33: Entrega de Carne
E34: OS | F34: Cliente | G34: Forma de Pgto | H34: Valor Parcela | I34: Nº Parcela | K34: OS | L34: Parcelas | M34: Valor Total
Q40: Total de OS | R40: =SUM(R6:R21) -> 0

Sheet 22
B1: ='21'!B1+1 -> 45557
B2: Fechamento Diário do Caixa
B4: Saldo Inicial | C4: 0 | E4: Vendas | K4: Despesas
B5: Vendas | C5: =SUMIF(I6:I31,">0",H6:H31) -> 0 | E5: Nº Venda | F5: Cliente | G5: Forma de Pgto | H5: Valor Venda | I5: Entrada | K5: Descrição | L5: Tipo de Pagto | M5: Valor
B6: Entrada | C6: =SUM(I6:I41) -> 0 | R6: =IF(vend22[[#This Row],[Nº Venda]]>1,1,0) -> 0
B7: Despesas | C7: =SUM(M6:M11) -> 0 | R7: =IF(vend22[[#This Row],[Nº Venda]]>1,1,0) -> 0
B8: Total entrada | C8: =SUM(C6:C7) -> 0 | R8: =IF(vend22[[#This Row],[Nº Venda]]>1,1,0) -> 0
R9: =IF(vend22[[#This Row],[Nº Venda]]>1,1,0) -> 0
B10: Tipos de Pagtos | R10: =IF(vend22[[#This Row],[Nº Venda]]>1,1,0) -> 0
B11: DN | C11: =(SUMIF($G$2:$G$31,B11,$I$2:$I$31))+(SUMIF($G$35:$G$41,B11,$H$35:$H$41)) -> 0 | O11: =IF(C16=0,0,1) -> 0 | R11: =IF(vend22[[#This Row],[Nº Venda]]>1,1,0) -> 0
B12: CTD | C12: =(SUMIF($G$2:$G$31,B12,$I$2:$I$31))+(SUMIF($G$35:$G$41,B12,$H$35:$H$41)) -> 0 | R12: =IF(vend22[[#This Row],[Nº Venda]]>1,1,0) -> 0
B13: CTC | C13: =(SUMIF($G$2:$G$31,B13,$I$2:$I$31))+(SUMIF($G$35:$G$41,B13,$H$35:$H$41)) -> 0 | K13: OS Entregue no Dia | R13: =IF(vend22[[#This Row],[Nº Venda]]>1,1,0) -> 0
B14: PCTC | C14: =(SUMIF($G$2:$G$31,B14,$I$2:$I$31))+(SUMIF($G$35:$G$41,B14,$H$35:$H$41)) -> 0 | K14: OS | L14: Vendedor | M14: CARNE | R14: =IF(vend22[[#This Row],[Nº Venda]]>1,1,0) -> 0
B15: PIX | C15: =(SUMIF($G$2:$G$31,B15,$I$2:$I$31))+(SUMIF($G$35:$G$41,B15,$H$35:$H$41)) -> 0 | R15: =IF(vend22[[#This Row],[Nº Venda]]>1,1,0) -> 0
B16: Total | C16: =SUM(C11:C15) -> 0 | R16: =IF(vend22[[#This Row],[Nº Venda]]>1,1,0) -> 0
R17: =IF(vend22[[#This Row],[Nº Venda]]>1,1,0) -> 0
B18: Entrega de Carne | R18: =IF(vend22[[#This Row],[Nº Venda]]>1,1,0) -> 0
B19: =COUNT(entr_carn22[OS]) -> 0 | C19: =SUM(entr_carn22[Valor Total]) -> 0 | R19: =IF(vend22[[#This Row],[Nº Venda]]>1,1,0) -> 0
B20: Total | C20: =SUM(C19:C19) -> 0 | R20: =IF(vend22[[#This Row],[Nº Venda]]>1,1,0) -> 0
B22: Venda | C22: =C5 -> 0
E24: Restante Entrada
E25: Nº Venda | F25: Cliente | G25: Forma de Pgto | H25: Valor Venda | I25: Entrada
E33: Recebimento de Carnê | K33: Entrega de Carne
E34: OS | F34: Cliente | G34: Forma de Pgto | H34: Valor Parcela | I34: Nº Parcela | K34: OS | L34: Parcelas | M34: Valor Total
Q40: Total de OS | R40: =SUM(R6:R21) -> 0

Sheet 23
B1: ='22'!B1+1 -> 45558
B2: Fechamento Diário do Caixa
B4: Saldo Inicial | C4: 0 | E4: Vendas | K4: Despesas
B5: Vendas | C5: =SUMIF(I6:I31,">0",H6:H31) -> 3400 | E5: Nº Venda | F5: Cliente | G5: Forma de Pgto | H5: Valor Venda | I5: Entrada | K5: Descrição | L5: Tipo de Pagto | M5: Valor
B6: Entrada | C6: =SUM(I6:I41) -> 550 | E6: 3727 | F6: SILVIA INES TOZZI | G6: CTD | H6: 2100 | I6: 10 | K6: CABO DE INTERNET | L6: DN | M6: 20 | R6: =IF(vend23[[#This Row],[Nº Venda]]>1,1,0) -> 1
B7: Despesas | C7: =SUM(M6:M11) -> 20 | E7: 3728 | F7: WALMIRA P. DE MOURA | G7: DN | H7: 800 | I7: 40 | R7: =IF(vend23[[#This Row],[Nº Venda]]>1,1,0) -> 1
B8: Total entrada | C8: =SUM(C6:C7) -> 570 | E8: 3729 | F8: IRANILDES DE JESUS | G8: CTC | H8: 250 | I8: 250 | R8: =IF(vend23[[#This Row],[Nº Venda]]>1,1,0) -> 1
E9: 3730 | F9: IRANILDES DE JESUS | G9: CTC | H9: 250 | I9: 250 | R9: =IF(vend23[[#This Row],[Nº Venda]]>1,1,0) -> 1
B10: Tipos de Pagtos | R10: =IF(vend23[[#This Row],[Nº Venda]]>1,1,0) -> 0
B11: DN | C11: =(SUMIF($G$2:$G$31,B11,$I$2:$I$31))+(SUMIF($G$35:$G$44,B11,$H$35:$H$44)) -> 40 | O11: =IF(C16=0,0,1) -> 1 | R11: =IF(vend23[[#This Row],[Nº Venda]]>1,1,0) -> 0
B12: CTD | C12: =(SUMIF($G$2:$G$31,B12,$I$2:$I$31))+(SUMIF($G$35:$G$44,B12,$H$35:$H$44)) -> 10 | R12: =IF(vend23[[#This Row],[Nº Venda]]>1,1,0) -> 0
B13: CTC | C13: =(SUMIF($G$2:$G$31,B13,$I$2:$I$31))+(SUMIF($G$35:$G$44,B13,$H$35:$H$44)) -> 500 | K13: OS Entregue no Dia | R13: =IF(vend23[[#This Row],[Nº Venda]]>1,1,0) -> 0
B14: PCTC | C14: =(SUMIF($G$2:$G$31,B14,$I$2:$I$31))+(SUMIF($G$35:$G$44,B14,$H$35:$H$44)) -> 0 | K14: OS | L14: Vendedor | M14: CARNE | R14: =IF(vend23[[#This Row],[Nº Venda]]>1,1,0) -> 0
B15: PIX | C15: =(SUMIF($G$2:$G$31,B15,$I$2:$I$31))+(SUMIF($G$35:$G$44,B15,$H$35:$H$44)) -> 0 | R15: =IF(vend23[[#This Row],[Nº Venda]]>1,1,0) -> 0
B16: Total | C16: =SUM(C11:C15) -> 550 | R16: =IF(vend23[[#This Row],[Nº Venda]]>1,1,0) -> 0
R17: =IF(vend23[[#This Row],[Nº Venda]]>1,1,0) -> 0
B18: Entrega de Carne | R18: =IF(vend23[[#This Row],[Nº Venda]]>1,1,0) -> 0
B19: =COUNT(entr_carn23[OS]) -> 0 | C19: =SUM(entr_carn23[Valor Total]) -> 0 | R19: =IF(vend23[[#This Row],[Nº Venda]]>1,1,0) -> 0
B20: Total | C20: =SUM(C19:C19) -> 0 | R20: =IF(vend23[[#This Row],[Nº Venda]]>1,1,0) -> 0
B22: Venda | C22: =C5 -> 3400
